Workbook

Sheet 預測IC
A1: LSTM
B2: Time | C2: 2013/12 | D2: 2014/01 | E2: 2014/02 | F2: 2014/03 | G2: 2014/04 | H2: 2014/05 | I2: 2014/06 | J2: 2014/07 | K2: 2014/08 | L2: 2014/09 | M2: 2014/10 | N2: 2014/11 | O2: 2014/12 | P2: 2015/01 | Q2: 2015/02 | R2: 2015/03 | S2: 2015/04 | T2: 2015/05 | U2: 2015/06 | V2: 2015/07 | W2: 2015/08 | X2: 2015/09 | Y2: 2015/10 | Z2: 2015/11 | AA2: 2015/12 | AB2: 2016/01 | AC2: 2016/02 | AD2: 2016/03 | AE2: 2016/04 | AF2: 2016/05 | AG2: 2016/06 | AH2: 2016/07 | AI2: 2016/08 | AJ2: 2016/09 | AK2: 2016/10 | AL2: 2016/11 | AM2: 2016/12 | AN2: 2017/01 | AO2: 2017/02 | AP2: 2017/03 | AQ2: 2017/04 | AR2: 2017/05 | AS2: 2017/06 | AT2: 2017/07 | AU2: 2017/08 | AV2: 2017/09 | AW2: 2017/10 | AX2: 2017/11 | AY2: 2017/12 | AZ2: 2018/01 | BA2: 2018/02 | BB2: 2018/03 | BC2: 2018/04 | BD2: 2018/05 | BE2: 2018/06 | BF2: 2018/07 | BG2: 2018/08 | BH2: 2018/09 | BI2: 2018/10 | BJ2: 2018/11 | BK2: 2018/12 | BL2: 2019/01 | BM2: 2019/02 | BN2: 2019/03 | BO2: 2019/04 | BP2: 2019/05 | BQ2: 2019/06 | BR2: 2019/07 | BS2: 2019/08 | BT2: 2019/09 | BU2: 2019/10 | BV2: 2019/11 | BW2: 2019/12 | BX2: 2020/01 | BY2: 2020/02 | BZ2: 2020/03 | CA2: 2020/04 | CB2: 2020/05 | CC2: 2020/06 | CD2: 2020/07 | CE2: 2020/08 | CF2: 2020/09 | CG2: 2020/10 | CH2: 2020/11 | CI2: 2020/12 | CJ2: 2021/01 | CK2: 2021/02 | CL2: 2021/03 | CM2: 2021/04 | CN2: 2021/05 | CO2: 2021/06 | CP2: 2021/07 | CQ2: 2021/08 | CR2: 2021/09 | CS2: 2021/10 | CT2: 2021/11 | CU2: 2021/12 | CV2: 2022/01 | CW2: 2022/02 | CX2: 2022/03 | CY2: 2022/04 | CZ2: 2022/05 | DA2: 2022/06 | DB2: 2022/07 | DC2: 2022/08 | DD2: 2022/09 | DE2: 2022/10 | DF2: 2022/11 | DG2: 2022/12 | DH2: 2023/01 | DI2: 2023/02 | DJ2: 2023/03 | DK2: 2023/04 | DL2: 2023/05 | DM2: 2023/06 | DN2: 2023/07 | DO2: 2023/08 | DP2: 2023/09 | DQ2: 2023/10 | DR2: 2023/11 | DS2: 2023/12 | DT2: 2024/01 | DU2: 2024/02 | DV2: 2024/03 | DW2: 2024/04 | DX2: 2024/05 | DY2: 2024/06 | DZ2: 2024/07 | EA2: 2024/08 | EB2: 2024/09 | EC2: 2024/10 | ED2: 2024/11 | EE2: 2024/12 | EF2: 2025/01 | EG2: 2025/02
B3: bm | C3: 0.021494569 | D3: 0.058087625 | E3: 0.022277532 | F3: 0.0076232916 | G3: 0.039053731 | H3: 0.065416932 | I3: 0.000281999 | J3: 0.0075884922 | K3: 0.074116856 | L3: 0.038932934 | M3: 0.031222356 | N3: 0.046852808 | O3: 0.033031996 | P3: -0.02222164 | Q3: -0.0051742098 | R3: 0.016297245 | S3: 0.089645803 | T3: 0.021271482 | U3: 0.038858928 | V3: 0.046255026 | W3: -0.033824027 | X3: 0.016226593 | Y3: 0.066536836 | Z3: 0.070697069 | AA3: -0.0059164725 | AB3: 0.0083319079 | AC3: 0.055074532 | AD3: 0.060238268 | AE3: 0.057245668 | AF3: 0.054834764 | AG3: -0.022278227 | AH3: -0.00055013085 | AI3: 0.021811854 | AJ3: 0.047870025 | AK3: -0.0082023181 | AL3: 0.025912138 | AM3: 0.025353372 | AN3: 0.014185794 | AO3: -0.032123089 | AP3: 0.021181002 | AQ3: 0.040065788 | AR3: 0.049255453 | AS3: 0.075326733 | AT3: 0.032457579 | AU3: 0.055688687 | AV3: 0.037392937 | AW3: 0.05450923 | AX3: 0.049577698 | AY3: 0.024729123 | AZ3: 0.031866461 | BA3: 0.05522158 | BB3: -0.019637225 | BC3: 0.076550268 | BD3: 0.031304825 | BE3: 0.051070344 | BF3: 0.043678727 | BG3: 0.055844154 | BH3: 0.042737655 | BI3: 0.029171534 | BJ3: 0.043696996 | BK3: 0.035036448 | BL3: 0.031556074 | BM3: 0.033252038 | BN3: 0.068805762 | BO3: 0.030356387 | BP3: 0.012893802 | BQ3: 0.020890445 | BR3: 0.011343209 | BS3: 0.038320299 | BT3: 0.025377579 | BU3: 0.047802065 | BV3: 0.07347253 | BW3: 0.10928106 | BX3: 0.036029756 | BY3: 0.023720546 | BZ3: 0.095607609 | CA3: 0.01821726 | CB3: 0.041878186 | CC3: 0.091926932 | CD3: 0.036699317 | CE3: 0.014055183 | CF3: 0.03517158 | CG3: 0.018634332 | CH3: 0.035546198 | CI3: 0.11597301 | CJ3: 0.036054283 | CK3: 0.019535236 | CL3: 0.042658728 | CM3: 0.098837614 | CN3: 0.010329253 | CO3: 0.024509367 | CP3: 0.0016102889 | CQ3: -0.063167043 | CR3: -0.00030367664 | CS3: 0.035372086 | CT3: 0.025477629 | CU3: 0.068784669 | CV3: 0.028049543 | CW3: 0.034555428 | CX3: 0.036761697 | CY3: 0.034295771 | CZ3: 0.034676019 | DA3: 0.066585951 | DB3: 0.055797953 | DC3: 0.034665983 | DD3: 0.089065865 | DE3: 0.061000079 | DF3: 0.0089102071 | DG3: 0.020509727 | DH3: 0.0074153906 | DI3: 0.034754626 | DJ3: -0.001059274 | DK3: 0.016924936 | DL3: 0.06108705 | DM3: -0.0057382337 | DN3: 0.045953296 | DO3: 0.018484823 | DP3: 0.031688698 | DQ3: 0.014766447 | DR3: 0.053203873 | DS3: 0.044875108 | DT3: 0.037542205 | DU3: 0.041164089 | DV3: 0.031495519 | DW3: 0.040104918 | DX3: 0.036577147 | DY3: 0.01389249 | DZ3: -0.089294262 | EA3: 0.048276339 | EB3: -0.018393256 | EC3: 0.1431451 | ED3: 0.044307247 | EE3: 0.059985425 | EF3: 0.027855758
B4: size | C4: -0.036761295 | D4: -0.025005475 | E4: -0.029296797 | F4: -0.02575282 | G4: -0.023844622 | H4: -0.031282429 | I4: -0.037815679 | J4: -0.017993957 | K4: -0.040390667 | L4: 0.023429023 | M4: -0.029016269 | N4: -0.032377996 | O4: -0.042524599 | P4: -0.037011519 | Q4: -0.039130412 | R4: -0.034647129 | S4: -0.033092748 | T4: -0.035924137 | U4: -0.034556545 | V4: -0.06285955 | W4: -0.033894949 | X4: -0.036156278 | Y4: -0.034599196 | Z4: -0.03322538 | AA4: -0.035133515 | AB4: -0.016098393 | AC4: -0.037427299 | AD4: -0.033796575 | AE4: -0.035489157 | AF4: -0.034209836 | AG4: -0.035171721 | AH4: -0.037516236 | AI4: -0.03832987 | AJ4: -0.033628419 | AK4: -0.03689637 | AL4: -0.035734512 | AM4: -0.035891693 | AN4: -0.037137847 | AO4: -0.041066829 | AP4: -0.037848193 | AQ4: -0.037976962 | AR4: 0.021341613 | AS4: -0.034798242 | AT4: -0.034050398 | AU4: -0.0063330336 | AV4: -0.048375942 | AW4: -0.036974024 | AX4: -0.025687609 | AY4: -0.030264335 | AZ4: -0.027165379 | BA4: -0.034559529 | BB4: -0.024865931 | BC4: -0.024013266 | BD4: -0.044926047 | BE4: -0.025099505 | BF4: -0.042518422 | BG4: -0.040340085 | BH4: -0.045496903 | BI4: -0.033084229 | BJ4: -0.034715328 | BK4: -0.03801471 | BL4: -0.021968897 | BM4: -0.037516344 | BN4: -0.017855197 | BO4: -0.032257199 | BP4: -0.03397505 | BQ4: -0.0091880606 | BR4: -0.025420915 | BS4: -0.030125072 | BT4: -0.014561947 | BU4: -0.033056311 | BV4: -0.012409049 | BW4: -0.019928811 | BX4: -0.032520987 | BY4: -0.020588364 | BZ4: -0.019920435 | CA4: 0.03069381 | CB4: -0.039390553 | CC4: -0.025789399 | CD4: -0.022566509 | CE4: -0.025649795 | CF4: -0.023216147 | CG4: -0.034563318 | CH4: -0.022808582 | CI4: -0.030658286 | CJ4: -0.026935978 | CK4: -0.027487637 | CL4: -0.010411849 | CM4: -0.031941824 | CN4: -0.024238706 | CO4: -0.01490476 | CP4: -0.027246417 | CQ4: -0.014037012 | CR4: -0.043880332 | CS4: -0.036805749 | CT4: -0.019506088 | CU4: -0.024396855 | CV4: -0.019005928 | CW4: -0.033681344 | CX4: -0.017200269 | CY4: -0.030219225 | CZ4: -0.023723485 | DA4: -0.035130113 | DB4: -0.033781495 | DC4: -0.035217952 | DD4: -0.033825558 | DE4: -0.033913001 | DF4: -0.075045913 | DG4: -0.025657829 | DH4: -0.032165661 | DI4: -0.031393699 | DJ4: -0.035382904 | DK4: -0.031648964 | DL4: -0.03591156 | DM4: -0.032739416 | DN4: -0.04406365 | DO4: -0.038424477 | DP4: -0.03869798 | DQ4: -0.036311068 | DR4: -0.046766933 | DS4: -0.0458919 | DT4: -0.027818196 | DU4: -0.046676248 | DV4: -0.042322345 | DW4: -0.031150103 | DX4: -0.018647574 | DY4: -0.037037484 | DZ4: -0.049548164 | EA4: -0.03733157 | EB4: -0.033544563 | EC4: -0.033939656 | ED4: -0.034055442 | EE4: -0.02932243 | EF4: -0.03497782
B5: mom | C5: -0.23615932 | D5: 0.30206522 | E5: 0.16382697 | F5: -0.62130255 | G5: -0.59304982 | H5: 0.18331669 | I5: -0.13340184 | J5: -0.15845844 | K5: -0.71178311 | L5: 0.21329308 | M5: -0.060562976 | N5: 0.45479259 | O5: 0.40223387 | P5: 0.040549103 | Q5: 0.43694466 | R5: -0.11541748 | S5: 0.10439617 | T5: -0.69569945 | U5: 0.050960947 | V5: 0.41305313 | W5: 0.2093827 | X5: -0.53402328 | Y5: -0.2385771 | Z5: 0.21657211 | AA5: -0.035983704 | AB5: 0.54654592 | AC5: -0.13678865 | AD5: 0.18661855 | AE5: 0.017126594 | AF5: 0.28047934 | AG5: -0.11216326 | AH5: 0.076471277 | AI5: 0.38649157 | AJ5: -0.053298142 | AK5: -0.21042225 | AL5: 0.09612564 | AM5: -0.44994819 | AN5: -0.18455184 | AO5: 0.21023896 | AP5: 0.55138236 | AQ5: 0.66285706 | AR5: 0.12583865 | AS5: -0.13164969 | AT5: -0.39592683 | AU5: 0.2372485 | AV5: -0.31184641 | AW5: -0.12641762 | AX5: 0.2149657 | AY5: -0.29770628 | AZ5: 0.14278762 | BA5: 0.47257468 | BB5: -0.072701506 | BC5: 0.45788476 | BD5: -0.11817045 | BE5: 0.1402144 | BF5: -0.02914623 | BG5: 0.054493379 | BH5: 0.001622027 | BI5: -0.1644803 | BJ5: 0.19206786 | BK5: 0.62006408 | BL5: 0.15779069 | BM5: -0.085973017 | BN5: 0.14220436 | BO5: 0.42143568 | BP5: -0.033276726 | BQ5: 0.17931992 | BR5: -0.1277799 | BS5: 0.097982287 | BT5: 0.28167909 | BU5: 0.0066495552 | BV5: -0.50387645 | BW5: -0.1925054 | BX5: -0.069034271 | BY5: 0.15446532 | BZ5: -0.36204326 | CA5: 0.082590386 | CB5: 0.21218678 | CC5: -0.062723942 | CD5: -0.030481087 | CE5: 0.54791367 | CF5: -0.1075777 | CG5: 0.038016949 | CH5: -0.19324093 | CI5: -0.12518318 | CJ5: -0.042053327 | CK5: -0.12538302 | CL5: -0.25265124 | CM5: -0.21032579 | CN5: 0.090569407 | CO5: 0.33166918 | CP5: 0.50127995 | CQ5: -0.24841265 | CR5: -0.016883623 | CS5: -0.099309795 | CT5: -0.11802272 | CU5: -0.15861692 | CV5: -0.71324062 | CW5: -0.0072468035 | CX5: 0.29018754 | CY5: 0.054072615 | CZ5: -0.10719351 | DA5: 0.044039391 | DB5: -0.073041812 | DC5: -0.60419607 | DD5: 0.39677462 | DE5: -0.072055139 | DF5: 0.043998342 | DG5: -0.031144226 | DH5: -0.3217777 | DI5: -0.28737813 | DJ5: 0.14427696 | DK5: -0.47954777 | DL5: -0.10485175 | DM5: 0.29051229 | DN5: 0.1066981 | DO5: 0.37107188 | DP5: 0.15711103 | DQ5: 0.78479344 | DR5: -0.051778618 | DS5: -0.13680993 | DT5: 0.060407959 | DU5: 0.053334836 | DV5: 0.17520425 | DW5: 0.33214319 | DX5: 0.078800529 | DY5: -0.34528133 | DZ5: 0.10926828 | EA5: -0.090946242 | EB5: -0.050370201 | EC5: 0.080373406 | ED5: -0.03828891 | EE5: 0.21982145 | EF5: 0.25723559
A6: 選絕對值最大 | C6: {=MATCH(MAX(ABS(C3:C5)), ABS(C3:C5), 0)} -> 3 | D6: {=MATCH(MAX(ABS(D3:D5)), ABS(D3:D5), 0)} -> 3 | E6: {=MATCH(MAX(ABS(E3:E5)), ABS(E3:E5), 0)} -> 3 | F6: {=MATCH(MAX(ABS(F3:F5)), ABS(F3:F5), 0)} -> 3 | G6: {=MATCH(MAX(ABS(G3:G5)), ABS(G3:G5), 0)} -> 3 | H6: {=MATCH(MAX(ABS(H3:H5)), ABS(H3:H5), 0)} -> 3 | I6: {=MATCH(MAX(ABS(I3:I5)), ABS(I3:I5), 0)} -> 3 | J6: {=MATCH(MAX(ABS(J3:J5)), ABS(J3:J5), 0)} -> 3 | ... EG6: {=MATCH(MAX(ABS(EG3:EG5)), ABS(EG3:EG5), 0)} -> 1
C7: =IF(C6=1,"bm",IF(C6=2,"size",IF(C6=3,"mom"))) -> mom | D7: =IF(D6=1,"bm",IF(D6=2,"size",IF(D6=3,"mom"))) -> mom | E7: =IF(E6=1,"bm",IF(E6=2,"size",IF(E6=3,"mom"))) -> mom | F7: =IF(F6=1,"bm",IF(F6=2,"size",IF(F6=3,"mom"))) -> mom | G7: =IF(G6=1,"bm",IF(G6=2,"size",IF(G6=3,"mom"))) -> mom | H7: =IF(H6=1,"bm",IF(H6=2,"size",IF(H6=3,"mom"))) -> mom | I7: =IF(I6=1,"bm",IF(I6=2,"size",IF(I6=3,"mom"))) -> mom | J7: =IF(J6=1,"bm",IF(J6=2,"size",IF(J6=3,"mom"))) -> mom | ... EG7: =IF(EG6=1,"bm",IF(EG6=2,"size",IF(EG6=3,"mom"))) -> bm
C8: =IF(C6=1,C3,IF(C6=2,C4,IF(C6=3,C5))) -> -0.23615932 | D8: =IF(D6=1,D3,IF(D6=2,D4,IF(D6=3,D5))) -> 0.30206522 | E8: =IF(E6=1,E3,IF(E6=2,E4,IF(E6=3,E5))) -> 0.16382697 | F8: =IF(F6=1,F3,IF(F6=2,F4,IF(F6=3,F5))) -> -0.62130255 | G8: =IF(G6=1,G3,IF(G6=2,G4,IF(G6=3,G5))) -> -0.59304982 | H8: =IF(H6=1,H3,IF(H6=2,H4,IF(H6=3,H5))) -> 0.18331669 | I8: =IF(I6=1,I3,IF(I6=2,I4,IF(I6=3,I5))) -> -0.13340184 | J8: =IF(J6=1,J3,IF(J6=2,J4,IF(J6=3,J5))) -> -0.15845844 | ... EG8: =IF(EG6=1,EG3,IF(EG6=2,EG4,IF(EG6=3,EG5))) -> 0
A10: 投資組合 | C10: 公司數 | D10: 964
A11: 等第 | B11: 分數 | C11: 2014/01 | D11: 2014/02 | E11: 2014/03 | F11: 2014/04 | G11: 2014/05 | H11: 2014/06 | I11: 2014/07 | J11: 2014/08 | K11: 2014/09 | L11: 2014/10 | M11: 2014/11 | N11: 2014/12 | O11: 2015/01 | P11: 2015/02 | Q11: 2015/03 | R11: 2015/04 | S11: 2015/05 | T11: 2015/06 | U11: 2015/07 | V11: 2015/08 | W11: 2015/09 | X11: 2015/10 | Y11: 2015/11 | Z11: 2015/12 | AA11: 2016/01 | AB11: 2016/02 | AC11: 2016/03 | AD11: 2016/04 | AE11: 2016/05 | AF11: 2016/06 | AG11: 2016/07 | AH11: 2016/08 | AI11: 2016/09 | AJ11: 2016/10 | AK11: 2016/11 | AL11: 2016/12 | AM11: 2017/01 | AN11: 2017/02 | AO11: 2017/03 | AP11: 2017/04 | AQ11: 2017/05 | AR11: 2017/06 | AS11: 2017/07 | AT11: 2017/08 | AU11: 2017/09 | AV11: 2017/10 | AW11: 2017/11 | AX11: 2017/12 | AY11: 2018/01 | AZ11: 2018/02 | BA11: 2018/03 | BB11: 2018/04 | BC11: 2018/05 | BD11: 2018/06 | BE11: 2018/07 | BF11: 2018/08 | BG11: 2018/09 | BH11: 2018/10 | BI11: 2018/11 | BJ11: 2018/12 | BK11: 2019/01 | BL11: 2019/02 | BM11: 2019/03 | BN11: 2019/04 | BO11: 2019/05 | BP11: 2019/06 | BQ11: 2019/07 | BR11: 2019/08 | BS11: 2019/09 | BT11: 2019/10 | BU11: 2019/11 | BV11: 2019/12 | BW11: 2020/01 | BX11: 2020/02 | BY11: 2020/03 | BZ11: 2020/04 | CA11: 2020/05 | CB11: 2020/06 | CC11: 2020/07 | CD11: 2020/08 | CE11: 2020/09 | CF11: 2020/10 | CG11: 2020/11 | CH11: 2020/12 | CI11: 2021/01 | CJ11: 2021/02 | CK11: 2021/03 | CL11: 2021/04 | CM11: 2021/05 | CN11: 2021/06 | CO11: 2021/07 | CP11: 2021/08 | CQ11: 2021/09 | CR11: 2021/10 | CS11: 2021/11 | CT11: 2021/12 | CU11: 2022/01 | CV11: 2022/02 | CW11: 2022/03 | CX11: 2022/04 | CY11: 2022/05 | CZ11: 2022/06 | DA11: 2022/07 | DB11: 2022/08 | DC11: 2022/09 | DD11: 2022/10 | DE11: 2022/11 | DF11: 2022/12 | DG11: 2023/01 | DH11: 2023/02 | DI11: 2023/03 | DJ11: 2023/04 | DK11: 2023/05 | DL11: 2023/06 | DM11: 2023/07 | DN11: 2023/08 | DO11: 2023/09 | DP11: 2023/10 | DQ11: 2023/11 | DR11: 2023/12 | DS11: 2024/01 | DT11: 2024/02 | DU11: 2024/03 | DV11: 2024/04 | DW11: 2024/05 | DX11: 2024/06 | DY11: 2024/07 | DZ11: 2024/08 | EA11: 2024/09 | EB11: 2024/10 | EC11: 2024/11 | ED11: 2024/12 | EE11: 2025/01 | EF11: 2025/02
A12: 10 | B12: 96 | C12: 0.014499247 | D12: 0.014678551 | E12: -0.0013937245 | F12: 0.055959385 | G12: -0.031947449 | H12: 0.0095992584 | I12: 0.0086581523 | J12: -0.0073897937 | K12: -0.029187998 | L12: 0.008758556 | M12: -0.026889174 | N12: -0.034703354 | O12: 0.027914759 | P12: -0.00025432811 | Q12: 0.0051156834 | R12: -0.013153489 | S12: 0.01105503 | T12: -0.047867716 | U12: -0.0013565231 | V12: 0.0095109537 | W12: -0.028417663 | X12: 0.10964075 | Y12: -0.020598394 | Z12: -0.053152087 | AA12: -0.026918479 | AB12: 0.01073333 | AC12: 0.046772946 | AD12: -0.0025304298 | AE12: -0.037897624 | AF12: -0.052012103 | AG12: 0.0038149304 | AH12: -0.015713034 | AI12: 0.0087937925 | AJ12: 0.018723296 | AK12: 0.016475368 | AL12: -0.04780049 | AM12: -0.016706752 | AN12: -0.026645629 | AO12: 0.014995471 | AP12: 0.0063803695 | AQ12: -0.0016969306 | AR12: 0.022223026 | AS12: -0.019976273 | AT12: -0.072195382 | AU12: 0.0037135364 | AV12: -0.053715631 | AW12: -0.017169705 | AX12: -0.044696012 | AY12: -0.017491322 | AZ12: -0.023614553 | BA12: -0.02643433 | BB12: 0.029036655 | BC12: 0.026690966 | BD12: 0.0082215801 | BE12: -0.035368545 | BF12: 0.067792352 | BG12: 0.033670862 | BH12: -0.024922145 | BI12: 0.043756064 | BJ12: -0.024663126 | BK12: -0.0006573835 | BL12: -0.032129098 | BM12: -0.050305685 | BN12: -0.011575967 | BO12: -0.0024940364 | BP12: -0.026421957 | BQ12: -0.018715509 | BR12: -0.068693615 | BS12: -0.032642855 | BT12: 0.016364783 | BU12: 0.0087815171 | BV12: 0.042282389 | BW12: 0.044477004 | BX12: 0.0069851539 | BY12: 0.058929916 | BZ12: -0.032378726 | CA12: 0.00060368843 | CB12: -0.027173863 | CC12: -0.016770964 | CD12: 0.11093363 | CE12: -0.050816539 | CF12: -0.0080212745 | CG12: -0.04927796 | CH12: 0.016463112 | CI12: 0.035598031 | CJ12: -0.054120067 | CK12: -0.056101441 | CL12: -0.07844028 | CM12: 0.026353951 | CN12: 0.078465204 | CO12: -0.024819785 | CP12: -0.001005022 | CQ12: 0.062684347 | CR12: 0.048146625 | CS12: -0.00097857359 | CT12: 0.0093290632 | CU12: 0.074779529 | CV12: -0.065033306 | CW12: 0.0055479247 | CX12: -0.030752638 | CY12: 0.016420596 | CZ12: 0.012324262 | DA12: 0.0056037841 | DB12: -0.035585283 | DC12: 0.0045013638 | DD12: -0.069960546 | DE12: 0.024737644 | DF12: 0.055485734 | DG12: 0.047394422 | DH12: -0.030803155 | DI12: -0.029979255 | DJ12: 0.041378043 | DK12: -0.0010711986 | DL12: -0.018669833 | DM12: 0.0091434933 | DN12: -0.018541443 | DO12: -0.019030728 | DP12: -0.059408695 | DQ12: 0.074540647 | DR12: 0.018778943 | DS12: -0.046024279 | DT12: 0.024813842 | DU12: 0.045787142 | DV12: -0.016751442 | DW12: 0.0020762117 | DX12: 0.018099137 | DY12: -0.062728222 | DZ12: 0.02003889 | EA12: 0.11312704 | EB12: 0.030525777 | EC12: 0.02665151 | ED12: -0.060508153 | EE12: -0.02821628 | EF12: -0.031810858
A13: 20 | B13: 48 | C13: -0.0074773642 | D13: -0.00545686 | E13: -0.0055236267 | F13: 0.059986527 | G13: -0.012047404 | H13: 0.017388387 | I13: -0.032285992 | J13: -0.023000409 | K13: -0.060326139 | L13: 0.02198047 | M13: -0.0032797582 | N13: -0.043392417 | O13: 0.017422699 | P13: -0.0062776477 | Q13: -0.017456384 | R13: -0.016510711 | S13: -0.006013803 | T13: -0.074234082 | U13: 0.028761331 | V13: 0.0022166399 | W13: -0.030968904 | X13: 0.12112777 | Y13: 0.0066833587 | Z13: -0.081251402 | AA13: -0.047712648 | AB13: 0.015001573 | AC13: 0.0667717 | AD13: -0.020440228 | AE13: -0.042517211 | AF13: -0.073281161 | AG13: -0.0099052077 | AH13: -0.024955207 | AI13: 0.018646046 | AJ13: 0.0017074508 | AK13: 0.03835939 | AL13: -0.049258885 | AM13: 0.014434106 | AN13: -0.029977661 | AO13: -0.0017088467 | AP13: -0.0021107071 | AQ13: -0.0023400742 | AR13: 0.020848044 | AS13: -0.023404964 | AT13: -0.086422915 | AU13: -0.015695418 | AV13: -0.079665976 | AW13: -0.026821238 | AX13: -0.032799832 | AY13: -0.014262204 | AZ13: -0.031220536 | BA13: -0.026188274 | BB13: 0.022547401 | BC13: 0.019110867 | BD13: 0.010962313 | BE13: -0.043773789 | BF13: 0.083929415 | BG13: 0.046566462 | BH13: -0.033944255 | BI13: 0.021601559 | BJ13: -0.024266088 | BK13: -0.0088783959 | BL13: -0.03446004 | BM13: -0.053371769 | BN13: -0.035552713 | BO13: -0.004492405 | BP13: -0.0079511464 | BQ13: 0.0011508192 | BR13: -0.079831457 | BS13: -0.040180514 | BT13: 0.00052107168 | BU13: 0.017706555 | BV13: 0.079930834 | BW13: 0.075714006 | BX13: 0.00074563881 | BY13: 0.039201957 | BZ13: -0.06597673 | CA13: 0.011020985 | CB13: -0.02601738 | CC13: -0.012530912 | CD13: 0.10508583 | CE13: -0.07943787 | CF13: 0.012043667 | CG13: -0.058014968 | CH13: 0.0040295061 | CI13: 0.014533303 | CJ13: -0.054810181 | CK13: -0.065687126 | CL13: -0.072724175 | CM13: 0.014010735 | CN13: 0.10099417 | CO13: -0.035334344 | CP13: 0.020576996 | CQ13: 0.071178865 | CR13: 0.064380649 | CS13: -0.0095676537 | CT13: -0.00040854012 | CU13: 0.10709096 | CV13: -0.077656051 | CW13: 0.0059770309 | CX13: -0.030582841 | CY13: 0.041201752 | CZ13: 0.0048982162 | DA13: -0.0055836769 | DB13: -0.061356185 | DC13: 0.014149867 | DD13: -0.068977059 | DE13: 0.022441996 | DF13: 0.083122187 | DG13: 0.07133576 | DH13: -0.038806517 | DI13: -0.02957042 | DJ13: 0.0070211236 | DK13: 0.023400892 | DL13: -0.022050691 | DM13: -0.011655894 | DN13: -0.012775889 | DO13: -0.044325139 | DP13: -0.058032309 | DQ13: 0.087129011 | DR13: 0.013771209 | DS13: -0.029915194 | DT13: 0.029845809 | DU13: 0.023698854 | DV13: -0.0098528048 | DW13: 0.013098229 | DX13: 0.02322961 | DY13: -0.0095046248 | DZ13: 0.030285251 | EA13: 0.12446896 | EB13: 0.057205293 | EC13: 0.041659753 | ED13: -0.065682094 | EE13: -0.03586748 | EF13: -0.047879265
A14: 50 | B14: 19 | C14: -0.033228978 | D14: -0.14164365 | E14: -0.047920746 | F14: 0.060341905 | G14: -0.05365663 | H14: -0.011508261 | I14: -0.030100135 | J14: -0.045231574 | K14: -0.050827466 | L14: 0.056271085 | M14: 0.019021714 | N14: -0.057369427 | O14: 0.0014944079 | P14: 0.006541421 | Q14: -0.079297658 | R14: 0.017762309 | S14: -0.024806746 | T14: -0.035019555 | U14: 0.030556169 | V14: -0.0524213 | W14: -0.047795003 | X14: 0.1866857 | Y14: 0.055190991 | Z14: -0.11670403 | AA14: -0.099905879 | AB14: 0.027335979 | AC14: -0.0030865623 | AD14: -0.069874592 | AE14: -0.10641207 | AF14: -0.096080095 | AG14: -0.025329295 | AH14: -0.080952184 | AI14: -0.035462644 | AJ14: -0.024505575 | AK14: 0.077475339 | AL14: -0.051230183 | AM14: 0.042463856 | AN14: -0.019132523 | AO14: -0.038044353 | AP14: 0.0083517816 | AQ14: 0.02973338 | AR14: 0.0075826917 | AS14: 0.0066693384 | AT14: -0.07940348 | AU14: -0.057421613 | AV14: -0.066258749 | AW14: -0.053928681 | AX14: -0.019370213 | AY14: -0.0016905718 | AZ14: -0.06107058 | BA14: -0.066889832 | BB14: 0.11031125 | BC14: -0.028505683 | BD14: 0.054089653 | BE14: -0.07008177 | BF14: 0.040770522 | BG14: 0.041374264 | BH14: -0.093750084 | BI14: -0.041031068 | BJ14: -0.068604196 | BK14: -0.03369142 | BL14: -0.059996896 | BM14: -0.046278325 | BN14: -0.02608796 | BO14: -0.013238241 | BP14: 0.050332283 | BQ14: 0.050884482 | BR14: -0.10005242 | BS14: -0.030332724 | BT14: -0.030726476 | BU14: -0.0088548354 | BV14: 0.10798163 | BW14: 0.13089751 | BX14: -0.014335295 | BY14: -0.04260449 | BZ14: -0.093374678 | CA14: 0.096516325 | CB14: -0.05947706 | CC14: -0.012794081 | CD14: 0.09801671 | CE14: -0.11435311 | CF14: 0.04287741 | CG14: -0.057320664 | CH14: 0.04887967 | CI14: 0.014701612 | CJ14: -0.017796116 | CK14: -0.053792087 | CL14: -0.13734357 | CM14: -0.0050971069 | CN14: 0.17459567 | CO14: -0.078763759 | CP14: 0.093659358 | CQ14: 0.0322279 | CR14: 0.062640655 | CS14: 0.0044126335 | CT14: 0.0096618863 | CU14: 0.101545 | CV14: -0.15139684 | CW14: -0.0033983825 | CX14: -0.090639227 | CY14: 0.09636113 | CZ14: 0.0103014 | DA14: -0.024304289 | DB14: -0.090239014 | DC14: 0.042998542 | DD14: -0.079205352 | DE14: 0.062526924 | DF14: 0.20156284 | DG14: 0.087324806 | DH14: -0.0084132404 | DI14: -0.040659135 | DJ14: 0.0087940294 | DK14: 0.077413284 | DL14: -0.040754872 | DM14: -0.032421917 | DN14: 0.044935741 | DO14: -0.070288549 | DP14: -0.062914808 | DQ14: 0.071172565 | DR14: 0.052622519 | DS14: -0.089437754 | DT14: 0.0077542903 | DU14: 0.11891759 | DV14: -0.045153224 | DW14: 0.031091969 | DX14: 0.027689697 | DY14: -0.047660987 | DZ14: 0.021697589 | EA14: 0.062912685 | EB14: 0.078179831 | EC14: 0.0060793821 | ED14: -0.10262971 | EE14: -0.042505739 | EF14: -0.084951384
A15: 100 | B15: 10 | C15: -0.036350225 | D15: -0.27303487 | E15: -0.095344605 | F15: -0.034921437 | G15: -0.034403921 | H15: -0.0012437261 | I15: -0.079293091 | J15: -0.06212121 | K15: -0.094514798 | L15: 0.081171061 | M15: 0.0021330164 | N15: -0.10979619 | O15: -0.012270796 | P15: 0.02189657 | Q15: -0.045898731 | R15: 0.12669106 | S15: 0.08548789 | T15: -0.045891077 | U15: 0.07819939 | V15: -0.11012701 | W15: -0.050671424 | X15: 0.21118633 | Y15: 0.052028798 | Z15: -0.062704119 | AA15: -0.16085038 | AB15: 0.022166401 | AC15: 0.0043176688 | AD15: -0.081713375 | AE15: -0.097797684 | AF15: -0.13772629 | AG15: -0.044324544 | AH15: -0.13296737 | AI15: -0.024849257 | AJ15: -0.033717922 | AK15: 0.069361451 | AL15: -0.032360174 | AM15: 0.068631207 | AN15: -0.03550046 | AO15: -0.05138452 | AP15: 0.090555375 | AQ15: 0.036453319 | AR15: 0.017733826 | AS15: 0.048733221 | AT15: -0.070989813 | AU15: -0.077174077 | AV15: -0.037297929 | AW15: -0.091727473 | AX15: -0.081360566 | AY15: -0.029005659 | AZ15: -0.067846329 | BA15: 0.015151738 | BB15: 0.19771315 | BC15: -0.030936692 | BD15: 0.0096474811 | BE15: -0.041397971 | BF15: 0.047662979 | BG15: 0.0024895387 | BH15: -0.054709226 | BI15: -0.021159114 | BJ15: -0.13011026 | BK15: 0.045604932 | BL15: -0.059755421 | BM15: -0.048219004 | BN15: -0.063720727 | BO15: 0.069555614 | BP15: 0.051616854 | BQ15: 0.043431253 | BR15: -0.12376214 | BS15: -0.011865911 | BT15: -0.059850936 | BU15: 0.01947642 | BV15: 0.10464004 | BW15: 0.29887899 | BX15: -0.053851569 | BY15: -0.12602357 | BZ15: -0.20472002 | CA15: 0.092920534 | CB15: -0.092684106 | CC15: -0.15231827 | CD15: 0.12015208 | CE15: -0.097490745 | CF15: 0.04134943 | CG15: -0.085886022 | CH15: 0.081342608 | CI15: -0.0025109388 | CJ15: -0.040671717 | CK15: -0.095640748 | CL15: -0.16165447 | CM15: -0.046626536 | CN15: 0.14314982 | CO15: -0.10697924 | CP15: 0.13009875 | CQ15: -0.02496336 | CR15: 0.024374319 | CS15: -0.0064830511 | CT15: -0.0049416704 | CU15: 0.12404993 | CV15: -0.18261155 | CW15: -0.01248466 | CX15: -0.15238778 | CY15: 0.092947904 | CZ15: 0.023763335 | DA15: -0.026375835 | DB15: -0.2096634 | DC15: 0.067692432 | DD15: -0.014506726 | DE15: 0.057163635 | DF15: 0.30272045 | DG15: 0.11309156 | DH15: 0.00093841477 | DI15: -0.054108319 | DJ15: 0.060023777 | DK15: 0.072188598 | DL15: 0.0003039932 | DM15: -0.039052117 | DN15: 0.081730712 | DO15: -0.034104416 | DP15: -0.13430495 | DQ15: 0.037038689 | DR15: 0.070010567 | DS15: -0.0095715425 | DT15: 0.05271879 | DU15: 0.18864064 | DV15: -0.046727729 | DW15: 0.050448237 | DX15: 0.02154567 | DY15: 0.083673635 | DZ15: 0.036596498 | EA15: 0.04345122 | EB15: 0.08808745 | EC15: 0.066081856 | ED15: -0.11335706 | EE15: -0.04934418 | EF15: -0.15968344
A16: 107 | B16: 9 | C16: -0.03943539 | D16: -0.23433798 | E16: -0.086704171 | F16: -0.078715472 | G16: -0.0081465507 | H16: -0.00064934946 | I16: -0.10921796 | J16: -0.073104639 | K16: -0.086420892 | L16: 0.085161604 | M16: 0.013987436 | N16: -0.1202425 | O16: -0.028587077 | P16: 0.0081881795 | Q16: -0.081478643 | R16: 0.10310969 | S16: 0.10985904 | T16: -0.038406673 | U16: 0.091471935 | V16: -0.075571486 | W16: -0.10163136 | X16: 0.24053196 | Y16: 0.050278834 | Z16: -0.043010058 | AA16: -0.16615889 | AB16: 0.032295414 | AC16: -0.012765448 | AD16: -0.053136056 | AE16: -0.09650236 | AF16: -0.14791561 | AG16: -0.04377616 | AH16: -0.14840163 | AI16: -0.033383256 | AJ16: -0.048120479 | AK16: 0.037433453 | AL16: -0.0054397026 | AM16: 0.052145732 | AN16: -0.022032518 | AO16: -0.041090153 | AP16: 0.094724683 | AQ16: 0.054497753 | AR16: 0.034371979 | AS16: 0.052642718 | AT16: -0.12256404 | AU16: -0.082090272 | AV16: -0.052080835 | AW16: -0.10898494 | AX16: -0.10062133 | AY16: -0.019601854 | AZ16: -0.088150182 | BA16: -0.033911562 | BB16: 0.22547356 | BC16: -0.038999392 | BD16: -0.016936218 | BE16: -0.061197644 | BF16: 0.064268054 | BG16: 0.013473282 | BH16: -0.062040026 | BI16: -0.04898994 | BJ16: -0.096566804 | BK16: 0.051371625 | BL16: -0.061173599 | BM16: -0.039497985 | BN16: -0.06130475 | BO16: 0.074216862 | BP16: 0.057750061 | BQ16: 0.023690719 | BR16: -0.13058297 | BS16: -0.032006987 | BT16: -0.046660882 | BU16: 0.05776511 | BV16: 0.036585638 | BW16: 0.31797083 | BX16: -0.066559519 | BY16: -0.13255841 | BZ16: -0.13158185 | CA16: 0.13046988 | CB16: -0.11586555 | CC16: -0.15907251 | CD16: 0.15507127 | CE16: -0.12131041 | CF16: 0.052800084 | CG16: -0.061727878 | CH16: 0.050448725 | CI16: -0.0042406681 | CJ16: -0.029703385 | CK16: -0.08842269 | CL16: -0.19674044 | CM16: -0.0069997267 | CN16: 0.16035992 | CO16: -0.13464021 | CP16: 0.11115145 | CQ16: -0.02033378 | CR16: 0.025228657 | CS16: -0.040852188 | CT16: -0.025557378 | CU16: 0.1354717 | CV16: -0.17225152 | CW16: -0.0091941595 | CX16: -0.16226598 | CY16: 0.081280638 | CZ16: 0.032724822 | DA16: -0.029804794 | DB16: -0.23166535 | DC16: 0.083264052 | DD16: -0.03174371 | DE16: 0.0345524 | DF16: 0.32557955 | DG16: 0.12637192 | DH16: -0.003978832 | DI16: -0.045399498 | DJ16: 0.070955052 | DK16: 0.057685769 | DL16: 0.021872874 | DM16: -0.018910374 | DN16: 0.11588673 | DO16: -0.046563866 | DP16: -0.16033399 | DQ16: 0.047070156 | DR16: 0.055191252 | DS16: 0.010423024 | DT16: 0.059112975 | DU16: 0.19010824 | DV16: -0.045728317 | DW16: 0.030139112 | DX16: 0.021947728 | DY16: 0.094984864 | DZ16: 0.012649172 | EA16: 0.00042051524 | EB16: 0.1006791 | EC16: 0.063532067 | ED16: -0.11541675 | EE16: -0.059240997 | EF16: -0.15799175
A17: 120 | B17: 8 | C17: -0.038913469 | D17: -0.16854736 | E17: -0.096671109 | F17: -0.080752164 | G17: -0.10538707 | H17: 0.0079428568 | I17: -0.11307752 | J17: -0.048286948 | K17: -0.10156008 | L17: 0.042234791 | M17: -0.014659142 | N17: -0.10927783 | O17: -0.011306676 | P17: 0.013382947 | Q17: -0.10026683 | R17: 0.13642645 | S17: 0.11905439 | T17: -0.023342586 | U17: 0.062405902 | V17: -0.097259656 | W17: -0.12866725 | X17: 0.23798943 | Y17: 0.073623131 | Z17: -0.048325674 | AA17: -0.19128344 | AB17: 0.044538303 | AC17: -0.020086255 | AD17: -0.049777375 | AE17: -0.12715842 | AF17: -0.12028632 | AG17: -0.062640142 | AH17: -0.14702489 | AI17: -0.057037976 | AJ17: -0.061612619 | AK17: 0.02937589 | AL17: -0.027018182 | AM17: 0.09335171 | AN17: 0.0064561354 | AO17: -0.076694528 | AP17: 0.09341758 | AQ17: 0.061277252 | AR17: 0.045802626 | AS17: 0.058802957 | AT17: -0.12707179 | AU17: -0.11569961 | AV17: -0.058529449 | AW17: -0.07618961 | AX17: -0.097619105 | AY17: -0.015478046 | AZ17: -0.070494231 | BA17: -0.038771615 | BB17: 0.23044204 | BC17: -0.027292824 | BD17: 0.01347483 | BE17: -0.044110253 | BF17: 0.055197497 | BG17: -0.035394236 | BH17: -0.048737994 | BI17: -0.0807384 | BJ17: -0.097868244 | BK17: 0.016751327 | BL17: -0.034152447 | BM17: -0.029059011 | BN17: -0.053470181 | BO17: 0.085087298 | BP17: 0.060638147 | BQ17: 0.025601716 | BR17: -0.11502235 | BS17: -0.020906018 | BT17: -0.05265016 | BU17: 0.071127819 | BV17: 0.038240957 | BW17: 0.20833683 | BX17: -0.08264099 | BY17: -0.14247738 | BZ17: -0.066857531 | CA17: 0.13087785 | CB17: -0.10916584 | CC17: -0.17495797 | CD17: 0.17295974 | CE17: -0.11249459 | CF17: 0.058238797 | CG17: -0.074714989 | CH17: 0.032969072 | CI17: -0.0037017834 | CJ17: -0.020950827 | CK17: -0.083955848 | CL17: -0.1368391 | CM17: 0.0016699729 | CN17: 0.17653128 | CO17: -0.13741288 | CP17: 0.10822138 | CQ17: 0.051907103 | CR17: 0.02300583 | CS17: -0.031345818 | CT17: -0.01733928 | CU17: 0.15535189 | CV17: -0.15147138 | CW17: -0.019761854 | CX17: -0.12500986 | CY17: 0.075608913 | CZ17: 0.031592684 | DA17: -0.043895859 | DB17: -0.22431697 | DC17: 0.098849393 | DD17: -0.029155421 | DE17: 0.024124863 | DF17: 0.35222555 | DG17: 0.12321247 | DH17: -0.012653895 | DI17: -0.035044536 | DJ17: 0.12892506 | DK17: 0.068118111 | DL17: 0.0039297317 | DM17: -0.037227476 | DN17: 0.10647996 | DO17: -0.065250544 | DP17: -0.14203416 | DQ17: 0.072654005 | DR17: 0.055884815 | DS17: 0.0065055362 | DT17: 0.059811935 | DU17: 0.1595551 | DV17: -0.045148836 | DW17: 0.048235393 | DX17: -0.02303518 | DY17: 0.12601054 | DZ17: -0.0047910532 | EA17: -0.0046325242 | EB17: 0.10728533 | EC17: 0.016425217 | ED17: -0.12832444 | EE17: -0.0642787 | EF17: -0.13981485
A18: 137 | B18: 7 | C18: -0.059146798 | D18: -0.18401889 | E18: -0.10047562 | F18: -0.11938296 | G18: -0.10831637 | H18: 0.0086222278 | I18: -0.12862656 | J18: -0.091173232 | K18: -0.13564789 | L18: 0.050758207 | M18: -0.029051464 | N18: -0.14120749 | O18: 0.031737941 | P18: 0.0083280859 | Q18: -0.09305959 | R18: 0.15418919 | S18: 0.14380523 | T18: -0.052309698 | U18: 0.055150343 | V18: -0.12139146 | W18: -0.16613483 | X18: 0.21512106 | Y18: 0.10387924 | Z18: -0.051469726 | AA18: -0.17257066 | AB18: 0.062644805 | AC18: 0.0013654205 | AD18: -0.072443789 | AE18: -0.14352924 | AF18: -0.15054364 | AG18: -0.08171998 | AH18: -0.1630685 | AI18: -0.08142375 | AJ18: -0.070867218 | AK18: 0.022832885 | AL18: -0.032812812 | AM18: 0.096053029 | AN18: -0.0027944178 | AO18: 0.02458428 | AP18: 0.095545793 | AQ18: 0.064154974 | AR18: 0.039002474 | AS18: 0.083253128 | AT18: -0.16638581 | AU18: -0.13889821 | AV18: -0.060235665 | AW18: -0.097766862 | AX18: -0.12606434 | AY18: -0.030189359 | AZ18: -0.051646327 | BA18: -0.03530224 | BB18: 0.31745743 | BC18: 0.027942051 | BD18: 0.0038573503 | BE18: -0.091172853 | BF18: 0.045884536 | BG18: -0.016806241 | BH18: -0.062935384 | BI18: -0.075991094 | BJ18: -0.098533857 | BK18: 0.0009810839 | BL18: -0.055787881 | BM18: -0.028081356 | BN18: -0.042191589 | BO18: 0.062169081 | BP18: 0.062463432 | BQ18: 0.086459691 | BR18: -0.12096182 | BS18: -0.032873257 | BT18: -0.061545323 | BU18: 0.080677444 | BV18: 0.039624426 | BW18: 0.2183755 | BX18: -0.074580863 | BY18: -0.087465268 | BZ18: -0.035347653 | CA18: 0.11432599 | CB18: -0.097387283 | CC18: -0.028173444 | CD18: 0.19371682 | CE18: -0.13007559 | CF18: -0.043957743 | CG18: -0.091609256 | CH18: 0.045365649 | CI18: 0.11505931 | CJ18: 0.0037723665 | CK18: -0.096058032 | CL18: -0.15291394 | CM18: 0.01554875 | CN18: 0.12094313 | CO18: -0.15059751 | CP18: 0.11627032 | CQ18: 0.038242676 | CR18: 0.033743302 | CS18: -0.057690649 | CT18: 0.016272494 | CU18: 0.14456482 | CV18: -0.12702227 | CW18: -0.0084560856 | CX18: -0.15307569 | CY18: 0.093178384 | CZ18: 0.091459213 | DA18: -0.04738094 | DB18: -0.22238211 | DC18: 0.082819707 | DD18: -0.041014187 | DE18: 0.038420587 | DF18: 0.36669201 | DG18: 0.11821709 | DH18: -0.013050033 | DI18: -0.018613248 | DJ18: 0.14619608 | DK18: 0.05725059 | DL18: 0.0038302741 | DM18: -0.0052506787 | DN18: 0.12510868 | DO18: -0.030199017 | DP18: -0.13348647 | DQ18: 0.065749458 | DR18: 0.076840655 | DS18: 0.025385651 | DT18: 0.022601035 | DU18: 0.16258878 | DV18: -0.070527693 | DW18: 0.05797738 | DX18: -0.068177294 | DY18: 0.1657631 | DZ18: -0.043227855 | EA18: -0.0047382972 | EB18: 0.10996435 | EC18: 0.0027641154 | ED18: -0.11047802 | EE18: -0.05301504 | EF18: -0.1549361
A19: 160 | B19: 6 | C19: -0.07386193 | D19: -0.21954287 | E19: -0.14058368 | F19: -0.17768866 | G19: -0.096065972 | H19: -0.012068788 | I19: -0.13411218 | J19: -0.11143724 | K19: -0.23878941 | L19: 0.02032665 | M19: 0.043690236 | N19: -0.15184358 | O19: 0.031561874 | P19: 0.023513161 | Q19: -0.081866113 | R19: 0.14558327 | S19: 0.12269188 | T19: -0.051464717 | U19: 0.067250002 | V19: -0.09268832 | W19: -0.17473476 | X19: 0.14939987 | Y19: 0.10313024 | Z19: -0.057888725 | AA19: -0.1318329 | AB19: 0.051718753 | AC19: 0.014141543 | AD19: -0.023997457 | AE19: -0.16941606 | AF19: -0.16883058 | AG19: -0.041487103 | AH19: -0.20415629 | AI19: -0.047766353 | AJ19: -0.07720271 | AK19: 0.040581523 | AL19: -0.014914608 | AM19: 0.061124131 | AN19: 0.010239548 | AO19: 0.055890126 | AP19: 0.12482825 | AQ19: 0.042375665 | AR19: -0.041144515 | AS19: 0.10919888 | AT19: -0.18459366 | AU19: -0.15301463 | AV19: 0.0030326096 | AW19: -0.1366934 | AX19: -0.2241238 | AY19: -0.066273243 | AZ19: -0.11561153 | BA19: -0.0015090166 | BB19: 0.36416093 | BC19: 0.18457179 | BD19: -0.014320047 | BE19: -0.089480722 | BF19: 0.013570974 | BG19: -0.016343658 | BH19: -0.057134461 | BI19: -0.10128423 | BJ19: -0.058912217 | BK19: -0.069519037 | BL19: -0.063164534 | BM19: -0.031786265 | BN19: -0.0721851 | BO19: 0.10556468 | BP19: 0.012410341 | BQ19: 0.10965313 | BR19: -0.13683924 | BS19: 0.0034999319 | BT19: -0.082323404 | BU19: 0.075936251 | BV19: 0.030350792 | BW19: 0.30745301 | BX19: -0.054830282 | BY19: -0.079866927 | BZ19: -0.0034250282 | CA19: 0.056215144 | CB19: -0.078976808 | CC19: -0.024723253 | CD19: 0.2156192 | CE19: -0.11441436 | CF19: -0.079051525 | CG19: -0.057117625 | CH19: 0.042715044 | CI19: 0.11073421 | CJ19: 0.011811923 | CK19: -0.11879726 | CL19: -0.11534778 | CM19: 0.075581871 | CN19: 0.14319321 | CO19: -0.16614656 | CP19: 0.13741472 | CQ19: 0.032394608 | CR19: 0.024299202 | CS19: -0.05425045 | CT19: 0.027940637 | CU19: 0.14660754 | CV19: -0.094553008 | CW19: -0.021901808 | CX19: -0.14815029 | CY19: 0.10789212 | CZ19: 0.057499263 | DA19: -0.058223877 | DB19: -0.28613845 | DC19: 0.065587585 | DD19: -0.0062011253 | DE19: 0.033018415 | DF19: 0.20550175 | DG19: 0.1264908 | DH19: -0.043220605 | DI19: -0.058647033 | DJ19: 0.16525047 | DK19: 0.01598429 | DL19: 0.011982786 | DM19: 0.046097902 | DN19: 0.1739283 | DO19: -0.04870552 | DP19: -0.17026813 | DQ19: 0.080374172 | DR19: 0.075962353 | DS19: 0.044918963 | DT19: 0.0050332465 | DU19: 0.19451944 | DV19: -0.071593387 | DW19: 0.056843988 | DX19: -0.094614193 | DY19: 0.15211941 | DZ19: -0.079643568 | EA19: 0.032919727 | EB19: 0.10875351 | EC19: -0.012190043 | ED19: -0.15093532 | EE19: -0.022815886 | EF19: -0.16823694
A20: 192 | B20: 5 | C20: 0.011241332 | D20: -0.22258639 | E20: -0.14612491 | F20: -0.20553126 | G20: -0.11718314 | H20: 0.011583026 | I20: -0.18586318 | J20: -0.14728813 | K20: -0.2147245 | L20: 0.0089997713 | M20: 0.077718228 | N20: -0.16814359 | O20: 0.049864886 | P20: 0.043138679 | Q20: -0.10704532 | R20: 0.19094247 | S20: 0.082562611 | T20: -0.085465456 | U20: 0.013720365 | V20: -0.1035176 | W20: -0.22644366 | X20: 0.21038641 | Y20: 0.12896504 | Z20: -0.074027168 | AA20: -0.13048337 | AB20: 0.032898545 | AC20: 0.047248263 | AD20: -0.026987304 | AE20: -0.19929286 | AF20: -0.22349782 | AG20: -0.032163249 | AH20: -0.21664245 | AI20: -0.083279354 | AJ20: -0.060725685 | AK20: 0.0082485151 | AL20: -0.020780265 | AM20: 0.06752986 | AN20: -0.034444519 | AO20: 0.049108295 | AP20: 0.13972026 | AQ20: 0.033308231 | AR20: -0.029739 | AS20: 0.042291716 | AT20: -0.23912375 | AU20: -0.14307264 | AV20: 0.032246613 | AW20: -0.22499784 | AX20: -0.20433922 | AY20: 0.082057636 | AZ20: -0.15627401 | BA20: -0.10207757 | BB20: 0.37844679 | BC20: 0.24014067 | BD20: -0.011308295 | BE20: -0.098278375 | BF20: 0.0056885823 | BG20: -0.0069261427 | BH20: -0.051899277 | BI20: -0.11425567 | BJ20: -0.049139784 | BK20: -0.10259828 | BL20: -0.069859442 | BM20: -0.047468551 | BN20: -0.085664631 | BO20: 0.13121844 | BP20: -0.0072822475 | BQ20: 0.10860027 | BR20: -0.18112708 | BS20: 0.032536198 | BT20: -0.096530501 | BU20: 0.098754949 | BV20: -0.081543442 | BW20: 0.35182955 | BX20: -0.057988018 | BY20: -0.0046393591 | BZ20: -0.0057200581 | CA20: -0.024248535 | CB20: 0.0001077551 | CC20: -0.026043034 | CD20: 0.1810275 | CE20: -0.11376847 | CF20: -0.10578489 | CG20: -0.075970241 | CH20: 0.022195229 | CI20: 0.085208202 | CJ20: 0.041509985 | CK20: -0.080589624 | CL20: -0.14931315 | CM20: 0.079454727 | CN20: 0.20489183 | CO20: -0.2285182 | CP20: 0.15666076 | CQ20: 0.023118045 | CR20: 0.025362553 | CS20: -0.097137099 | CT20: 0.018076711 | CU20: 0.14672801 | CV20: -0.11921413 | CW20: 0.0099530629 | CX20: -0.14515419 | CY20: 0.10096666 | CZ20: 0.013062634 | DA20: -0.047471893 | DB20: -0.38248992 | DC20: 0.037332311 | DD20: -0.0035971848 | DE20: 0.010418722 | DF20: 0.24557421 | DG20: 0.12407331 | DH20: -0.048058412 | DI20: -0.074248336 | DJ20: 0.13655809 | DK20: 0.020765658 | DL20: 0.019465373 | DM20: -0.042864774 | DN20: 0.18323473 | DO20: -0.049820855 | DP20: -0.20015543 | DQ20: 0.057460182 | DR20: 0.07851266 | DS20: -0.069792758 | DT20: -0.029685339 | DU20: 0.27264433 | DV20: -0.10204218 | DW20: 0.062285392 | DX20: -0.097851218 | DY20: 0.18740183 | DZ20: 0.018115127 | EA20: -0.0059255993 | EB20: 0.082407142 | EC20: 0.034049581 | ED20: -0.17691886 | EE20: -0.020017587 | EF20: -0.20954174
A21: 241 | B21: 4 | C21: 0.010384834 | D21: -0.32500828 | E21: -0.043717555 | F21: -0.18403858 | G21: -0.14384215 | H21: -0.037844077 | I21: -0.23932306 | J21: -0.090566639 | K21: -0.20688003 | L21: 0.057226167 | M21: 0.099684593 | N21: -0.13905068 | O21: 0.034351989 | P21: 0.039891723 | Q21: -0.081195369 | R21: 0.14269209 | S21: 0.20915948 | T21: -0.098461673 | U21: -0.080215736 | V21: -0.10537077 | W21: -0.32292055 | X21: 0.21363094 | Y21: 0.092729224 | Z21: -0.1093802 | AA21: -0.11063591 | AB21: 0.021955944 | AC21: 0.018827737 | AD21: 0.025933276 | AE21: -0.24045611 | AF21: -0.29514426 | AG21: -0.011046572 | AH21: -0.24035126 | AI21: -0.067729681 | AJ21: -0.078941164 | AK21: -0.018318369 | AL21: -0.037391486 | AM21: -0.063125718 | AN21: -0.02178903 | AO21: 0.085567775 | AP21: 0.18810121 | AQ21: 0.037036188 | AR21: -0.034197901 | AS21: 0.045406682 | AT21: -0.26483826 | AU21: -0.06345533 | AV21: 0.068713913 | AW21: -0.26325492 | AX21: -0.2177183 | AY21: 0.065722295 | AZ21: -0.093059394 | BA21: -0.019293208 | BB21: 0.40443143 | BC21: 0.16446053 | BD21: -0.030287979 | BE21: -0.13674536 | BF21: 0.0035771002 | BG21: 0.036635189 | BH21: -0.067916731 | BI21: -0.15387465 | BJ21: -0.031982514 | BK21: -0.082973162 | BL21: -0.08734079 | BM21: -0.040795286 | BN21: -0.1882475 | BO21: 0.17006877 | BP21: 0.0041808023 | BQ21: 0.072890743 | BR21: -0.14206146 | BS21: 0.065741821 | BT21: -0.092952203 | BU21: 0.13549646 | BV21: -0.04433998 | BW21: 0.18446067 | BX21: -0.088379335 | BY21: -0.055666292 | BZ21: 0.051498204 | CA21: -0.038078939 | CB21: -0.073466099 | CC21: -0.046693549 | CD21: 0.28805606 | CE21: -0.14537496 | CF21: -0.11452616 | CG21: -0.085085335 | CH21: 0.15662644 | CI21: 0.073182727 | CJ21: 0.055140849 | CK21: -0.06715963 | CL21: -0.18743312 | CM21: 0.062994333 | CN21: 0.080851509 | CO21: -0.23779198 | CP21: 0.098307306 | CQ21: 0.022912194 | CR21: 0.011615789 | CS21: -0.061269036 | CT21: 0.086072557 | CU21: 0.15891662 | CV21: -0.15433184 | CW21: 0.065005417 | CX21: -0.15696885 | CY21: 0.15245231 | CZ21: 0.013847206 | DA21: 0.0011922565 | DB21: -0.47235074 | DC21: 0.1539048 | DD21: -0.0028187944 | DE21: 0.028977737 | DF21: 0.30115021 | DG21: 0.14818493 | DH21: 0.010355572 | DI21: -0.090149203 | DJ21: 0.15660572 | DK21: 0.020966062 | DL21: 0.012736992 | DM21: 0.004254564 | DN21: 0.22029564 | DO21: 0.018558809 | DP21: -0.22901989 | DQ21: 0.070422699 | DR21: 0.050170859 | DS21: -0.084605434 | DT21: -0.0052151903 | DU21: 0.33980664 | DV21: -0.15489825 | DW21: 0.12266433 | DX21: -0.11682889 | DY21: 0.22566188 | DZ21: 0.17989102 | EA21: -0.035066457 | EB21: 0.026302194 | EC21: 0.014037055 | ED21: -0.054498856 | EE21: 0.010955945 | EF21: -0.17865428
A22: 321 | B22: 3 | C22: 0.025922327 | D22: -0.41742192 | E22: -0.022230412 | F22: -0.067831061 | G22: -0.10388436 | H22: -0.22980554 | I22: -0.2544329 | J22: -0.11837828 | K22: -0.24536591 | L22: 0.10748717 | M22: 0.074100059 | N22: -0.098030861 | O22: -0.0067158783 | P22: 0.042858489 | Q22: -0.089282518 | R22: 0.18067973 | S22: 0.24705663 | T22: -0.12881242 | U22: -0.15202918 | V22: -0.057024135 | W22: -0.34619349 | X22: 0.22178676 | Y22: 0.047938332 | Z22: -0.15015011 | AA22: -0.082524426 | AB22: -0.0038652301 | AC22: 0.085776461 | AD22: 0.018593749 | AE22: -0.22862111 | AF22: -0.42991677 | AG22: -0.010812101 | AH22: -0.24762225 | AI22: -0.067392901 | AJ22: -0.045866129 | AK22: -0.078575769 | AL22: -0.0011447262 | AM22: -0.056373754 | AN22: -0.027860567 | AO22: 0.15815288 | AP22: 0.25139506 | AQ22: -0.055126721 | AR22: -0.1081837 | AS22: -0.073843703 | AT22: -0.017728371 | AU22: -0.1099146 | AV22: 0.089753982 | AW22: -0.37079928 | AX22: 0.009875186 | AY22: 0.098456276 | AZ22: -0.2274855 | BA22: -0.04917694 | BB22: 0.51826405 | BC22: 0.19562604 | BD22: -0.058336355 | BE22: -0.12806788 | BF22: 0.013638817 | BG22: 0.046279512 | BH22: -0.0079934121 | BI22: -0.087318059 | BJ22: 0.010233975 | BK22: -0.020854755 | BL22: -0.13947139 | BM22: -0.0024304832 | BN22: 0.028518806 | BO22: 0.033751102 | BP22: 0.00054100012 | BQ22: 0.091228191 | BR22: -0.10656678 | BS22: 0.09704759 | BT22: 0.067143215 | BU22: 0.21294877 | BV22: -0.048603535 | BW22: 0.13217179 | BX22: -0.15293737 | BY22: -0.05559705 | BZ22: 0.056322352 | CA22: -0.063406764 | CB22: -0.06360427 | CC22: -0.014985703 | CD22: 0.33387804 | CE22: -0.13394243 | CF22: -0.10077036 | CG22: -0.20708533 | CH22: 0.15360628 | CI22: 0.064617323 | CJ22: 0.12632536 | CK22: -0.11092354 | CL22: -0.094997012 | CM22: 0.046441279 | CN22: 0.15280392 | CO22: -0.18528576 | CP22: 0.17184373 | CQ22: 0.017159616 | CR22: -0.028422205 | CS22: -0.084781936 | CT22: 0.12609138 | CU22: 0.16735391 | CV22: -0.16622268 | CW22: 0.036451253 | CX22: -0.054293295 | CY22: 0.16243987 | CZ22: 0.0075872464 | DA22: -0.0039917539 | DB22: -0.59337517 | DC22: 0.14116724 | DD22: -0.031710169 | DE22: -0.017756504 | DF22: 0.38966763 | DG22: 0.088121411 | DH22: -0.034688752 | DI22: -0.081105544 | DJ22: 0.15369976 | DK22: 0.023346177 | DL22: 0.0032133307 | DM22: 0.042676549 | DN22: 0.30537503 | DO22: -0.023768668 | DP22: -0.16956243 | DQ22: 0.16540417 | DR22: -0.0060925526 | DS22: -0.12952384 | DT22: 0.027128754 | DU22: 0.37526887 | DV22: -0.15706237 | DW22: -0.0021072618 | DX22: -0.16435212 | DY22: 0.31775437 | DZ22: 0.16562625 | EA22: -0.034191242 | EB22: 0.12976595 | EC22: 0.021495102 | ED22: -0.077413567 | EE22: 0.035899357 | EF22: -0.1611462
A23: 482 | B23: 2 | C23: 0.031325685 | D23: 0.088966623 | E23: -0.015061588 | F23: -0.18239608 | G23: 0.026971569 | H23: -0.26281024 | I23: -0.25570287 | J23: -0.15529382 | K23: -0.14260758 | L23: 0.23244436 | M23: 0.25844992 | N23: -0.12680001 | O23: -0.019407711 | P23: 0.010683505 | Q23: -0.25084968 | R23: 0.089628003 | S23: 0.169295 | T23: -0.15460269 | U23: -0.21298177 | V23: 0.063357011 | W23: -0.50391933 | X23: 0.18178119 | Y23: 0.0075887634 | Z23: -0.14764041 | AA23: 0.056748446 | AB23: -0.030991385 | AC23: 0.1687548 | AD23: 0.0029952916 | AE23: -0.33234425 | AF23: -0.32465933 | AG23: 0.14589389 | AH23: 0.13564892 | AI23: -0.07545017 | AJ23: 0.016962455 | AK23: -0.091199224 | AL23: -0.051310311 | AM23: 0.020470543 | AN23: -0.16052014 | AO23: 0.09078248 | AP23: -0.010447821 | AQ23: 0.17571221 | AR23: -0.2534608 | AS23: -0.081663621 | AT23: -0.1095059 | AU23: -0.20359589 | AV23: 0.049150067 | AW23: -0.58225997 | AX23: 0.014812779 | AY23: 0.0581396 | AZ23: -0.31598452 | BA23: 0.17208091 | BB23: 0.68602333 | BC23: 0.25286918 | BD23: -0.015350669 | BE23: -0.12429214 | BF23: -0.022846991 | BG23: 0.074761471 | BH23: 0.053596864 | BI23: -0.13821956 | BJ23: -0.058020214 | BK23: -0.0050098635 | BL23: -0.11436629 | BM23: 0.069495462 | BN23: 0.02660347 | BO23: -0.0051495895 | BP23: 0.022475721 | BQ23: 0.059356425 | BR23: -0.10282259 | BS23: 0.22056709 | BT23: 0.070189264 | BU23: 0.20568774 | BV23: -0.053269051 | BW23: 0.015362515 | BX23: -0.12421952 | BY23: 0.11824923 | BZ23: 0.20232498 | CA23: 0.03428362 | CB23: 0.041664988 | CC23: 0.22495863 | CD23: 0.19167646 | CE23: -0.20459072 | CF23: -0.016160835 | CG23: -0.21663724 | CH23: 0.16212257 | CI23: 0.1352222 | CJ23: 0.1565159 | CK23: -0.071856391 | CL23: -0.16404946 | CM23: 0.006975009 | CN23: 0.27710426 | CO23: -0.26845098 | CP23: 0.24610177 | CQ23: -0.02470227 | CR23: -0.038232839 | CS23: -0.065159884 | CT23: 0.032850224 | CU23: 0.20210388 | CV23: -0.15333097 | CW23: 0.10090133 | CX23: -0.061859993 | CY23: 0.28171083 | CZ23: -0.061281101 | DA23: -0.030982136 | DB23: -0.86457557 | DC23: 0.1579489 | DD23: -0.092798675 | DE23: -0.060085948 | DF23: 0.40879492 | DG23: 0.15297665 | DH23: -0.1095822 | DI23: -0.18491271 | DJ23: 0.12003258 | DK23: 0.047749797 | DL23: -0.026242652 | DM23: -0.010710334 | DN23: 0.26497486 | DO23: 0.084670828 | DP23: -0.17683962 | DQ23: 0.24594611 | DR23: -0.089886003 | DS23: -0.24719455 | DT23: -0.022296457 | DU23: 0.52524171 | DV23: -0.1927414 | DW23: -0.26698913 | DX23: -0.17100279 | DY23: 0.26822193 | DZ23: 0.12933302 | EA23: -0.093362079 | EB23: 0.24428466 | EC23: -0.036584316 | ED23: -0.091425905 | EE23: 0.069545558 | EF23: -0.083271777
A24: 964 | B24: 1 | C24: 0.027766967 | D24: 0.081988379 | E24: 0.081880335 | F24: -0.20154572 | G24: 0.022622389 | H24: -0.35082219 | I24: -0.24038624 | J24: -0.0040357249 | K24: -0.050444336 | L24: 0.33375944 | M24: 0.14681934 | N24: -0.10519171 | O24: 0.036648791 | P24: 0.077736486 | Q24: 0.090144949 | R24: 0.10836549 | S24: 0.1398838 | T24: 0.27048671 | U24: -0.39296188 | V24: 0.11654032 | W24: -0.64293353 | X24: -0.036157896 | Y24: 0.02939884 | Z24: -0.15040993 | AA24: -0.21854458 | AB24: -0.30039379 | AC24: 0.40174733 | AD24: 0.059922147 | AE24: -0.54125812 | AF24: -0.49538941 | AG24: 0.38005539 | AH24: 0.30212276 | AI24: -0.15191167 | AJ24: 0.020112365 | AK24: -0.11317916 | AL24: -0.10745443 | AM24: -0.014966545 | AN24: -0.11066077 | AO24: 0.1029057 | AP24: -0.41640853 | AQ24: 0.35649193 | AR24: -0.020350844 | AS24: -0.0032867737 | AT24: -0.15076898 | AU24: -0.22984102 | AV24: -0.24768466 | AW24: 0.14871096 | AX24: -0.11149134 | AY24: 0.26743574 | AZ24: -0.60989956 | BA24: 0.10178269 | BB24: 0.87270315 | BC24: -0.0043668696 | BD24: 0.17257014 | BE24: 0.057380538 | BF24: 0.087651336 | BG24: 0.026835966 | BH24: 0.009569451 | BI24: 0.028151632 | BJ24: 0.060567254 | BK24: -0.010019727 | BL24: -0.10610692 | BM24: -0.08478294 | BN24: 0.019890158 | BO24: 0.20807633 | BP24: -0.031794104 | BQ24: -0.013857466 | BR24: -0.098920889 | BS24: 0.12162104 | BT24: 0.055799256 | BU24: 0.22832663 | BV24: -0.046258706 | BW24: 0.15102745 | BX24: -0.05804337 | BY24: 0.11840823 | BZ24: 0.32032943 | CA24: 0.085352139 | CB24: -0.064127083 | CC24: 0.43985451 | CD24: 0.14430631 | CE24: -0.17930378 | CF24: 0.043964634 | CG24: -0.51996897 | CH24: 0.21297288 | CI24: 0.29359964 | CJ24: 0.30018689 | CK24: -0.32305927 | CL24: -0.015683748 | CM24: 0.044688538 | CN24: 0.6096772 | CO24: -0.57240961 | CP24: 0.19806735 | CQ24: -0.16018965 | CR24: -0.096817907 | CS24: -0.10797424 | CT24: -0.18289659 | CU24: 0.052729045 | CV24: -0.18286409 | CW24: 0.17511717 | CX24: -0.14669463 | CY24: 0.36022805 | CZ24: -0.16210691 | DA24: 0.024511204 | DB24: -0.94810959 | DC24: 0.28272978 | DD24: 0.19584472 | DE24: 0.13158559 | DF24: 0.52558501 | DG24: 0.24858898 | DH24: -0.10283284 | DI24: -0.4230988 | DJ24: 0.22936987 | DK24: 0.16602173 | DL24: -0.061360513 | DM24: -0.1083161 | DN24: 0.51684794 | DO24: 0.08311429 | DP24: -0.22357182 | DQ24: 0.3590713 | DR24: -0.02051563 | DS24: -0.14400697 | DT24: -0.029435726 | DU24: 0.77054331 | DV24: -0.75045655 | DW24: -0.38336324 | DX24: -0.17373733 | DY24: 0.032066536 | DZ24: -0.048904664 | EA24: -0.023171502 | EB24: 0.58969792 | EC24: -0.014309919 | ED24: -0.056172845 | EE24: -0.035663983 | EF24: -0.12895777
A25: 大盤 | B25: TWII | C25: -0.017446771 | D25: 0.020701061 | E25: 0.023982129 | F25: -0.006557579 | G25: 0.03184513 | H25: 0.034348533 | I25: -0.0082549328 | J25: 0.012843524 | K25: -0.051018525 | L25: 0.00087394274 | M25: 0.023389576 | N25: 0.012988972 | O25: 0.0058545887 | P25: 0.027413207 | Q25: -0.0037129361 | R25: 0.024076614 | S25: -0.012190025 | T25: -0.039749578 | U25: -0.07315545 | V25: -0.05826023 | W25: 0.00077279757 | X25: 0.044591521 | Y25: -0.02769968 | Z25: 0.0020950059 | AA25: -0.023400551 | AB25: 0.032129371 | AC25: 0.038903273 | AD25: -0.042865382 | AE25: 0.018647195 | AF25: 0.015229768 | AG25: 0.036016604 | AH25: 0.0093546114 | AI25: 0.010748251 | AJ25: 0.013357754 | AK25: -0.0053327473 | AL25: 0.0013831358 | AM25: 0.020795928 | AN25: 0.031517702 | AO25: 0.0062417165 | AP25: 0.0061452617 | AQ25: 0.016946358 | AR25: 0.03468283 | AS25: 0.0030985886 | AT25: 0.015081347 | AU25: -0.019251209 | AV25: 0.038711513 | AW25: -0.021856951 | AX25: 0.0077743007 | AY25: 0.042397247 | AZ25: -0.026308975 | BA25: 0.0095717493 | BB25: -0.024249741 | BC25: 0.020163374 | BD25: -0.0035049988 | BE25: 0.020151935 | BF25: 0.00058133623 | BG25: -0.005219701 | BH25: -0.11587176 | BI25: 0.0087252257 | BJ25: -0.016377261 | BK25: 0.020840372 | BL25: 0.044975872 | BM25: 0.023954306 | BN25: 0.030239101 | BO25: -0.043725888 | BP25: 0.02188947 | BQ25: 0.0086274303 | BR25: -0.019192954 | BS25: 0.01973513 | BT25: 0.047694337 | BU25: 0.011454817 | BV25: 0.043228621 | BW25: -0.04274743 | BX25: -0.017811292 | BY25: -0.1511531 | BZ25: 0.124224 | CA25: -0.0045572538 | CB25: 0.06021124 | CC25: 0.085992033 | CD25: -0.0058084796 | CE25: -0.006041347 | CF25: 0.0024523244 | CG25: 0.089636252 | CH25: 0.070992733 | CI25: 0.027170643 | CJ25: 0.052468428 | CK25: 0.029480661 | CL25: 0.066825081 | CM25: -0.028772229 | CN25: 0.039462516 | CO25: -0.029031087 | CP25: 0.013983883 | CQ25: -0.032276965 | CR25: 0.0031035766 | CS25: 0.025591856 | CT25: 0.044391886 | CU25: -0.030338959 | CV25: -0.0012579765 | CW25: 0.0023363565 | CX25: -0.064264145 | CY25: 0.012909779 | CZ25: -0.12547709 | DA25: 0.011690683 | DB25: 0.0063378437 | DC25: -0.11730536 | DD25: -0.036010872 | DE25: 0.1389113 | DF25: -0.051143506 | DG25: 0.076731447 | DH25: 0.015508782 | DI25: 0.023223774 | DJ25: -0.018372876 | DK25: 0.062199014 | DL25: 0.020098304 | DM25: 0.01349894 | DN25: -0.030252213 | DO25: -0.017022836 | DP25: -0.021788523 | DQ25: 0.085745625 | DR25: 0.028106744 | DS25: -0.0023031598 | DT25: 0.058471198 | DU25: 0.067658949 | DV25: 0.0050207706 | DW25: 0.037416184 | DX25: 0.084111004 | DY25: -0.036832399 | DZ25: 0.0030917028 | EA25: -0.0019576282 | EB25: 0.026459104 | EC25: -0.024752539 | ED25: 0.034115491 | EE25: 0.021061974 | EF25: -0.020277393

Sheet 預測(LSTM)勝率
A1: LSTM
B2: Time | C2: 2013/12 | D2: 2014/01 | E2: 2014/02 | F2: 2014/03 | G2: 2014/04 | H2: 2014/05 | I2: 2014/06 | J2: 2014/07 | K2: 2014/08 | L2: 2014/09 | M2: 2014/10 | N2: 2014/11 | O2: 2014/12 | P2: 2015/01 | Q2: 2015/02 | R2: 2015/03 | S2: 2015/04 | T2: 2015/05 | U2: 2015/06 | V2: 2015/07 | W2: 2015/08 | X2: 2015/09 | Y2: 2015/10 | Z2: 2015/11 | AA2: 2015/12 | AB2: 2016/01 | AC2: 2016/02 | AD2: 2016/03 | AE2: 2016/04 | AF2: 2016/05 | AG2: 2016/06 | AH2: 2016/07 | AI2: 2016/08 | AJ2: 2016/09 | AK2: 2016/10 | AL2: 2016/11 | AM2: 2016/12 | AN2: 2017/01 | AO2: 2017/02 | AP2: 2017/03 | AQ2: 2017/04 | AR2: 2017/05 | AS2: 2017/06 | AT2: 2017/07 | AU2: 2017/08 | AV2: 2017/09 | AW2: 2017/10 | AX2: 2017/11 | AY2: 2017/12 | AZ2: 2018/01 | BA2: 2018/02 | BB2: 2018/03 | BC2: 2018/04 | BD2: 2018/05 | BE2: 2018/06 | BF2: 2018/07 | BG2: 2018/08 | BH2: 2018/09 | BI2: 2018/10 | BJ2: 2018/11 | BK2: 2018/12 | BL2: 2019/01 | BM2: 2019/02 | BN2: 2019/03 | BO2: 2019/04 | BP2: 2019/05 | BQ2: 2019/06 | BR2: 2019/07 | BS2: 2019/08 | BT2: 2019/09 | BU2: 2019/10 | BV2: 2019/11 | BW2: 2019/12 | BX2: 2020/01 | BY2: 2020/02 | BZ2: 2020/03 | CA2: 2020/04 | CB2: 2020/05 | CC2: 2020/06 | CD2: 2020/07 | CE2: 2020/08 | CF2: 2020/09 | CG2: 2020/10 | CH2: 2020/11 | CI2: 2020/12 | CJ2: 2021/01 | CK2: 2021/02 | CL2: 2021/03 | CM2: 2021/04 | CN2: 2021/05 | CO2: 2021/06 | CP2: 2021/07 | CQ2: 2021/08 | CR2: 2021/09 | CS2: 2021/10 | CT2: 2021/11 | CU2: 2021/12 | CV2: 2022/01 | CW2: 2022/02 | CX2: 2022/03 | CY2: 2022/04 | CZ2: 2022/05 | DA2: 2022/06 | DB2: 2022/07 | DC2: 2022/08 | DD2: 2022/09 | DE2: 2022/10 | DF2: 2022/11 | DG2: 2022/12 | DH2: 2023/01 | DI2: 2023/02 | DJ2: 2023/03 | DK2: 2023/04 | DL2: 2023/05 | DM2: 2023/06 | DN2: 2023/07 | DO2: 2023/08 | DP2: 2023/09 | DQ2: 2023/10 | DR2: 2023/11 | DS2: 2023/12 | DT2: 2024/01 | DU2: 2024/02 | DV2: 2024/03 | DW2: 2024/04 | DX2: 2024/05 | DY2: 2024/06 | DZ2: 2024/07 | EA2: 2024/08 | EB2: 2024/09 | EC2: 2024/10 | ED2: 2024/11 | EE2: 2024/12 | EF2: 2025/01 | EG2: 2025/02
B3: bm | C3: 0.040547289 | D3: 0.014746175 | E3: -0.051652342 | F3: -0.054286115 | G3: -0.057552006 | H3: -0.076259449 | I3: -0.10788648 | J3: 0.013737112 | K3: -0.059229229 | L3: -0.10780369 | M3: 0.024141319 | N3: -0.13467413 | O3: -0.0079268562 | P3: -0.075651743 | Q3: -0.08644776 | R3: -0.0030133345 | S3: -0.040853243 | T3: -0.032101776 | U3: -0.10543977 | V3: -0.045746464 | W3: -0.0068120561 | X3: 0.09770143 | Y3: 0.061205495 | Z3: 0.016075654 | AA3: -0.012703552 | AB3: -0.010262255 | AC3: 0.029340141 | AD3: -0.0058081243 | AE3: 0.011994774 | AF3: 0.039971381 | AG3: -0.012103247 | AH3: 0.022090664 | AI3: 0.021936081 | AJ3: 0.025844747 | AK3: -0.0023109075 | AL3: -0.020252099 | AM3: 0.022393657 | AN3: -0.0035141658 | AO3: -0.029745672 | AP3: -0.026837837 | AQ3: -0.021697119 | AR3: 0.023448717 | AS3: 0.015802857 | AT3: 0.066039756 | AU3: 0.062266789 | AV3: 0.057940513 | AW3: 0.10639411 | AX3: -0.0057518133 | AY3: 0.003456265 | AZ3: 0.08603631 | BA3: 0.10234847 | BB3: 0.063502729 | BC3: 0.048442636 | BD3: 0.077497914 | BE3: 0.027031764 | BF3: 0.021175273 | BG3: -0.012267982 | BH3: 0.051240973 | BI3: 0.055158429 | BJ3: 0.086648971 | BK3: 0.081092678 | BL3: 0.057930887 | BM3: 0.014249544 | BN3: -0.0046854224 | BO3: 0.04586114 | BP3: 0.086037964 | BQ3: 0.14414221 | BR3: 0.037985831 | BS3: 0.081880234 | BT3: 0.043688308 | BU3: 0.10545724 | BV3: 0.11753765 | BW3: 0.092942402 | BX3: 0.035637498 | BY3: 0.04292509 | BZ3: 0.098455094 | CA3: 0.018217886 | CB3: 0.019438757 | CC3: -0.0050573386 | CD3: -0.057951014 | CE3: -0.011938484 | CF3: 0.0064156759 | CG3: 0.0056247138 | CH3: 0.058184978 | CI3: 0.012768986 | CJ3: -0.080891326 | CK3: 0.073738843 | CL3: 0.067692369 | CM3: -0.018292543 | CN3: 0.0046888106 | CO3: -0.012873714 | CP3: -0.052108333 | CQ3: -0.072693914 | CR3: -0.060804408 | CS3: 0.015148262 | CT3: -0.063390315 | CU3: -0.06107983 | CV3: -0.021700332 | CW3: -0.060720678 | CX3: -0.040655192 | CY3: -0.045480587 | CZ3: -0.069138072 | DA3: -0.089778468 | DB3: -0.065274872 | DC3: -0.013747443 | DD3: -0.059340179 | DE3: -0.0029697688 | DF3: 0.02926687 | DG3: -0.024713881 | DH3: -0.035376154 | DI3: -0.027640743 | DJ3: -0.0057575447 | DK3: -0.048771854 | DL3: -0.011303868 | DM3: -0.049678039 | DN3: -0.012807783 | DO3: -0.01587224 | DP3: -0.0075895861 | DQ3: 0.040078633 | DR3: -0.01592231 | DS3: 0.023432238 | DT3: -0.053663064 | DU3: -0.044161681 | DV3: -0.023813089 | DW3: 0.025176367 | DX3: -0.032621369 | DY3: 0.013060666 | DZ3: -0.047912493 | EA3: 0.014760353 | EB3: -0.029227724 | EC3: -0.035695001 | ED3: -0.052812476 | EE3: -0.013054582 | EF3: -0.069071874
B4: size | C4: -0.018580828 | D4: -0.04825278 | E4: 0.0078275679 | F4: -0.026776634 | G4: 0.016258875 | H4: -0.0087667406 | I4: -0.0070548905 | J4: -0.032917611 | K4: 0.0073888558 | L4: 0.035096999 | M4: -0.019348426 | N4: -0.012498206 | O4: -0.067216232 | P4: -0.027688211 | Q4: -0.059864789 | R4: -0.077407129 | S4: -0.083726525 | T4: -0.059324656 | U4: -0.0023863558 | V4: 0.0046488689 | W4: -0.074044973 | X4: -0.098803863 | Y4: -0.091002114 | Z4: -0.068004087 | AA4: -0.086181231 | AB4: -0.088893928 | AC4: -0.01658844 | AD4: 0.063448824 | AE4: -0.059580553 | AF4: 0.0010961501 | AG4: 0.028850742 | AH4: 0.029070802 | AI4: -0.01015707 | AJ4: 0.044545107 | AK4: -0.01327528 | AL4: 0.014735002 | AM4: 0.0052847122 | AN4: 0.047137059 | AO4: 0.007465574 | AP4: 0.0046993392 | AQ4: 0.020851189 | AR4: 0.054104723 | AS4: -0.0056461818 | AT4: 0.00404533 | AU4: 0.02062845 | AV4: 0.021113886 | AW4: -0.041878089 | AX4: 0.015781458 | AY4: -0.02299829 | AZ4: 0.0058780294 | BA4: -0.021811418 | BB4: -0.076676466 | BC4: 0.010045491 | BD4: -0.047882307 | BE4: -0.06855423 | BF4: -0.082745306 | BG4: -0.12042424 | BH4: -0.10103763 | BI4: -0.039490096 | BJ4: -0.064256303 | BK4: -0.14447127 | BL4: -0.11201132 | BM4: -0.03482601 | BN4: -0.085986465 | BO4: -0.070973977 | BP4: -0.034846526 | BQ4: -0.020351751 | BR4: -0.023155609 | BS4: -0.032191597 | BT4: -0.068826571 | BU4: -0.092764981 | BV4: -0.081678107 | BW4: -0.06856361 | BX4: -0.019831985 | BY4: -0.061186798 | BZ4: -0.070581049 | CA4: -0.072609454 | CB4: -0.088862821 | CC4: -0.065672167 | CD4: -0.070492014 | CE4: -0.089266889 | CF4: -0.019554028 | CG4: -0.038807325 | CH4: -0.026853707 | CI4: -0.023996761 | CJ4: -0.0069834162 | CK4: -0.011856382 | CL4: -0.011220707 | CM4: -0.019751672 | CN4: -0.017389096 | CO4: 0.00091980241 | CP4: -0.027678527 | CQ4: -0.027226128 | CR4: -0.034191106 | CS4: -0.037506074 | CT4: -0.049283858 | CU4: -0.023866469 | CV4: -0.0027314594 | CW4: 0.025829777 | CX4: -0.077818602 | CY4: -0.017143354 | CZ4: 0.0064833509 | DA4: 0.02112148 | DB4: 0.0016250079 | DC4: 0.014495826 | DD4: 0.037542593 | DE4: -0.047325566 | DF4: 0.033347134 | DG4: -0.018042853 | DH4: -0.012872834 | DI4: 0.025734814 | DJ4: 0.014163728 | DK4: -0.03316791 | DL4: -0.021062262 | DM4: 0.014148561 | DN4: -0.019859655 | DO4: -0.038560558 | DP4: 0.052595932 | DQ4: 0.050834373 | DR4: 0.034424391 | DS4: 0.026739173 | DT4: -0.022692034 | DU4: 0.023562549 | DV4: 0.011204046 | DW4: 0.0097593218 | DX4: -0.012008918 | DY4: -0.012910018 | DZ4: 0.014516729 | EA4: 0.020058911 | EB4: 0.052505847 | EC4: 0.032138381 | ED4: -0.0095858695 | EE4: 0.016591379 | EF4: 0.024656091
