Workbook

Sheet 預測IC
A1: NN4
B2: Time | C2: 2013/12 | D2: 2014/01 | E2: 2014/02 | F2: 2014/03 | G2: 2014/04 | H2: 2014/05 | I2: 2014/06 | J2: 2014/07 | K2: 2014/08 | L2: 2014/09 | M2: 2014/10 | N2: 2014/11 | O2: 2014/12 | P2: 2015/01 | Q2: 2015/02 | R2: 2015/03 | S2: 2015/04 | T2: 2015/05 | U2: 2015/06 | V2: 2015/07 | W2: 2015/08 | X2: 2015/09 | Y2: 2015/10 | Z2: 2015/11 | AA2: 2015/12 | AB2: 2016/01 | AC2: 2016/02 | AD2: 2016/03 | AE2: 2016/04 | AF2: 2016/05 | AG2: 2016/06 | AH2: 2016/07 | AI2: 2016/08 | AJ2: 2016/09 | AK2: 2016/10 | AL2: 2016/11 | AM2: 2016/12 | AN2: 2017/01 | AO2: 2017/02 | AP2: 2017/03 | AQ2: 2017/04 | AR2: 2017/05 | AS2: 2017/06 | AT2: 2017/07 | AU2: 2017/08 | AV2: 2017/09 | AW2: 2017/10 | AX2: 2017/11 | AY2: 2017/12 | AZ2: 2018/01 | BA2: 2018/02 | BB2: 2018/03 | BC2: 2018/04 | BD2: 2018/05 | BE2: 2018/06 | BF2: 2018/07 | BG2: 2018/08 | BH2: 2018/09 | BI2: 2018/10 | BJ2: 2018/11 | BK2: 2018/12 | BL2: 2019/01 | BM2: 2019/02 | BN2: 2019/03 | BO2: 2019/04 | BP2: 2019/05 | BQ2: 2019/06 | BR2: 2019/07 | BS2: 2019/08 | BT2: 2019/09 | BU2: 2019/10 | BV2: 2019/11 | BW2: 2019/12 | BX2: 2020/01 | BY2: 2020/02 | BZ2: 2020/03 | CA2: 2020/04 | CB2: 2020/05 | CC2: 2020/06 | CD2: 2020/07 | CE2: 2020/08 | CF2: 2020/09 | CG2: 2020/10 | CH2: 2020/11 | CI2: 2020/12 | CJ2: 2021/01 | CK2: 2021/02 | CL2: 2021/03 | CM2: 2021/04 | CN2: 2021/05 | CO2: 2021/06 | CP2: 2021/07 | CQ2: 2021/08 | CR2: 2021/09 | CS2: 2021/10 | CT2: 2021/11 | CU2: 2021/12 | CV2: 2022/01 | CW2: 2022/02 | CX2: 2022/03 | CY2: 2022/04 | CZ2: 2022/05 | DA2: 2022/06 | DB2: 2022/07 | DC2: 2022/08 | DD2: 2022/09 | DE2: 2022/10 | DF2: 2022/11 | DG2: 2022/12 | DH2: 2023/01 | DI2: 2023/02 | DJ2: 2023/03 | DK2: 2023/04 | DL2: 2023/05 | DM2: 2023/06 | DN2: 2023/07 | DO2: 2023/08 | DP2: 2023/09 | DQ2: 2023/10 | DR2: 2023/11 | DS2: 2023/12 | DT2: 2024/01 | DU2: 2024/02 | DV2: 2024/03 | DW2: 2024/04 | DX2: 2024/05 | DY2: 2024/06 | DZ2: 2024/07 | EA2: 2024/08 | EB2: 2024/09 | EC2: 2024/10 | ED2: 2024/11 | EE2: 2024/12 | EF2: 2025/01 | EG2: 2025/02
B3: bm | C3: 0.053380691 | D3: 0.019098755 | E3: 0.038903147 | F3: 0.006802408 | G3: 0.012291163 | H3: 0.017075401 | I3: 0.043437455 | J3: 0.022794386 | K3: 0.025884099 | L3: 0.03705984 | M3: 0.025352443 | N3: 0.022137836 | O3: 0.049354821 | P3: 0.0360782 | Q3: 0.0060449373 | R3: 0.0033859401 | S3: -0.0020781485 | T3: -0.022465851 | U3: -0.015456527 | V3: -0.00097821467 | W3: -0.011060316 | X3: -0.00067155808 | Y3: -0.017966148 | Z3: -0.025221735 | AA3: 0.034736544 | AB3: -0.017717708 | AC3: -0.012529988 | AD3: 0.0084126927 | AE3: 0.0031373762 | AF3: 0.018776387 | AG3: -0.043333326 | AH3: 0.021684444 | AI3: 0.042865973 | AJ3: 0.040528882 | AK3: 0.042677276 | AL3: 0.042865951 | AM3: 0.047705099 | AN3: 0.044681475 | AO3: 0.049907289 | AP3: 0.047438353 | AQ3: 0.033652849 | AR3: 0.018763172 | AS3: 0.040618647 | AT3: 0.019566406 | AU3: 0.030446794 | AV3: 0.019622993 | AW3: 0.029586772 | AX3: 0.031509295 | AY3: 0.014002978 | AZ3: 0.0063738404 | BA3: 0.010355084 | BB3: 0.0051876255 | BC3: 0.0078440113 | BD3: 0.0084061269 | BE3: -0.0050238539 | BF3: 0.023039479 | BG3: 0.0095878113 | BH3: -0.084409468 | BI3: 0.023758147 | BJ3: 0.020965053 | BK3: 0.016576048 | BL3: 0.011380131 | BM3: 0.0089813527 | BN3: 0.0098703858 | BO3: -0.0013130086 | BP3: 0.016382337 | BQ3: 0.047462419 | BR3: 0.032633718 | BS3: 0.054500699 | BT3: 0.012507681 | BU3: 0.017222486 | BV3: 0.012570482 | BW3: -0.0049899798 | BX3: -0.0015832115 | BY3: -0.0016474293 | BZ3: 0.036023159 | CA3: 0.019331902 | CB3: 0.012768192 | CC3: 0.0012653216 | CD3: 0.036446176 | CE3: 0.010827552 | CF3: 0.0081559047 | CG3: 0.001104167 | CH3: 0.035072215 | CI3: 0.024559047 | CJ3: 0.020746624 | CK3: 0.009461537 | CL3: 0.0057826559 | CM3: -0.020046353 | CN3: 0.0049867467 | CO3: 0.010287073 | CP3: 0.0091046616 | CQ3: 0.016216964 | CR3: 0.023265561 | CS3: 0.0158605 | CT3: 0.010978778 | CU3: 0.036009509 | CV3: 0.034486167 | CW3: 0.022519557 | CX3: 0.019207012 | CY3: 0.024746167 | CZ3: 0.031119177 | DA3: 0.039866019 | DB3: 0.03700773 | DC3: 0.019792236 | DD3: 0.025975974 | DE3: 0.028975984 | DF3: 0.043441508 | DG3: 0.030526776 | DH3: 0.024306972 | DI3: 0.029352387 | DJ3: 0.03992869 | DK3: 0.025980398 | DL3: 0.025819797 | DM3: 0.022522526 | DN3: 0.018935321 | DO3: 0.015926205 | DP3: 0.024080398 | DQ3: 0.025253983 | DR3: 0.017146798 | DS3: 0.03688072 | DT3: 0.026786022 | DU3: 0.026876723 | DV3: 0.026783179 | DW3: 0.016589746 | DX3: 0.028465604 | DY3: 0.03151679 | DZ3: 0.011472784 | EA3: 0.039311234 | EB3: 0.011679307 | EC3: 0.029493488 | ED3: 0.014745266 | EE3: 0.02212207 | EF3: 0.033925179
B4: size | C4: 0.099771723 | D4: -0.048145149 | E4: -0.022423536 | F4: -0.03092359 | G4: -0.041859966 | H4: -0.027551875 | I4: -0.028741911 | J4: -0.036191553 | K4: -0.033944845 | L4: -0.037480712 | M4: -0.038226228 | N4: -0.028931739 | O4: -0.036612466 | P4: -0.038424995 | Q4: -0.024131393 | R4: -0.035332572 | S4: -0.028889749 | T4: -0.028651971 | U4: -0.030279767 | V4: -0.02720996 | W4: -0.027900077 | X4: -0.028770851 | Y4: -0.03207811 | Z4: -0.030241664 | AA4: -0.03021602 | AB4: -0.028631076 | AC4: -0.027421203 | AD4: -0.028836533 | AE4: -0.030896399 | AF4: -0.029104374 | AG4: -0.028324617 | AH4: -0.020311087 | AI4: -0.034272376 | AJ4: -0.033625115 | AK4: -0.027353102 | AL4: -0.027455468 | AM4: -0.028936265 | AN4: -0.024949074 | AO4: -0.034107022 | AP4: -0.033338342 | AQ4: -0.021358797 | AR4: -0.026061825 | AS4: -0.029215205 | AT4: -0.026710503 | AU4: -0.030300269 | AV4: -0.032673545 | AW4: -0.027749334 | AX4: -0.026509466 | AY4: -0.033140793 | AZ4: -0.027217986 | BA4: -0.030951863 | BB4: -0.033691503 | BC4: -0.031448625 | BD4: -0.031621113 | BE4: -0.032706749 | BF4: -0.030923545 | BG4: -0.03195487 | BH4: -0.030400252 | BI4: -0.031127494 | BJ4: -0.030582078 | BK4: -0.032318864 | BL4: -0.031555992 | BM4: -0.03169376 | BN4: -0.012288306 | BO4: -0.023035662 | BP4: -0.035096336 | BQ4: -0.030655 | BR4: -0.011176202 | BS4: -0.033343028 | BT4: -0.026367433 | BU4: -0.036507525 | BV4: -0.033560742 | BW4: -0.024210105 | BX4: -0.033166561 | BY4: -0.032165386 | BZ4: -0.035884105 | CA4: -0.032357048 | CB4: -0.024709199 | CC4: -0.028877668 | CD4: -0.026096851 | CE4: -0.031489693 | CF4: -0.030856378 | CG4: -0.030586652 | CH4: -0.031124169 | CI4: -0.030887619 | CJ4: -0.03313582 | CK4: -0.031962626 | CL4: -0.0314424 | CM4: -0.030555531 | CN4: -0.03157983 | CO4: -0.030647209 | CP4: -0.030090014 | CQ4: -0.03185311 | CR4: -0.029662993 | CS4: -0.030695755 | CT4: -0.02313577 | CU4: -0.027380981 | CV4: -0.028338037 | CW4: -0.03222578 | CX4: -0.027984483 | CY4: -0.028027313 | CZ4: -0.025761629 | DA4: -0.028369945 | DB4: -0.033535846 | DC4: -0.031756718 | DD4: -0.031705938 | DE4: -0.029670332 | DF4: -0.030024087 | DG4: -0.027606867 | DH4: -0.029870637 | DI4: -0.029808983 | DJ4: -0.030160911 | DK4: -0.029925931 | DL4: -0.030308904 | DM4: -0.028274259 | DN4: -0.027238119 | DO4: -0.028595686 | DP4: -0.026695834 | DQ4: -0.027433051 | DR4: -0.028683912 | DS4: -0.028039401 | DT4: -0.028481074 | DU4: -0.028131839 | DV4: -0.028057404 | DW4: -0.026179386 | DX4: -0.02758223 | DY4: -0.029751539 | DZ4: -0.023914756 | EA4: -0.026012249 | EB4: -0.02659614 | EC4: -0.028463233 | ED4: -0.024121465 | EE4: -0.035137765 | EF4: -0.03114395
B5: mom | C5: -0.0028657506 | D5: -0.0069339015 | E5: -0.0053875917 | F5: -0.0050763469 | G5: -0.0075573726 | H5: -0.0057500093 | I5: -0.0068604206 | J5: -0.0064445543 | K5: -0.0072415825 | L5: -0.0074818125 | M5: -0.0057027275 | N5: 0.012163333 | O5: 0.021172851 | P5: 0.0044824411 | Q5: 0.0027122241 | R5: -0.0045487876 | S5: -0.0027382763 | T5: 0.0053517525 | U5: -0.0066941008 | V5: 0.0023452155 | W5: 0.00081899657 | X5: -0.0038575775 | Y5: -0.003401346 | Z5: -0.0043022791 | AA5: -0.010302481 | AB5: -0.0085672205 | AC5: -0.016086685 | AD5: -0.01153013 | AE5: -0.0092503801 | AF5: -0.0052100425 | AG5: -0.0067270645 | AH5: -0.004258275 | AI5: -0.0037179599 | AJ5: -0.0030319714 | AK5: -0.0045918752 | AL5: -0.0050076684 | AM5: -0.0080656121 | AN5: 0.001068754 | AO5: -0.0059967521 | AP5: -0.0061906483 | AQ5: -0.00085457828 | AR5: -0.0036546465 | AS5: -0.0030794814 | AT5: 0.017204531 | AU5: -0.010902966 | AV5: 0.0112829 | AW5: -0.007904117 | AX5: -0.011263063 | AY5: -0.0005223045 | AZ5: 0.0085165314 | BA5: -0.00030747673 | BB5: -0.0072396048 | BC5: 0.0011019472 | BD5: -0.015344121 | BE5: -0.0055029336 | BF5: -0.0047479346 | BG5: -0.0083916401 | BH5: -0.0068760309 | BI5: 7.6195021e-05 | BJ5: -0.0020668169 | BK5: -0.011106087 | BL5: -0.012728592 | BM5: -0.0039286776 | BN5: -0.00059765868 | BO5: -0.0060457494 | BP5: -0.0094306832 | BQ5: 0.00015003682 | BR5: 0.00041660958 | BS5: -0.00080116763 | BT5: -0.0034547495 | BU5: -0.0064658378 | BV5: -0.0088213878 | BW5: -0.0047403104 | BX5: -0.0021907545 | BY5: -0.002759198 | BZ5: -0.0029730485 | CA5: -0.017626945 | CB5: -0.018505253 | CC5: -0.0089888945 | CD5: -0.0065797777 | CE5: 0.0044988636 | CF5: -0.0049164481 | CG5: -0.0011630631 | CH5: -0.0024271582 | CI5: -0.0062176655 | CJ5: 0.0053816773 | CK5: -0.0067625879 | CL5: -0.0092751253 | CM5: 0.003406229 | CN5: -0.001753664 | CO5: 0.0027562631 | CP5: -0.0045939274 | CQ5: -0.0049152453 | CR5: 0.00098757504 | CS5: -0.005571878 | CT5: -0.00010985811 | CU5: -0.0039590937 | CV5: 1.2909717e-05 | CW5: -0.0033259171 | CX5: -0.001488457 | CY5: -0.002202491 | CZ5: 3.4225348e-05 | DA5: -0.0015060748 | DB5: -0.0035330171 | DC5: -0.0038886347 | DD5: -0.0047214343 | DE5: -0.0055942605 | DF5: -0.019860882 | DG5: -0.0053180065 | DH5: -0.0042921891 | DI5: -0.01564867 | DJ5: 0.0022675006 | DK5: -0.0090083564 | DL5: -0.0038728507 | DM5: -0.0013934468 | DN5: -0.0030848102 | DO5: 0.00276296 | DP5: -0.0061495178 | DQ5: -0.0043366211 | DR5: -0.0079563092 | DS5: -0.0035810128 | DT5: -0.00020724919 | DU5: -0.0056763785 | DV5: -0.0037179622 | DW5: -0.0070113302 | DX5: -0.0071585495 | DY5: -0.0033162229 | DZ5: -0.0019952012 | EA5: -0.002544669 | EB5: -0.0044937851 | EC5: -0.0046182843 | ED5: -0.0063655591 | EE5: -0.0059092026 | EF5: -0.0066195657
A6: 選絕對值最大 | C6: {=MATCH(MAX(ABS(C3:C5)), ABS(C3:C5), 0)} -> 2 | D6: {=MATCH(MAX(ABS(D3:D5)), ABS(D3:D5), 0)} -> 2 | E6: {=MATCH(MAX(ABS(E3:E5)), ABS(E3:E5), 0)} -> 1 | F6: {=MATCH(MAX(ABS(F3:F5)), ABS(F3:F5), 0)} -> 2 | G6: {=MATCH(MAX(ABS(G3:G5)), ABS(G3:G5), 0)} -> 2 | H6: {=MATCH(MAX(ABS(H3:H5)), ABS(H3:H5), 0)} -> 2 | I6: {=MATCH(MAX(ABS(I3:I5)), ABS(I3:I5), 0)} -> 1 | J6: {=MATCH(MAX(ABS(J3:J5)), ABS(J3:J5), 0)} -> 2 | ... EG6: {=MATCH(MAX(ABS(EG3:EG5)), ABS(EG3:EG5), 0)} -> 1
C7: =IF(C6=1,"bm",IF(C6=2,"size",IF(C6=3,"mom"))) -> size | D7: =IF(D6=1,"bm",IF(D6=2,"size",IF(D6=3,"mom"))) -> size | E7: =IF(E6=1,"bm",IF(E6=2,"size",IF(E6=3,"mom"))) -> bm | F7: =IF(F6=1,"bm",IF(F6=2,"size",IF(F6=3,"mom"))) -> size | G7: =IF(G6=1,"bm",IF(G6=2,"size",IF(G6=3,"mom"))) -> size | H7: =IF(H6=1,"bm",IF(H6=2,"size",IF(H6=3,"mom"))) -> size | I7: =IF(I6=1,"bm",IF(I6=2,"size",IF(I6=3,"mom"))) -> bm | J7: =IF(J6=1,"bm",IF(J6=2,"size",IF(J6=3,"mom"))) -> size | ... EG7: =IF(EG6=1,"bm",IF(EG6=2,"size",IF(EG6=3,"mom"))) -> bm
C8: =IF(C6=1,C3,IF(C6=2,C4,IF(C6=3,C5))) -> 0.099771723 | D8: =IF(D6=1,D3,IF(D6=2,D4,IF(D6=3,D5))) -> -0.048145149 | E8: =IF(E6=1,E3,IF(E6=2,E4,IF(E6=3,E5))) -> 0.038903147 | F8: =IF(F6=1,F3,IF(F6=2,F4,IF(F6=3,F5))) -> -0.03092359 | G8: =IF(G6=1,G3,IF(G6=2,G4,IF(G6=3,G5))) -> -0.041859966 | H8: =IF(H6=1,H3,IF(H6=2,H4,IF(H6=3,H5))) -> -0.027551875 | I8: =IF(I6=1,I3,IF(I6=2,I4,IF(I6=3,I5))) -> 0.043437455 | J8: =IF(J6=1,J3,IF(J6=2,J4,IF(J6=3,J5))) -> -0.036191553 | ... EG8: =IF(EG6=1,EG3,IF(EG6=2,EG4,IF(EG6=3,EG5))) -> 0
A10: 投資組合 | C10: 公司數 | D10: 964
A11: 等第 | B11: 分數 | C11: 2014/01 | D11: 2014/02 | E11: 2014/03 | F11: 2014/04 | G11: 2014/05 | H11: 2014/06 | I11: 2014/07 | J11: 2014/08 | K11: 2014/09 | L11: 2014/10 | M11: 2014/11 | N11: 2014/12 | O11: 2015/01 | P11: 2015/02 | Q11: 2015/03 | R11: 2015/04 | S11: 2015/05 | T11: 2015/06 | U11: 2015/07 | V11: 2015/08 | W11: 2015/09 | X11: 2015/10 | Y11: 2015/11 | Z11: 2015/12 | AA11: 2016/01 | AB11: 2016/02 | AC11: 2016/03 | AD11: 2016/04 | AE11: 2016/05 | AF11: 2016/06 | AG11: 2016/07 | AH11: 2016/08 | AI11: 2016/09 | AJ11: 2016/10 | AK11: 2016/11 | AL11: 2016/12 | AM11: 2017/01 | AN11: 2017/02 | AO11: 2017/03 | AP11: 2017/04 | AQ11: 2017/05 | AR11: 2017/06 | AS11: 2017/07 | AT11: 2017/08 | AU11: 2017/09 | AV11: 2017/10 | AW11: 2017/11 | AX11: 2017/12 | AY11: 2018/01 | AZ11: 2018/02 | BA11: 2018/03 | BB11: 2018/04 | BC11: 2018/05 | BD11: 2018/06 | BE11: 2018/07 | BF11: 2018/08 | BG11: 2018/09 | BH11: 2018/10 | BI11: 2018/11 | BJ11: 2018/12 | BK11: 2019/01 | BL11: 2019/02 | BM11: 2019/03 | BN11: 2019/04 | BO11: 2019/05 | BP11: 2019/06 | BQ11: 2019/07 | BR11: 2019/08 | BS11: 2019/09 | BT11: 2019/10 | BU11: 2019/11 | BV11: 2019/12 | BW11: 2020/01 | BX11: 2020/02 | BY11: 2020/03 | BZ11: 2020/04 | CA11: 2020/05 | CB11: 2020/06 | CC11: 2020/07 | CD11: 2020/08 | CE11: 2020/09 | CF11: 2020/10 | CG11: 2020/11 | CH11: 2020/12 | CI11: 2021/01 | CJ11: 2021/02 | CK11: 2021/03 | CL11: 2021/04 | CM11: 2021/05 | CN11: 2021/06 | CO11: 2021/07 | CP11: 2021/08 | CQ11: 2021/09 | CR11: 2021/10 | CS11: 2021/11 | CT11: 2021/12 | CU11: 2022/01 | CV11: 2022/02 | CW11: 2022/03 | CX11: 2022/04 | CY11: 2022/05 | CZ11: 2022/06 | DA11: 2022/07 | DB11: 2022/08 | DC11: 2022/09 | DD11: 2022/10 | DE11: 2022/11 | DF11: 2022/12 | DG11: 2023/01 | DH11: 2023/02 | DI11: 2023/03 | DJ11: 2023/04 | DK11: 2023/05 | DL11: 2023/06 | DM11: 2023/07 | DN11: 2023/08 | DO11: 2023/09 | DP11: 2023/10 | DQ11: 2023/11 | DR11: 2023/12 | DS11: 2024/01 | DT11: 2024/02 | DU11: 2024/03 | DV11: 2024/04 | DW11: 2024/05 | DX11: 2024/06 | DY11: 2024/07 | DZ11: 2024/08 | EA11: 2024/09 | EB11: 2024/10 | EC11: 2024/11 | ED11: 2024/12 | EE11: 2025/01 | EF11: 2025/02
A12: 10 | B12: 96 | C12: -0.084653347 | D12: 0.11468863 | E12: -0.0067540284 | F12: 0.013421104 | G12: 0.011724668 | H12: 0.038530512 | I12: 0.036303937 | J12: -0.029408123 | K12: 0.01877438 | L12: -0.041890941 | M12: -0.00039647701 | N12: 0.069326987 | O12: 0.018629889 | P12: 0.00022997129 | Q12: 0.035269885 | R12: 0.0066628838 | S12: -0.016472395 | T12: -0.0077398001 | U12: -0.016178599 | V12: 0.0062044701 | W12: 0.064039415 | X12: 0.02707389 | Y12: 0.015440368 | Z12: 0.0051659076 | AA12: -0.039403661 | AB12: -0.0037114184 | AC12: 0.0051673798 | AD12: 0.0093922433 | AE12: -0.058316963 | AF12: 0.046181509 | AG12: -0.029982145 | AH12: 0.013405805 | AI12: 0.019506051 | AJ12: 0.012983748 | AK12: 0.048123704 | AL12: 0.017859003 | AM12: 0.030086116 | AN12: 0.069233234 | AO12: 0.002228793 | AP12: -0.033718345 | AQ12: -0.0076219364 | AR12: -0.0075044281 | AS12: 0.019099718 | AT12: -0.022296661 | AU12: 0.020708659 | AV12: -0.021789895 | AW12: 0.00062147702 | AX12: 0.043598467 | AY12: -0.0077141493 | AZ12: 0.066563803 | BA12: 0.071276156 | BB12: 0.0057853949 | BC12: 0.0035752709 | BD12: 0.049233622 | BE12: -0.045598545 | BF12: -0.02360106 | BG12: 0.010004059 | BH12: -0.01422336 | BI12: 0.020837761 | BJ12: 0.043422499 | BK12: -0.020075652 | BL12: 0.011060369 | BM12: -0.030171909 | BN12: -0.019502538 | BO12: 0.016913769 | BP12: -0.026421957 | BQ12: 0.01389675 | BR12: -0.0022610085 | BS12: 0.018863293 | BT12: -0.021288097 | BU12: -0.04808337 | BV12: 0.032053226 | BW12: 0.05548756 | BX12: 0.015984152 | BY12: -0.045815986 | BZ12: 0.045356946 | CA12: 0.014580558 | CB12: 0.072475876 | CC12: 0.065566613 | CD12: 0.11093363 | CE12: 0.15400701 | CF12: 0.0040778953 | CG12: 0.0003086485 | CH12: 0.063297372 | CI12: -0.024341498 | CJ12: 0.0035684802 | CK12: 0.034514755 | CL12: 0.03313401 | CM12: -0.071708388 | CN12: -0.023307541 | CO12: 0.071292243 | CP12: -0.012796158 | CQ12: 0.069976747 | CR12: 0.048146625 | CS12: -0.01450965 | CT12: 0.032114011 | CU12: 0.035623716 | CV12: 0.0081126264 | CW12: 0.029757689 | CX12: 0.046547458 | CY12: 0.046072978 | CZ12: 0.077792327 | DA12: 0.0056037841 | DB12: -0.022981876 | DC12: 0.011472973 | DD12: -0.039091997 | DE12: -0.037235545 | DF12: -0.0068345257 | DG12: -0.00094770894 | DH12: 0.061195155 | DI12: 0.059749068 | DJ12: 0.0080625983 | DK12: -0.031928199 | DL12: 0.0030891115 | DM12: -0.019237694 | DN12: 0.021916732 | DO12: 0.030556942 | DP12: 0.045953548 | DQ12: -0.03386212 | DR12: 0.017064979 | DS12: -0.035726155 | DT12: 0.025117616 | DU12: -0.057230283 | DV12: 0.029540061 | DW12: 0.044967834 | DX12: -0.050152081 | DY12: 0.01535727 | DZ12: 0.0062271493 | EA12: 0.064003941 | EB12: 0.0057859706 | EC12: 0.02665151 | ED12: -0.0069574815 | EE12: -0.026506892 | EF12: 0.039233348
A13: 20 | B13: 48 | C13: -0.10411275 | D13: 0.12374503 | E13: -0.034496619 | F13: -0.01145524 | G13: 0.015744426 | H13: 0.029989632 | I13: 0.032682863 | J13: -0.043899227 | K13: -0.0013673068 | L13: -0.0060251613 | M13: 0.025687102 | N13: 0.099806917 | O13: 0.036273276 | P13: 0.016791628 | Q13: 0.073224368 | R13: 0.014159944 | S13: -0.012243671 | T13: -0.02210402 | U13: 0.0015970162 | V13: -0.020094328 | W13: 0.075476562 | X13: 0.053276895 | Y13: 0.013920993 | Z13: 0.020583761 | AA13: -0.03211951 | AB13: -0.016036099 | AC13: 0.0080314398 | AD13: 0.02154369 | AE13: -0.065719382 | AF13: 0.051935558 | AG13: -0.031681783 | AH13: 0.0096413392 | AI13: 0.01206755 | AJ13: -0.01628047 | AK13: 0.065987913 | AL13: 0.023151429 | AM13: 0.046282444 | AN13: 0.10533024 | AO13: 0.0093111879 | AP13: -0.05955084 | AQ13: -0.0060492888 | AR13: 0.0092507325 | AS13: 0.041313118 | AT13: 0.0016899629 | AU13: 0.040976126 | AV13: -0.01095891 | AW13: 0.0040800136 | AX13: 0.067153788 | AY13: -0.023672609 | AZ13: 0.055449776 | BA13: 0.07982912 | BB13: 0.026046346 | BC13: 0.0014836385 | BD13: 0.041676314 | BE13: -0.046048257 | BF13: -0.026302897 | BG13: 0.0083310656 | BH13: -0.0084757298 | BI13: 0.02583237 | BJ13: 0.051451919 | BK13: -0.025125773 | BL13: 0.013619178 | BM13: -0.027203867 | BN13: 0.0048576031 | BO13: 0.0034067145 | BP13: -0.0079511464 | BQ13: 0.041653064 | BR13: -0.0066814175 | BS13: 0.0074194718 | BT13: -0.03366777 | BU13: -0.074658168 | BV13: 0.031440738 | BW13: 0.086230155 | BX13: 0.0014774348 | BY13: -0.03082776 | BZ13: 0.076138123 | CA13: 0.024012674 | CB13: 0.12042697 | CC13: 0.12011817 | CD13: 0.10508583 | CE13: 0.18382784 | CF13: 0.018228941 | CG13: 0.0075602687 | CH13: 0.058334612 | CI13: -0.0078955344 | CJ13: 0.020881327 | CK13: 0.031859597 | CL13: 0.044000391 | CM13: -0.10145222 | CN13: -0.030131025 | CO13: 0.085566239 | CP13: -0.034377539 | CQ13: 0.067112905 | CR13: 0.064380649 | CS13: 0.0039476507 | CT13: 0.043462268 | CU13: 0.037161402 | CV13: -0.0029533122 | CW13: 0.010456963 | CX13: 0.0049872956 | CY13: 0.062296947 | CZ13: 0.05722422 | DA13: -0.0055836769 | DB13: -0.04176157 | DC13: 0.023540999 | DD13: -0.051406654 | DE13: -0.042564179 | DF13: -0.028518797 | DG13: -0.0016306572 | DH13: 0.088720601 | DI13: 0.089748564 | DJ13: -0.0033317562 | DK13: -0.019386634 | DL13: 0.027121939 | DM13: 0.00053162261 | DN13: 0.016935235 | DO13: 0.037863465 | DP13: 0.044997151 | DQ13: -0.033966462 | DR13: 0.01516855 | DS13: -0.038887628 | DT13: 0.05083126 | DU13: -0.033006159 | DV13: 0.043254779 | DW13: 0.042028686 | DX13: -0.06452338 | DY13: 0.035386045 | DZ13: 0.018302124 | EA13: 0.073242869 | EB13: 0.00020120622 | EC13: 0.041659753 | ED13: 0.00708472 | EE13: -0.041234384 | EF13: 0.066577215
A14: 50 | B14: 19 | C14: -0.11994149 | D14: 0.22230845 | E14: -0.047525943 | F14: 0.034542464 | G14: 0.085148762 | H14: 0.059587806 | I14: 0.04378736 | J14: -0.10509439 | K14: 0.012451162 | L14: -0.0084804476 | M14: -0.075951543 | N14: 0.20483258 | O14: 0.037475787 | P14: 0.047779764 | Q14: 0.058237946 | R14: -0.014151796 | S14: 0.0385341 | T14: -0.017360731 | U14: 0.03657913 | V14: -0.038375546 | W14: 0.11616579 | X14: 0.053581709 | Y14: -0.016762663 | Z14: 0.021252201 | AA14: -0.03945018 | AB14: -0.074982913 | AC14: -0.029292084 | AD14: 0.039327892 | AE14: -0.0040189068 | AF14: 0.084317009 | AG14: -0.020520895 | AH14: 0.0052502779 | AI14: 0.072072951 | AJ14: 0.015059036 | AK14: 0.076911431 | AL14: 0.03796919 | AM14: 0.061242166 | AN14: 0.098594667 | AO14: 0.060905705 | AP14: -0.069976525 | AQ14: -0.00036796774 | AR14: 0.018170823 | AS14: 0.085376986 | AT14: -0.018407426 | AU14: 0.039991649 | AV14: 0.0084264533 | AW14: -0.018362932 | AX14: 0.13695103 | AY14: -0.058839376 | AZ14: 0.025628928 | BA14: 0.096337325 | BB14: 0.10189834 | BC14: 0.012074322 | BD14: 0.01641751 | BE14: -0.024117018 | BF14: -0.0052428879 | BG14: 0.010496608 | BH14: -0.0053427556 | BI14: 0.032270131 | BJ14: 0.024016934 | BK14: 0.033237382 | BL14: 0.010571835 | BM14: -0.021375047 | BN14: 0.046576644 | BO14: 0.014903579 | BP14: 0.050332283 | BQ14: 0.015843524 | BR14: -0.02792943 | BS14: -0.041493955 | BT14: 0.015287928 | BU14: -0.11115945 | BV14: 0.041282489 | BW14: 0.11840804 | BX14: -0.00030713422 | BY14: -0.080399769 | BZ14: 0.060034057 | CA14: 0.033455158 | CB14: 0.1644655 | CC14: 0.12059616 | CD14: 0.09801671 | CE14: 0.1705553 | CF14: -0.020310217 | CG14: 0.13892668 | CH14: 0.064661392 | CI14: -0.0038293561 | CJ14: 0.020066825 | CK14: -0.00046385957 | CL14: 0.13003287 | CM14: -0.11006897 | CN14: -0.019401547 | CO14: 0.17324915 | CP14: -0.10547972 | CQ14: 0.079536741 | CR14: 0.062640655 | CS14: -0.0038161133 | CT14: 0.061872352 | CU14: -0.043917103 | CV14: 0.022745715 | CW14: 0.0082340019 | CX14: 0.024244256 | CY14: 0.050137743 | CZ14: 0.064063563 | DA14: -0.024304289 | DB14: -0.023561073 | DC14: 0.014753761 | DD14: -0.053899967 | DE14: -0.031057667 | DF14: -0.035856631 | DG14: 0.011446556 | DH14: 0.058741194 | DI14: 0.086646448 | DJ14: 0.0010237243 | DK14: -0.08162155 | DL14: -0.0092741824 | DM14: -0.0011211497 | DN14: 0.030298833 | DO14: 0.10259219 | DP14: 0.0036178583 | DQ14: -0.056019286 | DR14: 0.0077944218 | DS14: -0.035044906 | DT14: 0.11767251 | DU14: -0.068795273 | DV14: 0.019432944 | DW14: 0.0018093095 | DX14: -0.10193151 | DY14: 0.03799708 | DZ14: 0.035031 | EA14: 0.078105266 | EB14: -0.025109521 | EC14: 0.0060793821 | ED14: -0.033597288 | EE14: 0.0033992535 | EF14: 0.06995642
A15: 100 | B15: 10 | C15: -0.22764466 | D15: 0.37270922 | E15: -0.010198426 | F15: 0.090303713 | G15: 0.096605591 | H15: 0.1188437 | I15: 0.058431444 | J15: -0.06452469 | K15: -0.0042103664 | L15: 0.012967085 | M15: -0.18849205 | N15: 0.33030934 | O15: 0.073757344 | P15: 0.052983283 | Q15: 0.10037535 | R15: 0.016755436 | S15: -0.043033934 | T15: -0.049338673 | U15: 0.046790243 | V15: -0.085680882 | W15: 0.10693456 | X15: 0.078436412 | Y15: -0.024188619 | Z15: -0.023656419 | AA15: -0.054081147 | AB15: -0.073995952 | AC15: -0.04005513 | AD15: 0.039690481 | AE15: 0.047286476 | AF15: 0.049772025 | AG15: -0.010123478 | AH15: -0.033604373 | AI15: 0.085430111 | AJ15: 0.00946486 | AK15: 0.06175962 | AL15: 0.044431662 | AM15: 0.055122622 | AN15: 0.10168871 | AO15: 0.063369812 | AP15: -0.078285694 | AQ15: -0.037367127 | AR15: 0.02455082 | AS15: 0.053821179 | AT15: 0.0068565183 | AU15: 0.039943261 | AV15: 0.033225302 | AW15: 0.015659939 | AX15: 0.12523398 | AY15: -0.043143498 | AZ15: 0.036847352 | BA15: 0.15768795 | BB15: 0.1087891 | BC15: -0.038491219 | BD15: 0.007362916 | BE15: -0.046217114 | BF15: -0.056978024 | BG15: 0.01377615 | BH15: -0.034441845 | BI15: 0.026351023 | BJ15: 0.075153898 | BK15: 0.072869419 | BL15: 7.7901404e-05 | BM15: -0.062598395 | BN15: 0.066054035 | BO15: 0.016589444 | BP15: 0.051616854 | BQ15: 0.012802931 | BR15: -0.050157429 | BS15: -0.016823777 | BT15: -0.036633666 | BU15: -0.085545734 | BV15: 0.086180137 | BW15: 0.20414584 | BX15: 0.023949431 | BY15: -0.093338392 | BZ15: 0.10290647 | CA15: 0.029964009 | CB15: 0.1310914 | CC15: 0.17365171 | CD15: 0.12015208 | CE15: 0.07336812 | CF15: -0.0036268169 | CG15: 0.22573123 | CH15: 0.062885958 | CI15: -0.069336845 | CJ15: 0.0073826304 | CK15: 0.034280211 | CL15: 0.21275089 | CM15: -0.10811976 | CN15: 0.00021713491 | CO15: 0.17335999 | CP15: -0.034393215 | CQ15: 0.13960362 | CR15: 0.024374319 | CS15: 0.016910987 | CT15: 0.032216556 | CU15: -0.06317866 | CV15: -0.0061418469 | CW15: -0.027257442 | CX15: 0.017868892 | CY15: 0.055732711 | CZ15: 0.079886948 | DA15: -0.026375835 | DB15: -0.030226618 | DC15: 0.076727024 | DD15: -0.067526409 | DE15: -0.065608102 | DF15: -0.042391306 | DG15: 0.016196732 | DH15: 0.12962194 | DI15: 0.042811767 | DJ15: -0.051853853 | DK15: -0.10032893 | DL15: 0.0077378338 | DM15: 0.0017732647 | DN15: -0.067022569 | DO15: 0.15954541 | DP15: -0.040330193 | DQ15: -0.07293808 | DR15: -0.022035265 | DS15: -0.076241908 | DT15: 0.034296399 | DU15: -0.11712765 | DV15: 0.051127 | DW15: -0.060826326 | DX15: -0.11861625 | DY15: 0.10653917 | DZ15: 0.040455653 | EA15: 0.027338726 | EB15: -0.05612648 | EC15: 0.066081856 | ED15: -0.072383319 | EE15: -0.0031907205 | EF15: 0.065700991
A16: 107 | B16: 9 | C16: -0.20787478 | D16: 0.40819498 | E16: -0.0028301766 | F16: 0.12425979 | G16: 0.10901251 | H16: 0.072848056 | I16: 0.057530619 | J16: -0.068694033 | K16: 0.017925105 | L16: 0.031027151 | M16: -0.1948764 | N16: 0.36698761 | O16: 0.079826861 | P16: 0.061979735 | Q16: 0.096618173 | R16: 0.019182762 | S16: -0.042415183 | T16: -0.023226785 | U16: 0.048651516 | V16: -0.10431618 | W16: 0.078373488 | X16: 0.073678278 | Y16: -0.0042874471 | Z16: -0.020075795 | AA16: -0.043487636 | AB16: -0.071016126 | AC16: -0.041040523 | AD16: 0.034811172 | AE16: 0.051534992 | AF16: 0.015008623 | AG16: -0.013290753 | AH16: -0.0317654 | AI16: 0.049078043 | AJ16: -0.0070259661 | AK16: 0.064421401 | AL16: 0.048688933 | AM16: 0.066076731 | AN16: 0.1064562 | AO16: 0.061424672 | AP16: -0.077798368 | AQ16: -0.0384662 | AR16: 0.03249276 | AS16: 0.065068225 | AT16: 0.0039394694 | AU16: 0.041826838 | AV16: 0.023608876 | AW16: 0.03925293 | AX16: 0.10082977 | AY16: -0.034673712 | AZ16: 0.046826876 | BA16: 0.1599907 | BB16: 0.13247474 | BC16: -0.039636816 | BD16: 0.0062821844 | BE16: -0.044139137 | BF16: -0.054584963 | BG16: 0.019331207 | BH16: 0.013775614 | BI16: 0.025620094 | BJ16: 0.081428119 | BK16: 0.1047732 | BL16: -0.0084142574 | BM16: -0.069805825 | BN16: 0.06719797 | BO16: 0.015960319 | BP16: 0.057750061 | BQ16: 0.016478016 | BR16: -0.026296848 | BS16: -0.013191573 | BT16: -0.038066078 | BU16: -0.10153657 | BV16: 0.094510468 | BW16: 0.22394491 | BX16: 0.024078272 | BY16: -0.11899471 | BZ16: 0.11152585 | CA16: 0.02743217 | CB16: 0.13930874 | CC16: 0.044388153 | CD16: 0.15507127 | CE16: 0.09361423 | CF16: -0.014696063 | CG16: 0.14619604 | CH16: 0.041697415 | CI16: -0.05834475 | CJ16: 0.027800423 | CK16: 0.070731881 | CL16: 0.24393816 | CM16: -0.11305584 | CN16: 0.0096090478 | CO16: 0.20954752 | CP16: -0.030684439 | CQ16: 0.16844978 | CR16: 0.025228657 | CS16: 0.021807009 | CT16: 0.048903526 | CU16: -0.063434654 | CV16: -0.016751084 | CW16: -0.031673114 | CX16: 0.0066867777 | CY16: 0.058554306 | CZ16: 0.10263326 | DA16: -0.029804794 | DB16: -0.04271217 | DC16: 0.063740659 | DD16: -0.074371115 | DE16: -0.056325913 | DF16: -0.023146433 | DG16: 0.014452948 | DH16: 0.13714776 | DI16: 0.047829608 | DJ16: -0.029141406 | DK16: -0.096254625 | DL16: 0.0013659721 | DM16: 0.038134996 | DN16: -0.056707577 | DO16: 0.16959095 | DP16: -0.024716583 | DQ16: -0.06756052 | DR16: -0.011178168 | DS16: -0.093752065 | DT16: 0.032059492 | DU16: -0.12277205 | DV16: 0.045148984 | DW16: -0.071302574 | DX16: -0.12528471 | DY16: 0.11635433 | DZ16: 0.058810748 | EA16: 0.046661372 | EB16: -0.070875444 | EC16: 0.063532067 | ED16: -0.080284913 | EE16: -0.0043966753 | EF16: 0.042474401
A17: 120 | B17: 8 | C17: -0.20609219 | D17: 0.43958849 | E17: 0.0073790015 | F17: 0.14677181 | G17: 0.11713148 | H17: 0.10499405 | I17: 0.11372503 | J17: -0.11529907 | K17: 0.039444992 | L17: 0.03377593 | M17: -0.22694064 | N17: 0.40510801 | O17: 0.10122677 | P17: 0.076915604 | Q17: 0.10643025 | R17: 0.0019752513 | S17: -0.055132026 | T17: -0.023507589 | U17: 0.052290234 | V17: -0.1163563 | W17: 0.079141989 | X17: 0.10018597 | Y17: 0.0015005013 | Z17: -0.02160849 | AA17: -0.03520979 | AB17: -0.058334161 | AC17: -0.040799011 | AD17: 0.068619823 | AE17: 0.0594435 | AF17: 0.0084112432 | AG17: -0.022740981 | AH17: -0.035472619 | AI17: 0.030587709 | AJ17: -0.042602631 | AK17: 0.073716275 | AL17: 0.050724406 | AM17: 0.075369368 | AN17: 0.11328712 | AO17: 0.012632335 | AP17: -0.077242814 | AQ17: -0.060527137 | AR17: 0.034997281 | AS17: 0.056323562 | AT17: 0.001432682 | AU17: 0.054555507 | AV17: 0.027563054 | AW17: 0.008421888 | AX17: 0.096240559 | AY17: -0.046811981 | AZ17: 0.047980434 | BA17: 0.16280641 | BB17: 0.15327128 | BC17: -0.057764693 | BD17: 0.019411872 | BE17: -0.016297389 | BF17: -0.077417604 | BG17: -0.013153311 | BH17: -0.013519461 | BI17: 0.057449624 | BJ17: 0.089191478 | BK17: 0.11481579 | BL17: 0.0075736051 | BM17: -0.077967326 | BN17: 0.073656768 | BO17: 0.031350299 | BP17: 0.060638147 | BQ17: 0.01137651 | BR17: -0.0096463751 | BS17: -0.0041034691 | BT17: -0.033647573 | BU17: -0.1045243 | BV17: 0.10664392 | BW17: 0.22723409 | BX17: 0.0070957898 | BY17: -0.095860872 | BZ17: 0.12057816 | CA17: 0.027196784 | CB17: 0.14963316 | CC17: 0.041760252 | CD17: 0.17295974 | CE17: 0.095708074 | CF17: -0.095123349 | CG17: 0.17703461 | CH17: 0.058636447 | CI17: -0.082452914 | CJ17: 0.038321941 | CK17: 0.075742962 | CL17: 0.2871791 | CM17: -0.095493871 | CN17: 0.013630624 | CO17: 0.19808042 | CP17: -0.021609529 | CQ17: 0.17312916 | CR17: 0.02300583 | CS17: 0.011545516 | CT17: 0.058653797 | CU17: -0.074408308 | CV17: 0.0038796079 | CW17: -0.023155845 | CX17: 0.024992449 | CY17: 0.059497952 | CZ17: 0.12424884 | DA17: -0.043895859 | DB17: -0.034883011 | DC17: 0.053888322 | DD17: -0.048130589 | DE17: -0.051666263 | DF17: -0.01123137 | DG17: -0.0018392819 | DH17: 0.1634318 | DI17: 0.07018239 | DJ17: -0.045336158 | DK17: -0.10278127 | DL17: -0.0057903457 | DM17: 0.042563609 | DN17: -0.060629183 | DO17: 0.17976293 | DP17: -0.02509743 | DQ17: -0.065244348 | DR17: -0.025726439 | DS17: -0.12431616 | DT17: 0.01674319 | DU17: -0.12949296 | DV17: 0.062269791 | DW17: -0.076598913 | DX17: -0.12953898 | DY17: 0.11213845 | DZ17: 0.049212629 | EA17: 0.011817924 | EB17: -0.07378097 | EC17: 0.016425217 | ED17: -0.082855622 | EE17: 0.00019352115 | EF17: 0.047709767
A18: 137 | B18: 7 | C18: -0.18975112 | D18: 0.40188368 | E18: -0.059000657 | F18: 0.21209065 | G18: 0.13305806 | H18: 0.12853956 | I18: 0.13550018 | J18: -0.12516179 | K18: 0.03158645 | L18: 0.04667272 | M18: -0.25351319 | N18: 0.46182002 | O18: 0.10367049 | P18: 0.054569613 | Q18: 0.12173637 | R18: 0.019326199 | S18: -0.06901334 | T18: -0.0050281402 | U18: 0.028135528 | V18: -0.13125393 | W18: 0.07729628 | X18: 0.12712281 | Y18: 0.024213808 | Z18: -0.016905716 | AA18: -0.041705245 | AB18: -0.061713851 | AC18: -0.074719823 | AD18: 0.096285845 | AE18: 0.077201592 | AF18: -0.0017514919 | AG18: -0.032493116 | AH18: -0.040197461 | AI18: 0.046855541 | AJ18: -0.047393756 | AK18: 0.030152481 | AL18: 0.047527764 | AM18: 0.066643405 | AN18: 0.07929464 | AO18: 0.005427535 | AP18: -0.078278592 | AQ18: -0.076230845 | AR18: 0.061694524 | AS18: 0.085826552 | AT18: 0.029654326 | AU18: 0.064575644 | AV18: 0.035057688 | AW18: 0.024538034 | AX18: 0.10756087 | AY18: -0.042777608 | AZ18: 0.066341276 | BA18: 0.18047976 | BB18: 0.16725802 | BC18: -0.052453267 | BD18: 0.02027514 | BE18: -0.022230541 | BF18: -0.038143151 | BG18: -0.0023082369 | BH18: -0.020503853 | BI18: 0.03348758 | BJ18: 0.099531519 | BK18: 0.073455627 | BL18: 0.026352779 | BM18: -0.069782333 | BN18: 0.078208699 | BO18: 0.0084067313 | BP18: 0.062463432 | BQ18: 0.0019167841 | BR18: -0.0057481936 | BS18: -0.0039836251 | BT18: -0.013299151 | BU18: -0.11146155 | BV18: 0.11550552 | BW18: 0.26103993 | BX18: -0.015811924 | BY18: -0.062686744 | BZ18: 0.15331999 | CA18: 0.033286165 | CB18: 0.10684606 | CC18: 0.10466062 | CD18: 0.19371682 | CE18: 0.077260395 | CF18: -0.10185862 | CG18: 0.22664141 | CH18: 0.16265705 | CI18: -0.11772541 | CJ18: 0.028685007 | CK18: 0.073220034 | CL18: 0.31710861 | CM18: -0.10276961 | CN18: -0.02861759 | CO18: 0.22828209 | CP18: -0.015497672 | CQ18: 0.20974121 | CR18: 0.033743302 | CS18: 0.02812856 | CT18: 0.076870227 | CU18: -0.071648691 | CV18: 0.091040282 | CW18: -0.028328257 | CX18: -0.014078748 | CY18: 0.071432459 | CZ18: 0.13284286 | DA18: -0.04738094 | DB18: -0.045735209 | DC18: 0.049208867 | DD18: -0.0710713 | DE18: -0.039307075 | DF18: -0.035042779 | DG18: -0.0076194732 | DH18: 0.19240138 | DI18: 0.097963127 | DJ18: -0.04520404 | DK18: -0.10652726 | DL18: -0.023410528 | DM18: 0.058457164 | DN18: -0.05687526 | DO18: 0.22032021 | DP18: -0.021510335 | DQ18: -0.061955529 | DR18: -0.010451249 | DS18: -0.147722 | DT18: -0.00740739 | DU18: -0.15871482 | DV18: 0.085403284 | DW18: -0.06863695 | DX18: -0.15360298 | DY18: 0.097428037 | DZ18: 0.054630374 | EA18: -0.0063615627 | EB18: -0.09704269 | EC18: 0.0027641154 | ED18: -0.080269196 | EE18: -0.0011112877 | EF18: 0.048955017
A19: 160 | B19: 6 | C19: -0.19660027 | D19: 0.40752071 | E19: -0.054898094 | F19: 0.23617047 | G19: 0.15286434 | H19: 0.17761032 | I19: 0.13465433 | J19: -0.15623035 | K19: 0.05654097 | L19: 0.030362833 | M19: -0.26154184 | N19: 0.53237404 | O19: 0.092221383 | P19: 0.022785213 | Q19: 0.17046229 | R19: 0.041942629 | S19: -0.078696261 | T19: -0.10952586 | U19: 0.044186858 | V19: -0.11868446 | W19: 0.072415569 | X19: 0.12292315 | Y19: 0.024064305 | Z19: -0.022223239 | AA19: -0.041570185 | AB19: -0.060762351 | AC19: -0.083512867 | AD19: 0.095993378 | AE19: 0.11523187 | AF19: 0.00026256872 | AG19: -0.022136219 | AH19: -0.056557715 | AI19: 0.081770125 | AJ19: -0.05154529 | AK19: 0.0075520425 | AL19: 0.070270946 | AM19: 0.043106012 | AN19: 0.083568294 | AO19: 0.025892903 | AP19: -0.08757412 | AQ19: -0.088252757 | AR19: 0.074616898 | AS19: 0.097796955 | AT19: 0.011184593 | AU19: 0.076428716 | AV19: 0.042677296 | AW19: 0.022356168 | AX19: 0.080206414 | AY19: -0.060853235 | AZ19: 0.084032472 | BA19: 0.18699678 | BB19: 0.20180191 | BC19: -0.061071731 | BD19: -7.3706968e-05 | BE19: -0.030390671 | BF19: -0.049436517 | BG19: 0.00096322011 | BH19: -0.0020182017 | BI19: 0.025936795 | BJ19: 0.051819308 | BK19: 0.097038423 | BL19: 0.025996465 | BM19: -0.088156797 | BN19: 0.08141326 | BO19: -0.018562314 | BP19: 0.012410341 | BQ19: 0.0099340445 | BR19: 0.006675246 | BS19: -0.024256339 | BT19: 0.013193669 | BU19: -0.13067063 | BV19: 0.10008527 | BW19: 0.2959763 | BX19: -0.03639889 | BY19: -0.027675492 | BZ19: 0.068702125 | CA19: 0.035609795 | CB19: 0.12783821 | CC19: 0.022506233 | CD19: 0.2156192 | CE19: 0.088474859 | CF19: -0.11169849 | CG19: 0.26389313 | CH19: 0.15288987 | CI19: -0.16520241 | CJ19: -0.0010381871 | CK19: 0.074585989 | CL19: 0.3111517 | CM19: -0.11023588 | CN19: -0.015943691 | CO19: 0.25123563 | CP19: -0.029036522 | CQ19: 0.22201357 | CR19: 0.024299202 | CS19: 0.043774987 | CT19: 0.026421201 | CU19: -0.083436397 | CV19: 0.10197986 | CW19: -0.032192133 | CX19: 0.0011275946 | CY19: 0.073151337 | CZ19: 0.11285183 | DA19: -0.058223877 | DB19: -0.035720899 | DC19: 0.030276457 | DD19: -0.063547464 | DE19: -0.0060057102 | DF19: -0.069693047 | DG19: -0.012746475 | DH19: 0.22458978 | DI19: 0.10846144 | DJ19: -0.048514351 | DK19: -0.12144231 | DL19: -0.023313545 | DM19: 0.057300431 | DN19: -0.064294394 | DO19: 0.24926195 | DP19: -0.0040024609 | DQ19: -0.050623171 | DR19: -0.017544799 | DS19: -0.17799555 | DT19: -0.0030761272 | DU19: -0.15058192 | DV19: 0.038124131 | DW19: -0.10129597 | DX19: -0.13836513 | DY19: 0.070109578 | DZ19: 0.078537948 | EA19: -0.028079353 | EB19: -0.10624586 | EC19: -0.012190043 | ED19: -0.086159551 | EE19: 0.0073065267 | EF19: 0.016977955
A20: 192 | B20: 5 | C20: -0.20155105 | D20: 0.38202502 | E20: 0.015499988 | F20: 0.18241962 | G20: 0.15802736 | H20: 0.14393228 | I20: 0.15814956 | J20: -0.13320729 | K20: 0.037404685 | L20: 0.030695483 | M20: -0.26869383 | N20: 0.50001148 | O20: 0.099101484 | P20: 0.040028495 | Q20: 0.22482481 | R20: 0.066469633 | S20: -0.057341083 | T20: -0.10084553 | U20: 0.032237658 | V20: -0.13628806 | W20: 0.091084869 | X20: 0.15004231 | Y20: -0.0048557579 | Z20: 0.02915735 | AA20: -0.021594553 | AB20: -0.060423624 | AC20: -0.096309043 | AD20: 0.12984342 | AE20: 0.01731115 | AF20: -0.0064692815 | AG20: -0.027659219 | AH20: -0.090178201 | AI20: 0.078154545 | AJ20: -0.061990035 | AK20: -0.013595115 | AL20: 0.072893452 | AM20: 0.033095981 | AN20: 0.075470194 | AO20: 0.045285082 | AP20: -0.13173046 | AQ20: 0.027452485 | AR20: 0.013289273 | AS20: 0.11209581 | AT20: -0.0028495391 | AU20: 0.075692387 | AV20: 0.071473186 | AW20: 0.0068652682 | AX20: 0.11073255 | AY20: -0.062285594 | AZ20: 0.099804303 | BA20: 0.15133773 | BB20: 0.23121363 | BC20: -0.069885233 | BD20: 0.0083601734 | BE20: -0.038466832 | BF20: -0.0552169 | BG20: -0.051727193 | BH20: 0.071606447 | BI20: 0.023171587 | BJ20: 0.055155921 | BK20: 0.11765037 | BL20: 0.019783342 | BM20: -0.05455591 | BN20: -0.018638027 | BO20: -0.0076105449 | BP20: -0.0072822475 | BQ20: 0.015451707 | BR20: 0.012073632 | BS20: 0.0054075062 | BT20: 0.052467623 | BU20: -0.149441 | BV20: 0.13370992 | BW20: 0.34204268 | BX20: -0.052861422 | BY20: -0.043183483 | BZ20: 0.090271404 | CA20: 0.050216826 | CB20: 0.12649505 | CC20: 0.012915147 | CD20: 0.1810275 | CE20: 0.085778173 | CF20: -0.13120856 | CG20: 0.32193852 | CH20: 0.071864026 | CI20: -0.13148573 | CJ20: -0.012323838 | CK20: 0.062276752 | CL20: 0.29793491 | CM20: -0.096775806 | CN20: -0.019347978 | CO20: 0.29657331 | CP20: 0.0074243419 | CQ20: 0.082519806 | CR20: 0.025362553 | CS20: 0.022293038 | CT20: 0.028414407 | CU20: -0.094867658 | CV20: 0.092511076 | CW20: -0.025816403 | CX20: 0.0093861438 | CY20: 0.10873284 | CZ20: 0.15516165 | DA20: -0.047471893 | DB20: -0.05690271 | DC20: 0.028901161 | DD20: -0.068163012 | DE20: -0.030466569 | DF20: 0.00085912153 | DG20: -0.0042022106 | DH20: 0.27829885 | DI20: 0.13759576 | DJ20: -0.039459946 | DK20: -0.08518754 | DL20: 0.010186969 | DM20: 0.069336107 | DN20: -0.064461202 | DO20: 0.25800136 | DP20: -0.021671262 | DQ20: -0.038540311 | DR20: -0.055557992 | DS20: -0.2060811 | DT20: 0.0048293442 | DU20: -0.17637517 | DV20: -0.030192896 | DW20: -0.10354617 | DX20: -0.15386633 | DY20: 0.053618609 | DZ20: 0.090199646 | EA20: 0.014917025 | EB20: -0.10631227 | EC20: 0.034049581 | ED20: -0.074625658 | EE20: 0.0017409798 | EF20: 0.020281417
A21: 241 | B21: 4 | C21: -0.21462958 | D21: 0.12638792 | E21: -0.00027935227 | F21: 0.2034135 | G21: 0.14533186 | H21: 0.16216409 | I21: 0.14725561 | J21: -0.13674292 | K21: 0.001470296 | L21: -0.0050291533 | M21: -0.19988497 | N21: 0.58489126 | O21: 0.12978246 | P21: 0.045427193 | Q21: 0.27408345 | R21: 0.084905231 | S21: -0.036563292 | T21: -0.13112036 | U21: -0.0098246407 | V21: -0.13175049 | W21: 0.12449862 | X21: 0.20780127 | Y21: -0.01014366 | Z21: 0.039457716 | AA21: 0.019491044 | AB21: -0.065287595 | AC21: -0.15954227 | AD21: 0.12882467 | AE21: 0.010311611 | AF21: -0.033566825 | AG21: -0.044302778 | AH21: -0.10758136 | AI21: 0.079594209 | AJ21: -0.070405342 | AK21: -0.035803168 | AL21: 0.065379823 | AM21: 0.068535807 | AN21: 0.11195606 | AO21: 0.047726396 | AP21: -0.072535144 | AQ21: 0.076865507 | AR21: -0.047988141 | AS21: 0.064455869 | AT21: -0.063444048 | AU21: 0.047809632 | AV21: 0.050897568 | AW21: 0.00979103 | AX21: 0.14314769 | AY21: -0.11887619 | AZ21: 0.10850236 | BA21: 0.13959268 | BB21: 0.29451264 | BC21: -0.080046888 | BD21: 0.038219147 | BE21: -0.040588333 | BF21: -0.062289949 | BG21: -0.078525059 | BH21: 0.076321363 | BI21: 0.046273769 | BJ21: 0.022394062 | BK21: 0.072723115 | BL21: 0.0037527985 | BM21: -0.094970355 | BN21: -0.025790766 | BO21: 0.015004103 | BP21: 0.0041808023 | BQ21: 0.054542231 | BR21: 0.012323862 | BS21: 0.0058601728 | BT21: 0.060820743 | BU21: -0.17073851 | BV21: 0.019240488 | BW21: 0.40213092 | BX21: -0.077165003 | BY21: -0.014916379 | BZ21: 0.047662929 | CA21: 0.095059434 | CB21: 0.20786985 | CC21: -0.0080189543 | CD21: 0.28805606 | CE21: 0.061514882 | CF21: -0.12717048 | CG21: 0.32016678 | CH21: 0.080100321 | CI21: -0.12329335 | CJ21: -0.011956467 | CK21: 0.0085636303 | CL21: 0.36208375 | CM21: -0.11623182 | CN21: -0.011281919 | CO21: 0.33548376 | CP21: -0.096253288 | CQ21: -0.059403617 | CR21: 0.011615789 | CS21: 0.030907746 | CT21: 0.047993104 | CU21: -0.06267356 | CV21: 0.098225632 | CW21: -0.030752481 | CX21: 0.013395524 | CY21: 0.10250516 | CZ21: 0.23745137 | DA21: 0.0011922565 | DB21: -0.051624434 | DC21: 0.048309147 | DD21: -0.067027496 | DE21: -0.054719268 | DF21: 0.021560881 | DG21: 0.0078463781 | DH21: 0.081436188 | DI21: 0.17983983 | DJ21: -0.037911313 | DK21: -0.090895591 | DL21: 0.032208203 | DM21: 0.024988802 | DN21: -0.046874835 | DO21: 0.3316268 | DP21: -0.037108633 | DQ21: -0.028216052 | DR21: -0.05355699 | DS21: -0.20083947 | DT21: -0.0097086429 | DU21: -0.14861472 | DV21: -0.049664404 | DW21: -0.10353449 | DX21: -0.18596621 | DY21: 0.024595996 | DZ21: 0.098930574 | EA21: -0.024865522 | EB21: -0.10329556 | EC21: 0.014037055 | ED21: -0.082730048 | EE21: -0.021310592 | EF21: -0.018771264
A22: 321 | B22: 3 | C22: -0.2052803 | D22: 0.14242785 | E22: -0.041027532 | F22: -0.13986745 | G22: 0.23294542 | H22: 0.12417806 | I22: 0.12349317 | J22: -0.1042535 | K22: 0.02865678 | L22: 0.014273209 | M22: -0.18466279 | N22: 0.75614344 | O22: 0.14348035 | P22: 0.090630874 | Q22: 0.12727089 | R22: 0.066698293 | S22: -0.039234144 | T22: -0.10484897 | U22: 0.052488906 | V22: -0.1756249 | W22: 0.15804775 | X22: 0.25720235 | Y22: -0.069853332 | Z22: 0.023866122 | AA22: 0.0070480169 | AB22: -0.038274054 | AC22: -0.17721308 | AD22: 0.013572789 | AE22: -0.085147686 | AF22: -0.086404239 | AG22: -0.05284154 | AH22: -0.10586596 | AI22: 0.094141261 | AJ22: -0.031699849 | AK22: 0.10128856 | AL22: 0.040340967 | AM22: 0.084088903 | AN22: 0.11113281 | AO22: 0.074717373 | AP22: -0.062536354 | AQ22: 0.079426117 | AR22: -0.067924488 | AS22: 0.082810439 | AT22: 0.0010736947 | AU22: 0.033500452 | AV22: 0.05964614 | AW22: -0.030149389 | AX22: 0.1737634 | AY22: -0.16372433 | AZ22: 0.1551884 | BA22: 0.049774958 | BB22: 0.36955058 | BC22: -0.087333382 | BD22: 0.079259545 | BE22: -0.068483037 | BF22: -0.054886014 | BG22: -0.096178529 | BH22: 0.12796054 | BI22: 0.082345467 | BJ22: 0.040890332 | BK22: 0.048315241 | BL22: 0.017863882 | BM22: -0.12093964 | BN22: -0.082937899 | BO22: 0.038350063 | BP22: 0.00054100012 | BQ22: 0.027830097 | BR22: 0.020813609 | BS22: -0.016372782 | BT22: -0.088726194 | BU22: -0.10435058 | BV22: 0.00068176017 | BW22: 0.4277165 | BX22: -0.1130289 | BY22: 0.032352876 | BZ22: 0.047257736 | CA22: 0.14407874 | CB22: 0.25473926 | CC22: -0.125104 | CD22: 0.33387804 | CE22: 0.066840146 | CF22: -0.15557257 | CG22: 0.44380082 | CH22: 0.11591877 | CI22: -0.23044917 | CJ22: -0.016242848 | CK22: -0.027152497 | CL22: 0.55395437 | CM22: -0.21983249 | CN22: 0.021850307 | CO22: 0.2720595 | CP22: -0.081323106 | CQ22: -0.07446701 | CR22: -0.028422205 | CS22: 0.024439587 | CT22: 0.038262615 | CU22: -0.12023171 | CV22: 0.1122337 | CW22: -0.013499799 | CX22: 0.047285453 | CY22: 0.10451083 | CZ22: 0.26292048 | DA22: -0.0039917539 | DB22: -0.058383507 | DC22: 0.072342034 | DD22: -0.015962578 | DE22: -0.13335614 | DF22: 0.017031775 | DG22: 0.031985043 | DH22: 0.081454382 | DI22: 0.060122111 | DJ22: -0.050246006 | DK22: -0.091428405 | DL22: 0.021680326 | DM22: 0.031884709 | DN22: -0.083173707 | DO22: 0.075715816 | DP22: -0.10509906 | DQ22: -0.051850202 | DR22: -0.0712363 | DS22: -0.19705092 | DT22: -0.043681446 | DU22: -0.16154691 | DV22: 0.053370167 | DW22: -0.081415413 | DX22: -0.22244261 | DY22: -0.0081471166 | DZ22: 0.1108345 | EA22: -0.070548649 | EB22: -0.14292708 | EC22: 0.021495102 | ED22: -0.057499219 | EE22: -0.047636659 | EF22: -0.034790246
A23: 482 | B23: 2 | C23: -0.28298927 | D23: 0.25409263 | E23: -0.080941173 | F23: -0.0037402329 | G23: 0.36163212 | H23: -0.018188471 | I23: 0.14815203 | J23: -0.11487751 | K23: -0.059917885 | L23: 0.050770834 | M23: -0.14728697 | N23: 0.97590144 | O23: 0.20456438 | P23: 0.054681526 | Q23: 0.29117349 | R23: 0.062821978 | S23: -0.072572664 | T23: -0.084676176 | U23: 0.059241789 | V23: -0.2324772 | W23: 0.25954732 | X23: 0.19455646 | Y23: -0.067949922 | Z23: 0.041051967 | AA23: 0.006606292 | AB23: -0.047748945 | AC23: -0.23400862 | AD23: 0.071628868 | AE23: -0.22171324 | AF23: -0.025300492 | AG23: -0.091873658 | AH23: -0.084171585 | AI23: 0.023228267 | AJ23: 0.0056431378 | AK23: 0.1141111 | AL23: 0.13143171 | AM23: 0.007769489 | AN23: 0.2423147 | AO23: -0.0053369522 | AP23: 0.0031210994 | AQ23: 0.089424992 | AR23: -0.14613616 | AS23: -0.014706888 | AT23: 0.016951231 | AU23: 0.033145526 | AV23: -0.09675725 | AW23: -0.05202691 | AX23: 0.069838154 | AY23: -0.16314791 | AZ23: 0.078071577 | BA23: 0.053998339 | BB23: 0.56682653 | BC23: -0.17300006 | BD23: 0.12597278 | BE23: -0.086532395 | BF23: -0.060012944 | BG23: -0.044908675 | BH23: 0.20348398 | BI23: 0.12120552 | BJ23: 0.057493861 | BK23: 0.047849323 | BL23: -0.05343222 | BM23: -0.18414781 | BN23: -0.038453237 | BO23: 0.06181548 | BP23: 0.022475721 | BQ23: 0.072047901 | BR23: 0.017844321 | BS23: -0.073275389 | BT23: -0.21818668 | BU23: -0.10568527 | BV23: -0.017018951 | BW23: 0.60099753 | BX23: -0.068735089 | BY23: 0.039939449 | BZ23: 0.0076697624 | CA23: 0.20637272 | CB23: 0.31616676 | CC23: -0.084544615 | CD23: 0.19167646 | CE23: 0.059602302 | CF23: -0.18343324 | CG23: 0.29290394 | CH23: 0.18019645 | CI23: -0.059122474 | CJ23: 0.038255249 | CK23: -0.056594325 | CL23: 0.82114883 | CM23: -0.23470497 | CN23: 0.049969056 | CO23: 0.26615854 | CP23: -0.11971831 | CQ23: -0.067315098 | CR23: -0.038232839 | CS23: 0.069015371 | CT23: 0.065390215 | CU23: -0.021056596 | CV23: -0.022245137 | CW23: 0.064165112 | CX23: -0.04425408 | CY23: 0.15375033 | CZ23: 0.18199879 | DA23: -0.030982136 | DB23: -0.015955157 | DC23: 0.072416034 | DD23: -0.018407826 | DE23: -0.1414453 | DF23: 0.061942127 | DG23: 0.038270012 | DH23: 0.13922689 | DI23: 0.096040551 | DJ23: -0.087058008 | DK23: -0.091244989 | DL23: -0.056607334 | DM23: 0.046477316 | DN23: -0.11820475 | DO23: 0.12406844 | DP23: -0.038404396 | DQ23: -0.12113204 | DR23: -0.1024258 | DS23: -0.28809658 | DT23: -0.054250461 | DU23: -0.055639479 | DV23: 0.0081332536 | DW23: 0.023051821 | DX23: -0.31349321 | DY23: 0.16987683 | DZ23: -0.21717399 | EA23: -0.023448908 | EB23: -0.1382255 | EC23: -0.036584316 | ED23: 0.038900423 | EE23: -0.069212076 | EF23: -0.047782279
A24: 964 | B24: 1 | C24: -0.099113364 | D24: 0.10060991 | E24: 0.07140033 | F24: 0.075326494 | G24: 0.22960705 | H24: 0.035855797 | I24: -0.0021119332 | J24: -0.1154628 | K24: 0.053732997 | L24: 0.093799693 | M24: -0.21778567 | N24: 1.7690314 | O24: 0.23530919 | P24: 0.0017362889 | Q24: -0.0028471356 | R24: -0.027822824 | S24: -0.01105446 | T24: -0.2878166 | U24: 0.28585629 | V24: -0.098678511 | W24: -0.16456452 | X24: -0.00089887647 | Y24: -0.12031749 | Z24: -0.024394549 | AA24: 0.013547768 | AB24: -0.18425142 | AC24: -0.24616896 | AD24: 0.1011753 | AE24: -0.17526882 | AF24: -0.16570378 | AG24: -0.13873572 | AH24: -0.05669736 | AI24: -0.0088083311 | AJ24: -0.080891244 | AK24: 0.084883953 | AL24: -0.054676935 | AM24: -0.018919281 | AN24: 0.22118947 | AO24: 0.066090112 | AP24: -0.022851715 | AQ24: 0.047076973 | AR24: -0.17083341 | AS24: -0.027956077 | AT24: 0.0059286096 | AU24: 0.04409532 | AV24: -0.019522214 | AW24: 0.0049875415 | AX24: 0.028306187 | AY24: -0.44347344 | AZ24: 0.11862373 | BA24: 0.050491305 | BB24: 0.69077653 | BC24: -0.2057496 | BD24: 0.018631034 | BE24: -0.10413112 | BF24: -0.10023171 | BG24: -0.17662354 | BH24: 0.38625534 | BI24: 0.16926892 | BJ24: 0.19964003 | BK24: 0.034827647 | BL24: -0.030898612 | BM24: -0.37691636 | BN24: -0.10891326 | BO24: -0.0056244216 | BP24: -0.031794104 | BQ24: -0.064169633 | BR24: 0.042356223 | BS24: -0.0012847175 | BT24: -0.27671902 | BU24: -0.0087484923 | BV24: -0.20330415 | BW24: 1.1090121 | BX24: -0.10395503 | BY24: -0.29033687 | BZ24: 0.2588929 | CA24: 0.10002492 | CB24: 0.63969813 | CC24: -0.18246988 | CD24: 0.14430631 | CE24: 0.16556487 | CF24: -0.16513135 | CG24: 0.23727783 | CH24: 0.3542773 | CI24: -0.058508157 | CJ24: 0.05717413 | CK24: 0.031855166 | CL24: 1.14862 | CM24: -0.63643326 | CN24: 0.01491653 | CO24: 0.45247744 | CP24: -0.24933872 | CQ24: -0.17760542 | CR24: -0.096817907 | CS24: -0.026854923 | CT24: -0.11954439 | CU24: -0.072751348 | CV24: 0.015064048 | CW24: -0.0015881422 | CX24: 0.052765259 | CY24: 0.32114775 | CZ24: 0.11220663 | DA24: 0.024511204 | DB24: -0.19546067 | DC24: 0.17955312 | DD24: 0.049299773 | DE24: -0.30663608 | DF24: -0.10466498 | DG24: 0.059105834 | DH24: 0.26580268 | DI24: 0.037184908 | DJ24: -0.13248861 | DK24: -0.11968018 | DL24: -0.031748698 | DM24: 0.00041344525 | DN24: -0.14903326 | DO24: 0.11561196 | DP24: -0.14433064 | DQ24: -0.05048619 | DR24: -0.023391731 | DS24: -0.21626154 | DT24: -0.074733345 | DU24: 0.021781395 | DV24: 0.098046835 | DW24: 0.1011825 | DX24: -0.31159313 | DY24: 0.34380429 | DZ24: -0.43350658 | EA24: 0.077350922 | EB24: -0.10922877 | EC24: -0.014309919 | ED24: -0.069835154 | EE24: -0.10748066 | EF24: 0.067276677
A25: 大盤 | B25: TWII | C25: -0.017446771 | D25: 0.020701061 | E25: 0.023982129 | F25: -0.006557579 | G25: 0.03184513 | H25: 0.034348533 | I25: -0.0082549328 | J25: 0.012843524 | K25: -0.051018525 | L25: 0.00087394274 | M25: 0.023389576 | N25: 0.012988972 | O25: 0.0058545887 | P25: 0.027413207 | Q25: -0.0037129361 | R25: 0.024076614 | S25: -0.012190025 | T25: -0.039749578 | U25: -0.07315545 | V25: -0.05826023 | W25: 0.00077279757 | X25: 0.044591521 | Y25: -0.02769968 | Z25: 0.0020950059 | AA25: -0.023400551 | AB25: 0.032129371 | AC25: 0.038903273 | AD25: -0.042865382 | AE25: 0.018647195 | AF25: 0.015229768 | AG25: 0.036016604 | AH25: 0.0093546114 | AI25: 0.010748251 | AJ25: 0.013357754 | AK25: -0.0053327473 | AL25: 0.0013831358 | AM25: 0.020795928 | AN25: 0.031517702 | AO25: 0.0062417165 | AP25: 0.0061452617 | AQ25: 0.016946358 | AR25: 0.03468283 | AS25: 0.0030985886 | AT25: 0.015081347 | AU25: -0.019251209 | AV25: 0.038711513 | AW25: -0.021856951 | AX25: 0.0077743007 | AY25: 0.042397247 | AZ25: -0.026308975 | BA25: 0.0095717493 | BB25: -0.024249741 | BC25: 0.020163374 | BD25: -0.0035049988 | BE25: 0.020151935 | BF25: 0.00058133623 | BG25: -0.005219701 | BH25: -0.11587176 | BI25: 0.0087252257 | BJ25: -0.016377261 | BK25: 0.020840372 | BL25: 0.044975872 | BM25: 0.023954306 | BN25: 0.030239101 | BO25: -0.043725888 | BP25: 0.02188947 | BQ25: 0.0086274303 | BR25: -0.019192954 | BS25: 0.01973513 | BT25: 0.047694337 | BU25: 0.011454817 | BV25: 0.043228621 | BW25: -0.04274743 | BX25: -0.017811292 | BY25: -0.1511531 | BZ25: 0.124224 | CA25: -0.0045572538 | CB25: 0.06021124 | CC25: 0.085992033 | CD25: -0.0058084796 | CE25: -0.006041347 | CF25: 0.0024523244 | CG25: 0.089636252 | CH25: 0.070992733 | CI25: 0.027170643 | CJ25: 0.052468428 | CK25: 0.029480661 | CL25: 0.066825081 | CM25: -0.028772229 | CN25: 0.039462516 | CO25: -0.029031087 | CP25: 0.013983883 | CQ25: -0.032276965 | CR25: 0.0031035766 | CS25: 0.025591856 | CT25: 0.044391886 | CU25: -0.030338959 | CV25: -0.0012579765 | CW25: 0.0023363565 | CX25: -0.064264145 | CY25: 0.012909779 | CZ25: -0.12547709 | DA25: 0.011690683 | DB25: 0.0063378437 | DC25: -0.11730536 | DD25: -0.036010872 | DE25: 0.1389113 | DF25: -0.051143506 | DG25: 0.076731447 | DH25: 0.015508782 | DI25: 0.023223774 | DJ25: -0.018372876 | DK25: 0.062199014 | DL25: 0.020098304 | DM25: 0.01349894 | DN25: -0.030252213 | DO25: -0.017022836 | DP25: -0.021788523 | DQ25: 0.085745625 | DR25: 0.028106744 | DS25: -0.0023031598 | DT25: 0.058471198 | DU25: 0.067658949 | DV25: 0.0050207706 | DW25: 0.037416184 | DX25: 0.084111004 | DY25: -0.036832399 | DZ25: 0.0030917028 | EA25: -0.0019576282 | EB25: 0.026459104 | EC25: -0.024752539 | ED25: 0.034115491 | EE25: 0.021061974 | EF25: -0.020277393

Sheet 夏普比率
A1: =預測IC!A1 -> NN4
B2: Time | C2: 2013/12 | D2: 2014/01 | E2: 2014/02 | F2: 2014/03 | G2: 2014/04 | H2: 2014/05 | I2: 2014/06 | J2: 2014/07 | K2: 2014/08 | L2: 2014/09 | M2: 2014/10 | N2: 2014/11 | O2: 2014/12 | P2: 2015/01 | Q2: 2015/02 | R2: 2015/03 | S2: 2015/04 | T2: 2015/05 | U2: 2015/06 | V2: 2015/07 | W2: 2015/08 | X2: 2015/09 | Y2: 2015/10 | Z2: 2015/11 | AA2: 2015/12 | AB2: 2016/01 | AC2: 2016/02 | AD2: 2016/03 | AE2: 2016/04 | AF2: 2016/05 | AG2: 2016/06 | AH2: 2016/07 | AI2: 2016/08 | AJ2: 2016/09 | AK2: 2016/10 | AL2: 2016/11 | AM2: 2016/12 | AN2: 2017/01 | AO2: 2017/02 | AP2: 2017/03 | AQ2: 2017/04 | AR2: 2017/05 | AS2: 2017/06 | AT2: 2017/07 | AU2: 2017/08 | AV2: 2017/09 | AW2: 2017/10 | AX2: 2017/11 | AY2: 2017/12 | AZ2: 2018/01 | BA2: 2018/02 | BB2: 2018/03 | BC2: 2018/04 | BD2: 2018/05 | BE2: 2018/06 | BF2: 2018/07 | BG2: 2018/08 | BH2: 2018/09 | BI2: 2018/10 | BJ2: 2018/11 | BK2: 2018/12 | BL2: 2019/01 | BM2: 2019/02 | BN2: 2019/03 | BO2: 2019/04 | BP2: 2019/05 | BQ2: 2019/06 | BR2: 2019/07 | BS2: 2019/08 | BT2: 2019/09 | BU2: 2019/10 | BV2: 2019/11 | BW2: 2019/12 | BX2: 2020/01 | BY2: 2020/02 | BZ2: 2020/03 | CA2: 2020/04 | CB2: 2020/05 | CC2: 2020/06 | CD2: 2020/07 | CE2: 2020/08 | CF2: 2020/09 | CG2: 2020/10 | CH2: 2020/11 | CI2: 2020/12 | CJ2: 2021/01 | CK2: 2021/02 | CL2: 2021/03 | CM2: 2021/04 | CN2: 2021/05 | CO2: 2021/06 | CP2: 2021/07 | CQ2: 2021/08 | CR2: 2021/09 | CS2: 2021/10 | CT2: 2021/11 | CU2: 2021/12 | CV2: 2022/01 | CW2: 2022/02 | CX2: 2022/03 | CY2: 2022/04 | CZ2: 2022/05 | DA2: 2022/06 | DB2: 2022/07 | DC2: 2022/08 | DD2: 2022/09 | DE2: 2022/10 | DF2: 2022/11 | DG2: 2022/12 | DH2: 2023/01 | DI2: 2023/02 | DJ2: 2023/03 | DK2: 2023/04 | DL2: 2023/05 | DM2: 2023/06 | DN2: 2023/07 | DO2: 2023/08 | DP2: 2023/09 | DQ2: 2023/10 | DR2: 2023/11 | DS2: 2023/12 | DT2: 2024/01 | DU2: 2024/02 | DV2: 2024/03 | DW2: 2024/04 | DX2: 2024/05 | DY2: 2024/06 | DZ2: 2024/07 | EA2: 2024/08 | EB2: 2024/09 | EC2: 2024/10 | ED2: 2024/11 | EE2: 2024/12 | EF2: 2025/01 | EG2: 2025/02
B3: bm | C3: 0.036997014 | D3: 0.033297818 | E3: 0.015421638 | F3: 0.016456983 | G3: 0.017226211 | H3: 0.028764108 | I3: 0.024279328 | J3: 0.027316419 | K3: 0.030174005 | L3: 0.025236297 | M3: 0.032729104 | N3: 0.031554761 | O3: 0.034033302 | P3: 0.033212911 | Q3: 0.029103335 | R3: 0.026473653 | S3: 0.028295346 | T3: 0.022620728 | U3: 0.016144007 | V3: 0.025033178 | W3: 0.045784045 | X3: 0.043057814 | Y3: 0.037785746 | Z3: 0.024097455 | AA3: 0.030094427 | AB3: 0.028087063 | AC3: 0.033771067 | AD3: 0.034131704 | AE3: 0.034141409 | AF3: 0.013117941 | AG3: 0.024857354 | AH3: 0.031884444 | AI3: 0.036385761 | AJ3: 0.035948919 | AK3: 0.043482831 | AL3: 0.038462078 | AM3: 0.039410244 | AN3: 0.050743621 | AO3: 0.053684812 | AP3: 0.049314899 | AQ3: 0.032773688 | AR3: 0.028295341 | AS3: 0.028377803 | AT3: 0.023069229 | AU3: 0.029397033 | AV3: 0.031037852 | AW3: 0.026297924 | AX3: 0.026164811 | AY3: 0.032053784 | AZ3: 0.034477531 | BA3: 0.029331891 | BB3: 0.034324948 | BC3: 0.037421777 | BD3: 0.031413722 | BE3: 0.032006411 | BF3: 0.028281828 | BG3: 0.041103437 | BH3: 0.045198779 | BI3: 0.04158804 | BJ3: 0.040723406 | BK3: 0.0363277 | BL3: 0.036173192 | BM3: 0.037708588 | BN3: 0.030814038 | BO3: 0.030655856 | BP3: 0.034399632 | BQ3: 0.03486865 | BR3: 0.03632404 | BS3: 0.036164468 | BT3: 0.038668895 | BU3: 0.041103484 | BV3: 0.028684133 | BW3: 0.03521651 | BX3: 0.0407672 | BY3: 0.021603538 | BZ3: 0.030433669 | CA3: 0.037311958 | CB3: 0.027612053 | CC3: 0.019742955 | CD3: 0.0077914602 | CE3: 0.022526807 | CF3: 0.034778188 | CG3: 0.032581362 | CH3: 0.040909001 | CI3: 0.039050253 | CJ3: 0.0245619 | CK3: 0.034134462 | CL3: 0.035925938 | CM3: 0.042466042 | CN3: 0.036523907 | CO3: 0.03765915 | CP3: 0.039957834 | CQ3: -0.0045921903 | CR3: 0.01500343 | CS3: 0.022458754 | CT3: 0.040972168 | CU3: 0.038942373 | CV3: 0.043015001 | CW3: 0.0397066 | CX3: 0.039171023 | CY3: 0.034940835 | CZ3: 0.036026834 | DA3: 0.044509548 | DB3: 0.039322897 | DC3: 0.037933403 | DD3: 0.039075001 | DE3: 0.041993976 | DF3: 0.041965349 | DG3: 0.040382245 | DH3: 0.03678724 | DI3: 0.036877766 | DJ3: 0.033682094 | DK3: 0.036536443 | DL3: 0.031530556 | DM3: 0.028662238 | DN3: 0.030844743 | DO3: 0.033675364 | DP3: 0.035102178 | DQ3: 0.036708207 | DR3: 0.034114422 | DS3: 0.036715906 | DT3: 0.034828053 | DU3: 0.023365577 | DV3: 0.025240939 | DW3: 0.035159203 | DX3: 0.032304964 | DY3: 0.023258217 | DZ3: 0.028308752 | EA3: 0.031397322 | EB3: 0.037230813 | EC3: 0.03334609 | ED3: 0.034186641 | EE3: 0.025041158 | EF3: 0.034121435
B4: size | C4: -0.049660318 | D4: -0.06445346 | E4: -0.095804929 | F4: -0.076694249 | G4: -0.02651532 | H4: -0.03415165 | I4: -0.04619091 | J4: -0.046178363 | K4: -0.045931909 | L4: -0.04081179 | M4: -0.018734141 | N4: -0.035831184 | O4: -0.057022861 | P4: -0.042462624 | Q4: -0.037772239 | R4: -0.028628159 | S4: -0.030997759 | T4: -0.0067040182 | U4: -0.037956684 | V4: -0.029502006 | W4: -0.041243237 | X4: -0.054483331 | Y4: -0.057374084 | Z4: -0.050628324 | AA4: -0.042319641 | AB4: -0.03427378 | AC4: -0.038455291 | AD4: -0.032603255 | AE4: -0.034794942 | AF4: -0.0016393719 | AG4: -0.03223915 | AH4: -0.025692957 | AI4: -0.030088885 | AJ4: -0.029719525 | AK4: -0.022742981 | AL4: -0.025322144 | AM4: -0.024117366 | AN4: -0.027272205 | AO4: -0.02838312 | AP4: -0.023965544 | AQ4: -0.030304468 | AR4: -0.017736018 | AS4: -0.014939197 | AT4: -0.013608707 | AU4: -0.016423914 | AV4: -0.024039604 | AW4: -0.021378703 | AX4: -0.023051307 | AY4: -0.023942341 | AZ4: -0.015978329 | BA4: -0.029633645 | BB4: -0.036923113 | BC4: -0.022611704 | BD4: -0.02696564 | BE4: -0.030957563 | BF4: -0.018181884 | BG4: -0.015961032 | BH4: -0.021358658 | BI4: -0.018895749 | BJ4: -0.021052816 | BK4: -0.02661183 | BL4: -0.017576751 | BM4: -0.021846036 | BN4: -0.013750921 | BO4: -0.0065027888 | BP4: -0.01217171 | BQ4: 0.00022277284 | BR4: -0.005245064 | BS4: -0.012938426 | BT4: -0.01635034 | BU4: -0.0017286047 | BV4: 0.015184016 | BW4: -0.0037692826 | BX4: -0.016045217 | BY4: -0.018894587 | BZ4: -0.0041566141 | CA4: -0.0182235 | CB4: -0.022303988 | CC4: -0.041111881 | CD4: -0.032535264 | CE4: -0.030323127 | CF4: -0.061293035 | CG4: -0.0441696 | CH4: -0.026870448 | CI4: -0.017734729 | CJ4: -0.011493971 | CK4: -0.01591057 | CL4: -0.015536443 | CM4: -0.01914162 | CN4: 0.0080306048 | CO4: 0.0041846284 | CP4: -0.0074834121 | CQ4: -0.00067070377 | CR4: -0.019179488 | CS4: -0.023347226 | CT4: -0.021789124 | CU4: -0.029507372 | CV4: -0.024862939 | CW4: -0.022835803 | CX4: -0.022235555 | CY4: -0.025586671 | CZ4: -0.030230897 | DA4: -0.043223926 | DB4: -0.044724836 | DC4: -0.070760187 | DD4: -0.057609849 | DE4: -0.034042017 | DF4: -0.027183612 | DG4: -0.03505246 | DH4: -0.0084282458 | DI4: -0.036370698 | DJ4: -0.038760924 | DK4: -0.027971575 | DL4: -0.016270629 | DM4: -0.017815732 | DN4: -0.0080526822 | DO4: -0.023536384 | DP4: -0.02948732 | DQ4: -0.037657448 | DR4: -0.029648059 | DS4: -0.030189606 | DT4: -0.041055976 | DU4: -0.037310577 | DV4: -0.0089387634 | DW4: -0.018377446 | DX4: -0.030385798 | DY4: -0.033048756 | DZ4: -0.030982286 | EA4: -0.031659362 | EB4: -0.036490653 | EC4: -0.041069205 | ED4: -0.031004875 | EE4: -0.023075953 | EF4: -0.01142086
