Workbook

Sheet 真實IC
A1: REAL
B2: Time | C2: 2013/12 | D2: 2014/01 | E2: 2014/02 | F2: 2014/03 | G2: 2014/04 | H2: 2014/05 | I2: 2014/06 | J2: 2014/07 | K2: 2014/08 | L2: 2014/09 | M2: 2014/10 | N2: 2014/11 | O2: 2014/12 | P2: 2015/01 | Q2: 2015/02 | R2: 2015/03 | S2: 2015/04 | T2: 2015/05 | U2: 2015/06 | V2: 2015/07 | W2: 2015/08 | X2: 2015/09 | Y2: 2015/10 | Z2: 2015/11 | AA2: 2015/12 | AB2: 2016/01 | AC2: 2016/02 | AD2: 2016/03 | AE2: 2016/04 | AF2: 2016/05 | AG2: 2016/06 | AH2: 2016/07 | AI2: 2016/08 | AJ2: 2016/09 | AK2: 2016/10 | AL2: 2016/11 | AM2: 2016/12 | AN2: 2017/01 | AO2: 2017/02 | AP2: 2017/03 | AQ2: 2017/04 | AR2: 2017/05 | AS2: 2017/06 | AT2: 2017/07 | AU2: 2017/08 | AV2: 2017/09 | AW2: 2017/10 | AX2: 2017/11 | AY2: 2017/12 | AZ2: 2018/01 | BA2: 2018/02 | BB2: 2018/03 | BC2: 2018/04 | BD2: 2018/05 | BE2: 2018/06 | BF2: 2018/07 | BG2: 2018/08 | BH2: 2018/09 | BI2: 2018/10 | BJ2: 2018/11 | BK2: 2018/12 | BL2: 2019/01 | BM2: 2019/02 | BN2: 2019/03 | BO2: 2019/04 | BP2: 2019/05 | BQ2: 2019/06 | BR2: 2019/07 | BS2: 2019/08 | BT2: 2019/09 | BU2: 2019/10 | BV2: 2019/11 | BW2: 2019/12 | BX2: 2020/01 | BY2: 2020/02 | BZ2: 2020/03 | CA2: 2020/04 | CB2: 2020/05 | CC2: 2020/06 | CD2: 2020/07 | CE2: 2020/08 | CF2: 2020/09 | CG2: 2020/10 | CH2: 2020/11 | CI2: 2020/12 | CJ2: 2021/01 | CK2: 2021/02 | CL2: 2021/03 | CM2: 2021/04 | CN2: 2021/05 | CO2: 2021/06 | CP2: 2021/07 | CQ2: 2021/08 | CR2: 2021/09 | CS2: 2021/10 | CT2: 2021/11 | CU2: 2021/12 | CV2: 2022/01 | CW2: 2022/02 | CX2: 2022/03 | CY2: 2022/04 | CZ2: 2022/05 | DA2: 2022/06 | DB2: 2022/07 | DC2: 2022/08 | DD2: 2022/09 | DE2: 2022/10 | DF2: 2022/11 | DG2: 2022/12 | DH2: 2023/01 | DI2: 2023/02 | DJ2: 2023/03 | DK2: 2023/04 | DL2: 2023/05 | DM2: 2023/06 | DN2: 2023/07 | DO2: 2023/08 | DP2: 2023/09 | DQ2: 2023/10 | DR2: 2023/11 | DS2: 2023/12 | DT2: 2024/01 | DU2: 2024/02 | DV2: 2024/03 | DW2: 2024/04 | DX2: 2024/05 | DY2: 2024/06 | DZ2: 2024/07 | EA2: 2024/08 | EB2: 2024/09 | EC2: 2024/10 | ED2: 2024/11 | EE2: 2024/12 | EF2: 2025/01
B3: bm | C3: 0.10910583 | D3: 0.01457658 | E3: -0.0361544 | F3: -0.0047426 | G3: -0.0057478 | H3: 0.04937802 | I3: 0.18325177 | J3: 0.11648631 | K3: -0.0305949 | L3: 0.01982805 | M3: -0.020999 | N3: 0.14977942 | O3: 0.01546341 | P3: -0.0917923 | Q3: -0.077409 | R3: 0.0547766 | S3: -0.1253344 | T3: -0.1190534 | U3: -0.0377701 | V3: 0.08118382 | W3: 0.08400897 | X3: 0.14701136 | Y3: -0.1253605 | Z3: 0.19195355 | AA3: -0.0843708 | AB3: 0.07289761 | AC3: 0.10260456 | AD3: 0.01577017 | AE3: -0.1520072 | AF3: 0.05925025 | AG3: 0.13005884 | AH3: 0.1152564 | AI3: 0.03260662 | AJ3: 0.02799911 | AK3: 0.14657042 | AL3: 0.04084192 | AM3: 0.13137637 | AN3: 0.22143296 | AO3: -0.020941 | AP3: -0.13716 | AQ3: -0.0248829 | AR3: 0.01551397 | AS3: 0.03437304 | AT3: 0.06309569 | AU3: 0.0432377 | AV3: -0.0742304 | AW3: 0.02799483 | AX3: 0.11986442 | AY3: 0.07655957 | AZ3: -0.0217304 | BA3: -0.0012465 | BB3: 0.10099582 | BC3: 0.02982693 | BD3: 0.00867577 | BE3: 0.06855721 | BF3: 0.1569126 | BG3: 0.15920373 | BH3: 0.06112167 | BI3: 0.09691285 | BJ3: -0.0547462 | BK3: -0.087493 | BL3: 0.09442675 | BM3: -0.0221911 | BN3: 0.01562861 | BO3: 0.08141824 | BP3: -0.0185089 | BQ3: 0.06872957 | BR3: 0.00310236 | BS3: 0.07496442 | BT3: 0.04520159 | BU3: 0.02567733 | BV3: 0.09180403 | BW3: -0.026354 | BX3: 0.01939483 | BY3: -0.0768389 | BZ3: 0.11330931 | CA3: -0.1073549 | CB3: 0.04084479 | CC3: -0.0198017 | CD3: 0.18837709 | CE3: 0.05557491 | CF3: 0.07487207 | CG3: 0.10000019 | CH3: 0.13602172 | CI3: -0.093741 | CJ3: 0.0039306 | CK3: 0.05650778 | CL3: 0.26354578 | CM3: -0.0095554 | CN3: -0.0315119 | CO3: -0.022619 | CP3: 0.13265561 | CQ3: 0.13307278 | CR3: -0.0149564 | CS3: -0.0334199 | CT3: 0.01228121 | CU3: 0.11681498 | CV3: -0.0031589 | CW3: 0.03821776 | CX3: 0.13917409 | CY3: -0.0237123 | CZ3: 0.21835291 | DA3: -0.0579674 | DB3: -0.0141042 | DC3: 0.11395608 | DD3: 0.07447226 | DE3: -0.0008997 | DF3: 0.00097707 | DG3: -0.0729801 | DH3: -0.0238453 | DI3: -0.1015307 | DJ3: 0.02769254 | DK3: -0.0493352 | DL3: -0.0056994 | DM3: -0.0369818 | DN3: 0.10981299 | DO3: 0.04203683 | DP3: 0.08456667 | DQ3: -0.1102798 | DR3: 0.09432871 | DS3: -0.0719069 | DT3: -0.0962364 | DU3: 0.00234555 | DV3: 0.13401742 | DW3: 0.09473252 | DX3: -0.1037732 | DY3: 0.07576215 | DZ3: -0.0318297 | EA3: 0.16130802 | EB3: 0.01020353 | EC3: 0.07398843 | ED3: -0.1573769 | EE3: 0.07913755 | EF3: 0.07252855
B4: size | C4: -0.2475887 | D4: -0.2746933 | E4: -0.0846484 | F4: 0.02264463 | G4: -0.04968 | H4: -0.1007596 | I4: -0.0125227 | J4: 0.07873654 | K4: -0.0341851 | L4: 0.08840679 | M4: -0.0030635 | N4: -0.212218 | O4: -0.0368054 | P4: 0.07103312 | Q4: -0.0712611 | R4: 0.02156045 | S4: 0.10111126 | T4: 0.04322473 | U4: 0.01488195 | V4: 0.00632602 | W4: -0.143553 | X4: -0.0642822 | Y4: -0.0190342 | Z4: -0.0206446 | AA4: 0.03305953 | AB4: -0.0194182 | AC4: -0.0631268 | AD4: -0.0656297 | AE4: 0.13799568 | AF4: -0.1005679 | AG4: -0.0379691 | AH4: -0.0458395 | AI4: -0.0510341 | AJ4: -0.0032204 | AK4: 0.00048952 | AL4: -0.1064467 | AM4: -0.013724 | AN4: -0.1219647 | AO4: -0.0485897 | AP4: -0.0019032 | AQ4: 0.02906749 | AR4: 0.05263577 | AS4: -0.0128933 | AT4: -0.0021311 | AU4: -0.1553844 | AV4: 0.01268178 | AW4: -0.0119423 | AX4: -0.0042538 | AY4: 0.02930087 | AZ4: -0.1341275 | BA4: -0.1371115 | BB4: 0.00175466 | BC4: 0.02511712 | BD4: -0.1196019 | BE4: 0.13576165 | BF4: 0.04709117 | BG4: -0.0260501 | BH4: 0.04375276 | BI4: -0.0813918 | BJ4: -0.1006008 | BK4: 0.09049007 | BL4: -0.0308985 | BM4: 0.05881417 | BN4: 0.08134563 | BO4: -0.0077164 | BP4: 0.10673487 | BQ4: -0.0271563 | BR4: -0.054431 | BS4: -0.0682293 | BT4: 0.09861222 | BU4: 0.12839854 | BV4: -0.0784025 | BW4: -0.1191337 | BX4: -0.0468901 | BY4: 0.10169835 | BZ4: -0.0256801 | CA4: -0.0833018 | CB4: -0.1578276 | CC4: -0.0710526 | CD4: -0.0738755 | CE4: -0.2367865 | CF4: 0.03262771 | CG4: 0.01342309 | CH4: -0.0027967 | CI4: 0.0479257 | CJ4: -0.003252 | CK4: -0.0757082 | CL4: -0.0443973 | CM4: 0.17898859 | CN4: 0.05799427 | CO4: -0.1393902 | CP4: 0.06471467 | CQ4: -0.1811879 | CR4: -0.0886335 | CS4: -0.0253218 | CT4: -0.1130791 | CU4: 0.00809596 | CV4: -0.0452002 | CW4: -0.0589412 | CX4: -0.1077283 | CY4: -0.0965035 | CZ4: -0.2103543 | DA4: -0.1099611 | DB4: -0.1908205 | DC4: -0.0207273 | DD4: 0.08702909 | DE4: 0.08202459 | DF4: -0.1668767 | DG4: 0.22243809 | DH4: -0.1442978 | DI4: -0.1196199 | DJ4: -0.1015928 | DK4: 0.09285506 | DL4: -0.0426305 | DM4: 0.08273207 | DN4: -0.0310495 | DO4: -0.098142 | DP4: -0.1305889 | DQ4: 0.04865572 | DR4: -0.0392519 | DS4: -0.1610302 | DT4: -0.078884 | DU4: 0.16407715 | DV4: 0.00750526 | DW4: -0.1016452 | DX4: -0.0560403 | DY4: -0.1066567 | DZ4: -0.0691866 | EA4: -0.1261887 | EB4: -0.0647371 | EC4: 0.05142609 | ED4: 0.03449673 | EE4: 0.1576776 | EF4: -0.12718
B5: mom | C5: -0.05424 | D5: 0.045377 | E5: -0.01775 | F5: -0.08769 | G5: 0.102759 | H5: 0.002511 | I5: -0.0183 | J5: 0.022111 | K5: 0.077258 | L5: 0.009344 | M5: 0.053602 | N5: -0.06788 | O5: 0.06493 | P5: 0.004881 | Q5: 0.019198 | R5: -0.00547 | S5: 0.036551 | T5: 0.129185 | U5: 0.013692 | V5: 0.015295 | W5: -0.10469 | X5: -0.29385 | Y5: 0.059212 | Z5: -0.18495 | AA5: 0.098247 | AB5: -0.00066 | AC5: -0.10369 | AD5: 0.003545 | AE5: 0.175601 | AF5: -0.15503 | AG5: -0.02633 | AH5: -0.005 | AI5: 0.028068 | AJ5: -0.02238 | AK5: -0.04702 | AL5: -0.10156 | AM5: 0.023525 | AN5: 0.052525 | AO5: 0.058503 | AP5: 0.033447 | AQ5: 0.0143 | AR5: 0.035904 | AS5: 0.039782 | AT5: 0.148456 | AU5: -0.04079 | AV5: 0.138959 | AW5: 0.059863 | AX5: -0.14979 | AY5: 0.061596 | AZ5: -0.06195 | BA5: -0.00239 | BB5: -0.14887 | BC5: 0.060351 | BD5: -0.01469 | BE5: -0.14652 | BF5: -0.20876 | BG5: -0.20144 | BH5: -0.11805 | BI5: -0.07703 | BJ5: -0.03622 | BK5: -0.01891 | BL5: -0.17126 | BM5: 0.132917 | BN5: -0.03591 | BO5: 0.021345 | BP5: 0.049635 | BQ5: -0.01721 | BR5: 0.189827 | BS5: -0.09761 | BT5: 0.037831 | BU5: 0.056008 | BV5: -0.11674 | BW5: -0.14132 | BX5: -0.00338 | BY5: 0.130336 | BZ5: 0.031698 | CA5: 0.040555 | CB5: -0.04204 | CC5: 0.050014 | CD5: -0.06846 | CE5: -0.08083 | CF5: -0.00195 | CG5: -0.11821 | CH5: -0.03672 | CI5: -0.08333 | CJ5: 0.230673 | CK5: 0.132779 | CL5: 0.141287 | CM5: -0.11269 | CN5: 0.223489 | CO5: -0.10442 | CP5: -0.01443 | CQ5: -0.20723 | CR5: -0.13486 | CS5: 0.073008 | CT5: -0.03022 | CU5: -0.28689 | CV5: 0.230731 | CW5: 0.091076 | CX5: -0.12249 | CY5: 0.078382 | CZ5: -0.04595 | DA5: 0.08267 | DB5: 0.149349 | DC5: -0.0478 | DD5: -0.16451 | DE5: -0.11057 | DF5: 0.057417 | DG5: -0.21489 | DH5: 0.062997 | DI5: 0.067721 | DJ5: 0.118802 | DK5: 0.007283 | DL5: 0.071321 | DM5: 0.021022 | DN5: -0.0304 | DO5: -0.09695 | DP5: -0.23068 | DQ5: 0.238184 | DR5: 0.003575 | DS5: 0.133956 | DT5: 0.115106 | DU5: 0.10408 | DV5: -0.05461 | DW5: -0.03329 | DX5: 0.055095 | DY5: 0.068794 | DZ5: 0.014481 | EA5: -0.29314 | EB5: -0.14098 | EC5: -0.01221 | ED5: 0.058168 | EE5: -0.1444 | EF5: -0.09701
A6: 選絕對值最大 | C6: {=MATCH(MAX(ABS(C3:C5)),ABS(C3:C5),0)} -> 2 | D6: {=MATCH(MAX(ABS(D3:D5)),ABS(D3:D5),0)} -> 2 | E6: {=MATCH(MAX(ABS(E3:E5)),ABS(E3:E5),0)} -> 2 | F6: {=MATCH(MAX(ABS(F3:F5)),ABS(F3:F5),0)} -> 3 | G6: {=MATCH(MAX(ABS(G3:G5)),ABS(G3:G5),0)} -> 3 | H6: {=MATCH(MAX(ABS(H3:H5)),ABS(H3:H5),0)} -> 2 | I6: {=MATCH(MAX(ABS(I3:I5)),ABS(I3:I5),0)} -> 1 | J6: {=MATCH(MAX(ABS(J3:J5)),ABS(J3:J5),0)} -> 1 | ... EF6: {=MATCH(MAX(ABS(EF3:EF5)),ABS(EF3:EF5),0)} -> 2
C7: =IF(C6=1,"bm",IF(C6=2,"size",IF(C6=3,"mom"))) -> size | D7: =IF(D6=1,"bm",IF(D6=2,"size",IF(D6=3,"mom"))) -> size | E7: =IF(E6=1,"bm",IF(E6=2,"size",IF(E6=3,"mom"))) -> size | F7: =IF(F6=1,"bm",IF(F6=2,"size",IF(F6=3,"mom"))) -> mom | G7: =IF(G6=1,"bm",IF(G6=2,"size",IF(G6=3,"mom"))) -> mom | H7: =IF(H6=1,"bm",IF(H6=2,"size",IF(H6=3,"mom"))) -> size | I7: =IF(I6=1,"bm",IF(I6=2,"size",IF(I6=3,"mom"))) -> bm | J7: =IF(J6=1,"bm",IF(J6=2,"size",IF(J6=3,"mom"))) -> bm | ... EF7: =IF(EF6=1,"bm",IF(EF6=2,"size",IF(EF6=3,"mom"))) -> size
C8: =IF(C6=1,C3,IF(C6=2,C4,IF(C6=3,C5))) -> -0.2475887 | D8: =IF(D6=1,D3,IF(D6=2,D4,IF(D6=3,D5))) -> -0.2746933 | E8: =IF(E6=1,E3,IF(E6=2,E4,IF(E6=3,E5))) -> -0.0846484 | F8: =IF(F6=1,F3,IF(F6=2,F4,IF(F6=3,F5))) -> -0.08769 | G8: =IF(G6=1,G3,IF(G6=2,G4,IF(G6=3,G5))) -> 0.102759 | H8: =IF(H6=1,H3,IF(H6=2,H4,IF(H6=3,H5))) -> -0.1007596 | I8: =IF(I6=1,I3,IF(I6=2,I4,IF(I6=3,I5))) -> 0.18325177 | J8: =IF(J6=1,J3,IF(J6=2,J4,IF(J6=3,J5))) -> 0.11648631 | ... EF8: =IF(EF6=1,EF3,IF(EF6=2,EF4,IF(EF6=3,EF5))) -> -0.12718
A10: 投資組合 | C10: 公司數 | D10: 964
A11: 等第 | B11: 分數 | C11: 2014/01 | D11: 2014/02 | E11: 2014/03 | F11: 2014/04 | G11: 2014/05 | H11: 2014/06 | I11: 2014/07 | J11: 2014/08 | K11: 2014/09 | L11: 2014/10 | M11: 2014/11 | N11: 2014/12 | O11: 2015/01 | P11: 2015/02 | Q11: 2015/03 | R11: 2015/04 | S11: 2015/05 | T11: 2015/06 | U11: 2015/07 | V11: 2015/08 | W11: 2015/09 | X11: 2015/10 | Y11: 2015/11 | Z11: 2015/12 | AA11: 2016/01 | AB11: 2016/02 | AC11: 2016/03 | AD11: 2016/04 | AE11: 2016/05 | AF11: 2016/06 | AG11: 2016/07 | AH11: 2016/08 | AI11: 2016/09 | AJ11: 2016/10 | AK11: 2016/11 | AL11: 2016/12 | AM11: 2017/01 | AN11: 2017/02 | AO11: 2017/03 | AP11: 2017/04 | AQ11: 2017/05 | AR11: 2017/06 | AS11: 2017/07 | AT11: 2017/08 | AU11: 2017/09 | AV11: 2017/10 | AW11: 2017/11 | AX11: 2017/12 | AY11: 2018/01 | AZ11: 2018/02 | BA11: 2018/03 | BB11: 2018/04 | BC11: 2018/05 | BD11: 2018/06 | BE11: 2018/07 | BF11: 2018/08 | BG11: 2018/09 | BH11: 2018/10 | BI11: 2018/11 | BJ11: 2018/12 | BK11: 2019/01 | BL11: 2019/02 | BM11: 2019/03 | BN11: 2019/04 | BO11: 2019/05 | BP11: 2019/06 | BQ11: 2019/07 | BR11: 2019/08 | BS11: 2019/09 | BT11: 2019/10 | BU11: 2019/11 | BV11: 2019/12 | BW11: 2020/01 | BX11: 2020/02 | BY11: 2020/03 | BZ11: 2020/04 | CA11: 2020/05 | CB11: 2020/06 | CC11: 2020/07 | CD11: 2020/08 | CE11: 2020/09 | CF11: 2020/10 | CG11: 2020/11 | CH11: 2020/12 | CI11: 2021/01 | CJ11: 2021/02 | CK11: 2021/03 | CL11: 2021/04 | CM11: 2021/05 | CN11: 2021/06 | CO11: 2021/07 | CP11: 2021/08 | CQ11: 2021/09 | CR11: 2021/10 | CS11: 2021/11 | CT11: 2021/12 | CU11: 2022/01 | CV11: 2022/02 | CW11: 2022/03 | CX11: 2022/04 | CY11: 2022/05 | CZ11: 2022/06 | DA11: 2022/07 | DB11: 2022/08 | DC11: 2022/09 | DD11: 2022/10 | DE11: 2022/11 | DF11: 2022/12 | DG11: 2023/01 | DH11: 2023/02 | DI11: 2023/03 | DJ11: 2023/04 | DK11: 2023/05 | DL11: 2023/06 | DM11: 2023/07 | DN11: 2023/08 | DO11: 2023/09 | DP11: 2023/10 | DQ11: 2023/11 | DR11: 2023/12 | DS11: 2024/01 | DT11: 2024/02 | DU11: 2024/03 | DV11: 2024/04 | DW11: 2024/05 | DX11: 2024/06 | DY11: 2024/07 | DZ11: 2024/08 | EA11: 2024/09 | EB11: 2024/10 | EC11: 2024/11 | ED11: 2024/12 | EE11: 2025/01 | EF11: 2025/02
A12: 10 | B12: 96 | C12: 0.084653542 | D12: 0.11468851 | E12: 0.048026281 | F12: 0.055959385 | G12: 0.031947449 | H12: 0.038530719 | I12: 0.036303937 | J12: 0.043784579 | K12: 0.029187998 | L12: 0.041890635 | M12: 0.026889174 | N12: 0.06932675 | O12: 0.027914759 | P12: 0.021420421 | Q12: 0.033792784 | R12: 0.013397506 | S12: 0.071053897 | T12: 0.047867716 | U12: 0.020367221 | V12: 0.045029991 | W12: 0.064039646 | X12: 0.10964075 | Y12: 0.016788377 | Z12: 0.063623683 | AA12: 0.026918479 | AB12: 0.034689111 | AC12: 0.046772946 | AD12: 0.0093919792 | AE12: 0.046437717 | AF12: 0.052012103 | AG12: 0.029982145 | AH12: 0.013405805 | AI12: 0.023246958 | AJ12: 0.012983748 | AK12: 0.048123704 | AL12: 0.03410526 | AM12: 0.030086116 | AN12: 0.069233234 | AO12: 0.014995471 | AP12: 0.033718345 | AQ12: 0.0066816458 | AR12: 0.0075043646 | AS12: 0.019976273 | AT12: 0.072195382 | AU12: 0.063410188 | AV12: 0.053715631 | AW12: 0.017169705 | AX12: 0.044696012 | AY12: 0.024955293 | AZ12: 0.06656425 | BA12: 0.071276302 | BB12: 0.029036655 | BC12: 0.026690966 | BD12: 0.049233948 | BE12: 0.035368545 | BF12: 0.067616949 | BG12: 0.046757754 | BH12: 0.035079589 | BI12: 0.050021253 | BJ12: 0.043422969 | BK12: 0.020075823 | BL12: 0.032129098 | BM12: 0.050305685 | BN12: 0.01950225 | BO12: 0.02424631 | BP12: 0.0264225 | BQ12: 0.01389675 | BR12: 0.068693615 | BS12: 0.032642855 | BT12: 0.021288177 | BU12: 0.048083198 | BV12: 0.042282389 | BW12: 0.044477004 | BX12: 0.015984312 | BY12: 0.058929916 | BZ12: 0.045356946 | CA12: 0.034400287 | CB12: 0.072475719 | CC12: 0.065566042 | CD12: 0.11093363 | CE12: 0.15400716 | CF12: 0.027767583 | CG12: 0.04927796 | CH12: 0.063297372 | CI12: 0.034655912 | CJ12: 0.054120067 | CK12: 0.056101441 | CL12: 0.11801561 | CM12: 0.071708563 | CN12: 0.078465204 | CO12: 0.071291854 | CP12: 0.045299021 | CQ12: 0.062684347 | CR12: 0.057159987 | CS12: 0.00097857359 | CT12: 0.032113958 | CU12: 0.074779529 | CV12: 0.065033306 | CW12: 0.013036669 | CX12: 0.060989883 | CY12: 0.046072656 | CZ12: 0.077792327 | DA12: 0.036978521 | DB12: 0.088981854 | DC12: 0.033973203 | DD12: 0.069960546 | DE12: 0.024737644 | DF12: 0.055486104 | DG12: 0.046409979 | DH12: 0.061195427 | DI12: 0.05974901 | DJ12: 0.041378043 | DK12: 0.031928208 | DL12: 0.018669833 | DM12: 0.019237615 | DN12: 0.042410365 | DO12: 0.03055726 | DP12: 0.059408695 | DQ12: 0.074540647 | DR12: 0.018778943 | DS12: 0.06965101 | DT12: 0.024813842 | DU12: 0.057230229 | DV12: 0.048550824 | DW12: 0.044967552 | DX12: 0.050152081 | DY12: 0.053145313 | DZ12: 0.0062268438 | EA12: 0.11312704 | EB12: 0.030525777 | EC12: 0.02665151 | ED12: 0.060508153 | EE12: 0.026506688 | EF12: 0.029233396
A13: 20 | B13: 48 | C13: 0.10411315 | D13: 0.1237451 | E13: 0.069861292 | F13: 0.059986527 | G13: 0.012047404 | H13: 0.029990354 | I13: 0.032682863 | J13: 0.034549892 | K13: 0.060326139 | L13: 0.0060251042 | M13: 0.0032797582 | N13: 0.099806729 | O13: 0.017422699 | P13: 0.020856913 | Q13: 0.044218264 | R13: 0.0064899102 | S13: 0.1229153 | T13: 0.074234082 | U13: 0.054161075 | V13: 0.052779739 | W13: 0.075476396 | X13: 0.12112777 | Y13: 0.026471883 | Z13: 0.078424435 | AA13: 0.047712648 | AB13: 0.04667822 | AC13: 0.0667717 | AD13: 0.021543083 | AE13: 0.077071417 | AF13: 0.073281161 | AG13: 0.031681783 | AH13: 0.0096413392 | AI13: 0.019910042 | AJ13: -0.01628047 | AK13: 0.065987913 | AL13: 0.022550104 | AM13: 0.046282444 | AN13: 0.10533024 | AO13: -0.0017088467 | AP13: 0.05955084 | AQ13: 0.011081896 | AR13: -0.0092504167 | AS13: 0.023404964 | AT13: 0.086422915 | AU13: 0.076783979 | AV13: 0.079665976 | AW13: 0.026821238 | AX13: 0.032799832 | AY13: 0.017564346 | AZ13: 0.055450188 | BA13: 0.079829271 | BB13: 0.022547401 | BC13: 0.019110867 | BD13: 0.041676729 | BE13: 0.043773789 | BF13: 0.12165714 | BG13: 0.088397546 | BH13: 0.041023656 | BI13: 0.052409132 | BJ13: 0.051452562 | BK13: 0.025126021 | BL13: 0.03446004 | BM13: 0.053371769 | BN13: -0.0048578333 | BO13: 0.030878716 | BP13: 0.0079520417 | BQ13: 0.041653064 | BR13: 0.079831457 | BS13: 0.040180514 | BT13: 0.033667896 | BU13: 0.074658167 | BV13: 0.079930834 | BW13: 0.075714006 | BX13: 0.0014771042 | BY13: 0.039201957 | BZ13: 0.076138123 | CA13: 0.033531566 | CB13: 0.12042692 | CC13: 0.12011792 | CD13: 0.10508583 | CE13: 0.18382773 | CF13: 0.044514267 | CG13: 0.058014968 | CH13: 0.058334612 | CI13: 0.051853509 | CJ13: 0.054810181 | CK13: 0.065687126 | CL13: 0.081453366 | CM13: 0.10145233 | CN13: 0.10099417 | CO13: 0.085566146 | CP13: 0.06972654 | CQ13: 0.071178865 | CR13: 0.11164489 | CS13: 0.0095676537 | CT13: 0.043462167 | CU13: 0.10709096 | CV13: 0.077656051 | CW13: 0.03630912 | CX13: 0.060033255 | CY13: 0.062296646 | CZ13: 0.05722422 | DA13: 0.049445771 | DB13: 0.10623525 | DC13: 0.029775566 | DD13: 0.068977059 | DE13: 0.022441996 | DF13: 0.083122687 | DG13: 0.047729313 | DH13: 0.088720708 | DI13: 0.089748125 | DJ13: 0.0070211236 | DK13: 0.019386396 | DL13: 0.022050691 | DM13: -0.00053195833 | DN13: 0.011499578 | DO13: 0.037863854 | DP13: 0.058032309 | DQ13: 0.087129011 | DR13: 0.013771209 | DS13: 0.068596688 | DT13: 0.029845809 | DU13: 0.033005958 | DV13: 0.079620144 | DW13: 0.042028479 | DX13: 0.06452338 | DY13: 0.056981146 | DZ13: 0.018301979 | EA13: 0.12446896 | EB13: 0.057205293 | EC13: 0.041659753 | ED13: 0.065682094 | EE13: 0.041234375 | EF13: 0.044513042
A14: 50 | B14: 19 | C14: 0.11994163 | D14: 0.22230879 | E14: 0.098768158 | F14: 0.060341905 | G14: 0.05365663 | H14: 0.059588947 | I14: 0.04378736 | J14: 0.023309972 | K14: 0.050827466 | L14: 0.0084802105 | M14: -0.019021714 | N14: 0.20483268 | O14: 0.0014944079 | P14: 0.058345922 | Q14: 0.12410387 | R14: -0.015941187 | S14: 0.16589323 | T14: 0.035019555 | U14: 0.10426666 | V14: 0.020089127 | W14: 0.11616537 | X14: 0.1866857 | Y14: 0.0052198746 | Z14: 0.038511926 | AA14: 0.099905879 | AB14: 0.070769377 | AC14: -0.0030865623 | AD14: 0.039327947 | AE14: 0.11683692 | AF14: 0.096080095 | AG14: 0.020520895 | AH14: 0.0052502779 | AI14: 0.010965316 | AJ14: 0.015059036 | AK14: 0.076911431 | AL14: 0.018559105 | AM14: 0.061242166 | AN14: 0.098594667 | AO14: -0.038044353 | AP14: 0.069976525 | AQ14: 0.0081264211 | AR14: -0.018170474 | AS14: -0.0066693384 | AT14: 0.07940348 | AU14: 0.13785311 | AV14: 0.066258749 | AW14: 0.053928681 | AX14: 0.019370213 | AY14: 0.015068119 | AZ14: 0.025629 | BA14: 0.096337421 | BB14: 0.11031125 | BC14: -0.028505683 | BD14: 0.016418895 | BE14: 0.07008177 | BF14: 0.15382926 | BG14: 0.12530531 | BH14: 0.073413464 | BI14: 0.050185213 | BJ14: 0.024017895 | BK14: -0.033237211 | BL14: 0.059996896 | BM14: 0.046278325 | BN14: -0.046576842 | BO14: 0.033609046 | BP14: -0.050331684 | BQ14: 0.015843524 | BR14: 0.10005242 | BS14: 0.030332724 | BT14: -0.015288316 | BU14: 0.11116011 | BV14: 0.10798163 | BW14: 0.13089751 | BX14: -0.00030736842 | BY14: -0.04260449 | BZ14: 0.060034057 | CA14: 0.024465266 | CB14: 0.16446579 | CC14: 0.12059521 | CD14: 0.09801671 | CE14: 0.17055484 | CF14: 0.092330683 | CG14: 0.057320664 | CH14: 0.064661392 | CI14: 0.10588478 | CJ14: 0.017796116 | CK14: 0.053792087 | CL14: 0.062269955 | CM14: 0.11006784 | CN14: 0.17459567 | CO14: 0.17324926 | CP14: 0.099809331 | CQ14: 0.0322279 | CR14: 0.20771971 | CS14: -0.0044126335 | CT14: 0.061872211 | CU14: 0.101545 | CV14: 0.15139684 | CW14: 0.044763884 | CX14: 0.036299409 | CY14: 0.050138053 | CZ14: 0.064063563 | DA14: 0.065392579 | DB14: 0.10460805 | DC14: 0.023632609 | DD14: 0.079205352 | DE14: 0.062526924 | DF14: 0.20156447 | DG14: 0.045583632 | DH14: 0.058742579 | DI14: 0.086646789 | DJ14: 0.0087940294 | DK14: 0.081621684 | DL14: 0.040754872 | DM14: 0.0011206842 | DN14: 0.042662496 | DO14: 0.102592 | DP14: 0.062914808 | DQ14: 0.071172565 | DR14: 0.052622519 | DS14: 0.056051684 | DT14: 0.0077542903 | DU14: 0.068796263 | DV14: 0.10826235 | DW14: 0.0018098947 | DX14: 0.10193151 | DY14: 0.074257842 | DZ14: 0.035030895 | EA14: 0.062912685 | EB14: 0.078179831 | EC14: 0.0060793821 | ED14: 0.10262971 | EE14: -0.0033992632 | EF14: 0.025524211
A15: 100 | B15: 10 | C15: 0.2276451 | D15: 0.3727097 | E15: 0.0620446 | F15: -0.034921437 | G15: 0.034403921 | H15: 0.1188444 | I15: 0.058431444 | J15: 0.049961465 | K15: 0.094514798 | L15: -0.0129669 | M15: -0.0021330164 | N15: 0.3303096 | O15: -0.012270796 | P15: 0.064116183 | Q15: 0.15553684 | R15: -0.05212969 | S15: 0.2700079 | T15: 0.045891077 | U15: 0.13696806 | V15: -0.017131853 | W15: 0.1069346 | X15: 0.21118633 | Y15: -0.020629974 | Z15: 0.046719972 | AA15: 0.16085038 | AB15: 0.083700173 | AC15: 0.0043176688 | AD15: 0.0396904 | AE15: 0.21179264 | AF15: 0.13772629 | AG15: 0.010123478 | AH15: -0.033604373 | AI15: 0.0742774 | AJ15: 0.00946486 | AK15: 0.06175962 | AL15: -0.0068828 | AM15: 0.055122622 | AN15: 0.10168871 | AO15: -0.05138452 | AP15: 0.078285694 | AQ15: 0.0197473 | AR15: -0.0245503 | AS15: -0.048733221 | AT15: 0.070989813 | AU15: 0.167109 | AV15: 0.037297929 | AW15: 0.091727473 | AX15: 0.081360566 | AY15: 0.028017064 | AZ15: 0.0368481 | BA15: 0.1576883 | BB15: 0.19771315 | BC15: -0.030936692 | BD15: 0.0073647 | BE15: 0.041397971 | BF15: 0.21087209 | BG15: 0.16605122 | BH15: 0.098649046 | BI15: 0.068586659 | BJ15: 0.075155 | BK15: -0.0728692 | BL15: 0.059755421 | BM15: 0.048219004 | BN15: -0.0660549 | BO15: 0.027734476 | BP15: -0.0516158 | BQ15: 0.012802931 | BR15: 0.12376214 | BS15: 0.011865911 | BT15: 0.0366326 | BU15: 0.0855465 | BV15: 0.10464004 | BW15: 0.29887899 | BX15: 0.02395 | BY15: -0.12602357 | BZ15: 0.10290647 | CA15: 0.018592021 | CB15: 0.1310916 | CC15: 0.1736496 | CD15: 0.12015208 | CE15: 0.0733674 | CF15: 0.09435665 | CG15: 0.085886022 | CH15: 0.062885958 | CI15: 0.038798415 | CJ15: 0.040671717 | CK15: 0.095640748 | CL15: 0.031421975 | CM15: 0.1081179 | CN15: 0.14314982 | CO15: 0.1733599 | CP15: 0.12753584 | CQ15: -0.02496336 | CR15: 0.18148893 | CS15: 0.0064830511 | CT15: 0.0322169 | CU15: 0.12404993 | CV15: 0.18261155 | CW15: 0.026072091 | CX15: 0.024039607 | CY15: 0.0557329 | CZ15: 0.079886948 | DA15: 0.0888618 | DB15: 0.0970477 | DC15: 0.03507515 | DD15: 0.014506726 | DE15: 0.057163635 | DF15: 0.3027216 | DG15: 0.0479178 | DH15: 0.1296235 | DI15: 0.042811 | DJ15: 0.060023777 | DK15: 0.100329 | DL15: -0.0003039932 | DM15: -0.0017735 | DN15: 0.043996497 | DO15: 0.1595456 | DP15: 0.13430495 | DQ15: 0.037038689 | DR15: 0.070010567 | DS15: 0.0375299 | DT15: 0.05271879 | DU15: 0.1171285 | DV15: 0.13976836 | DW15: -0.0608268 | DX15: 0.11861625 | DY15: 0.1436096 | DZ15: 0.0404552 | EA15: 0.04345122 | EB15: 0.08808745 | EC15: 0.066081856 | ED15: 0.11335706 | EE15: 0.0031902 | EF15: 0.0296441
A16: 107 | B16: 9 | C16: 0.20787511 | D16: 0.40819544 | E16: 0.065004889 | F16: -0.078715472 | G16: 0.0081465507 | H16: 0.072848778 | I16: 0.057530619 | J16: 0.046709926 | K16: 0.086420892 | L16: -0.031026556 | M16: -0.013987436 | N16: 0.36698789 | O16: -0.028587077 | P16: 0.061045232 | Q16: 0.15790307 | R16: -0.048990978 | S16: 0.28706302 | T16: 0.038406673 | U16: 0.13006247 | V16: -0.0060221453 | W16: 0.078373444 | X16: 0.24053196 | Y16: -0.020180588 | Z16: 0.043057931 | AA16: 0.16615889 | AB16: 0.074985042 | AC16: -0.012765448 | AD16: 0.034811 | AE16: 0.20962824 | AF16: 0.14791561 | AG16: 0.013290753 | AH16: -0.0317654 | AI16: 0.090523111 | AJ16: -0.0070259661 | AK16: 0.064421401 | AL16: -0.014473667 | AM16: 0.066076731 | AN16: 0.1064562 | AO16: -0.041090153 | AP16: 0.077798368 | AQ16: 0.024032556 | AR16: -0.032492222 | AS16: -0.052642718 | AT16: 0.12256404 | AU16: 0.17023656 | AV16: 0.052080835 | AW16: 0.10898494 | AX16: 0.10062133 | AY16: 0.03381259 | AZ16: 0.046827889 | BA16: 0.15999111 | BB16: 0.22547356 | BC16: -0.038999392 | BD16: 0.0062841111 | BE16: 0.061197644 | BF16: 0.24778686 | BG16: 0.16122957 | BH16: 0.096162035 | BI16: 0.041443808 | BJ16: 0.081428889 | BK16: -0.10477322 | BL16: 0.061173599 | BM16: 0.039497985 | BN16: -0.067199333 | BO16: 0.02189036 | BP16: -0.057748889 | BQ16: 0.016478016 | BR16: 0.13058297 | BS16: 0.032006987 | BT16: 0.038065333 | BU16: 0.10153722 | BV16: 0.036585638 | BW16: 0.31797083 | BX16: 0.024078889 | BY16: -0.13255841 | BZ16: 0.11152585 | CA16: 0.02971439 | CB16: 0.139309 | CC16: 0.044386333 | CD16: 0.15507127 | CE16: 0.093613778 | CF16: 0.10520126 | CG16: 0.061727878 | CH16: 0.041697415 | CI16: 0.038709882 | CJ16: 0.029703385 | CK16: 0.08842269 | CL16: 0.015878682 | CM16: 0.11305433 | CN16: 0.16035992 | CO16: 0.209547 | CP16: 0.13663169 | CQ16: -0.02033378 | CR16: 0.18928653 | CS16: 0.040852188 | CT16: 0.048903889 | CU16: 0.1354717 | CV16: 0.17225152 | CW16: 0.047341659 | CX16: 0.012240285 | CY16: 0.058554556 | CZ16: 0.10263326 | DA16: 0.11818056 | DB16: 0.098016667 | DC16: 0.042942362 | DD16: 0.03174371 | DE16: 0.0345524 | DF16: 0.32558089 | DG16: 0.045677 | DH16: 0.13714944 | DI16: 0.047828778 | DJ16: 0.070955052 | DK16: 0.096254333 | DL16: -0.021872874 | DM16: -0.038135333 | DN16: 0.042437853 | DO16: 0.16959067 | DP16: 0.16033399 | DQ16: 0.047070156 | DR16: 0.055191252 | DS16: 0.021439889 | DT16: 0.059112975 | DU16: 0.122773 | DV16: 0.13695373 | DW16: -0.071303111 | DX16: 0.12528471 | DY16: 0.15757178 | DZ16: 0.058810444 | EA16: 0.00042051524 | EB16: 0.1006791 | EC16: 0.063532067 | ED16: 0.11541675 | EE16: 0.0043961111 | EF16: 0.034548444
A17: 120 | B17: 8 | C17: 0.20609237 | D17: 0.43958837 | E17: 0.079588 | F17: -0.080752164 | G17: 0.10538707 | H17: 0.10499475 | I17: 0.11372503 | J17: 0.041858395 | K17: 0.10156008 | L17: -0.033774875 | M17: 0.014659142 | N17: 0.40510825 | O17: -0.011306676 | P17: 0.066339369 | Q17: 0.16180129 | R17: -0.052057609 | S17: 0.31065343 | T17: 0.023342586 | U17: 0.14127114 | V17: 0.0040111898 | W17: 0.079142125 | X17: 0.23798943 | Y17: -0.022928011 | Z17: 0.053868489 | AA17: 0.19128344 | AB17: 0.084852063 | AC17: -0.020086255 | AD17: 0.068619875 | AE17: 0.2221227 | AF17: 0.12028632 | AG17: 0.022740981 | AH17: -0.035472619 | AI17: 0.11486512 | AJ17: -0.042602631 | AK17: 0.073716275 | AL17: -0.009984875 | AM17: 0.075369368 | AN17: 0.11328712 | AO17: -0.076694528 | AP17: 0.077242814 | AQ17: 0.009230375 | AR17: -0.034996625 | AS17: -0.058802957 | AT17: 0.12707179 | AU17: 0.17756263 | AV17: 0.058529449 | AW17: 0.07618961 | AX17: 0.097619105 | AY17: 0.027423697 | AZ17: 0.047981375 | BA17: 0.1628065 | BB17: 0.23044204 | BC17: -0.027292824 | BD17: 0.019414125 | BE17: 0.044110253 | BF17: 0.14777683 | BG17: 0.18575158 | BH17: 0.13319111 | BI17: 0.087111945 | BJ17: 0.0891925 | BK17: -0.11481613 | BL17: 0.034152447 | BM17: 0.029059011 | BN17: -0.073658 | BO17: 0.035179615 | BP17: -0.060636875 | BQ17: 0.01137651 | BR17: 0.11502235 | BS17: 0.020906018 | BT17: 0.03364725 | BU17: 0.10452438 | BV17: 0.038240957 | BW17: 0.20833683 | BX17: 0.0070965 | BY17: -0.14247738 | BZ17: 0.12057816 | CA17: 0.027934832 | CB17: 0.14963338 | CC17: 0.0417585 | CD17: 0.17295974 | CE17: 0.095707625 | CF17: 0.098746197 | CG17: 0.074714989 | CH17: 0.058636447 | CI17: 0.014531185 | CJ17: 0.020950827 | CK17: 0.083955848 | CL17: -0.0094263448 | CM17: 0.095492625 | CN17: 0.17653128 | CO17: 0.19808038 | CP17: 0.14815927 | CQ17: 0.051907103 | CR17: 0.19640263 | CS17: 0.031345818 | CT17: 0.05865425 | CU17: 0.15535189 | CV17: 0.15147138 | CW17: 0.063393219 | CX17: 0.010772395 | CY17: 0.059498125 | CZ17: 0.12424884 | DA17: 0.094495625 | DB17: 0.104271 | DC17: 0.043363469 | DD17: 0.029155421 | DE17: 0.024124863 | DF17: 0.35222738 | DG17: 0.047211125 | DH17: 0.16343337 | DI17: 0.07018125 | DJ17: 0.12892506 | DK17: 0.10277988 | DL17: -0.0039297317 | DM17: -0.0425635 | DN17: 0.035489033 | DO17: 0.179762 | DP17: 0.14203416 | DQ17: 0.072654005 | DR17: 0.055884815 | DS17: 0.037353625 | DT17: 0.059811935 | DU17: 0.129494 | DV17: 0.1177654 | DW17: -0.07659975 | DX17: 0.12953898 | DY17: 0.10728225 | DZ17: 0.049212 | EA17: -0.0046325242 | EB17: 0.10728533 | EC17: 0.016425217 | ED17: 0.12832444 | EE17: -0.000194375 | EF17: 0.04098475
A18: 137 | B18: 7 | C18: 0.18975114 | D18: 0.401884 | E18: 0.053437857 | F18: -0.11938296 | G18: 0.10831637 | H18: 0.12854 | I18: 0.13550018 | J18: 0.043411516 | K18: 0.13564789 | L18: -0.046671571 | M18: 0.029051464 | N18: 0.46182043 | O18: 0.031737941 | P18: 0.082552612 | Q18: 0.18897542 | R18: -0.061492238 | S18: 0.38373263 | T18: 0.052309698 | U18: 0.13249502 | V18: 0.012895135 | W18: 0.077297 | X18: 0.21512106 | Y18: -0.019232334 | Z18: 0.089234363 | AA18: 0.17257066 | AB18: 0.0846983 | AC18: 0.0013654205 | AD18: 0.096285857 | AE18: 0.25839135 | AF18: 0.15054364 | AG18: 0.032493116 | AH18: -0.040197461 | AI18: 0.11808643 | AJ18: -0.047393756 | AK18: 0.030152481 | AL18: -0.00085714286 | AM18: 0.066643405 | AN18: 0.07929464 | AO18: 0.02458428 | AP18: 0.078278592 | AQ18: -0.016788143 | AR18: -0.061694429 | AS18: -0.083253128 | AT18: 0.16638581 | AU18: 0.19666014 | AV18: 0.060235665 | AW18: 0.097766862 | AX18: 0.12606434 | AY18: 0.034783279 | AZ18: 0.066342 | BA18: 0.18047986 | BB18: 0.31745743 | BC18: 0.027942051 | BD18: 0.020277714 | BE18: 0.091172853 | BF18: 0.16498649 | BG18: 0.14671397 | BH18: 0.13789827 | BI18: 0.10900001 | BJ18: 0.099532714 | BK18: -0.073456143 | BL18: 0.055787881 | BM18: 0.028081356 | BN18: -0.078210143 | BO18: 0.020227496 | BP18: -0.062462 | BQ18: 0.0019167841 | BR18: 0.12096182 | BS18: 0.032873257 | BT18: 0.013298857 | BU18: 0.11146214 | BV18: 0.039624426 | BW18: 0.2183755 | BX18: -0.015810714 | BY18: -0.087465268 | BZ18: 0.15331999 | CA18: 0.016076544 | CB18: 0.10684629 | CC18: 0.10465971 | CD18: 0.19371682 | CE18: 0.077259857 | CF18: 0.071817592 | CG18: 0.091609256 | CH18: 0.16265705 | CI18: 0.03886914 | CJ18: -0.0037723665 | CK18: 0.096058032 | CL18: -0.030989545 | CM18: 0.10276871 | CN18: 0.12094313 | CO18: 0.228282 | CP18: 0.16283911 | CQ18: 0.038242676 | CR18: 0.19372241 | CS18: 0.057690649 | CT18: 0.076870857 | CU18: 0.14456482 | CV18: 0.12702227 | CW18: 0.066558574 | CX18: 0.061560186 | CY18: 0.071432143 | CZ18: 0.13284286 | DA18: 0.078357857 | DB18: 0.118114 | DC18: 0.036408781 | DD18: 0.041014187 | DE18: 0.038420587 | DF18: 0.36669357 | DG18: 0.054770714 | DH18: 0.19240257 | DI18: 0.097962857 | DJ18: 0.14619608 | DK18: 0.10652586 | DL18: -0.0038302741 | DM18: -0.058456714 | DN18: -0.016722064 | DO18: 0.22031957 | DP18: 0.13348647 | DQ18: 0.065749458 | DR18: 0.076840655 | DS18: 0.011277143 | DT18: 0.022601035 | DU18: 0.15871543 | DV18: 0.10564061 | DW18: -0.068637857 | DX18: 0.15360298 | DY18: 0.13683229 | DZ18: 0.054629714 | EA18: -0.0047382972 | EB18: 0.10996435 | EC18: 0.0027641154 | ED18: 0.11047802 | EE18: 0.0011102857 | EF18: 0.063951857
A19: 160 | B19: 6 | C19: 0.19659983 | D19: 0.40752133 | E19: 0.0658125 | F19: -0.17768866 | G19: 0.096065972 | H19: 0.17761017 | I19: 0.13465433 | J19: 0.035429585 | K19: 0.23878941 | L19: -0.030361167 | M19: -0.043690236 | N19: 0.5323745 | O19: 0.031561874 | P19: 0.092534186 | Q19: 0.19716309 | R19: -0.090299091 | S19: 0.18416012 | T19: 0.051464717 | U19: 0.13569834 | V19: 0.036618688 | W19: 0.072415833 | X19: 0.14939987 | Y19: -0.025628638 | Z19: 0.091619111 | AA19: 0.1318329 | AB19: 0.10225361 | AC19: 0.014141543 | AD19: 0.095992833 | AE19: 0.30849286 | AF19: 0.16883058 | AG19: 0.022136219 | AH19: -0.056557715 | AI19: 0.091549333 | AJ19: -0.05154529 | AK19: 0.0075520425 | AL19: -0.0011383333 | AM19: 0.043106012 | AN19: 0.083568294 | AO19: 0.055890126 | AP19: 0.08757412 | AQ19: -0.054927833 | AR19: -0.074616833 | AS19: -0.10919888 | AT19: 0.18459366 | AU19: 0.23884517 | AV19: -0.0030326096 | AW19: 0.1366934 | AX19: 0.2241238 | AY19: 0.02952897 | AZ19: 0.084032333 | BA19: 0.186997 | BB19: 0.36416093 | BC19: 0.18457179 | BD19: -7.0833333e-05 | BE19: 0.089480722 | BF19: 0.14180943 | BG19: 0.15330875 | BH19: 0.14049691 | BI19: 0.12779863 | BJ19: 0.051820167 | BK19: -0.097038833 | BL19: 0.063164534 | BM19: 0.031786265 | BN19: -0.081415167 | BO19: 0.025728961 | BP19: -0.012408667 | BQ19: 0.0099340445 | BR19: 0.13683924 | BS19: -0.0034999319 | BT19: -0.013194833 | BU19: 0.13067083 | BV19: 0.030350792 | BW19: 0.30745301 | BX19: -0.036397167 | BY19: -0.079866927 | BZ19: 0.068702125 | CA19: 0.029328755 | CB19: 0.1278385 | CC19: 0.022505667 | CD19: 0.2156192 | CE19: 0.088474167 | CF19: 0.079904397 | CG19: 0.057117625 | CH19: 0.15288987 | CI19: 0.037066946 | CJ19: -0.011811923 | CK19: 0.11879726 | CL19: -0.04324028 | CM19: 0.11023517 | CN19: 0.14319321 | CO19: 0.25123567 | CP19: 0.1590326 | CQ19: 0.032394608 | CR19: 0.17630672 | CS19: 0.05425045 | CT19: 0.026422 | CU19: 0.14660754 | CV19: 0.094553008 | CW19: 0.060515879 | CX19: 0.057634726 | CY19: 0.073150833 | CZ19: 0.11285183 | DA19: 0.0751825 | DB19: 0.147961 | DC19: -0.0351794 | DD19: 0.0062011253 | DE19: 0.033018415 | DF19: 0.20550283 | DG19: 0.0663745 | DH19: 0.22459133 | DI19: 0.10846167 | DJ19: 0.16525047 | DK19: 0.12144067 | DL19: -0.011982786 | DM19: -0.057299833 | DN19: 0.0024751231 | DO19: 0.24926117 | DP19: 0.17026813 | DQ19: 0.080374172 | DR19: 0.075962353 | DS19: -0.0056783333 | DT19: 0.0050332465 | DU19: 0.1505825 | DV19: 0.11152471 | DW19: -0.101297 | DX19: 0.13836513 | DY19: 0.139248 | DZ19: 0.0785375 | EA19: 0.032919727 | EB19: 0.10875351 | EC19: -0.012190043 | ED19: 0.15093532 | EE19: -0.0073063333 | EF19: 0.07402
A20: 192 | B20: 5 | C20: 0.201551 | D20: 0.3820258 | E20: 0.0573352 | F20: -0.20553126 | G20: 0.11718314 | H20: 0.1439322 | I20: 0.15814956 | J20: 0.034471259 | K20: 0.2147245 | L20: -0.0306936 | M20: -0.077718228 | N20: 0.5000116 | O20: 0.049864886 | P20: 0.091169928 | Q20: 0.21672574 | R20: -0.10925306 | S20: 0.15518262 | T20: 0.085465456 | U20: 0.14864968 | V20: 0.012644103 | W20: 0.091085 | X20: 0.21038641 | Y20: -0.04206749 | Z20: 0.10561696 | AA20: 0.13048337 | AB20: 0.084759841 | AC20: 0.047248263 | AD20: 0.1298426 | AE20: 0.16122121 | AF20: 0.22349782 | AG20: 0.027659219 | AH20: -0.090178201 | AI20: 0.1163372 | AJ20: -0.061990035 | AK20: -0.013595115 | AL20: -0.005618 | AM20: 0.033095981 | AN20: 0.075470194 | AO20: 0.049108295 | AP20: 0.13173046 | AQ20: 0.0728986 | AR20: -0.0132892 | AS20: -0.042291716 | AT20: 0.23912375 | AU20: 0.281699 | AV20: -0.032246613 | AW20: 0.22499784 | AX20: 0.20433922 | AY20: 0.038674698 | AZ20: 0.0998042 | BA20: 0.151338 | BB20: 0.37844679 | BC20: 0.24014067 | BD20: 0.0083636 | BE20: 0.098278375 | BF20: 0.13797126 | BG20: 0.094062056 | BH20: 0.1500573 | BI20: 0.13174527 | BJ20: 0.0551578 | BK20: -0.117651 | BL20: 0.069859442 | BM20: 0.047468551 | BN20: 0.018636 | BO20: -0.038461718 | BP20: 0.0072838 | BQ20: 0.015451707 | BR20: 0.18112708 | BS20: -0.032536198 | BT20: -0.0524686 | BU20: 0.149441 | BV20: -0.081543442 | BW20: 0.35182955 | BX20: -0.0528586 | BY20: -0.0046393591 | BZ20: 0.090271404 | CA20: 0.040102728 | CB20: 0.1264954 | CC20: 0.0129148 | CD20: 0.1810275 | CE20: 0.0857774 | CF20: 0.080957937 | CG20: 0.075970241 | CH20: 0.071864026 | CI20: 0.030394674 | CJ20: -0.041509985 | CK20: 0.080589624 | CL20: -0.092184934 | CM20: 0.0967742 | CN20: 0.20489183 | CO20: 0.2965734 | CP20: 0.19203121 | CQ20: 0.023118045 | CR20: 0.19548611 | CS20: 0.097137099 | CT20: 0.0284154 | CU20: 0.14672801 | CV20: 0.11921413 | CW20: 0.067903708 | CX20: 0.090298551 | CY20: 0.1087322 | CZ20: 0.15516165 | DA20: 0.0770816 | DB20: 0.076967 | DC20: -0.049613069 | DD20: 0.0035971848 | DE20: 0.010418722 | DF20: 0.2455754 | DG20: 0.0523458 | DH20: 0.2782996 | DI20: 0.137596 | DJ20: 0.13655809 | DK20: 0.0851846 | DL20: -0.019465373 | DM20: -0.0693358 | DN20: 0.058019207 | DO20: 0.258001 | DP20: 0.20015543 | DQ20: 0.057460182 | DR20: 0.07851266 | DS20: -0.007492 | DT20: -0.029685339 | DU20: 0.1763758 | DV20: 0.12934547 | DW20: -0.1035466 | DX20: 0.15386633 | DY20: 0.1215906 | DZ20: 0.0901994 | EA20: -0.0059255993 | EB20: 0.082407142 | EC20: 0.034049581 | ED20: 0.17691886 | EE20: -0.0017416 | EF20: 0.0858
A21: 241 | B21: 4 | C21: 0.2146305 | D21: 0.126389 | E21: -0.0136915 | F21: -0.18403858 | G21: 0.14384215 | H21: 0.162164 | I21: 0.14725561 | J21: 0.060435326 | K21: 0.20688003 | L21: 0.005031 | M21: -0.099684593 | N21: 0.5848905 | O21: 0.034351989 | P21: 0.1447726 | Q21: 0.25731007 | R21: -0.095575311 | S21: 0.12859029 | T21: 0.098461673 | U21: 0.086278418 | V21: 0.053557619 | W21: 0.12449875 | X21: 0.21363094 | Y21: -0.020833083 | Z21: 0.11420399 | AA21: 0.11063591 | AB21: 0.12983958 | AC21: 0.018827737 | AD21: 0.1288245 | AE21: 0.12810498 | AF21: 0.29514426 | AG21: 0.044302778 | AH21: -0.10758136 | AI21: 0.10212425 | AJ21: -0.070405342 | AK21: -0.035803168 | AL21: 0.01978025 | AM21: 0.068535807 | AN21: 0.11195606 | AO21: 0.085567775 | AP21: 0.072535144 | AQ21: 0.133224 | AR21: 0.04798825 | AS21: -0.045406682 | AT21: 0.26483826 | AU21: 0.34648125 | AV21: -0.068713913 | AW21: 0.26325492 | AX21: 0.2177183 | AY21: 0.047021291 | AZ21: 0.108503 | BA21: 0.1395925 | BB21: 0.40443143 | BC21: 0.16446053 | BD21: 0.0382225 | BE21: 0.13674536 | BF21: 0.19911722 | BG21: 0.092285572 | BH21: 0.10684211 | BI21: 0.1659696 | BJ21: 0.02239625 | BK21: -0.07272375 | BL21: 0.08734079 | BM21: 0.040795286 | BN21: 0.02578825 | BO21: -0.063857236 | BP21: -0.00418 | BQ21: 0.054542231 | BR21: 0.14206146 | BS21: -0.065741821 | BT21: -0.060822 | BU21: 0.170738 | BV21: -0.04433998 | BW21: 0.18446067 | BX21: -0.07716325 | BY21: -0.055666292 | BZ21: 0.047662929 | CA21: 0.060517603 | CB21: 0.20787025 | CC21: -0.0080195 | CD21: 0.28805606 | CE21: 0.0615145 | CF21: 0.13126568 | CG21: 0.085085335 | CH21: 0.080100321 | CI21: 0.080499616 | CJ21: -0.055140849 | CK21: 0.06715963 | CL21: -0.13389042 | CM21: 0.11623025 | CN21: 0.080851509 | CO21: 0.335483 | CP21: 0.22270006 | CQ21: 0.022912194 | CR21: 0.23905997 | CS21: 0.061269036 | CT21: 0.04799475 | CU21: 0.15891662 | CV21: 0.15433184 | CW21: 0.038345517 | CX21: 0.10212218 | CY21: 0.10250525 | CZ21: 0.23745137 | DA21: 0.04170975 | DB21: 0.0714595 | DC21: -0.045047559 | DD21: 0.0028187944 | DE21: 0.028977737 | DF21: 0.30115175 | DG21: 0.05941075 | DH21: 0.081437 | DI21: 0.17984 | DJ21: 0.15660572 | DK21: 0.09089325 | DL21: -0.012736992 | DM21: -0.02498825 | DN21: 0.071197612 | DO21: 0.33162625 | DP21: 0.22901989 | DQ21: 0.070422699 | DR21: 0.050170859 | DS21: -0.00167375 | DT21: -0.0052151903 | DU21: 0.14861475 | DV21: 0.14027598 | DW21: -0.103536 | DX21: 0.18596621 | DY21: 0.16673 | DZ21: 0.09893 | EA21: -0.035066457 | EB21: 0.026302194 | EC21: 0.014037055 | ED21: 0.054498856 | EE21: 0.02131 | EF21: 0.0287945
A22: 321 | B22: 3 | C22: 0.20528267 | D22: 0.14242933 | E22: -0.017356667 | F22: -0.067831061 | G22: 0.10388436 | H22: 0.124178 | I22: 0.12349317 | J22: 0.052598589 | K22: 0.24536591 | L22: -0.014272 | M22: -0.074100059 | N22: 0.75614233 | O22: -0.0067158783 | P22: 0.072782884 | Q22: 0.27677689 | R22: -0.036628434 | S22: 0.16964656 | T22: 0.12881242 | U22: 0.11059002 | V22: 0.038286777 | W22: 0.158048 | X22: 0.22178676 | Y22: -0.015732208 | Z22: 0.075548269 | AA22: 0.082524426 | AB22: 0.13443621 | AC22: 0.085776461 | AD22: 0.013571333 | AE22: 0.13082384 | AF22: 0.42991677 | AG22: 0.05284154 | AH22: -0.10586596 | AI22: 0.11100467 | AJ22: -0.031699849 | AK22: 0.10128856 | AL22: -0.0094396667 | AM22: 0.084088903 | AN22: 0.11113281 | AO22: 0.15815288 | AP22: 0.062536354 | AQ22: 0.11012933 | AR22: 0.067924667 | AS22: 0.073843703 | AT22: 0.017728371 | AU22: 0.429355 | AV22: -0.089753982 | AW22: 0.37079928 | AX22: -0.009875186 | AY22: 0.071733385 | AZ22: 0.15518867 | BA22: 0.049774667 | BB22: 0.51826405 | BC22: 0.19562604 | BD22: 0.079264 | BE22: 0.12806788 | BF22: 0.19910245 | BG22: -0.041231469 | BH22: 0.12770701 | BI22: 0.11108872 | BJ22: 0.040893333 | BK22: -0.048315667 | BL22: 0.13947139 | BM22: 0.0024304832 | BN22: 0.082934333 | BO22: -0.050484429 | BP22: -0.00054 | BQ22: 0.027830097 | BR22: 0.10656678 | BS22: -0.09704759 | BT22: 0.088724333 | BU22: 0.104351 | BV22: -0.048603535 | BW22: 0.13217179 | BX22: -0.11302667 | BY22: -0.05559705 | BZ22: 0.047257736 | CA22: 0.027490078 | CB22: 0.25474 | CC22: -0.125105 | CD22: 0.33387804 | CE22: 0.06684 | CF22: 0.18879979 | CG22: 0.20708533 | CH22: 0.11591877 | CI22: 0.11777975 | CJ22: -0.12632536 | CK22: 0.11092354 | CL22: -0.2406518 | CM22: 0.21983 | CN22: 0.15280392 | CO22: 0.272059 | CP22: 0.25940856 | CQ22: 0.017159616 | CR22: 0.24677277 | CS22: 0.084781936 | CT22: 0.038264667 | CU22: 0.16735391 | CV22: 0.16622268 | CW22: 0.022884042 | CX22: 0.0037495933 | CY22: 0.104511 | CZ22: 0.26292048 | DA22: 0.032454 | DB22: 0.054040667 | DC22: -0.020724784 | DD22: 0.031710169 | DE22: -0.017756504 | DF22: 0.389668 | DG22: 0.071891 | DH22: 0.081455333 | DI22: 0.060122333 | DJ22: 0.15369976 | DK22: 0.091427667 | DL22: -0.0032133307 | DM22: -0.031884333 | DN22: 0.046763328 | DO22: 0.075715333 | DP22: 0.16956243 | DQ22: 0.16540417 | DR22: -0.0060925526 | DS22: -0.036349 | DT22: 0.027128754 | DU22: 0.16154567 | DV22: 0.12570512 | DW22: -0.081416 | DX22: 0.22244261 | DY22: 0.11995633 | DZ22: 0.11083367 | EA22: -0.034191242 | EB22: 0.12976595 | EC22: 0.021495102 | ED22: 0.077413567 | EE22: 0.047636 | EF22: 0.036592667
A23: 482 | B23: 2 | C23: 0.282989 | D23: 0.254094 | E23: 0.133005 | F23: -0.18239608 | G23: -0.026971569 | H23: -0.0181885 | I23: 0.14815203 | J23: -0.098162291 | K23: 0.14260758 | L23: -0.050771 | M23: -0.25844992 | N23: 0.975901 | O23: -0.019407711 | P23: 0.090401711 | Q23: -0.059568017 | R23: -0.056211143 | S23: 0.11372453 | T23: 0.15460269 | U23: 0.093757422 | V23: -0.023029457 | W23: 0.259547 | X23: 0.18178119 | Y23: -0.014659802 | Z23: 0.033032515 | AA23: -0.056748446 | AB23: 0.06403978 | AC23: 0.1687548 | AD23: 0.071627 | AE23: 0.13721199 | AF23: 0.32465933 | AG23: 0.091873658 | AH23: -0.084171585 | AI23: 0.209152 | AJ23: 0.0056431378 | AK23: 0.1141111 | AL23: -0.0140665 | AM23: 0.007769489 | AN23: 0.2423147 | AO23: 0.09078248 | AP23: -0.0031210994 | AQ23: 0.099379 | AR23: 0.146136 | AS23: 0.081663621 | AT23: 0.1095059 | AU23: 0.608332 | AV23: -0.049150067 | AW23: 0.58225997 | AX23: -0.014812779 | AY23: 0.17023398 | AZ23: 0.078071 | BA23: 0.053998 | BB23: 0.68602333 | BC23: 0.25286918 | BD23: 0.1259795 | BE23: 0.12429214 | BF23: 0.21000911 | BG23: 0.038322827 | BH23: 0.063365196 | BI23: 0.19111208 | BJ23: 0.057495 | BK23: -0.047852 | BL23: 0.11436629 | BM23: -0.069495462 | BN23: 0.03845 | BO23: 0.036524942 | BP23: -0.022474 | BQ23: 0.072047901 | BR23: 0.10282259 | BS23: -0.22056709 | BT23: 0.2181855 | BU23: 0.1056865 | BV23: -0.053269051 | BW23: 0.015362515 | BX23: -0.06873 | BY23: 0.11824923 | BZ23: 0.0076697624 | CA23: 0.0756532 | CB23: 0.3161675 | CC23: -0.084545 | CD23: 0.19167646 | CE23: 0.059602 | CF23: 0.15713491 | CG23: 0.21663724 | CH23: 0.18019645 | CI23: 0.30989942 | CJ23: -0.1565159 | CK23: 0.071856391 | CL23: -0.40866101 | CM23: 0.234705 | CN23: 0.27710426 | CO23: 0.2661575 | CP23: 0.31136074 | CQ23: -0.02470227 | CR23: 0.15099817 | CS23: 0.065159884 | CT23: 0.0653915 | CU23: 0.20210388 | CV23: 0.15333097 | CW23: -0.024186288 | CX23: -0.088716994 | CY23: 0.1537505 | CZ23: 0.18199879 | DA23: 0.064645 | DB23: 0.018748 | DC23: 0.11919049 | DD23: 0.092798675 | DE23: -0.060085948 | DF23: 0.4087975 | DG23: 0.0676225 | DH23: 0.139228 | DI23: 0.096041 | DJ23: 0.12003258 | DK23: 0.0912435 | DL23: 0.026242652 | DM23: -0.046477 | DN23: 0.006497196 | DO23: 0.124068 | DP23: 0.17683962 | DQ23: 0.24594611 | DR23: -0.089886003 | DS23: -0.116578 | DT23: -0.022296457 | DU23: 0.055638 | DV23: 0.27627161 | DW23: 0.0230525 | DX23: 0.31349321 | DY23: -0.053925 | DZ23: -0.217175 | EA23: -0.093362079 | EB23: 0.24428466 | EC23: -0.036584316 | ED23: 0.091425905 | EE23: 0.069211 | EF23: 0.093414
A24: 964 | B24: 1 | C24: 0.099113 | D24: 0.10061 | E24: 0.284512 | F24: -0.20154572 | G24: -0.022622389 | H24: 0.035856 | I24: -0.0021119332 | J24: -0.099972193 | K24: 0.050444336 | L24: -0.0938 | M24: -0.14681934 | N24: 1.769032 | O24: 0.036648791 | P24: 0.10424841 | Q24: -0.060964962 | R24: -0.24569737 | S24: 0.35251446 | T24: -0.27048671 | U24: 0.14851867 | V24: -0.067139303 | W24: -0.164562 | X24: -0.036157896 | Y24: -0.0094770149 | Z24: 0.10584233 | AA24: 0.21854458 | AB24: 0.19533962 | AC24: 0.40174733 | AD24: 0.101174 | AE24: 0.19314179 | AF24: 0.49538941 | AG24: 0.13873572 | AH24: -0.05669736 | AI24: 0.310414 | AJ24: -0.080891244 | AK24: 0.084883953 | AL24: 0.087173 | AM24: -0.018919281 | AN24: 0.22118947 | AO24: 0.1029057 | AP24: 0.022851715 | AQ24: 0.217124 | AR24: 0.170833 | AS24: 0.0032867737 | AT24: 0.15076898 | AU24: 0.477054 | AV24: 0.24768466 | AW24: -0.14871096 | AX24: 0.11149134 | AY24: 0.16812729 | AZ24: 0.118622 | BA24: 0.050491 | BB24: 0.87270315 | BC24: -0.0043668696 | BD24: 0.01864 | BE24: -0.057380538 | BF24: -0.064370421 | BG24: -0.090984228 | BH24: 0.14767357 | BI24: 0.22362911 | BJ24: 0.19964 | BK24: -0.03483 | BL24: 0.10610692 | BM24: 0.08478294 | BN24: 0.108911 | BO24: -0.16110969 | BP24: 0.031793 | BQ24: -0.064169633 | BR24: 0.098920889 | BS24: -0.12162104 | BT24: 0.276718 | BU24: 0.008749 | BV24: -0.046258706 | BW24: 0.15102745 | BX24: -0.10395 | BY24: 0.11840823 | BZ24: 0.2588929 | CA24: 0.11522168 | CB24: 0.639699 | CC24: -0.18247 | CD24: 0.14430631 | CE24: 0.165565 | CF24: 0.22172136 | CG24: 0.51996897 | CH24: 0.3542773 | CI24: -0.32845182 | CJ24: -0.30018689 | CK24: 0.32305927 | CL24: 0.14175533 | CM24: 0.63644 | CN24: 0.6096772 | CO24: 0.452474 | CP24: 0.1603442 | CQ24: -0.16018965 | CR24: 0.13778746 | CS24: 0.10797424 | CT24: -0.119542 | CU24: 0.052729045 | CV24: 0.18286409 | CW24: -0.23499322 | CX24: 0.055207194 | CY24: 0.321148 | CZ24: 0.11220663 | DA24: 0.03398 | DB24: -0.0165 | DC24: 0.19117576 | DD24: -0.19584472 | DE24: 0.13158559 | DF24: 0.525588 | DG24: 0.119545 | DH24: 0.265805 | DI24: 0.037185 | DJ24: 0.22936987 | DK24: 0.119679 | DL24: 0.061360513 | DM24: -0.00041 | DN24: 0.23333457 | DO24: 0.115615 | DP24: 0.22357182 | DQ24: 0.3590713 | DR24: -0.02051563 | DS24: -0.067366 | DT24: -0.029435726 | DU24: -0.021782 | DV24: 0.1582247 | DW24: 0.101183 | DX24: 0.31159313 | DY24: -0.00324 | DZ24: -0.43351 | EA24: -0.023171502 | EB24: 0.58969792 | EC24: -0.014309919 | ED24: 0.056172845 | EE24: 0.107482 | EF24: 0.134085
A26: 大盤 | B26: TWII | C26: -0.01745 | D26: 0.020701 | E26: 0.023982 | F26: -0.00656 | G26: 0.031845 | H26: 0.034349 | I26: -0.00825 | J26: 0.012844 | K26: -0.05102 | L26: 0.000874 | M26: 0.02339 | N26: 0.012989 | O26: 0.005855 | P26: 0.027413 | Q26: -0.00371 | R26: 0.024077 | S26: -0.01219 | T26: -0.03975 | U26: -0.07316 | V26: -0.05826 | W26: 0.000773 | X26: 0.044592 | Y26: -0.0277 | Z26: 0.002095 | AA26: -0.0234 | AB26: 0.032129 | AC26: 0.038903 | AD26: -0.04287 | AE26: 0.018647 | AF26: 0.01523 | AG26: 0.036017 | AH26: 0.009355 | AI26: 0.010748 | AJ26: 0.013358 | AK26: -0.00533 | AL26: 0.001383 | AM26: 0.020796 | AN26: 0.031518 | AO26: 0.006242 | AP26: 0.006145 | AQ26: 0.016946 | AR26: 0.034683 | AS26: 0.003099 | AT26: 0.015081 | AU26: -0.01925 | AV26: 0.038712 | AW26: -0.02186 | AX26: 0.007774 | AY26: 0.042397 | AZ26: -0.02631 | BA26: 0.009572 | BB26: -0.02425 | BC26: 0.020163 | BD26: -0.0035 | BE26: 0.020152 | BF26: 0.000581 | BG26: -0.00522 | BH26: -0.11587 | BI26: 0.008725 | BJ26: -0.01638 | BK26: 0.02084 | BL26: 0.044976 | BM26: 0.023954 | BN26: 0.030239 | BO26: -0.04373 | BP26: 0.021889 | BQ26: 0.008627 | BR26: -0.01919 | BS26: 0.019735 | BT26: 0.047694 | BU26: 0.011455 | BV26: 0.043229 | BW26: -0.04275 | BX26: -0.01781 | BY26: -0.15115 | BZ26: 0.124224 | CA26: -0.00456 | CB26: 0.060211 | CC26: 0.085992 | CD26: -0.00581 | CE26: -0.00604 | CF26: 0.002452 | CG26: 0.089636 | CH26: 0.070993 | CI26: 0.027171 | CJ26: 0.052468 | CK26: 0.029481 | CL26: 0.066825 | CM26: -0.02877 | CN26: 0.039463 | CO26: -0.02903 | CP26: 0.013984 | CQ26: -0.03228 | CR26: 0.003104 | CS26: 0.025592 | CT26: 0.044392 | CU26: -0.03034 | CV26: -0.00126 | CW26: 0.002336 | CX26: -0.06426 | CY26: 0.01291 | CZ26: -0.12548 | DA26: 0.011691 | DB26: 0.006338 | DC26: -0.11731 | DD26: -0.03601 | DE26: 0.138911 | DF26: -0.05114 | DG26: 0.076731 | DH26: 0.015509 | DI26: 0.023224 | DJ26: -0.01837 | DK26: 0.062199 | DL26: 0.020098 | DM26: 0.013499 | DN26: -0.03025 | DO26: -0.01702 | DP26: -0.02179 | DQ26: 0.085746 | DR26: 0.028107 | DS26: -0.0023 | DT26: 0.058471 | DU26: 0.067659 | DV26: 0.005021 | DW26: 0.037416 | DX26: 0.084111 | DY26: -0.03683 | DZ26: 0.003092 | EA26: -0.00196 | EB26: 0.026459 | EC26: -0.02475 | ED26: 0.034115 | EE26: 0.021062 | EF26: -0.020277393
B28: 低 | C28: 5455 | D28: 5455 | E28: 5455 | F28: 6130 | G28: 6130 | H28: 5455 | I28: 6114 | J28: 6242 | K28: 5324 | L28: 5455 | M28: 5324 | N28: 5455 | O28: 5324 | P28: 5455 | Q28: 5455 | R28: 5455 | S28: 5455 | T28: 2439 | U28: 4413 | V28: 4413 | W28: 6291 | X28: 2388 | Y28: 8044 | Z28: 6225 | AA28: 6259 | AB28: 6225 | AC28: 9906 | AD28: 6291 | AE28: 5381 | AF28: 5455 | AG28: 6225 | AH28: 6225 | AI28: 6291 | AJ28: 6225 | AK28: 6225 | AL28: 6291 | AM28: 6225 | AN28: 6225 | AO28: 6259 | AP28: 6225 | AQ28: 6291 | AR28: 6291 | AS28: 3064 | AT28: 3064 | AU28: 6291 | AV28: 3064 | AW28: 5205 | AX28: 3064 | AY28: 6225 | AZ28: 6291 | BA28: 6291 | BB28: 4903 | BC28: 4903 | BD28: 6291 | BE28: 6165 | BF28: 6165 | BG28: 6165 | BH28: 6165 | BI28: 6225 | BJ28: 4402 | BK28: 1475 | BL28: 4303 | BM28: 4303 | BN28: 1475 | BO28: 6225 | BP28: 1475 | BQ28: 6225 | BR28: 4303 | BS28: 3085 | BT28: 1475 | BU28: 1475 | BV28: 5310 | BW28: 3085 | BX28: 5205 | BY28: 3085 | BZ28: 8080 | CA28: 8080 | CB28: 5205 | CC28: 8087 | CD28: 5205 | CE28: 5205 | CF28: 5205 | CG28: 8070 | CH28: 5205 | CI28: 5205 | CJ28: 8070 | CK28: 8070 | CL28: 8080 | CM28: 5205 | CN28: 8070 | CO28: 5205 | CP28: 6287 | CQ28: 1325 | CR28: 3043 | CS28: 1325 | CT28: 5205 | CU28: 3064 | CV28: 1325 | CW28: 6276 | CX28: 8101 | CY28: 5205 | CZ28: 8101 | DA28: 1538 | DB28: 5314 | DC28: 6225 | DD28: 2007 | DE28: 2486 | DF28: 6225 | DG28: 5314 | DH28: 1538 | DI28: 8080 | DJ28: 6104 | DK28: 8080 | DL28: 5468 | DM28: 8080 | DN28: 8084 | DO28: 8080 | DP28: 8933 | DQ28: 8933 | DR28: 4419 | DS28: 2321 | DT28: 8933 | DU28: 5345 | DV28: 4419 | DW28: 4304 | DX28: 4419 | DY28: 2321 | DZ28: 8101 | EA28: 6235 | EB28: 6235 | EC28: 6287 | ED28: 6287 | EE28: 2321 | EF28: 2321
B29: 公司名稱 | C29: 昇益 | D29: 昇益 | E29: 昇益 | F29: 上亞科技 | G29: 上亞科技 | H29: 昇益 | I29: 久威 | J29: 立康 | K29: 士開 | L29: 昇益 | M29: 士開 | N29: 昇益 | O29: 士開 | P29: 昇益 | Q29: 昇益 | R29: 昇益 | S29: 昇益 | T29: 美律 | U29: 飛寶企業 | V29: 飛寶企業 | W29: 沛亨 | X29: 威盛 | Y29: 網家 | Z29: 天瀚 | AA29: 百徽 | AB29: 天瀚 | AC29: 欣巴巴 | AD29: 沛亨 | AE29: 合正 | AF29: 昇益 | AG29: 天瀚 | AH29: 天瀚 | AI29: 沛亨 | AJ29: 天瀚 | AK29: 天瀚 | AL29: 沛亨 | AM29: 天瀚 | AN29: 天瀚 | AO29: 百徽 | AP29: 天瀚 | AQ29: 沛亨 | AR29: 沛亨 | AS29: 泰偉 | AT29: 泰偉 | AU29: 沛亨 | AV29: 泰偉 | AW29: 中茂 | AX29: 泰偉 | AY29: 天瀚 | AZ29: 沛亨 | BA29: 沛亨 | BB29: 聯光通 | BC29: 聯光通 | BD29: 沛亨 | BE29: 浪凡 | BF29: 浪凡 | BG29: 浪凡 | BH29: 浪凡 | BI29: 天瀚 | BJ29: 郡都開發 | BK29: 業旺 | BL29: 信立 | BM29: 信立 | BN29: 業旺 | BO29: 天瀚 | BP29: 業旺 | BQ29: 天瀚 | BR29: 信立 | BS29: 新零售 | BT29: 業旺 | BU29: 業旺 | BV29: 天剛 | BW29: 新零售 | BX29: 中茂 | BY29: 新零售 | BZ29: 印鉐 | CA29: 印鉐 | CB29: 中茂 | CC29: 麗升能源 | CD29: 中茂 | CE29: 中茂 | CF29: 中茂 | CG29: 長華* | CH29: 中茂 | CI29: 中茂 | CJ29: 長華* | CK29: 長華* | CL29: 印鉐 | CM29: 中茂 | CN29: 長華* | CO29: 中茂 | CP29: 元隆 | CQ29: 恒大 | CR29: 科風 | CS29: 恒大 | CT29: 中茂 | CU29: 泰偉 | CV29: 恒大 | CW29: 安鈦克 | CX29: 華冠 | CY29: 中茂 | CZ29: 華冠 | DA29: 正峰 | DB29: 世紀 | DC29: 天瀚 | DD29: 燁興 | DE29: 一詮 | DF29: 天瀚 | DG29: 世紀 | DH29: 正峰 | DI29: 印鉐 | DJ29: 創惟 | DK29: 印鉐 | DL29: 凱鈺 | DM29: 印鉐 | DN29: 巨虹 | DO29: 印鉐 | DP29: 愛地雅 | DQ29: 愛地雅 | DR29: 皇家美食 | DS29: 東訊 | DT29: 愛地雅 | DU29: 天揚 | DV29: 皇家美食 | DW29: 勝昱 | DX29: 皇家美食 | DY29: 東訊 | DZ29: 華冠 | EA29: 華孚 | EB29: 華孚 | EC29: 元隆 | ED29: 元隆 | EE29: 東訊 | EF29: 東訊
B30: 高 | C30: 2330 | D30: 2330 | E30: 2330 | F30: 5364 | G30: 5364 | H30: 2330 | I30: 2323 | J30: 2323 | K30: 5364 | L30: 2330 | M30: 5364 | N30: 2330 | O30: 2408 | P30: 2323 | Q30: 2323 | R30: 2323 | S30: 2323 | T30: 2408 | U30: 2323 | V30: 2323 | W30: 2330 | X30: 5455 | Y30: 2323 | Z30: 2323 | AA30: 4502 | AB30: 2323 | AC30: 4502 | AD30: 2330 | AE30: 4502 | AF30: 4502 | AG30: 1314 | AH30: 2323 | AI30: 2330 | AJ30: 2323 | AK30: 2323 | AL30: 2330 | AM30: 2323 | AN30: 2323 | AO30: 6283 | AP30: 2323 | AQ30: 2330 | AR30: 2330 | AS30: 2496 | AT30: 2496 | AU30: 2330 | AV30: 2337 | AW30: 2337 | AX30: 2337 | AY30: 3252 | AZ30: 2330 | BA30: 2330 | BB30: 6150 | BC30: 6150 | BD30: 2330 | BE30: 2342 | BF30: 2342 | BG30: 2342 | BH30: 2342 | BI30: 1906 | BJ30: 2330 | BK30: 2330 | BL30: 1529 | BM30: 1529 | BN30: 2330 | BO30: 8085 | BP30: 2330 | BQ30: 3252 | BR30: 1529 | BS30: 1529 | BT30: 2330 | BU30: 2330 | BV30: 1529 | BW30: 5340 | BX30: 2330 | BY30: 2429 | BZ30: 5608 | CA30: 5608 | CB30: 2330 | CC30: 2330 | CD30: 5608 | CE30: 2330 | CF30: 1314 | CG30: 1325 | CH30: 1314 | CI30: 3252 | CJ30: 6204 | CK30: 6259 | CL30: 3252 | CM30: 2330 | CN30: 2609 | CO30: 2330 | CP30: 3252 | CQ30: 5475 | CR30: 2609 | CS30: 2609 | CT30: 2330 | CU30: 5475 | CV30: 5475 | CW30: 5475 | CX30: 1906 | CY30: 2330 | CZ30: 1906 | DA30: 2330 | DB30: 2330 | DC30: 1314 | DD30: 2364 | DE30: 2364 | DF30: 2330 | DG30: 2330 | DH30: 2330 | DI30: 2330 | DJ30: 3043 | DK30: 2330 | DL30: 3043 | DM30: 2330 | DN30: 2603 | DO30: 2330 | DP30: 3043 | DQ30: 5314 | DR30: 1906 | DS30: 2330 | DT30: 8077 | DU30: 2330 | DV30: 1314 | DW30: 2330 | DX30: 1314 | DY30: 2330 | DZ30: 2330 | EA30: 6228 | EB30: 6144 | EC30: 1314 | ED30: 1312 | EE30: 2330 | EF30: 2330
B31: 公司名稱 | C31: 台積電 | D31: 台積電 | E31: 台積電 | F31: 力麗店 | G31: 力麗店 | H31: 台積電 | I31: 中環 | J31: 中環 | K31: 力麗店 | L31: 台積電 | M31: 力麗店 | N31: 台積電 | O31: 南亞科 | P31: 中環 | Q31: 中環 | R31: 中環 | S31: 中環 | T31: 南亞科 | U31: 中環 | V31: 中環 | W31: 台積電 | X31: 昇益 | Y31: 中環 | Z31: 中環 | AA31: 健信 | AB31: 中環 | AC31: 健信 | AD31: 台積電 | AE31: 健信 | AF31: 健信 | AG31: 中石化 | AH31: 中環 | AI31: 台積電 | AJ31: 中環 | AK31: 中環 | AL31: 台積電 | AM31: 中環 | AN31: 中環 | AO31: 淳安 | AP31: 中環 | AQ31: 台積電 | AR31: 台積電 | AS31: 卓越 | AT31: 卓越 | AU31: 台積電 | AV31: 旺宏 | AW31: 旺宏 | AX31: 旺宏 | AY31: 海灣 | AZ31: 台積電 | BA31: 台積電 | BB31: 撼訊 | BC31: 撼訊 | BD31: 台積電 | BE31: 茂矽 | BF31: 茂矽 | BG31: 茂矽 | BH31: 茂矽 | BI31: 寶隆 | BJ31: 台積電 | BK31: 台積電 | BL31: 樂事綠能 | BM31: 樂事綠能 | BN31: 台積電 | BO31: 福華 | BP31: 台積電 | BQ31: 海灣 | BR31: 樂事綠能 | BS31: 樂事綠能 | BT31: 台積電 | BU31: 台積電 | BV31: 樂事綠能 | BW31: 建榮 | BX31: 台積電 | BY31: 銘旺科 | BZ31: 四維航 | CA31: 四維航 | CB31: 台積電 | CC31: 台積電 | CD31: 四維航 | CE31: 台積電 | CF31: 中石化 | CG31: 恒大 | CH31: 中石化 | CI31: 海灣 | CJ31: 艾華 | CK31: 百徽 | CL31: 海灣 | CM31: 台積電 | CN31: 陽明 | CO31: 台積電 | CP31: 海灣 | CQ31: 德宏 | CR31: 陽明 | CS31: 陽明 | CT31: 台積電 | CU31: 德宏 | CV31: 德宏 | CW31: 德宏 | CX31: 寶隆 | CY31: 台積電 | CZ31: 寶隆 | DA31: 台積電 | DB31: 台積電 | DC31: 中石化 | DD31: 倫飛 | DE31: 倫飛 | DF31: 台積電 | DG31: 台積電 | DH31: 台積電 | DI31: 台積電 | DJ31: 科風 | DK31: 台積電 | DL31: 科風 | DM31: 台積電 | DN31: 長榮 | DO31: 台積電 | DP31: 科風 | DQ31: 世紀 | DR31: 寶隆 | DS31: 台積電 | DT31: 洛碁 | DU31: 台積電 | DV31: 中石化 | DW31: 台積電 | DX31: 中石化 | DY31: 台積電 | DZ31: 台積電 | EA31: 全譜 | EB31: 得利影 | EC31: 中石化 | ED31: 國喬 | EE31: 台積電 | EF31: 台積電

Sheet OLS勝率(真實)
A1: REAL
B2: Time | C2: 2013/12 | D2: 2014/01 | E2: 2014/02 | F2: 2014/03 | G2: 2014/04 | H2: 2014/05 | I2: 2014/06 | J2: 2014/07 | K2: 2014/08 | L2: 2014/09 | M2: 2014/10 | N2: 2014/11 | O2: 2014/12 | P2: 2015/01 | Q2: 2015/02 | R2: 2015/03 | S2: 2015/04 | T2: 2015/05 | U2: 2015/06 | V2: 2015/07 | W2: 2015/08 | X2: 2015/09 | Y2: 2015/10 | Z2: 2015/11 | AA2: 2015/12 | AB2: 2016/01 | AC2: 2016/02 | AD2: 2016/03 | AE2: 2016/04 | AF2: 2016/05 | AG2: 2016/06 | AH2: 2016/07 | AI2: 2016/08 | AJ2: 2016/09 | AK2: 2016/10 | AL2: 2016/11 | AM2: 2016/12 | AN2: 2017/01 | AO2: 2017/02 | AP2: 2017/03 | AQ2: 2017/04 | AR2: 2017/05 | AS2: 2017/06 | AT2: 2017/07 | AU2: 2017/08 | AV2: 2017/09 | AW2: 2017/10 | AX2: 2017/11 | AY2: 2017/12 | AZ2: 2018/01 | BA2: 2018/02 | BB2: 2018/03 | BC2: 2018/04 | BD2: 2018/05 | BE2: 2018/06 | BF2: 2018/07 | BG2: 2018/08 | BH2: 2018/09 | BI2: 2018/10 | BJ2: 2018/11 | BK2: 2018/12 | BL2: 2019/01 | BM2: 2019/02 | BN2: 2019/03 | BO2: 2019/04 | BP2: 2019/05 | BQ2: 2019/06 | BR2: 2019/07 | BS2: 2019/08 | BT2: 2019/09 | BU2: 2019/10 | BV2: 2019/11 | BW2: 2019/12 | BX2: 2020/01 | BY2: 2020/02 | BZ2: 2020/03 | CA2: 2020/04 | CB2: 2020/05 | CC2: 2020/06 | CD2: 2020/07 | CE2: 2020/08 | CF2: 2020/09 | CG2: 2020/10 | CH2: 2020/11 | CI2: 2020/12 | CJ2: 2021/01 | CK2: 2021/02 | CL2: 2021/03 | CM2: 2021/04 | CN2: 2021/05 | CO2: 2021/06 | CP2: 2021/07 | CQ2: 2021/08 | CR2: 2021/09 | CS2: 2021/10 | CT2: 2021/11 | CU2: 2021/12 | CV2: 2022/01 | CW2: 2022/02 | CX2: 2022/03 | CY2: 2022/04 | CZ2: 2022/05 | DA2: 2022/06 | DB2: 2022/07 | DC2: 2022/08 | DD2: 2022/09 | DE2: 2022/10 | DF2: 2022/11 | DG2: 2022/12 | DH2: 2023/01 | DI2: 2023/02 | DJ2: 2023/03 | DK2: 2023/04 | DL2: 2023/05 | DM2: 2023/06 | DN2: 2023/07 | DO2: 2023/08 | DP2: 2023/09 | DQ2: 2023/10 | DR2: 2023/11 | DS2: 2023/12 | DT2: 2024/01 | DU2: 2024/02 | DV2: 2024/03 | DW2: 2024/04 | DX2: 2024/05 | DY2: 2024/06 | DZ2: 2024/07 | EA2: 2024/08 | EB2: 2024/09 | EC2: 2024/10 | ED2: 2024/11 | EE2: 2024/12 | EF2: 2025/01
B3: bm | C3: 0.10910583 | D3: 0.01457658 | E3: -0.0361544 | F3: -0.0047426 | G3: -0.0057478 | H3: 0.04937802 | I3: 0.18325177 | J3: 0.11648631 | K3: -0.0305949 | L3: 0.01982805 | M3: -0.020999 | N3: 0.14977942 | O3: 0.01546341 | P3: -0.0917923 | Q3: -0.077409 | R3: 0.0547766 | S3: -0.1253344 | T3: -0.1190534 | U3: -0.0377701 | V3: 0.08118382 | W3: 0.08400897 | X3: 0.14701136 | Y3: -0.1253605 | Z3: 0.19195355 | AA3: -0.0843708 | AB3: 0.07289761 | AC3: 0.10260456 | AD3: 0.01577017 | AE3: -0.1520072 | AF3: 0.05925025 | AG3: 0.13005884 | AH3: 0.1152564 | AI3: 0.03260662 | AJ3: 0.02799911 | AK3: 0.14657042 | AL3: 0.04084192 | AM3: 0.13137637 | AN3: 0.22143296 | AO3: -0.020941 | AP3: -0.13716 | AQ3: -0.0248829 | AR3: 0.01551397 | AS3: 0.03437304 | AT3: 0.06309569 | AU3: 0.0432377 | AV3: -0.0742304 | AW3: 0.02799483 | AX3: 0.11986442 | AY3: 0.07655957 | AZ3: -0.0217304 | BA3: -0.0012465 | BB3: 0.10099582 | BC3: 0.02982693 | BD3: 0.00867577 | BE3: 0.06855721 | BF3: 0.1569126 | BG3: 0.15920373 | BH3: 0.06112167 | BI3: 0.09691285 | BJ3: -0.0547462 | BK3: -0.087493 | BL3: 0.09442675 | BM3: -0.0221911 | BN3: 0.01562861 | BO3: 0.08141824 | BP3: -0.0185089 | BQ3: 0.06872957 | BR3: 0.00310236 | BS3: 0.07496442 | BT3: 0.04520159 | BU3: 0.02567733 | BV3: 0.09180403 | BW3: -0.026354 | BX3: 0.01939483 | BY3: -0.0768389 | BZ3: 0.11330931 | CA3: -0.1073549 | CB3: 0.04084479 | CC3: -0.0198017 | CD3: 0.18837709 | CE3: 0.05557491 | CF3: 0.07487207 | CG3: 0.10000019 | CH3: 0.13602172 | CI3: -0.093741 | CJ3: 0.0039306 | CK3: 0.05650778 | CL3: 0.26354578 | CM3: -0.0095554 | CN3: -0.0315119 | CO3: -0.022619 | CP3: 0.13265561 | CQ3: 0.13307278 | CR3: -0.0149564 | CS3: -0.0334199 | CT3: 0.01228121 | CU3: 0.11681498 | CV3: -0.0031589 | CW3: 0.03821776 | CX3: 0.13917409 | CY3: -0.0237123 | CZ3: 0.21835291 | DA3: -0.0579674 | DB3: -0.0141042 | DC3: 0.11395608 | DD3: 0.07447226 | DE3: -0.0008997 | DF3: 0.00097707 | DG3: -0.0729801 | DH3: -0.0238453 | DI3: -0.1015307 | DJ3: 0.02769254 | DK3: -0.0493352 | DL3: -0.0056994 | DM3: -0.0369818 | DN3: 0.10981299 | DO3: 0.04203683 | DP3: 0.08456667 | DQ3: -0.1102798 | DR3: 0.09432871 | DS3: -0.0719069 | DT3: -0.0962364 | DU3: 0.00234555 | DV3: 0.13401742 | DW3: 0.09473252 | DX3: -0.1037732 | DY3: 0.07576215 | DZ3: -0.0318297 | EA3: 0.16130802 | EB3: 0.01020353 | EC3: 0.07398843 | ED3: -0.1573769 | EE3: 0.07913755 | EF3: 0.07252855
