Workbook

Sheet 預測IC
A1: XGB
B2: Time | C2: 2013/12 | D2: 2014/01 | E2: 2014/02 | F2: 2014/03 | G2: 2014/04 | H2: 2014/05 | I2: 2014/06 | J2: 2014/07 | K2: 2014/08 | L2: 2014/09 | M2: 2014/10 | N2: 2014/11 | O2: 2014/12 | P2: 2015/01 | Q2: 2015/02 | R2: 2015/03 | S2: 2015/04 | T2: 2015/05 | U2: 2015/06 | V2: 2015/07 | W2: 2015/08 | X2: 2015/09 | Y2: 2015/10 | Z2: 2015/11 | AA2: 2015/12 | AB2: 2016/01 | AC2: 2016/02 | AD2: 2016/03 | AE2: 2016/04 | AF2: 2016/05 | AG2: 2016/06 | AH2: 2016/07 | AI2: 2016/08 | AJ2: 2016/09 | AK2: 2016/10 | AL2: 2016/11 | AM2: 2016/12 | AN2: 2017/01 | AO2: 2017/02 | AP2: 2017/03 | AQ2: 2017/04 | AR2: 2017/05 | AS2: 2017/06 | AT2: 2017/07 | AU2: 2017/08 | AV2: 2017/09 | AW2: 2017/10 | AX2: 2017/11 | AY2: 2017/12 | AZ2: 2018/01 | BA2: 2018/02 | BB2: 2018/03 | BC2: 2018/04 | BD2: 2018/05 | BE2: 2018/06 | BF2: 2018/07 | BG2: 2018/08 | BH2: 2018/09 | BI2: 2018/10 | BJ2: 2018/11 | BK2: 2018/12 | BL2: 2019/01 | BM2: 2019/02 | BN2: 2019/03 | BO2: 2019/04 | BP2: 2019/05 | BQ2: 2019/06 | BR2: 2019/07 | BS2: 2019/08 | BT2: 2019/09 | BU2: 2019/10 | BV2: 2019/11 | BW2: 2019/12 | BX2: 2020/01 | BY2: 2020/02 | BZ2: 2020/03 | CA2: 2020/04 | CB2: 2020/05 | CC2: 2020/06 | CD2: 2020/07 | CE2: 2020/08 | CF2: 2020/09 | CG2: 2020/10 | CH2: 2020/11 | CI2: 2020/12 | CJ2: 2021/01 | CK2: 2021/02 | CL2: 2021/03 | CM2: 2021/04 | CN2: 2021/05 | CO2: 2021/06 | CP2: 2021/07 | CQ2: 2021/08 | CR2: 2021/09 | CS2: 2021/10 | CT2: 2021/11 | CU2: 2021/12 | CV2: 2022/01 | CW2: 2022/02 | CX2: 2022/03 | CY2: 2022/04 | CZ2: 2022/05 | DA2: 2022/06 | DB2: 2022/07 | DC2: 2022/08 | DD2: 2022/09 | DE2: 2022/10 | DF2: 2022/11 | DG2: 2022/12 | DH2: 2023/01 | DI2: 2023/02 | DJ2: 2023/03 | DK2: 2023/04 | DL2: 2023/05 | DM2: 2023/06 | DN2: 2023/07 | DO2: 2023/08 | DP2: 2023/09 | DQ2: 2023/10 | DR2: 2023/11 | DS2: 2023/12 | DT2: 2024/01 | DU2: 2024/02 | DV2: 2024/03 | DW2: 2024/04 | DX2: 2024/05 | DY2: 2024/06 | DZ2: 2024/07 | EA2: 2024/08 | EB2: 2024/09 | EC2: 2024/10 | ED2: 2024/11 | EE2: 2024/12 | EF2: 2025/01 | EG2: 2025/02
B3: bm | C3: 0.040547289 | D3: 0.014746175 | E3: -0.051652342 | F3: -0.054286115 | G3: -0.057552006 | H3: -0.076259449 | I3: -0.10788648 | J3: 0.013737112 | K3: -0.059229229 | L3: -0.10780369 | M3: 0.024141319 | N3: -0.13467413 | O3: -0.0079268562 | P3: -0.075651743 | Q3: -0.08644776 | R3: -0.0030133345 | S3: -0.040853243 | T3: -0.032101776 | U3: -0.10543977 | V3: -0.045746464 | W3: -0.0068120561 | X3: 0.09770143 | Y3: 0.061205495 | Z3: 0.016075654 | AA3: -0.012703552 | AB3: -0.010262255 | AC3: 0.029340141 | AD3: -0.0058081243 | AE3: 0.011994774 | AF3: 0.039971381 | AG3: -0.012103247 | AH3: 0.022090664 | AI3: 0.021936081 | AJ3: 0.025844747 | AK3: -0.0023109075 | AL3: -0.020252099 | AM3: 0.022393657 | AN3: -0.0035141658 | AO3: -0.029745672 | AP3: -0.026837837 | AQ3: -0.021697119 | AR3: 0.023448717 | AS3: 0.015802857 | AT3: 0.066039756 | AU3: 0.062266789 | AV3: 0.057940513 | AW3: 0.10639411 | AX3: -0.0057518133 | AY3: 0.003456265 | AZ3: 0.08603631 | BA3: 0.10234847 | BB3: 0.063502729 | BC3: 0.048442636 | BD3: 0.077497914 | BE3: 0.027031764 | BF3: 0.021175273 | BG3: -0.012267982 | BH3: 0.051240973 | BI3: 0.055158429 | BJ3: 0.086648971 | BK3: 0.081092678 | BL3: 0.057930887 | BM3: 0.014249544 | BN3: -0.0046854224 | BO3: 0.04586114 | BP3: 0.086037964 | BQ3: 0.14414221 | BR3: 0.037985831 | BS3: 0.081880234 | BT3: 0.043688308 | BU3: 0.10545724 | BV3: 0.11753765 | BW3: 0.092942402 | BX3: 0.035637498 | BY3: 0.04292509 | BZ3: 0.098455094 | CA3: 0.018217886 | CB3: 0.019438757 | CC3: -0.0050573386 | CD3: -0.057951014 | CE3: -0.011938484 | CF3: 0.0064156759 | CG3: 0.0056247138 | CH3: 0.058184978 | CI3: 0.012768986 | CJ3: -0.080891326 | CK3: 0.073738843 | CL3: 0.067692369 | CM3: -0.018292543 | CN3: 0.0046888106 | CO3: -0.012873714 | CP3: -0.052108333 | CQ3: -0.072693914 | CR3: -0.060804408 | CS3: 0.015148262 | CT3: -0.063390315 | CU3: -0.06107983 | CV3: -0.021700332 | CW3: -0.060720678 | CX3: -0.040655192 | CY3: -0.045480587 | CZ3: -0.069138072 | DA3: -0.089778468 | DB3: -0.065274872 | DC3: -0.013747443 | DD3: -0.059340179 | DE3: -0.0029697688 | DF3: 0.02926687 | DG3: -0.024713881 | DH3: -0.035376154 | DI3: -0.027640743 | DJ3: -0.0057575447 | DK3: -0.048771854 | DL3: -0.011303868 | DM3: -0.049678039 | DN3: -0.012807783 | DO3: -0.01587224 | DP3: -0.0075895861 | DQ3: 0.040078633 | DR3: -0.01592231 | DS3: 0.023432238 | DT3: -0.053663064 | DU3: -0.044161681 | DV3: -0.023813089 | DW3: 0.025176367 | DX3: -0.032621369 | DY3: 0.013060666 | DZ3: -0.047912493 | EA3: 0.014760353 | EB3: -0.029227724 | EC3: -0.035695001 | ED3: -0.052812476 | EE3: -0.013054582 | EF3: -0.069071874
B4: size | C4: -0.018580828 | D4: -0.04825278 | E4: 0.0078275679 | F4: -0.026776634 | G4: 0.016258875 | H4: -0.0087667406 | I4: -0.0070548905 | J4: -0.032917611 | K4: 0.0073888558 | L4: 0.035096999 | M4: -0.019348426 | N4: -0.012498206 | O4: -0.067216232 | P4: -0.027688211 | Q4: -0.059864789 | R4: -0.077407129 | S4: -0.083726525 | T4: -0.059324656 | U4: -0.0023863558 | V4: 0.0046488689 | W4: -0.074044973 | X4: -0.098803863 | Y4: -0.091002114 | Z4: -0.068004087 | AA4: -0.086181231 | AB4: -0.088893928 | AC4: -0.01658844 | AD4: 0.063448824 | AE4: -0.059580553 | AF4: 0.0010961501 | AG4: 0.028850742 | AH4: 0.029070802 | AI4: -0.01015707 | AJ4: 0.044545107 | AK4: -0.01327528 | AL4: 0.014735002 | AM4: 0.0052847122 | AN4: 0.047137059 | AO4: 0.007465574 | AP4: 0.0046993392 | AQ4: 0.020851189 | AR4: 0.054104723 | AS4: -0.0056461818 | AT4: 0.00404533 | AU4: 0.02062845 | AV4: 0.021113886 | AW4: -0.041878089 | AX4: 0.015781458 | AY4: -0.02299829 | AZ4: 0.0058780294 | BA4: -0.021811418 | BB4: -0.076676466 | BC4: 0.010045491 | BD4: -0.047882307 | BE4: -0.06855423 | BF4: -0.082745306 | BG4: -0.12042424 | BH4: -0.10103763 | BI4: -0.039490096 | BJ4: -0.064256303 | BK4: -0.14447127 | BL4: -0.11201132 | BM4: -0.03482601 | BN4: -0.085986465 | BO4: -0.070973977 | BP4: -0.034846526 | BQ4: -0.020351751 | BR4: -0.023155609 | BS4: -0.032191597 | BT4: -0.068826571 | BU4: -0.092764981 | BV4: -0.081678107 | BW4: -0.06856361 | BX4: -0.019831985 | BY4: -0.061186798 | BZ4: -0.070581049 | CA4: -0.072609454 | CB4: -0.088862821 | CC4: -0.065672167 | CD4: -0.070492014 | CE4: -0.089266889 | CF4: -0.019554028 | CG4: -0.038807325 | CH4: -0.026853707 | CI4: -0.023996761 | CJ4: -0.0069834162 | CK4: -0.011856382 | CL4: -0.011220707 | CM4: -0.019751672 | CN4: -0.017389096 | CO4: 0.00091980241 | CP4: -0.027678527 | CQ4: -0.027226128 | CR4: -0.034191106 | CS4: -0.037506074 | CT4: -0.049283858 | CU4: -0.023866469 | CV4: -0.0027314594 | CW4: 0.025829777 | CX4: -0.077818602 | CY4: -0.017143354 | CZ4: 0.0064833509 | DA4: 0.02112148 | DB4: 0.0016250079 | DC4: 0.014495826 | DD4: 0.037542593 | DE4: -0.047325566 | DF4: 0.033347134 | DG4: -0.018042853 | DH4: -0.012872834 | DI4: 0.025734814 | DJ4: 0.014163728 | DK4: -0.03316791 | DL4: -0.021062262 | DM4: 0.014148561 | DN4: -0.019859655 | DO4: -0.038560558 | DP4: 0.052595932 | DQ4: 0.050834373 | DR4: 0.034424391 | DS4: 0.026739173 | DT4: -0.022692034 | DU4: 0.023562549 | DV4: 0.011204046 | DW4: 0.0097593218 | DX4: -0.012008918 | DY4: -0.012910018 | DZ4: 0.014516729 | EA4: 0.020058911 | EB4: 0.052505847 | EC4: 0.032138381 | ED4: -0.0095858695 | EE4: 0.016591379 | EF4: 0.024656091
B5: mom | C5: -0.019821944 | D5: -0.024067564 | E5: -0.0075782482 | F5: 0.038560428 | G5: -0.0070930333 | H5: -0.028790984 | I5: -0.050696284 | J5: -0.0017502174 | K5: -0.0048410315 | L5: -0.025085138 | M5: 0.034981705 | N5: 0.071464717 | O5: 0.049568243 | P5: 0.09211605 | Q5: 0.074587479 | R5: 0.036225241 | S5: 0.06888067 | T5: 0.050580025 | U5: 0.05002277 | V5: 0.065072879 | W5: 0.082305394 | X5: 0.049790494 | Y5: 0.1621349 | Z5: 0.049829394 | AA5: -0.0096141994 | AB5: -0.0094462801 | AC5: -0.015571467 | AD5: -0.005602458 | AE5: 0.024225909 | AF5: 0.064355873 | AG5: 0.06078143 | AH5: 0.028772563 | AI5: 0.042393733 | AJ5: 0.013549104 | AK5: 0.10434017 | AL5: 0.023477694 | AM5: 0.049679872 | AN5: -0.019429741 | AO5: -0.0099202199 | AP5: 0.013758846 | AQ5: -0.0049647922 | AR5: -0.013557843 | AS5: -0.026926255 | AT5: -0.0070274342 | AU5: 0.0095545966 | AV5: 0.039484385 | AW5: 0.010149264 | AX5: 0.027402362 | AY5: 0.036360435 | AZ5: -0.012621585 | BA5: 0.005026157 | BB5: 0.037919752 | BC5: 0.053017329 | BD5: -0.056791071 | BE5: -0.010663942 | BF5: -0.045907319 | BG5: -0.041811094 | BH5: -0.0086124791 | BI5: 0.0057994141 | BJ5: -0.012436195 | BK5: 0.028031733 | BL5: 0.012374575 | BM5: 0.033071969 | BN5: 0.053148314 | BO5: -0.00026408641 | BP5: 0.025249753 | BQ5: 0.016997438 | BR5: 0.039869186 | BS5: 0.014649399 | BT5: -0.0013528261 | BU5: -0.016242431 | BV5: -0.019686919 | BW5: 0.01865354 | BX5: 0.012438855 | BY5: 0.011720257 | BZ5: 0.026449056 | CA5: 0.020457806 | CB5: -0.010790687 | CC5: 0.027279854 | CD5: -0.0028258781 | CE5: -0.039107587 | CF5: 0.026439348 | CG5: -0.013538158 | CH5: 0.033741135 | CI5: -0.018029187 | CJ5: 0.0077282675 | CK5: 0.045171477 | CL5: -0.001433647 | CM5: -0.043408293 | CN5: -0.048494712 | CO5: -0.034412362 | CP5: -0.031831637 | CQ5: -0.029545931 | CR5: -0.046193767 | CS5: -0.02242364 | CT5: 0.027818739 | CU5: 0.034685932 | CV5: 0.020741159 | CW5: 0.039250623 | CX5: 0.02362325 | CY5: 0.020947697 | CZ5: 0.0027976942 | DA5: 0.031392038 | DB5: 0.002502433 | DC5: 0.046531398 | DD5: 0.037525449 | DE5: 0.060277972 | DF5: -0.016737031 | DG5: -0.0095816031 | DH5: 0.023357641 | DI5: -0.041918892 | DJ5: -0.0011311463 | DK5: 0.041163765 | DL5: 0.028391024 | DM5: -0.028915755 | DN5: -0.016116664 | DO5: -0.0044103554 | DP5: -0.028036362 | DQ5: 0.0037302354 | DR5: 0.004896184 | DS5: 0.01518423 | DT5: -0.027093893 | DU5: 0.021577414 | DV5: -0.0016142901 | DW5: -0.0041363826 | DX5: -0.044376425 | DY5: -0.033609867 | DZ5: -0.048759568 | EA5: 0.0057486207 | EB5: 0.0058685942 | EC5: 0.042290993 | ED5: 0.025345668 | EE5: 0.0070743728 | EF5: 0.037159268
A6: 選絕對值最大 | C6: {=MATCH(MAX(ABS(C3:C5)), ABS(C3:C5), 0)} -> 1 | D6: {=MATCH(MAX(ABS(D3:D5)), ABS(D3:D5), 0)} -> 2 | E6: {=MATCH(MAX(ABS(E3:E5)), ABS(E3:E5), 0)} -> 1 | F6: {=MATCH(MAX(ABS(F3:F5)), ABS(F3:F5), 0)} -> 1 | G6: {=MATCH(MAX(ABS(G3:G5)), ABS(G3:G5), 0)} -> 1 | H6: {=MATCH(MAX(ABS(H3:H5)), ABS(H3:H5), 0)} -> 1 | I6: {=MATCH(MAX(ABS(I3:I5)), ABS(I3:I5), 0)} -> 1 | J6: {=MATCH(MAX(ABS(J3:J5)), ABS(J3:J5), 0)} -> 2 | ... EG6: {=MATCH(MAX(ABS(EG3:EG5)), ABS(EG3:EG5), 0)} -> 1
C7: =IF(C6=1,"bm",IF(C6=2,"size",IF(C6=3,"mom"))) -> bm | D7: =IF(D6=1,"bm",IF(D6=2,"size",IF(D6=3,"mom"))) -> size | E7: =IF(E6=1,"bm",IF(E6=2,"size",IF(E6=3,"mom"))) -> bm | F7: =IF(F6=1,"bm",IF(F6=2,"size",IF(F6=3,"mom"))) -> bm | G7: =IF(G6=1,"bm",IF(G6=2,"size",IF(G6=3,"mom"))) -> bm | H7: =IF(H6=1,"bm",IF(H6=2,"size",IF(H6=3,"mom"))) -> bm | I7: =IF(I6=1,"bm",IF(I6=2,"size",IF(I6=3,"mom"))) -> bm | J7: =IF(J6=1,"bm",IF(J6=2,"size",IF(J6=3,"mom"))) -> size | ... EG7: =IF(EG6=1,"bm",IF(EG6=2,"size",IF(EG6=3,"mom"))) -> bm
C8: =IF(C6=1,C3,IF(C6=2,C4,IF(C6=3,C5))) -> 0.040547289 | D8: =IF(D6=1,D3,IF(D6=2,D4,IF(D6=3,D5))) -> -0.04825278 | E8: =IF(E6=1,E3,IF(E6=2,E4,IF(E6=3,E5))) -> -0.051652342 | F8: =IF(F6=1,F3,IF(F6=2,F4,IF(F6=3,F5))) -> -0.054286115 | G8: =IF(G6=1,G3,IF(G6=2,G4,IF(G6=3,G5))) -> -0.057552006 | H8: =IF(H6=1,H3,IF(H6=2,H4,IF(H6=3,H5))) -> -0.076259449 | I8: =IF(I6=1,I3,IF(I6=2,I4,IF(I6=3,I5))) -> -0.10788648 | J8: =IF(J6=1,J3,IF(J6=2,J4,IF(J6=3,J5))) -> -0.032917611 | ... EG8: =IF(EG6=1,EG3,IF(EG6=2,EG4,IF(EG6=3,EG5))) -> 0
A10: 投資組合 | C10: 公司數 | D10: 964
A11: 等第 | B11: 分數 | C11: 2014/01 | D11: 2014/02 | E11: 2014/03 | F11: 2014/04 | G11: 2014/05 | H11: 2014/06 | I11: 2014/07 | J11: 2014/08 | K11: 2014/09 | L11: 2014/10 | M11: 2014/11 | N11: 2014/12 | O11: 2015/01 | P11: 2015/02 | Q11: 2015/03 | R11: 2015/04 | S11: 2015/05 | T11: 2015/06 | U11: 2015/07 | V11: 2015/08 | W11: 2015/09 | X11: 2015/10 | Y11: 2015/11 | Z11: 2015/12 | AA11: 2016/01 | AB11: 2016/02 | AC11: 2016/03 | AD11: 2016/04 | AE11: 2016/05 | AF11: 2016/06 | AG11: 2016/07 | AH11: 2016/08 | AI11: 2016/09 | AJ11: 2016/10 | AK11: 2016/11 | AL11: 2016/12 | AM11: 2017/01 | AN11: 2017/02 | AO11: 2017/03 | AP11: 2017/04 | AQ11: 2017/05 | AR11: 2017/06 | AS11: 2017/07 | AT11: 2017/08 | AU11: 2017/09 | AV11: 2017/10 | AW11: 2017/11 | AX11: 2017/12 | AY11: 2018/01 | AZ11: 2018/02 | BA11: 2018/03 | BB11: 2018/04 | BC11: 2018/05 | BD11: 2018/06 | BE11: 2018/07 | BF11: 2018/08 | BG11: 2018/09 | BH11: 2018/10 | BI11: 2018/11 | BJ11: 2018/12 | BK11: 2019/01 | BL11: 2019/02 | BM11: 2019/03 | BN11: 2019/04 | BO11: 2019/05 | BP11: 2019/06 | BQ11: 2019/07 | BR11: 2019/08 | BS11: 2019/09 | BT11: 2019/10 | BU11: 2019/11 | BV11: 2019/12 | BW11: 2020/01 | BX11: 2020/02 | BY11: 2020/03 | BZ11: 2020/04 | CA11: 2020/05 | CB11: 2020/06 | CC11: 2020/07 | CD11: 2020/08 | CE11: 2020/09 | CF11: 2020/10 | CG11: 2020/11 | CH11: 2020/12 | CI11: 2021/01 | CJ11: 2021/02 | CK11: 2021/03 | CL11: 2021/04 | CM11: 2021/05 | CN11: 2021/06 | CO11: 2021/07 | CP11: 2021/08 | CQ11: 2021/09 | CR11: 2021/10 | CS11: 2021/11 | CT11: 2021/12 | CU11: 2022/01 | CV11: 2022/02 | CW11: 2022/03 | CX11: 2022/04 | CY11: 2022/05 | CZ11: 2022/06 | DA11: 2022/07 | DB11: 2022/08 | DC11: 2022/09 | DD11: 2022/10 | DE11: 2022/11 | DF11: 2022/12 | DG11: 2023/01 | DH11: 2023/02 | DI11: 2023/03 | DJ11: 2023/04 | DK11: 2023/05 | DL11: 2023/06 | DM11: 2023/07 | DN11: 2023/08 | DO11: 2023/09 | DP11: 2023/10 | DQ11: 2023/11 | DR11: 2023/12 | DS11: 2024/01 | DT11: 2024/02 | DU11: 2024/03 | DV11: 2024/04 | DW11: 2024/05 | DX11: 2024/06 | DY11: 2024/07 | DZ11: 2024/08 | EA11: 2024/09 | EB11: 2024/10 | EC11: 2024/11 | ED11: 2024/12 | EE11: 2025/01 | EF11: 2025/02
A12: 10 | B12: 96 | C12: 0.047013509 | D12: 0.11468863 | E12: 0.0067540284 | F12: 0.019868825 | G12: -0.0079043467 | H12: -0.0093593838 | I12: -0.036303937 | J12: -0.029408123 | K12: 0.010988404 | L12: 0.0022772308 | M12: 0.026889174 | N12: -0.052074108 | O12: 0.017240739 | P12: -0.00025432811 | Q12: 0.033792784 | R12: 0.0066628838 | S12: -0.016472395 | T12: -0.0077398001 | U12: 0.020367221 | V12: 0.0095109537 | W12: -0.028417663 | X12: 0.02707389 | Y12: 0.020598394 | Z12: 0.0051659076 | AA12: -0.011512546 | AB12: -0.0037114184 | AC12: 0.035114764 | AD12: -0.0093922433 | AE12: -0.058316963 | AF12: -0.052012103 | AG12: -0.0038149304 | AH12: -0.021100659 | AI12: 0.0087937925 | AJ12: -0.021062263 | AK12: -0.016475368 | AL12: -0.04780049 | AM12: 0.016706752 | AN12: -0.05713329 | AO12: -0.002228793 | AP12: 0.033718345 | AQ12: 0.0076219364 | AR12: 0.0075044281 | AS12: -0.019976273 | AT12: 0.013834905 | AU12: 0.020708659 | AV12: -0.041360085 | AW12: 0.00062147702 | AX12: -0.044696012 | AY12: 0.017491322 | AZ12: -0.0023000261 | BA12: 0.0049378882 | BB12: 0.0057853949 | BC12: 0.026690966 | BD12: 0.013630557 | BE12: -0.045598545 | BF12: -0.02360106 | BG12: 0.010004059 | BH12: -0.024922145 | BI12: 0.050021253 | BJ12: -0.00079599332 | BK12: -0.020075652 | BL12: 0.011060369 | BM12: -0.030171909 | BN12: -0.019502538 | BO12: 0.016913769 | BP12: -0.010508985 | BQ12: 0.01389675 | BR12: 0.068693615 | BS12: 0.018863293 | BT12: -0.021288097 | BU12: 0.0087815171 | BV12: 0.023062456 | BW12: -0.029483769 | BX12: 0.011477162 | BY12: -0.045815986 | BZ12: 0.045356946 | CA12: 0.014580558 | CB12: 0.072475876 | CC12: 0.065566613 | CD12: 0.044258489 | CE12: 0.15400701 | CF12: 0.0080212745 | CG12: 0.0003086485 | CH12: 0.063297372 | CI12: -0.024341498 | CJ12: -0.01544518 | CK12: 0.012803144 | CL12: 0.11801561 | CM12: 0.026353951 | CN12: -0.078465204 | CO12: 0.024819785 | CP12: -0.045299021 | CQ12: -0.036572195 | CR12: -0.0021178784 | CS12: -0.01450965 | CT12: 0.00082403602 | CU12: -0.035623716 | CV12: -0.0081126264 | CW12: -0.0055479247 | CX12: 0.046547458 | CY12: 0.0059829422 | CZ12: -0.077792327 | DA12: -0.0056037841 | DB12: 0.022981876 | DC12: -0.0045013638 | DD12: -0.024888978 | DE12: -0.024737644 | DF12: -0.055485734 | DG12: 0.00094770894 | DH12: 0.003822682 | DI12: -0.029979255 | DJ12: -0.015118208 | DK12: 0.015945953 | DL12: 0.018669833 | DM12: 0.0048403492 | DN12: 0.021916732 | DO12: 0.030556942 | DP12: -0.045953548 | DQ12: 0.03386212 | DR12: -0.017064979 | DS12: -0.069650552 | DT12: 0.045297883 | DU12: -0.013752648 | DV12: -0.048550824 | DW12: 0.043725564 | DX12: -0.018099137 | DY12: -0.062728222 | DZ12: -0.02003889 | EA12: -0.051097633 | EB12: -0.0057859706 | EC12: 0.014883918 | ED12: 0.060508153 | EE12: 0.026506892 | EF12: -0.039233348
A13: 20 | B13: 48 | C13: 0.042506118 | D13: 0.12374503 | E13: 0.034496619 | F13: 0.034922156 | G13: 0.01490798 | H13: -0.015930385 | I13: -0.032682863 | J13: -0.043899227 | K13: 0.04533099 | L13: 0.029135669 | M13: 0.0032797582 | N13: -0.043151952 | O13: 0.039789292 | P13: -0.0062776477 | Q13: 0.044218264 | R13: 0.014159944 | S13: -0.012243671 | T13: -0.02210402 | U13: 0.054161075 | V13: 0.0022166399 | W13: -0.030968904 | X13: 0.053276895 | Y13: -0.0066833587 | Z13: 0.020583761 | AA13: -0.016440619 | AB13: -0.016036099 | AC13: 0.021871556 | AD13: -0.02154369 | AE13: -0.065719382 | AF13: -0.073281161 | AG13: 0.0099052077 | AH13: -0.031875515 | AI13: 0.018646046 | AJ13: -0.019886324 | AK13: -0.03835939 | AL13: -0.049258885 | AM13: -0.014434106 | AN13: -0.07124522 | AO13: -0.0093111879 | AP13: 0.05955084 | AQ13: 0.0060492888 | AR13: -0.0092507325 | AS13: -0.023404964 | AT13: 0.040463088 | AU13: 0.040976126 | AV13: -0.0094754726 | AW13: 0.0040800136 | AX13: -0.032799832 | AY13: 0.014262204 | AZ13: -0.0081034675 | BA13: 0.0065409376 | BB13: 0.026046346 | BC13: 0.019110867 | BD13: 0.0033444284 | BE13: -0.046048257 | BF13: -0.026302897 | BG13: 0.0083310656 | BH13: -0.033944255 | BI13: 0.052409132 | BJ13: -0.016847086 | BK13: -0.025125773 | BL13: 0.013619178 | BM13: -0.027203867 | BN13: 0.0048576031 | BO13: 0.0034067145 | BP13: 0.0094326957 | BQ13: 0.041653064 | BR13: 0.079831457 | BS13: 0.0074194718 | BT13: -0.03366777 | BU13: 0.017706555 | BV13: 0.020653597 | BW13: 0.0017632378 | BX13: 0.021078068 | BY13: -0.03082776 | BZ13: 0.076138123 | CA13: 0.024012674 | CB13: 0.12042697 | CC13: 0.12011817 | CD13: 0.055256048 | CE13: 0.18382784 | CF13: -0.012043667 | CG13: 0.0075602687 | CH13: 0.058334612 | CI13: -0.0078955344 | CJ13: 0.003106088 | CK13: 0.032045269 | CL13: 0.081453366 | CM13: 0.014010735 | CN13: -0.10099417 | CO13: 0.035334344 | CP13: -0.06972654 | CQ13: -0.03818495 | CR13: -0.008279781 | CS13: 0.0039476507 | CT13: -0.0080707993 | CU13: -0.037161402 | CV13: 0.0029533122 | CW13: -0.0059770309 | CX13: 0.0049872956 | CY13: 0.01311874 | CZ13: -0.05722422 | DA13: 0.0055836769 | DB13: 0.04176157 | DC13: -0.014149867 | DD13: -0.010697601 | DE13: -0.022441996 | DF13: -0.083122187 | DG13: 0.0016306572 | DH13: -0.011295768 | DI13: -0.02957042 | DJ13: -0.0059835846 | DK13: -0.012409074 | DL13: 0.022050691 | DM13: 0.006658869 | DN13: 0.016935235 | DO13: 0.037863465 | DP13: -0.044997151 | DQ13: 0.033966462 | DR13: -0.01516855 | DS13: -0.068596853 | DT13: 0.035426301 | DU13: -0.018705164 | DV13: -0.079620144 | DW13: 0.04441779 | DX13: -0.02322961 | DY13: -0.0095046248 | DZ13: -0.030285251 | EA13: -0.062118677 | EB13: -0.00020120622 | EC13: 0.021984853 | ED13: 0.065682094 | EE13: 0.041234384 | EF13: -0.066577215
A14: 50 | B14: 19 | C14: -0.037017512 | D14: 0.22230845 | E14: 0.047525943 | F14: 0.048454143 | G14: 0.041019916 | H14: -0.0076743243 | I14: -0.04378736 | J14: -0.10509439 | K14: 0.1341787 | L14: -0.0048471972 | M14: -0.019021714 | N14: -0.082758985 | O14: 0.039642308 | P14: 0.006541421 | Q14: 0.12410387 | R14: -0.014151796 | S14: 0.0385341 | T14: -0.017360731 | U14: 0.10426666 | V14: -0.0524213 | W14: -0.047795003 | X14: 0.053581709 | Y14: -0.055190991 | Z14: 0.021252201 | AA14: -0.0026273998 | AB14: -0.074982913 | AC14: -0.013517269 | AD14: -0.039327892 | AE14: -0.0040189068 | AF14: -0.096080095 | AG14: 0.025329295 | AH14: -0.06341038 | AI14: -0.035462644 | AJ14: -0.096294977 | AK14: -0.077475339 | AL14: -0.051230183 | AM14: -0.042463856 | AN14: -0.11032368 | AO14: -0.060905705 | AP14: 0.069976525 | AQ14: 0.00036796774 | AR14: -0.018170823 | AS14: 0.0066693384 | AT14: 0.03450658 | AU14: 0.039991649 | AV14: -0.018682885 | AW14: -0.018362932 | AX14: -0.019370213 | AY14: 0.0016905718 | AZ14: -0.053348569 | BA14: 0.017621646 | BB14: 0.10189834 | BC14: -0.028505683 | BD14: 0.043327782 | BE14: -0.024117018 | BF14: -0.0052428879 | BG14: 0.010496608 | BH14: -0.093750084 | BI14: 0.050185213 | BJ14: -0.020017224 | BK14: 0.033237382 | BL14: 0.010571835 | BM14: -0.021375047 | BN14: 0.046576644 | BO14: 0.014903579 | BP14: 0.015673733 | BQ14: 0.015843524 | BR14: 0.10005242 | BS14: -0.041493955 | BT14: 0.015287928 | BU14: -0.0088548354 | BV14: 0.025727182 | BW14: 0.012507948 | BX14: 0.05497076 | BY14: -0.080399769 | BZ14: 0.060034057 | CA14: 0.033455158 | CB14: 0.1644655 | CC14: 0.12059616 | CD14: 0.047921841 | CE14: 0.1705553 | CF14: -0.04287741 | CG14: 0.13892668 | CH14: 0.064661392 | CI14: -0.0038293561 | CJ14: 0.028667855 | CK14: 0.014016364 | CL14: 0.062269955 | CM14: -0.0050971069 | CN14: -0.17459567 | CO14: 0.078763759 | CP14: -0.099809331 | CQ14: -0.053211628 | CR14: -0.055909138 | CS14: -0.0038161133 | CT14: -0.019100577 | CU14: 0.043917103 | CV14: -0.022745715 | CW14: 0.0033983825 | CX14: 0.024244256 | CY14: 0.02875912 | CZ14: -0.064063563 | DA14: 0.024304289 | DB14: 0.023561073 | DC14: -0.042998542 | DD14: 0.01675855 | DE14: -0.062526924 | DF14: -0.20156284 | DG14: -0.011446556 | DH14: -0.0047748372 | DI14: -0.040659135 | DJ14: -0.015897592 | DK14: -0.019071063 | DL14: 0.040754872 | DM14: -0.0055042691 | DN14: 0.030298833 | DO14: 0.10259219 | DP14: -0.0036178583 | DQ14: 0.056019286 | DR14: -0.0077944218 | DS14: -0.05605182 | DT14: 0.044516954 | DU14: 0.044914949 | DV14: -0.10826235 | DW14: 0.098344367 | DX14: -0.027689697 | DY14: -0.047660987 | DZ14: -0.021697589 | EA14: -0.10752548 | EB14: 0.025109521 | EC14: 0.043260018 | ED14: 0.10262971 | EE14: -0.0033992535 | EF14: -0.06995642
A15: 100 | B15: 10 | C15: -0.096503142 | D15: 0.37270922 | E15: 0.010198426 | F15: 0.10856229 | G15: 0.060636929 | H15: -0.050157825 | I15: -0.058431444 | J15: -0.06452469 | K15: 0.28659463 | L15: -0.032558505 | M15: -0.0021330164 | N15: -0.12086815 | O15: 0.046103493 | P15: 0.02189657 | Q15: 0.15553684 | R15: 0.016755436 | S15: -0.043033934 | T15: -0.049338673 | U15: 0.13696806 | V15: -0.11012701 | W15: -0.050671424 | X15: 0.078436412 | Y15: -0.052028798 | Z15: -0.023656419 | AA15: 0.046586124 | AB15: -0.073995952 | AC15: 0.016480966 | AD15: -0.039690481 | AE15: 0.047286476 | AF15: -0.13772629 | AG15: 0.044324544 | AH15: 0.014500687 | AI15: -0.024849257 | AJ15: -0.0041844346 | AK15: -0.069361451 | AL15: -0.032360174 | AM15: -0.068631207 | AN15: -0.060734932 | AO15: -0.063369812 | AP15: 0.078285694 | AQ15: 0.037367127 | AR15: -0.02455082 | AS15: 0.048733221 | AT15: 0.065254991 | AU15: 0.039943261 | AV15: -0.047226818 | AW15: 0.015659939 | AX15: -0.081360566 | AY15: 0.029005659 | AZ15: -0.09132328 | BA15: 0.010613515 | BB15: 0.1087891 | BC15: -0.030936692 | BD15: 0.053043274 | BE15: -0.046217114 | BF15: -0.056978024 | BG15: 0.01377615 | BH15: -0.054709226 | BI15: 0.068586659 | BJ15: -0.011265027 | BK15: 0.072869419 | BL15: 7.7901404e-05 | BM15: -0.062598395 | BN15: 0.066054035 | BO15: 0.016589444 | BP15: 0.014184221 | BQ15: 0.012802931 | BR15: 0.12376214 | BS15: -0.016823777 | BT15: -0.036633666 | BU15: 0.01947642 | BV15: 0.058914968 | BW15: -0.03594589 | BX15: 0.028635895 | BY15: -0.093338392 | BZ15: 0.10290647 | CA15: 0.029964009 | CB15: 0.1310914 | CC15: 0.17365171 | CD15: 0.08909452 | CE15: 0.07336812 | CF15: -0.04134943 | CG15: 0.22573123 | CH15: 0.062885958 | CI15: -0.069336845 | CJ15: 0.087044356 | CK15: 0.056672646 | CL15: 0.031421975 | CM15: -0.046626536 | CN15: -0.14314982 | CO15: 0.10697924 | CP15: -0.12753584 | CQ15: -0.037378011 | CR15: -0.04823707 | CS15: 0.016910987 | CT15: -0.007394575 | CU15: 0.06317866 | CV15: 0.0061418469 | CW15: 0.01248466 | CX15: 0.017868892 | CY15: 0.042470673 | CZ15: -0.079886948 | DA15: 0.026375835 | DB15: 0.030226618 | DC15: -0.067692432 | DD15: 0.04939369 | DE15: -0.057163635 | DF15: -0.30272045 | DG15: -0.016196732 | DH15: 0.018709011 | DI15: -0.054108319 | DJ15: -0.047566622 | DK15: -0.10177483 | DL15: -0.0003039932 | DM15: 0.023808547 | DN15: -0.067022569 | DO15: 0.15954541 | DP15: 0.040330193 | DQ15: 0.07293808 | DR15: 0.022035265 | DS15: -0.037530144 | DT15: 0.072163632 | DU15: 0.045770729 | DV15: -0.13976836 | DW15: 0.025538627 | DX15: -0.02154567 | DY15: 0.083673635 | DZ15: -0.036596498 | EA15: -0.10917693 | EB15: 0.05612648 | EC15: 0.076157077 | ED15: 0.11335706 | EE15: 0.0031907205 | EF15: -0.065700991
A16: 107 | B16: 9 | C16: -0.027383645 | D16: 0.40819498 | E16: 0.0028301766 | F16: 0.099382493 | G16: 0.073696265 | H16: -0.060999005 | I16: -0.057530619 | J16: -0.068694033 | K16: 0.28467055 | L16: -0.0098865346 | M16: -0.013987436 | N16: -0.12567063 | O16: 0.015621092 | P16: 0.0081881795 | Q16: 0.15790307 | R16: 0.019182762 | S16: -0.042415183 | T16: -0.023226785 | U16: 0.13006247 | V16: -0.075571486 | W16: -0.10163136 | X16: 0.073678278 | Y16: -0.050278834 | Z16: -0.020075795 | AA16: 0.050225527 | AB16: -0.071016126 | AC16: 0.047226236 | AD16: -0.034811172 | AE16: 0.051534992 | AF16: -0.14791561 | AG16: 0.04377616 | AH16: 0.044107019 | AI16: -0.033383256 | AJ16: 0.017629242 | AK16: -0.037433453 | AL16: -0.0054397026 | AM16: -0.052145732 | AN16: -0.052712143 | AO16: -0.061424672 | AP16: 0.077798368 | AQ16: 0.0384662 | AR16: -0.03249276 | AS16: 0.052642718 | AT16: 0.049547155 | AU16: 0.041826838 | AV16: -0.0090725068 | AW16: 0.03925293 | AX16: -0.10062133 | AY16: 0.019601854 | AZ16: -0.10490964 | BA16: 0.014923105 | BB16: 0.13247474 | BC16: -0.038999392 | BD16: 0.035936712 | BE16: -0.044139137 | BF16: -0.054584963 | BG16: 0.019331207 | BH16: -0.062040026 | BI16: 0.041443808 | BJ16: -0.020503816 | BK16: 0.1047732 | BL16: -0.0084142574 | BM16: -0.069805825 | BN16: 0.06719797 | BO16: 0.015960319 | BP16: 0.020843184 | BQ16: 0.016478016 | BR16: 0.13058297 | BS16: -0.013191573 | BT16: -0.038066078 | BU16: 0.05776511 | BV16: 0.060711239 | BW16: -0.065740927 | BX16: 0.031559238 | BY16: -0.11899471 | BZ16: 0.11152585 | CA16: 0.02743217 | CB16: 0.13930874 | CC16: 0.044388153 | CD16: 0.08775109 | CE16: 0.09361423 | CF16: -0.052800084 | CG16: 0.14619604 | CH16: 0.041697415 | CI16: -0.05834475 | CJ16: 0.045523551 | CK16: 0.076472984 | CL16: 0.015878682 | CM16: -0.0069997267 | CN16: -0.16035992 | CO16: 0.13464021 | CP16: -0.13663169 | CQ16: -0.041435606 | CR16: -0.048299767 | CS16: 0.021807009 | CT16: -0.0050674065 | CU16: 0.063434654 | CV16: 0.016751084 | CW16: 0.0091941595 | CX16: 0.0066867777 | CY16: 0.049117049 | CZ16: -0.10263326 | DA16: 0.029804794 | DB16: 0.04271217 | DC16: -0.083264052 | DD16: 0.070070935 | DE16: -0.0345524 | DF16: -0.32557955 | DG16: -0.014452948 | DH16: 0.019129343 | DI16: -0.045399498 | DJ16: -0.051753221 | DK16: -0.13359436 | DL16: -0.021872874 | DM16: 0.03033095 | DN16: -0.056707577 | DO16: 0.16959095 | DP16: 0.024716583 | DQ16: 0.06756052 | DR16: 0.011178168 | DS16: -0.021440673 | DT16: 0.10053413 | DU16: 0.064473734 | DV16: -0.13695373 | DW16: 0.04091773 | DX16: -0.021947728 | DY16: 0.094984864 | DZ16: -0.012649172 | EA16: -0.13979902 | EB16: 0.070875444 | EC16: 0.068501481 | ED16: 0.11541675 | EE16: 0.0043966753 | EF16: -0.042474401
A17: 120 | B17: 8 | C17: -0.041028984 | D17: 0.43958849 | E17: -0.0073790015 | F17: 0.11283752 | G17: 0.071222767 | H17: -0.076687822 | I17: -0.11372503 | J17: -0.11529907 | K17: 0.29682655 | L17: -0.0097108895 | M17: 0.014659142 | N17: -0.13594843 | O17: 0.024632055 | P17: 0.013382947 | Q17: 0.16180129 | R17: 0.0019752513 | S17: -0.055132026 | T17: -0.023507589 | U17: 0.14127114 | V17: -0.097259656 | W17: -0.12866725 | X17: 0.10018597 | Y17: -0.073623131 | Z17: -0.02160849 | AA17: 0.062254197 | AB17: -0.058334161 | AC17: 0.05872869 | AD17: -0.068619823 | AE17: 0.0594435 | AF17: -0.12028632 | AG17: 0.062640142 | AH17: 0.03192145 | AI17: -0.057037976 | AJ17: 0.02220746 | AK17: -0.02937589 | AL17: -0.027018182 | AM17: -0.09335171 | AN17: -0.049360372 | AO17: -0.012632335 | AP17: 0.077242814 | AQ17: 0.060527137 | AR17: -0.034997281 | AS17: 0.058802957 | AT17: 0.052267806 | AU17: 0.054555507 | AV17: -0.021205903 | AW17: 0.008421888 | AX17: -0.097619105 | AY17: 0.015478046 | AZ17: -0.1251576 | BA17: 0.0098251791 | BB17: 0.15327128 | BC17: -0.027292824 | BD17: 0.022356482 | BE17: -0.016297389 | BF17: -0.077417604 | BG17: -0.013153311 | BH17: -0.048737994 | BI17: 0.087111945 | BJ17: -0.0098580643 | BK17: 0.11481579 | BL17: 0.0075736051 | BM17: -0.077967326 | BN17: 0.073656768 | BO17: 0.031350299 | BP17: 0.03599598 | BQ17: 0.01137651 | BR17: 0.11502235 | BS17: -0.0041034691 | BT17: -0.033647573 | BU17: 0.071127819 | BV17: 0.070210303 | BW17: -0.080431713 | BX17: 0.028822965 | BY17: -0.095860872 | BZ17: 0.12057816 | CA17: 0.027196784 | CB17: 0.14963316 | CC17: 0.041760252 | CD17: 0.064105945 | CE17: 0.095708074 | CF17: -0.058238797 | CG17: 0.17703461 | CH17: 0.058636447 | CI17: -0.082452914 | CJ17: 0.050742321 | CK17: 0.091738573 | CL17: -0.0094263448 | CM17: 0.0016699729 | CN17: -0.17653128 | CO17: 0.13741288 | CP17: -0.14815927 | CQ17: -0.041087933 | CR17: -0.050676491 | CS17: 0.011545516 | CT17: -0.049260056 | CU17: 0.074408308 | CV17: -0.0038796079 | CW17: 0.019761854 | CX17: 0.024992449 | CY17: 0.049383299 | CZ17: -0.12424884 | DA17: 0.043895859 | DB17: 0.034883011 | DC17: -0.098849393 | DD17: 0.085133933 | DE17: -0.024124863 | DF17: -0.35222555 | DG17: 0.0018392819 | DH17: 0.038726651 | DI17: -0.035044536 | DJ17: -0.0571465 | DK17: -0.15603643 | DL17: -0.0039297317 | DM17: 0.052252911 | DN17: -0.060629183 | DO17: 0.17976293 | DP17: 0.02509743 | DQ17: 0.065244348 | DR17: 0.025726439 | DS17: -0.037354089 | DT17: 0.09313895 | DU17: 0.071730706 | DV17: -0.1177654 | DW17: 0.048681483 | DX17: 0.02303518 | DY17: 0.12601054 | DZ17: 0.0047910532 | EA17: -0.16457152 | EB17: 0.07378097 | EC17: 0.12151202 | ED17: 0.12832444 | EE17: -0.00019352115 | EF17: -0.047709767
A18: 137 | B18: 7 | C18: -0.053942228 | D18: 0.40188368 | E18: 0.059000657 | F18: 0.13441437 | G18: 0.080794247 | H18: -0.12191279 | I18: -0.13550018 | J18: -0.12516179 | K18: 0.3586821 | L18: -0.012982487 | M18: 0.029051464 | N18: -0.14299243 | O18: 0.024323875 | P18: 0.0083280859 | Q18: 0.18897542 | R18: 0.019326199 | S18: -0.06901334 | T18: -0.0050281402 | U18: 0.13249502 | V18: -0.12139146 | W18: -0.16613483 | X18: 0.12712281 | Y18: -0.10387924 | Z18: -0.016905716 | AA18: 0.054804498 | AB18: -0.061713851 | AC18: 0.057823013 | AD18: -0.096285845 | AE18: 0.077201592 | AF18: -0.15054364 | AG18: 0.08171998 | AH18: 0.03591323 | AI18: -0.08142375 | AJ18: 0.0073274439 | AK18: -0.022832885 | AL18: -0.032812812 | AM18: -0.096053029 | AN18: -0.053661578 | AO18: -0.005427535 | AP18: 0.078278592 | AQ18: 0.076230845 | AR18: -0.061694524 | AS18: 0.083253128 | AT18: 0.04332565 | AU18: 0.064575644 | AV18: -0.028768756 | AW18: 0.024538034 | AX18: -0.12606434 | AY18: 0.030189359 | AZ18: -0.14840908 | BA18: 0.00063231092 | BB18: 0.16725802 | BC18: 0.027942051 | BD18: -0.024016272 | BE18: -0.022230541 | BF18: -0.038143151 | BG18: -0.0023082369 | BH18: -0.062935384 | BI18: 0.10900001 | BJ18: 0.0059560641 | BK18: 0.073455627 | BL18: 0.026352779 | BM18: -0.069782333 | BN18: 0.078208699 | BO18: 0.0084067313 | BP18: 0.04685754 | BQ18: 0.0019167841 | BR18: 0.12096182 | BS18: -0.0039836251 | BT18: -0.013299151 | BU18: 0.080677444 | BV18: 0.080923395 | BW18: -0.085311087 | BX18: 0.019018475 | BY18: -0.062686744 | BZ18: 0.15331999 | CA18: 0.033286165 | CB18: 0.10684606 | CC18: 0.10466062 | CD18: 0.050445795 | CE18: 0.077260395 | CF18: 0.043957743 | CG18: 0.22664141 | CH18: 0.16265705 | CI18: -0.11772541 | CJ18: 0.062313678 | CK18: 0.090667784 | CL18: -0.030989545 | CM18: 0.01554875 | CN18: -0.12094313 | CO18: 0.15059751 | CP18: -0.16283911 | CQ18: -0.047976536 | CR18: -0.055156129 | CS18: 0.02812856 | CT18: -0.090515429 | CU18: 0.071648691 | CV18: -0.091040282 | CW18: 0.0084560856 | CX18: -0.014078748 | CY18: 0.051357414 | CZ18: -0.13284286 | DA18: 0.04738094 | DB18: 0.045735209 | DC18: -0.082819707 | DD18: 0.082462353 | DE18: -0.038420587 | DF18: -0.36669201 | DG18: 0.0076194732 | DH18: 0.028038013 | DI18: -0.018613248 | DJ18: -0.050654511 | DK18: -0.15851363 | DL18: -0.0038302741 | DM18: 0.066508141 | DN18: -0.05687526 | DO18: 0.22032021 | DP18: 0.021510335 | DQ18: 0.061955529 | DR18: 0.010451249 | DS18: -0.011277982 | DT18: 0.11601739 | DU18: 0.096895186 | DV18: -0.10564061 | DW18: 0.081908692 | DX18: 0.068177294 | DY18: 0.1657631 | DZ18: 0.043227855 | EA18: -0.19894575 | EB18: 0.09704269 | EC18: 0.14304023 | ED18: 0.11047802 | EE18: 0.0011112877 | EF18: -0.048955017
A19: 160 | B19: 6 | C19: -0.077959416 | D19: 0.40752071 | E19: 0.054898094 | F19: 0.038646682 | G19: 0.097512091 | H19: -0.14889412 | I19: -0.13465433 | J19: -0.15623035 | K19: 0.41833785 | L19: -0.043048958 | M19: -0.043690236 | N19: -0.095347886 | O19: -0.019797434 | P19: 0.023513161 | Q19: 0.19716309 | R19: 0.041942629 | S19: -0.078696261 | T19: -0.10952586 | U19: 0.13569834 | V19: -0.09268832 | W19: -0.17473476 | X19: 0.12292315 | Y19: -0.10313024 | Z19: -0.022223239 | AA19: 0.047300122 | AB19: -0.060762351 | AC19: 0.028452835 | AD19: -0.095993378 | AE19: 0.11523187 | AF19: -0.16883058 | AG19: 0.041487103 | AH19: 0.016089488 | AI19: -0.047766353 | AJ19: -0.012167192 | AK19: -0.040581523 | AL19: -0.014914608 | AM19: -0.061124131 | AN19: -0.062111384 | AO19: -0.025892903 | AP19: 0.08757412 | AQ19: 0.088252757 | AR19: -0.074616898 | AS19: 0.10919888 | AT19: 0.049294982 | AU19: 0.076428716 | AV19: -0.050033021 | AW19: 0.022356168 | AX19: -0.2241238 | AY19: 0.066273243 | AZ19: -0.18687962 | BA19: -0.034363884 | BB19: 0.20180191 | BC19: 0.18457179 | BD19: -0.0032343926 | BE19: -0.030390671 | BF19: -0.049436517 | BG19: 0.00096322011 | BH19: -0.057134461 | BI19: 0.12779863 | BJ19: 0.021707302 | BK19: 0.097038423 | BL19: 0.025996465 | BM19: -0.088156797 | BN19: 0.08141326 | BO19: -0.018562314 | BP19: 0.062818808 | BQ19: 0.0099340445 | BR19: 0.13683924 | BS19: -0.024256339 | BT19: 0.013193669 | BU19: 0.075936251 | BV19: 0.093655241 | BW19: -0.10896696 | BX19: 0.034087785 | BY19: -0.027675492 | BZ19: 0.068702125 | CA19: 0.035609795 | CB19: 0.12783821 | CC19: 0.022506233 | CD19: 0.087664948 | CE19: 0.088474859 | CF19: 0.079051525 | CG19: 0.26389313 | CH19: 0.15288987 | CI19: -0.16520241 | CJ19: 0.0619405 | CK19: 0.10396772 | CL19: -0.04324028 | CM19: 0.075581871 | CN19: -0.14319321 | CO19: 0.16614656 | CP19: -0.1590326 | CQ19: 0.0027299082 | CR19: -0.04969419 | CS19: 0.043774987 | CT19: -0.12262043 | CU19: 0.083436397 | CV19: -0.10197986 | CW19: 0.021901808 | CX19: 0.0011275946 | CY19: 0.07092187 | CZ19: -0.11285183 | DA19: 0.058223877 | DB19: 0.035720899 | DC19: -0.065587585 | DD19: 0.10625734 | DE19: -0.033018415 | DF19: -0.20550175 | DG19: 0.012746475 | DH19: 0.00015698313 | DI19: -0.058647033 | DJ19: -0.080499602 | DK19: -0.12414459 | DL19: -0.011982786 | DM19: 0.081952255 | DN19: -0.064294394 | DO19: 0.24926195 | DP19: 0.0040024609 | DQ19: 0.050623171 | DR19: 0.017544799 | DS19: 0.0056773135 | DT19: 0.1331285 | DU19: 0.1428307 | DV19: -0.11152471 | DW19: 0.060609139 | DX19: 0.094614193 | DY19: 0.15211941 | DZ19: 0.079643568 | EA19: -0.23304583 | EB19: 0.10624586 | EC19: 0.1437742 | ED19: 0.15093532 | EE19: -0.0073065267 | EF19: -0.016977955
A20: 192 | B20: 5 | C20: -0.1393246 | D20: 0.38202502 | E20: -0.015499988 | F20: 0.091218422 | G20: 0.10036591 | H20: -0.164372 | I20: -0.15814956 | J20: -0.13320729 | K20: 0.090108654 | L20: -0.095708636 | M20: -0.077718228 | N20: -0.10192493 | O20: -0.11011453 | P20: 0.043138679 | Q20: 0.21672574 | R20: 0.066469633 | S20: -0.057341083 | T20: -0.10084553 | U20: 0.14864968 | V20: -0.1035176 | W20: -0.22644366 | X20: 0.15004231 | Y20: -0.12896504 | Z20: 0.02915735 | AA20: 0.066961979 | AB20: -0.060423624 | AC20: 0.056443346 | AD20: -0.12984342 | AE20: 0.01731115 | AF20: -0.22349782 | AG20: 0.032163249 | AH20: 0.027806702 | AI20: -0.083279354 | AJ20: -0.017241716 | AK20: -0.0082485151 | AL20: -0.020780265 | AM20: -0.06752986 | AN20: 0.032916683 | AO20: -0.045285082 | AP20: 0.13173046 | AQ20: -0.027452485 | AR20: -0.013289273 | AS20: 0.042291716 | AT20: 0.0058587738 | AU20: 0.075692387 | AV20: -0.054625714 | AW20: 0.0068652682 | AX20: -0.20433922 | AY20: -0.082057636 | AZ20: -0.21380243 | BA20: -0.036798865 | BB20: 0.23121363 | BC20: 0.24014067 | BD20: -0.053429813 | BE20: -0.038466832 | BF20: -0.0552169 | BG20: -0.051727193 | BH20: -0.051899277 | BI20: 0.13174527 | BJ20: 0.021629512 | BK20: 0.11765037 | BL20: 0.019783342 | BM20: -0.05455591 | BN20: -0.018638027 | BO20: -0.0076105449 | BP20: 0.060407521 | BQ20: 0.015451707 | BR20: 0.18112708 | BS20: 0.0054075062 | BT20: 0.052467623 | BU20: 0.098754949 | BV20: 0.11591833 | BW20: -0.13550325 | BX20: 0.030693637 | BY20: -0.043183483 | BZ20: 0.090271404 | CA20: 0.050216826 | CB20: 0.12649505 | CC20: 0.012915147 | CD20: 0.096064648 | CE20: 0.085778173 | CF20: 0.10578489 | CG20: 0.32193852 | CH20: 0.071864026 | CI20: -0.13148573 | CJ20: 0.12344032 | CK20: 0.090978397 | CL20: -0.092184934 | CM20: 0.079454727 | CN20: -0.20489183 | CO20: 0.2285182 | CP20: -0.19203121 | CQ20: -0.0061113579 | CR20: -0.073116245 | CS20: 0.022293038 | CT20: -0.090474037 | CU20: 0.094867658 | CV20: -0.092511076 | CW20: -0.0099530629 | CX20: 0.0093861438 | CY20: 0.012479733 | CZ20: -0.15516165 | DA20: 0.047471893 | DB20: 0.05690271 | DC20: -0.037332311 | DD20: 0.14810881 | DE20: -0.010418722 | DF20: -0.24557421 | DG20: 0.0042022106 | DH20: 0.010975412 | DI20: -0.074248336 | DJ20: -0.08127702 | DK20: -0.084953981 | DL20: -0.019465373 | DM20: -0.0092836503 | DN20: -0.064461202 | DO20: 0.25800136 | DP20: 0.021671262 | DQ20: 0.038540311 | DR20: 0.055557992 | DS20: 0.0074906958 | DT20: 0.13343598 | DU20: 0.17206911 | DV20: -0.12934547 | DW20: 0.069060204 | DX20: 0.097851218 | DY20: 0.18740183 | DZ20: -0.018115127 | EA20: -0.29368998 | EB20: 0.10631227 | EC20: 0.13100615 | ED20: 0.17691886 | EE20: -0.0017409798 | EF20: -0.020281417
A21: 241 | B21: 4 | C21: -0.19764916 | D21: 0.12638792 | E21: 0.00027935227 | F21: 0.051097484 | G21: 0.007296138 | H21: -0.19866806 | I21: -0.14725561 | J21: -0.13674292 | K21: 0.088973017 | L21: -0.10967961 | M21: -0.099684593 | N21: -0.099587412 | O21: -0.13927749 | P21: 0.039891723 | Q21: 0.25731007 | R21: 0.084905231 | S21: -0.036563292 | T21: -0.13112036 | U21: 0.086278418 | V21: -0.10537077 | W21: -0.32292055 | X21: 0.20780127 | Y21: -0.092729224 | Z21: 0.039457716 | AA21: 0.028033456 | AB21: -0.065287595 | AC21: 0.07430113 | AD21: -0.12882467 | AE21: 0.010311611 | AF21: -0.29514426 | AG21: 0.011046572 | AH21: 0.043406383 | AI21: -0.067729681 | AJ21: -0.0051859256 | AK21: 0.018318369 | AL21: -0.037391486 | AM21: 0.063125718 | AN21: 0.018695533 | AO21: -0.047726396 | AP21: 0.072535144 | AQ21: -0.076865507 | AR21: 0.047988141 | AS21: 0.045406682 | AT21: -0.0024929113 | AU21: 0.047809632 | AV21: -0.05552078 | AW21: 0.00979103 | AX21: -0.2177183 | AY21: -0.065722295 | AZ21: -0.25491127 | BA21: -0.071032182 | BB21: 0.29451264 | BC21: 0.16446053 | BD21: -0.021750863 | BE21: -0.040588333 | BF21: -0.062289949 | BG21: -0.078525059 | BH21: -0.067916731 | BI21: 0.1659696 | BJ21: 0.023579026 | BK21: 0.072723115 | BL21: 0.0037527985 | BM21: -0.094970355 | BN21: -0.025790766 | BO21: 0.015004103 | BP21: 0.10450913 | BQ21: 0.054542231 | BR21: 0.14206146 | BS21: 0.0058601728 | BT21: 0.060820743 | BU21: 0.13549646 | BV21: 0.142143 | BW21: -0.1466792 | BX21: -0.0029908193 | BY21: -0.014916379 | BZ21: 0.047662929 | CA21: 0.095059434 | CB21: 0.20786985 | CC21: -0.0080189543 | CD21: 0.084423551 | CE21: 0.061514882 | CF21: 0.11452616 | CG21: 0.32016678 | CH21: 0.080100321 | CI21: -0.12329335 | CJ21: 0.085627757 | CK21: 0.12705055 | CL21: -0.13389042 | CM21: 0.062994333 | CN21: -0.080851509 | CO21: 0.23779198 | CP21: -0.22270006 | CQ21: -0.0032880917 | CR21: -0.090824278 | CS21: 0.030907746 | CT21: -0.082292873 | CU21: 0.06267356 | CV21: -0.098225632 | CW21: -0.065005417 | CX21: 0.013395524 | CY21: 0.0084819164 | CZ21: -0.23745137 | DA21: -0.0011922565 | DB21: 0.051624434 | DC21: -0.1539048 | DD21: -0.12132269 | DE21: -0.028977737 | DF21: -0.30115021 | DG21: -0.0078463781 | DH21: -0.01407682 | DI21: -0.090149203 | DJ21: -0.073302792 | DK21: -0.13950271 | DL21: -0.012736992 | DM21: 0.02983412 | DN21: -0.046874835 | DO21: 0.3316268 | DP21: 0.037108633 | DQ21: 0.028216052 | DR21: 0.05355699 | DS21: 0.0016720947 | DT21: 0.1705708 | DU21: 0.028090294 | DV21: -0.14027598 | DW21: 0.12824787 | DX21: 0.11682889 | DY21: 0.22566188 | DZ21: -0.17989102 | EA21: -0.26605683 | EB21: 0.10329556 | EC21: 0.14009402 | ED21: 0.054498856 | EE21: 0.021310592 | EF21: 0.018771264
A22: 321 | B22: 3 | C22: 0.064235718 | D22: 0.14242785 | E22: 0.041027532 | F22: 0.097433996 | G22: 0.032954824 | H22: -0.17874946 | I22: -0.12349317 | J22: -0.1042535 | K22: 0.15328677 | L22: -0.17118336 | M22: -0.074100059 | N22: -0.13328042 | O22: -0.066442332 | P22: 0.042858489 | Q22: 0.27677689 | R22: 0.066698293 | S22: -0.039234144 | T22: -0.10484897 | U22: 0.11059002 | V22: -0.057024135 | W22: -0.34619349 | X22: 0.25720235 | Y22: -0.047938332 | Z22: 0.023866122 | AA22: 0.11812061 | AB22: -0.038274054 | AC22: 0.074420381 | AD22: -0.013572789 | AE22: -0.085147686 | AF22: -0.42991677 | AG22: 0.010812101 | AH22: -0.00048894599 | AI22: -0.067392901 | AJ22: -0.013081542 | AK22: 0.078575769 | AL22: -0.0011447262 | AM22: 0.056373754 | AN22: 0.035264122 | AO22: -0.074717373 | AP22: 0.062536354 | AQ22: -0.079426117 | AR22: 0.067924488 | AS22: -0.073843703 | AT22: -0.025136362 | AU22: 0.033500452 | AV22: -0.059813177 | AW22: -0.030149389 | AX22: 0.009875186 | AY22: -0.098456276 | AZ22: -0.15490378 | BA22: -0.045598425 | BB22: 0.36955058 | BC22: 0.19562604 | BD22: -0.022174181 | BE22: -0.068483037 | BF22: -0.054886014 | BG22: -0.096178529 | BH22: -0.0079934121 | BI22: 0.11108872 | BJ22: 0.054996415 | BK22: 0.048315241 | BL22: 0.017863882 | BM22: -0.12093964 | BN22: -0.082937899 | BO22: 0.038350063 | BP22: 0.07483555 | BQ22: 0.027830097 | BR22: 0.10656678 | BS22: -0.016372782 | BT22: -0.088726194 | BU22: 0.21294877 | BV22: 0.15854397 | BW22: -0.1746685 | BX22: 0.036637446 | BY22: 0.032352876 | BZ22: 0.047257736 | CA22: 0.14407874 | CB22: 0.25473926 | CC22: -0.125104 | CD22: 0.095518543 | CE22: 0.066840146 | CF22: 0.10077036 | CG22: 0.44380082 | CH22: 0.11591877 | CI22: -0.23044917 | CJ22: 0.10337951 | CK22: 0.036163343 | CL22: -0.2406518 | CM22: 0.046441279 | CN22: -0.15280392 | CO22: 0.18528576 | CP22: -0.25940856 | CQ22: 0.012333779 | CR22: -0.16185042 | CS22: 0.024439587 | CT22: -0.058232521 | CU22: 0.12023171 | CV22: -0.1122337 | CW22: -0.036451253 | CX22: 0.047285453 | CY22: 0.0079888258 | CZ22: -0.26292048 | DA22: 0.0039917539 | DB22: 0.058383507 | DC22: -0.14116724 | DD22: -0.1478941 | DE22: 0.017756504 | DF22: -0.38966763 | DG22: -0.031985043 | DH22: -0.013945346 | DI22: -0.081105544 | DJ22: -0.042776922 | DK22: -0.17913471 | DL22: -0.0032133307 | DM22: 0.063466051 | DN22: -0.083173707 | DO22: 0.075715816 | DP22: 0.10509906 | DQ22: 0.051850202 | DR22: 0.0712363 | DS22: 0.036346262 | DT22: 0.058357009 | DU22: 0.057495391 | DV22: -0.12570512 | DW22: 0.078389724 | DX22: 0.16435212 | DY22: 0.31775437 | DZ22: -0.16562625 | EA22: -0.14035616 | EB22: 0.14292708 | EC22: -0.028428812 | ED22: 0.077413567 | EE22: 0.047636659 | EF22: 0.034790246
A23: 482 | B23: 2 | C23: -0.034987009 | D23: 0.25409263 | E23: 0.080941173 | F23: 0.14166491 | G23: 0.052224174 | H23: -0.20371831 | I23: -0.14815203 | J23: -0.11487751 | K23: 0.20448948 | L23: -0.05404353 | M23: -0.25844992 | N23: -0.15641924 | O23: -0.12289971 | P23: 0.010683505 | Q23: -0.059568017 | R23: 0.062821978 | S23: -0.072572664 | T23: -0.084676176 | U23: 0.093757422 | V23: 0.063357011 | W23: -0.50391933 | X23: 0.19455646 | Y23: -0.0075887634 | Z23: 0.041051967 | AA23: 0.15164933 | AB23: -0.047748945 | AC23: 0.076346338 | AD23: -0.071628868 | AE23: -0.22171324 | AF23: -0.32465933 | AG23: -0.14589389 | AH23: -0.03727949 | AI23: -0.07545017 | AJ23: -0.02358744 | AK23: 0.091199224 | AL23: -0.051310311 | AM23: -0.020470543 | AN23: 0.1276296 | AO23: 0.0053369522 | AP23: -0.0031210994 | AQ23: -0.089424992 | AR23: 0.14613616 | AS23: -0.081663621 | AT23: -0.041427722 | AU23: 0.033145526 | AV23: -0.027638994 | AW23: -0.05202691 | AX23: 0.014812779 | AY23: -0.0581396 | AZ23: -0.063753617 | BA23: 0.0096467801 | BB23: 0.56682653 | BC23: 0.25286918 | BD23: 0.094830881 | BE23: -0.086532395 | BF23: -0.060012944 | BG23: -0.044908675 | BH23: 0.053596864 | BI23: 0.19111208 | BJ23: 0.10400332 | BK23: 0.047849323 | BL23: -0.05343222 | BM23: -0.18414781 | BN23: -0.038453237 | BO23: 0.06181548 | BP23: 0.098266399 | BQ23: 0.072047901 | BR23: 0.10282259 | BS23: -0.073275389 | BT23: -0.21818668 | BU23: 0.20568774 | BV23: 0.11346757 | BW23: -0.20215233 | BX23: -0.0082131197 | BY23: 0.039939449 | BZ23: 0.0076697624 | CA23: 0.20637272 | CB23: 0.31616676 | CC23: -0.084544615 | CD23: 0.14124194 | CE23: 0.059602302 | CF23: 0.016160835 | CG23: 0.29290394 | CH23: 0.18019645 | CI23: -0.059122474 | CJ23: 0.019875368 | CK23: 0.096116995 | CL23: -0.40866101 | CM23: 0.006975009 | CN23: -0.27710426 | CO23: 0.26845098 | CP23: -0.31136074 | CQ23: 0.0091837445 | CR23: -0.011597804 | CS23: 0.069015371 | CT23: -0.045662542 | CU23: 0.021056596 | CV23: 0.022245137 | CW23: -0.10090133 | CX23: -0.04425408 | CY23: -0.022046531 | CZ23: -0.18199879 | DA23: 0.030982136 | DB23: 0.015955157 | DC23: -0.1579489 | DD23: -0.21341104 | DE23: 0.060085948 | DF23: -0.40879492 | DG23: -0.038270012 | DH23: -0.055413447 | DI23: -0.18491271 | DJ23: 0.033824576 | DK23: -0.27783322 | DL23: 0.026242652 | DM23: 0.019497305 | DN23: -0.11820475 | DO23: 0.12406844 | DP23: 0.038404396 | DQ23: 0.12113204 | DR23: 0.1024258 | DS23: 0.11657599 | DT23: 0.12395522 | DU23: -0.034287185 | DV23: -0.27627161 | DW23: 0.14122823 | DX23: 0.17100279 | DY23: 0.26822193 | DZ23: -0.12933302 | EA23: 0.02875878 | EB23: 0.1382255 | EC23: -0.12320494 | ED23: 0.091425905 | EE23: 0.069212076 | EF23: 0.047782279
A24: 964 | B24: 1 | C24: 0.16299314 | D24: 0.10060991 | E24: -0.07140033 | F24: 0.22715955 | G24: -0.22576002 | H24: -0.24668673 | I24: 0.0021119332 | J24: -0.1154628 | K24: 0.021515278 | L24: -0.095623251 | M24: -0.14681934 | N24: -0.14413045 | O24: -0.24427786 | P24: 0.077736486 | Q24: -0.060964962 | R24: -0.027822824 | S24: -0.01105446 | T24: -0.2878166 | U24: 0.14851867 | V24: 0.11654032 | W24: -0.64293353 | X24: -0.00089887647 | Y24: -0.02939884 | Z24: -0.024394549 | AA24: 0.094359583 | AB24: -0.18425142 | AC24: 0.12538038 | AD24: -0.1011753 | AE24: -0.17526882 | AF24: -0.49538941 | AG24: -0.38005539 | AH24: 0.068613799 | AI24: -0.15191167 | AJ24: -0.085435202 | AK24: 0.11317916 | AL24: -0.10745443 | AM24: 0.014966545 | AN24: 0.16294174 | AO24: -0.066090112 | AP24: 0.022851715 | AQ24: -0.047076973 | AR24: 0.17083341 | AS24: -0.0032867737 | AT24: 0.030459207 | AU24: 0.04409532 | AV24: -0.087151952 | AW24: 0.0049875415 | AX24: -0.11149134 | AY24: -0.26743574 | AZ24: 0.037867074 | BA24: -0.053794732 | BB24: 0.69077653 | BC24: -0.0043668696 | BD24: 0.18559522 | BE24: -0.10413112 | BF24: -0.10023171 | BG24: -0.17662354 | BH24: 0.009569451 | BI24: 0.22362911 | BJ24: 0.0033483158 | BK24: 0.034827647 | BL24: -0.030898612 | BM24: -0.37691636 | BN24: -0.10891326 | BO24: -0.0056244216 | BP24: 0.12335118 | BQ24: -0.064169633 | BR24: 0.098920889 | BS24: -0.0012847175 | BT24: -0.27671902 | BU24: 0.22832663 | BV24: 0.10772845 | BW24: -0.061835884 | BX24: -0.13296006 | BY24: -0.29033687 | BZ24: 0.2588929 | CA24: 0.10002492 | CB24: 0.63969813 | CC24: -0.18246988 | CD24: 0.029953526 | CE24: 0.16556487 | CF24: -0.043964634 | CG24: 0.23727783 | CH24: 0.3542773 | CI24: -0.058508157 | CJ24: -0.013109485 | CK24: 0.093530079 | CL24: 0.14175533 | CM24: 0.044688538 | CN24: -0.6096772 | CO24: 0.57240961 | CP24: -0.1603442 | CQ24: -0.11468717 | CR24: -0.061084838 | CS24: -0.026854923 | CT24: -0.096419008 | CU24: 0.072751348 | CV24: -0.015064048 | CW24: -0.17511717 | CX24: 0.052765259 | CY24: 0.080066905 | CZ24: -0.11220663 | DA24: -0.024511204 | DB24: 0.19546067 | DC24: -0.28272978 | DD24: -0.15338138 | DE24: -0.13158559 | DF24: -0.52558501 | DG24: -0.059105834 | DH24: -0.00084652507 | DI24: -0.4230988 | DJ24: -0.021081471 | DK24: -0.33950921 | DL24: 0.061360513 | DM24: 0.14143953 | DN24: -0.14903326 | DO24: 0.11561196 | DP24: 0.14433064 | DQ24: 0.05048619 | DR24: 0.023391731 | DS24: 0.067362546 | DT24: 0.038362866 | DU24: 0.047638587 | DV24: -0.1582247 | DW24: 0.10885709 | DX24: 0.17373733 | DY24: 0.032066536 | DZ24: 0.048904664 | EA24: 0.054920184 | EB24: 0.10922877 | EC24: -0.25665138 | ED24: 0.056172845 | EE24: 0.10748066 | EF24: -0.067276677
A25: 大盤 | B25: TWII | C25: -0.017446771 | D25: 0.020701061 | E25: 0.023982129 | F25: -0.006557579 | G25: 0.03184513 | H25: 0.034348533 | I25: -0.0082549328 | J25: 0.012843524 | K25: -0.051018525 | L25: 0.00087394274 | M25: 0.023389576 | N25: 0.012988972 | O25: 0.0058545887 | P25: 0.027413207 | Q25: -0.0037129361 | R25: 0.024076614 | S25: -0.012190025 | T25: -0.039749578 | U25: -0.07315545 | V25: -0.05826023 | W25: 0.00077279757 | X25: 0.044591521 | Y25: -0.02769968 | Z25: 0.0020950059 | AA25: -0.023400551 | AB25: 0.032129371 | AC25: 0.038903273 | AD25: -0.042865382 | AE25: 0.018647195 | AF25: 0.015229768 | AG25: 0.036016604 | AH25: 0.0093546114 | AI25: 0.010748251 | AJ25: 0.013357754 | AK25: -0.0053327473 | AL25: 0.0013831358 | AM25: 0.020795928 | AN25: 0.031517702 | AO25: 0.0062417165 | AP25: 0.0061452617 | AQ25: 0.016946358 | AR25: 0.03468283 | AS25: 0.0030985886 | AT25: 0.015081347 | AU25: -0.019251209 | AV25: 0.038711513 | AW25: -0.021856951 | AX25: 0.0077743007 | AY25: 0.042397247 | AZ25: -0.026308975 | BA25: 0.0095717493 | BB25: -0.024249741 | BC25: 0.020163374 | BD25: -0.0035049988 | BE25: 0.020151935 | BF25: 0.00058133623 | BG25: -0.005219701 | BH25: -0.11587176 | BI25: 0.0087252257 | BJ25: -0.016377261 | BK25: 0.020840372 | BL25: 0.044975872 | BM25: 0.023954306 | BN25: 0.030239101 | BO25: -0.043725888 | BP25: 0.02188947 | BQ25: 0.0086274303 | BR25: -0.019192954 | BS25: 0.01973513 | BT25: 0.047694337 | BU25: 0.011454817 | BV25: 0.043228621 | BW25: -0.04274743 | BX25: -0.017811292 | BY25: -0.1511531 | BZ25: 0.124224 | CA25: -0.0045572538 | CB25: 0.06021124 | CC25: 0.085992033 | CD25: -0.0058084796 | CE25: -0.006041347 | CF25: 0.0024523244 | CG25: 0.089636252 | CH25: 0.070992733 | CI25: 0.027170643 | CJ25: 0.052468428 | CK25: 0.029480661 | CL25: 0.066825081 | CM25: -0.028772229 | CN25: 0.039462516 | CO25: -0.029031087 | CP25: 0.013983883 | CQ25: -0.032276965 | CR25: 0.0031035766 | CS25: 0.025591856 | CT25: 0.044391886 | CU25: -0.030338959 | CV25: -0.0012579765 | CW25: 0.0023363565 | CX25: -0.064264145 | CY25: 0.012909779 | CZ25: -0.12547709 | DA25: 0.011690683 | DB25: 0.0063378437 | DC25: -0.11730536 | DD25: -0.036010872 | DE25: 0.1389113 | DF25: -0.051143506 | DG25: 0.076731447 | DH25: 0.015508782 | DI25: 0.023223774 | DJ25: -0.018372876 | DK25: 0.062199014 | DL25: 0.020098304 | DM25: 0.01349894 | DN25: -0.030252213 | DO25: -0.017022836 | DP25: -0.021788523 | DQ25: 0.085745625 | DR25: 0.028106744 | DS25: -0.0023031598 | DT25: 0.058471198 | DU25: 0.067658949 | DV25: 0.0050207706 | DW25: 0.037416184 | DX25: 0.084111004 | DY25: -0.036832399 | DZ25: 0.0030917028 | EA25: -0.0019576282 | EB25: 0.026459104 | EC25: -0.024752539 | ED25: 0.034115491 | EE25: 0.021061974 | EF25: -0.020277393

Sheet 預測(XGB)勝率
A1: XGB
B2: Time | C2: 2013/12 | D2: 2014/01 | E2: 2014/02 | F2: 2014/03 | G2: 2014/04 | H2: 2014/05 | I2: 2014/06 | J2: 2014/07 | K2: 2014/08 | L2: 2014/09 | M2: 2014/10 | N2: 2014/11 | O2: 2014/12 | P2: 2015/01 | Q2: 2015/02 | R2: 2015/03 | S2: 2015/04 | T2: 2015/05 | U2: 2015/06 | V2: 2015/07 | W2: 2015/08 | X2: 2015/09 | Y2: 2015/10 | Z2: 2015/11 | AA2: 2015/12 | AB2: 2016/01 | AC2: 2016/02 | AD2: 2016/03 | AE2: 2016/04 | AF2: 2016/05 | AG2: 2016/06 | AH2: 2016/07 | AI2: 2016/08 | AJ2: 2016/09 | AK2: 2016/10 | AL2: 2016/11 | AM2: 2016/12 | AN2: 2017/01 | AO2: 2017/02 | AP2: 2017/03 | AQ2: 2017/04 | AR2: 2017/05 | AS2: 2017/06 | AT2: 2017/07 | AU2: 2017/08 | AV2: 2017/09 | AW2: 2017/10 | AX2: 2017/11 | AY2: 2017/12 | AZ2: 2018/01 | BA2: 2018/02 | BB2: 2018/03 | BC2: 2018/04 | BD2: 2018/05 | BE2: 2018/06 | BF2: 2018/07 | BG2: 2018/08 | BH2: 2018/09 | BI2: 2018/10 | BJ2: 2018/11 | BK2: 2018/12 | BL2: 2019/01 | BM2: 2019/02 | BN2: 2019/03 | BO2: 2019/04 | BP2: 2019/05 | BQ2: 2019/06 | BR2: 2019/07 | BS2: 2019/08 | BT2: 2019/09 | BU2: 2019/10 | BV2: 2019/11 | BW2: 2019/12 | BX2: 2020/01 | BY2: 2020/02 | BZ2: 2020/03 | CA2: 2020/04 | CB2: 2020/05 | CC2: 2020/06 | CD2: 2020/07 | CE2: 2020/08 | CF2: 2020/09 | CG2: 2020/10 | CH2: 2020/11 | CI2: 2020/12 | CJ2: 2021/01 | CK2: 2021/02 | CL2: 2021/03 | CM2: 2021/04 | CN2: 2021/05 | CO2: 2021/06 | CP2: 2021/07 | CQ2: 2021/08 | CR2: 2021/09 | CS2: 2021/10 | CT2: 2021/11 | CU2: 2021/12 | CV2: 2022/01 | CW2: 2022/02 | CX2: 2022/03 | CY2: 2022/04 | CZ2: 2022/05 | DA2: 2022/06 | DB2: 2022/07 | DC2: 2022/08 | DD2: 2022/09 | DE2: 2022/10 | DF2: 2022/11 | DG2: 2022/12 | DH2: 2023/01 | DI2: 2023/02 | DJ2: 2023/03 | DK2: 2023/04 | DL2: 2023/05 | DM2: 2023/06 | DN2: 2023/07 | DO2: 2023/08 | DP2: 2023/09 | DQ2: 2023/10 | DR2: 2023/11 | DS2: 2023/12 | DT2: 2024/01 | DU2: 2024/02 | DV2: 2024/03 | DW2: 2024/04 | DX2: 2024/05 | DY2: 2024/06 | DZ2: 2024/07 | EA2: 2024/08 | EB2: 2024/09 | EC2: 2024/10 | ED2: 2024/11 | EE2: 2024/12 | EF2: 2025/01 | EG2: 2025/02
B3: bm | C3: 0.040547289 | D3: 0.014746175 | E3: -0.051652342 | F3: -0.054286115 | G3: -0.057552006 | H3: -0.076259449 | I3: -0.10788648 | J3: 0.013737112 | K3: -0.059229229 | L3: -0.10780369 | M3: 0.024141319 | N3: -0.13467413 | O3: -0.0079268562 | P3: -0.075651743 | Q3: -0.08644776 | R3: -0.0030133345 | S3: -0.040853243 | T3: -0.032101776 | U3: -0.10543977 | V3: -0.045746464 | W3: -0.0068120561 | X3: 0.09770143 | Y3: 0.061205495 | Z3: 0.016075654 | AA3: -0.012703552 | AB3: -0.010262255 | AC3: 0.029340141 | AD3: -0.0058081243 | AE3: 0.011994774 | AF3: 0.039971381 | AG3: -0.012103247 | AH3: 0.022090664 | AI3: 0.021936081 | AJ3: 0.025844747 | AK3: -0.0023109075 | AL3: -0.020252099 | AM3: 0.022393657 | AN3: -0.0035141658 | AO3: -0.029745672 | AP3: -0.026837837 | AQ3: -0.021697119 | AR3: 0.023448717 | AS3: 0.015802857 | AT3: 0.066039756 | AU3: 0.062266789 | AV3: 0.057940513 | AW3: 0.10639411 | AX3: -0.0057518133 | AY3: 0.003456265 | AZ3: 0.08603631 | BA3: 0.10234847 | BB3: 0.063502729 | BC3: 0.048442636 | BD3: 0.077497914 | BE3: 0.027031764 | BF3: 0.021175273 | BG3: -0.012267982 | BH3: 0.051240973 | BI3: 0.055158429 | BJ3: 0.086648971 | BK3: 0.081092678 | BL3: 0.057930887 | BM3: 0.014249544 | BN3: -0.0046854224 | BO3: 0.04586114 | BP3: 0.086037964 | BQ3: 0.14414221 | BR3: 0.037985831 | BS3: 0.081880234 | BT3: 0.043688308 | BU3: 0.10545724 | BV3: 0.11753765 | BW3: 0.092942402 | BX3: 0.035637498 | BY3: 0.04292509 | BZ3: 0.098455094 | CA3: 0.018217886 | CB3: 0.019438757 | CC3: -0.0050573386 | CD3: -0.057951014 | CE3: -0.011938484 | CF3: 0.0064156759 | CG3: 0.0056247138 | CH3: 0.058184978 | CI3: 0.012768986 | CJ3: -0.080891326 | CK3: 0.073738843 | CL3: 0.067692369 | CM3: -0.018292543 | CN3: 0.0046888106 | CO3: -0.012873714 | CP3: -0.052108333 | CQ3: -0.072693914 | CR3: -0.060804408 | CS3: 0.015148262 | CT3: -0.063390315 | CU3: -0.06107983 | CV3: -0.021700332 | CW3: -0.060720678 | CX3: -0.040655192 | CY3: -0.045480587 | CZ3: -0.069138072 | DA3: -0.089778468 | DB3: -0.065274872 | DC3: -0.013747443 | DD3: -0.059340179 | DE3: -0.0029697688 | DF3: 0.02926687 | DG3: -0.024713881 | DH3: -0.035376154 | DI3: -0.027640743 | DJ3: -0.0057575447 | DK3: -0.048771854 | DL3: -0.011303868 | DM3: -0.049678039 | DN3: -0.012807783 | DO3: -0.01587224 | DP3: -0.0075895861 | DQ3: 0.040078633 | DR3: -0.01592231 | DS3: 0.023432238 | DT3: -0.053663064 | DU3: -0.044161681 | DV3: -0.023813089 | DW3: 0.025176367 | DX3: -0.032621369 | DY3: 0.013060666 | DZ3: -0.047912493 | EA3: 0.014760353 | EB3: -0.029227724 | EC3: -0.035695001 | ED3: -0.052812476 | EE3: -0.013054582 | EF3: -0.069071874
B4: size | C4: -0.018580828 | D4: -0.04825278 | E4: 0.0078275679 | F4: -0.026776634 | G4: 0.016258875 | H4: -0.0087667406 | I4: -0.0070548905 | J4: -0.032917611 | K4: 0.0073888558 | L4: 0.035096999 | M4: -0.019348426 | N4: -0.012498206 | O4: -0.067216232 | P4: -0.027688211 | Q4: -0.059864789 | R4: -0.077407129 | S4: -0.083726525 | T4: -0.059324656 | U4: -0.0023863558 | V4: 0.0046488689 | W4: -0.074044973 | X4: -0.098803863 | Y4: -0.091002114 | Z4: -0.068004087 | AA4: -0.086181231 | AB4: -0.088893928 | AC4: -0.01658844 | AD4: 0.063448824 | AE4: -0.059580553 | AF4: 0.0010961501 | AG4: 0.028850742 | AH4: 0.029070802 | AI4: -0.01015707 | AJ4: 0.044545107 | AK4: -0.01327528 | AL4: 0.014735002 | AM4: 0.0052847122 | AN4: 0.047137059 | AO4: 0.007465574 | AP4: 0.0046993392 | AQ4: 0.020851189 | AR4: 0.054104723 | AS4: -0.0056461818 | AT4: 0.00404533 | AU4: 0.02062845 | AV4: 0.021113886 | AW4: -0.041878089 | AX4: 0.015781458 | AY4: -0.02299829 | AZ4: 0.0058780294 | BA4: -0.021811418 | BB4: -0.076676466 | BC4: 0.010045491 | BD4: -0.047882307 | BE4: -0.06855423 | BF4: -0.082745306 | BG4: -0.12042424 | BH4: -0.10103763 | BI4: -0.039490096 | BJ4: -0.064256303 | BK4: -0.14447127 | BL4: -0.11201132 | BM4: -0.03482601 | BN4: -0.085986465 | BO4: -0.070973977 | BP4: -0.034846526 | BQ4: -0.020351751 | BR4: -0.023155609 | BS4: -0.032191597 | BT4: -0.068826571 | BU4: -0.092764981 | BV4: -0.081678107 | BW4: -0.06856361 | BX4: -0.019831985 | BY4: -0.061186798 | BZ4: -0.070581049 | CA4: -0.072609454 | CB4: -0.088862821 | CC4: -0.065672167 | CD4: -0.070492014 | CE4: -0.089266889 | CF4: -0.019554028 | CG4: -0.038807325 | CH4: -0.026853707 | CI4: -0.023996761 | CJ4: -0.0069834162 | CK4: -0.011856382 | CL4: -0.011220707 | CM4: -0.019751672 | CN4: -0.017389096 | CO4: 0.00091980241 | CP4: -0.027678527 | CQ4: -0.027226128 | CR4: -0.034191106 | CS4: -0.037506074 | CT4: -0.049283858 | CU4: -0.023866469 | CV4: -0.0027314594 | CW4: 0.025829777 | CX4: -0.077818602 | CY4: -0.017143354 | CZ4: 0.0064833509 | DA4: 0.02112148 | DB4: 0.0016250079 | DC4: 0.014495826 | DD4: 0.037542593 | DE4: -0.047325566 | DF4: 0.033347134 | DG4: -0.018042853 | DH4: -0.012872834 | DI4: 0.025734814 | DJ4: 0.014163728 | DK4: -0.03316791 | DL4: -0.021062262 | DM4: 0.014148561 | DN4: -0.019859655 | DO4: -0.038560558 | DP4: 0.052595932 | DQ4: 0.050834373 | DR4: 0.034424391 | DS4: 0.026739173 | DT4: -0.022692034 | DU4: 0.023562549 | DV4: 0.011204046 | DW4: 0.0097593218 | DX4: -0.012008918 | DY4: -0.012910018 | DZ4: 0.014516729 | EA4: 0.020058911 | EB4: 0.052505847 | EC4: 0.032138381 | ED4: -0.0095858695 | EE4: 0.016591379 | EF4: 0.024656091
