Workbook

Sheet 預測IC
A1: NN1
B2: Time | C2: 2013/12 | D2: 2014/01 | E2: 2014/02 | F2: 2014/03 | G2: 2014/04 | H2: 2014/05 | I2: 2014/06 | J2: 2014/07 | K2: 2014/08 | L2: 2014/09 | M2: 2014/10 | N2: 2014/11 | O2: 2014/12 | P2: 2015/01 | Q2: 2015/02 | R2: 2015/03 | S2: 2015/04 | T2: 2015/05 | U2: 2015/06 | V2: 2015/07 | W2: 2015/08 | X2: 2015/09 | Y2: 2015/10 | Z2: 2015/11 | AA2: 2015/12 | AB2: 2016/01 | AC2: 2016/02 | AD2: 2016/03 | AE2: 2016/04 | AF2: 2016/05 | AG2: 2016/06 | AH2: 2016/07 | AI2: 2016/08 | AJ2: 2016/09 | AK2: 2016/10 | AL2: 2016/11 | AM2: 2016/12 | AN2: 2017/01 | AO2: 2017/02 | AP2: 2017/03 | AQ2: 2017/04 | AR2: 2017/05 | AS2: 2017/06 | AT2: 2017/07 | AU2: 2017/08 | AV2: 2017/09 | AW2: 2017/10 | AX2: 2017/11 | AY2: 2017/12 | AZ2: 2018/01 | BA2: 2018/02 | BB2: 2018/03 | BC2: 2018/04 | BD2: 2018/05 | BE2: 2018/06 | BF2: 2018/07 | BG2: 2018/08 | BH2: 2018/09 | BI2: 2018/10 | BJ2: 2018/11 | BK2: 2018/12 | BL2: 2019/01 | BM2: 2019/02 | BN2: 2019/03 | BO2: 2019/04 | BP2: 2019/05 | BQ2: 2019/06 | BR2: 2019/07 | BS2: 2019/08 | BT2: 2019/09 | BU2: 2019/10 | BV2: 2019/11 | BW2: 2019/12 | BX2: 2020/01 | BY2: 2020/02 | BZ2: 2020/03 | CA2: 2020/04 | CB2: 2020/05 | CC2: 2020/06 | CD2: 2020/07 | CE2: 2020/08 | CF2: 2020/09 | CG2: 2020/10 | CH2: 2020/11 | CI2: 2020/12 | CJ2: 2021/01 | CK2: 2021/02 | CL2: 2021/03 | CM2: 2021/04 | CN2: 2021/05 | CO2: 2021/06 | CP2: 2021/07 | CQ2: 2021/08 | CR2: 2021/09 | CS2: 2021/10 | CT2: 2021/11 | CU2: 2021/12 | CV2: 2022/01 | CW2: 2022/02 | CX2: 2022/03 | CY2: 2022/04 | CZ2: 2022/05 | DA2: 2022/06 | DB2: 2022/07 | DC2: 2022/08 | DD2: 2022/09 | DE2: 2022/10 | DF2: 2022/11 | DG2: 2022/12 | DH2: 2023/01 | DI2: 2023/02 | DJ2: 2023/03 | DK2: 2023/04 | DL2: 2023/05 | DM2: 2023/06 | DN2: 2023/07 | DO2: 2023/08 | DP2: 2023/09 | DQ2: 2023/10 | DR2: 2023/11 | DS2: 2023/12 | DT2: 2024/01 | DU2: 2024/02 | DV2: 2024/03 | DW2: 2024/04 | DX2: 2024/05 | DY2: 2024/06 | DZ2: 2024/07 | EA2: 2024/08 | EB2: 2024/09 | EC2: 2024/10 | ED2: 2024/11 | EE2: 2024/12 | EF2: 2025/01 | EG2: 2025/02
B3: bm | C3: 0.057230778 | D3: 0.075454518 | E3: 0.053419497 | F3: 0.048055463 | G3: 0.056244601 | H3: 0.053408809 | I3: 0.054677729 | J3: 0.061407112 | K3: 0.061087191 | L3: 0.061945472 | M3: 0.064090975 | N3: 0.050166409 | O3: 0.050939202 | P3: 0.05394581 | Q3: 0.05463516 | R3: 0.054097041 | S3: 0.054209419 | T3: 0.056115322 | U3: 0.054694336 | V3: 0.055520311 | W3: 0.057895616 | X3: 0.056128561 | Y3: 0.054498971 | Z3: 0.056409225 | AA3: 0.054687083 | AB3: 0.054479975 | AC3: 0.057393115 | AD3: 0.057433717 | AE3: 0.042686142 | AF3: 0.056140695 | AG3: 0.055614285 | AH3: 0.020760968 | AI3: 0.025099238 | AJ3: 0.029194398 | AK3: 0.030455951 | AL3: 0.034250386 | AM3: 0.039540499 | AN3: 0.043252841 | AO3: 0.044728361 | AP3: 0.042892594 | AQ3: 0.045430332 | AR3: 0.044913445 | AS3: 0.048380431 | AT3: 0.041918073 | AU3: 0.041785151 | AV3: 0.04308163 | AW3: 0.046142738 | AX3: 0.045525301 | AY3: 0.047935985 | AZ3: 0.041659117 | BA3: 0.038711324 | BB3: 0.038947169 | BC3: 0.042427823 | BD3: 0.04405136 | BE3: 0.045637585 | BF3: 0.048670642 | BG3: 0.049968019 | BH3: 0.051808406 | BI3: 0.05058419 | BJ3: 0.052059561 | BK3: 0.052372251 | BL3: 0.050854672 | BM3: 0.052194197 | BN3: 0.056162696 | BO3: 0.054506797 | BP3: 0.040165633 | BQ3: 0.052233845 | BR3: 0.036525637 | BS3: 0.052801784 | BT3: 0.048056014 | BU3: -0.09914422 | BV3: 0.052249499 | BW3: 0.03947461 | BX3: 0.047410384 | BY3: 0.047043912 | BZ3: 0.046114489 | CA3: 0.042742863 | CB3: 0.03848974 | CC3: 0.037457056 | CD3: 0.039794289 | CE3: 0.037495688 | CF3: 0.025139354 | CG3: 0.035978682 | CH3: 0.031778947 | CI3: 0.034042399 | CJ3: 0.038737696 | CK3: 0.039908383 | CL3: 0.037117619 | CM3: 0.017108668 | CN3: 0.040649183 | CO3: 0.02801203 | CP3: 0.0060336315 | CQ3: 0.033265896 | CR3: 0.033467647 | CS3: 0.022955686 | CT3: 0.018620189 | CU3: 0.016736574 | CV3: 0.0088566393 | CW3: 0.018140115 | CX3: 0.023012115 | CY3: 0.025537871 | CZ3: -0.010740899 | DA3: 0.017809309 | DB3: 0.031221993 | DC3: 0.0099241827 | DD3: 0.033772524 | DE3: 0.023819208 | DF3: 0.025578402 | DG3: 0.013096854 | DH3: 0.025391292 | DI3: 0.023517698 | DJ3: 0.0031970106 | DK3: 0.00061636377 | DL3: 0.0051844632 | DM3: 0.025786715 | DN3: 0.0097193727 | DO3: 0.0026195138 | DP3: -0.0043171626 | DQ3: 0.02653504 | DR3: 0.032421928 | DS3: 0.026365884 | DT3: 0.018022846 | DU3: 0.020606074 | DV3: 0.023552461 | DW3: 0.021600418 | DX3: 0.014226238 | DY3: 0.015565707 | DZ3: 0.013406808 | EA3: 0.0049481243 | EB3: -0.012768214 | EC3: 0.036291156 | ED3: 0.024168495 | EE3: 0.02159296 | EF3: 0.026417185
B4: size | C4: -0.085349202 | D4: -0.051032018 | E4: -0.023255905 | F4: -0.030555792 | G4: -0.041839428 | H4: -0.027263831 | I4: -0.048288483 | J4: -0.037104912 | K4: -0.036805965 | L4: -0.034764141 | M4: -0.037611727 | N4: -0.027905764 | O4: -0.034595735 | P4: -0.038765542 | Q4: -0.038997773 | R4: -0.033448916 | S4: -0.028517939 | T4: -0.021613039 | U4: -0.028846664 | V4: -0.027737571 | W4: -0.027205523 | X4: -0.028771609 | Y4: -0.026057502 | Z4: -0.03021864 | AA4: -0.029684331 | AB4: -0.028848922 | AC4: -0.029010216 | AD4: -0.036633201 | AE4: -0.029560335 | AF4: -0.028750766 | AG4: -0.027635267 | AH4: -0.018871812 | AI4: -0.037307039 | AJ4: -0.036262792 | AK4: -0.053278349 | AL4: -0.026777856 | AM4: -0.029865123 | AN4: -0.024307838 | AO4: -0.035743501 | AP4: -0.018087024 | AQ4: -0.021320786 | AR4: -0.017324459 | AS4: -0.029941695 | AT4: -0.028656892 | AU4: -0.030558156 | AV4: -0.031591557 | AW4: -0.030951437 | AX4: -0.029038088 | AY4: -0.033474009 | AZ4: -0.027750198 | BA4: -0.030938461 | BB4: -0.033736609 | BC4: -0.030917056 | BD4: -0.030206932 | BE4: -0.032964803 | BF4: -0.03150446 | BG4: -0.0322075 | BH4: -0.031379879 | BI4: -0.03114317 | BJ4: -0.03100197 | BK4: -0.032686032 | BL4: -0.031904723 | BM4: -0.031684242 | BN4: -0.0067815874 | BO4: -0.022827595 | BP4: -0.030927822 | BQ4: -0.033150502 | BR4: -0.011577768 | BS4: -0.033143915 | BT4: -0.025744425 | BU4: -0.0359312 | BV4: -0.033979345 | BW4: -0.024172651 | BX4: -0.032862037 | BY4: -0.03183778 | BZ4: -0.035272162 | CA4: -0.03279594 | CB4: -0.031129474 | CC4: -0.032271598 | CD4: -0.024898069 | CE4: -0.030599274 | CF4: -0.030437306 | CG4: -0.029704332 | CH4: -0.031244969 | CI4: -0.031521577 | CJ4: -0.025299424 | CK4: -0.031607468 | CL4: -0.031105751 | CM4: -0.031131431 | CN4: -0.030764317 | CO4: -0.030509215 | CP4: -0.030214524 | CQ4: -0.030587129 | CR4: -0.030247388 | CS4: -0.029346619 | CT4: -0.021990741 | CU4: -0.026671428 | CV4: -0.028046217 | CW4: -0.03342649 | CX4: -0.026143188 | CY4: -0.027580429 | CZ4: -0.026062973 | DA4: -0.029111568 | DB4: -0.03321771 | DC4: -0.032092787 | DD4: -0.03114957 | DE4: -0.029670034 | DF4: -0.029392391 | DG4: -0.027210658 | DH4: -0.03003967 | DI4: -0.029861368 | DJ4: -0.029900726 | DK4: -0.029505167 | DL4: -0.03022231 | DM4: -0.028697766 | DN4: -0.027542079 | DO4: -0.028353909 | DP4: -0.059928406 | DQ4: -0.040838063 | DR4: -0.014053512 | DS4: -0.016584598 | DT4: -0.016068093 | DU4: -0.016360313 | DV4: -0.027348608 | DW4: -0.027253827 | DX4: -0.027536197 | DY4: -0.027489709 | DZ4: -0.028728349 | EA4: -0.028270183 | EB4: -0.028071156 | EC4: -0.028958322 | ED4: -0.029004596 | EE4: -0.02837378 | EF4: -0.022930523
B5: mom | C5: -0.0073430501 | D5: 0.016763182 | E5: 0.02049776 | F5: 0.024616705 | G5: 0.029157292 | H5: 0.029083796 | I5: 0.029971791 | J5: 0.032223135 | K5: 0.037759751 | L5: 0.040105008 | M5: 0.04335247 | N5: 0.043786589 | O5: 0.04743493 | P5: 0.027232466 | Q5: 0.055018827 | R5: 0.05573111 | S5: 0.05257532 | T5: 0.054881215 | U5: 0.04972358 | V5: 0.045027103 | W5: 0.042282227 | X5: 0.034414954 | Y5: -0.033293303 | Z5: -0.030751135 | AA5: 0.010843869 | AB5: -0.035410937 | AC5: -0.038289722 | AD5: -0.041016027 | AE5: -0.040779795 | AF5: -0.040989466 | AG5: -0.040635053 | AH5: -0.039753091 | AI5: 0.00066369399 | AJ5: 0.014860556 | AK5: 0.041335825 | AL5: 0.054104809 | AM5: 0.05419872 | AN5: 0.018182263 | AO5: 0.044361383 | AP5: 0.050771181 | AQ5: 0.057908576 | AR5: 0.055189714 | AS5: 0.057133187 | AT5: 0.06207218 | AU5: 0.057220872 | AV5: 0.047043707 | AW5: 0.044183865 | AX5: 0.025188584 | AY5: 0.002421625 | AZ5: 0.03267093 | BA5: 0.052844863 | BB5: 0.030312689 | BC5: 0.019591218 | BD5: -0.00086559728 | BE5: 0.022725981 | BF5: 0.052427184 | BG5: 0.050593615 | BH5: 0.066552937 | BI5: 0.085135356 | BJ5: 0.082012884 | BK5: -0.037758213 | BL5: -0.039183177 | BM5: -0.038690481 | BN5: 0.01088668 | BO5: -0.015017953 | BP5: 0.024017714 | BQ5: -0.036908474 | BR5: -0.02858663 | BS5: 0.011689777 | BT5: 0.0026358534 | BU5: 0.049531873 | BV5: -0.035415012 | BW5: -0.02289705 | BX5: 0.0045871362 | BY5: 0.013327729 | BZ5: 0.067076296 | CA5: 0.069593862 | CB5: -0.061369147 | CC5: 0.012457933 | CD5: 0.0289496 | CE5: 0.035223342 | CF5: 0.046291191 | CG5: 0.077153936 | CH5: 0.071323618 | CI5: 0.089874282 | CJ5: -0.013270102 | CK5: 0.0011145901 | CL5: 0.0096226819 | CM5: -0.025430763 | CN5: -0.03436872 | CO5: 0.040211219 | CP5: 0.092609324 | CQ5: -0.042657427 | CR5: -0.046656184 | CS5: -0.054819997 | CT5: 0.015666779 | CU5: 0.069270656 | CV5: 0.066144675 | CW5: -0.025959613 | CX5: 0.073974848 | CY5: 0.075364649 | CZ5: 0.099710718 | DA5: 0.076109506 | DB5: 0.05309983 | DC5: 0.082278982 | DD5: 0.08773613 | DE5: 0.089432731 | DF5: 0.089542538 | DG5: 0.010863081 | DH5: 0.089483082 | DI5: 0.085889444 | DJ5: 0.075929016 | DK5: 0.079263374 | DL5: 0.064476602 | DM5: 0.069953628 | DN5: 0.056044459 | DO5: -0.016482294 | DP5: -0.034329806 | DQ5: -0.02956488 | DR5: -0.0051183403 | DS5: 0.0023898259 | DT5: -0.025626864 | DU5: -0.030835196 | DV5: -0.031236397 | DW5: -0.067960456 | DX5: -0.035862029 | DY5: -0.043715 | DZ5: 0.046174705 | EA5: -0.015363239 | EB5: -0.022685507 | EC5: -0.038448673 | ED5: 0.0021381937 | EE5: 0.02502403 | EF5: 0.021722723
A6: 選絕對值最大 | C6: {=MATCH(MAX(ABS(C3:C5)), ABS(C3:C5), 0)} -> 2 | D6: {=MATCH(MAX(ABS(D3:D5)), ABS(D3:D5), 0)} -> 1 | E6: {=MATCH(MAX(ABS(E3:E5)), ABS(E3:E5), 0)} -> 1 | F6: {=MATCH(MAX(ABS(F3:F5)), ABS(F3:F5), 0)} -> 1 | G6: {=MATCH(MAX(ABS(G3:G5)), ABS(G3:G5), 0)} -> 1 | H6: {=MATCH(MAX(ABS(H3:H5)), ABS(H3:H5), 0)} -> 1 | I6: {=MATCH(MAX(ABS(I3:I5)), ABS(I3:I5), 0)} -> 1 | J6: {=MATCH(MAX(ABS(J3:J5)), ABS(J3:J5), 0)} -> 1 | ... EG6: {=MATCH(MAX(ABS(EG3:EG5)), ABS(EG3:EG5), 0)} -> 1
C7: =IF(C6=1,"bm",IF(C6=2,"size",IF(C6=3,"mom"))) -> size | D7: =IF(D6=1,"bm",IF(D6=2,"size",IF(D6=3,"mom"))) -> bm | E7: =IF(E6=1,"bm",IF(E6=2,"size",IF(E6=3,"mom"))) -> bm | F7: =IF(F6=1,"bm",IF(F6=2,"size",IF(F6=3,"mom"))) -> bm | G7: =IF(G6=1,"bm",IF(G6=2,"size",IF(G6=3,"mom"))) -> bm | H7: =IF(H6=1,"bm",IF(H6=2,"size",IF(H6=3,"mom"))) -> bm | I7: =IF(I6=1,"bm",IF(I6=2,"size",IF(I6=3,"mom"))) -> bm | J7: =IF(J6=1,"bm",IF(J6=2,"size",IF(J6=3,"mom"))) -> bm | ... EG7: =IF(EG6=1,"bm",IF(EG6=2,"size",IF(EG6=3,"mom"))) -> bm
C8: =IF(C6=1,C3,IF(C6=2,C4,IF(C6=3,C5))) -> -0.085349202 | D8: =IF(D6=1,D3,IF(D6=2,D4,IF(D6=3,D5))) -> 0.075454518 | E8: =IF(E6=1,E3,IF(E6=2,E4,IF(E6=3,E5))) -> 0.053419497 | F8: =IF(F6=1,F3,IF(F6=2,F4,IF(F6=3,F5))) -> 0.048055463 | G8: =IF(G6=1,G3,IF(G6=2,G4,IF(G6=3,G5))) -> 0.056244601 | H8: =IF(H6=1,H3,IF(H6=2,H4,IF(H6=3,H5))) -> 0.053408809 | I8: =IF(I6=1,I3,IF(I6=2,I4,IF(I6=3,I5))) -> 0.054677729 | J8: =IF(J6=1,J3,IF(J6=2,J4,IF(J6=3,J5))) -> 0.061407112 | ... EG8: =IF(EG6=1,EG3,IF(EG6=2,EG4,IF(EG6=3,EG5))) -> 0
A10: 投資組合 | C10: 公司數 | D10: 964
A11: 等第 | B11: 分數 | C11: 2014/01 | D11: 2014/02 | E11: 2014/03 | F11: 2014/04 | G11: 2014/05 | H11: 2014/06 | I11: 2014/07 | J11: 2014/08 | K11: 2014/09 | L11: 2014/10 | M11: 2014/11 | N11: 2014/12 | O11: 2015/01 | P11: 2015/02 | Q11: 2015/03 | R11: 2015/04 | S11: 2015/05 | T11: 2015/06 | U11: 2015/07 | V11: 2015/08 | W11: 2015/09 | X11: 2015/10 | Y11: 2015/11 | Z11: 2015/12 | AA11: 2016/01 | AB11: 2016/02 | AC11: 2016/03 | AD11: 2016/04 | AE11: 2016/05 | AF11: 2016/06 | AG11: 2016/07 | AH11: 2016/08 | AI11: 2016/09 | AJ11: 2016/10 | AK11: 2016/11 | AL11: 2016/12 | AM11: 2017/01 | AN11: 2017/02 | AO11: 2017/03 | AP11: 2017/04 | AQ11: 2017/05 | AR11: 2017/06 | AS11: 2017/07 | AT11: 2017/08 | AU11: 2017/09 | AV11: 2017/10 | AW11: 2017/11 | AX11: 2017/12 | AY11: 2018/01 | AZ11: 2018/02 | BA11: 2018/03 | BB11: 2018/04 | BC11: 2018/05 | BD11: 2018/06 | BE11: 2018/07 | BF11: 2018/08 | BG11: 2018/09 | BH11: 2018/10 | BI11: 2018/11 | BJ11: 2018/12 | BK11: 2019/01 | BL11: 2019/02 | BM11: 2019/03 | BN11: 2019/04 | BO11: 2019/05 | BP11: 2019/06 | BQ11: 2019/07 | BR11: 2019/08 | BS11: 2019/09 | BT11: 2019/10 | BU11: 2019/11 | BV11: 2019/12 | BW11: 2020/01 | BX11: 2020/02 | BY11: 2020/03 | BZ11: 2020/04 | CA11: 2020/05 | CB11: 2020/06 | CC11: 2020/07 | CD11: 2020/08 | CE11: 2020/09 | CF11: 2020/10 | CG11: 2020/11 | CH11: 2020/12 | CI11: 2021/01 | CJ11: 2021/02 | CK11: 2021/03 | CL11: 2021/04 | CM11: 2021/05 | CN11: 2021/06 | CO11: 2021/07 | CP11: 2021/08 | CQ11: 2021/09 | CR11: 2021/10 | CS11: 2021/11 | CT11: 2021/12 | CU11: 2022/01 | CV11: 2022/02 | CW11: 2022/03 | CX11: 2022/04 | CY11: 2022/05 | CZ11: 2022/06 | DA11: 2022/07 | DB11: 2022/08 | DC11: 2022/09 | DD11: 2022/10 | DE11: 2022/11 | DF11: 2022/12 | DG11: 2023/01 | DH11: 2023/02 | DI11: 2023/03 | DJ11: 2023/04 | DK11: 2023/05 | DL11: 2023/06 | DM11: 2023/07 | DN11: 2023/08 | DO11: 2023/09 | DP11: 2023/10 | DQ11: 2023/11 | DR11: 2023/12 | DS11: 2024/01 | DT11: 2024/02 | DU11: 2024/03 | DV11: 2024/04 | DW11: 2024/05 | DX11: 2024/06 | DY11: 2024/07 | DZ11: 2024/08 | EA11: 2024/09 | EB11: 2024/10 | EC11: 2024/11 | ED11: 2024/12 | EE11: 2025/01 | EF11: 2025/02
A12: 10 | B12: 96 | C12: 0.084653347 | D12: 0.020821795 | E12: -0.0067540284 | F12: -0.019868825 | G12: 0.0079043467 | H12: 0.0093593838 | I12: 0.036303937 | J12: 0.043784579 | K12: -0.010988404 | L12: -0.0022772308 | M12: -0.015551804 | N12: 0.052074108 | O12: 0.018629889 | P12: -0.021420421 | Q12: 0.0051156834 | R12: 0.013153489 | S12: -0.071053897 | T12: -0.043243489 | U12: -0.020367221 | V12: 0.045029991 | W12: 0.022278442 | X12: 0.048519275 | Y12: -0.016788377 | Z12: 0.063623683 | AA12: -0.039403661 | AB12: 0.034689111 | AC12: 0.035114764 | AD12: 0.00584711 | AE12: -0.037897624 | AF12: 0.020432151 | AG12: 0.029982145 | AH12: 0.015713034 | AI12: 0.023246459 | AJ12: 0.021062263 | AK12: 0.0095035079 | AL12: -0.04780049 | AM12: 0.016706752 | AN12: 0.069233234 | AO12: 0.002228793 | AP12: 0.0063803695 | AQ12: -0.0016969306 | AR12: 0.022223026 | AS12: 0.019976273 | AT12: 0.072195382 | AU12: 0.0037135364 | AV12: 0.053715631 | AW12: 0.00062147702 | AX12: 0.043598467 | AY12: 0.024955293 | AZ12: -0.0023000261 | BA12: -0.02643433 | BB12: 0.015274605 | BC12: 0.012272789 | BD12: 0.013630557 | BE12: 0.01860881 | BF12: -0.067616949 | BG12: -0.046757754 | BH12: -0.035079589 | BI12: -0.043756064 | BJ12: -0.024663126 | BK12: -0.021284665 | BL12: 0.024709246 | BM12: -0.005169092 | BN12: 0.011516536 | BO12: 0.02424631 | BP12: -0.010508985 | BQ12: 0.01389675 | BR12: -0.0022610085 | BS12: 0.018863293 | BT12: 0.022031469 | BU12: -0.0087815171 | BV12: 0.023062456 | BW12: -0.029483769 | BX12: 0.011477162 | BY12: -0.0333708 | BZ12: 0.032378726 | CA12: 0.00060368843 | CB12: 0.027173863 | CC12: -0.016770964 | CD12: 0.11093363 | CE12: 0.011619408 | CF12: 0.0080212745 | CG12: -0.04927796 | CH12: -0.016463112 | CI12: -0.035598031 | CJ12: 0.01544518 | CK12: 0.012803144 | CL12: 0.11801561 | CM12: -0.071708388 | CN12: -0.027083701 | CO12: -0.024819785 | CP12: -0.001005022 | CQ12: 0.062684347 | CR12: 0.057159987 | CS12: -0.00097857359 | CT12: 0.032114011 | CU12: -0.074779529 | CV12: 0.065033306 | CW12: 0.029757689 | CX12: -0.030752638 | CY12: 0.016420596 | CZ12: -0.012324262 | DA12: 0.016824333 | DB12: 0.035585283 | DC12: -0.0045013638 | DD12: -0.069960546 | DE12: -0.024737644 | DF12: 0.01162432 | DG12: -0.046409818 | DH12: 0.030803155 | DI12: 0.029979255 | DJ12: 0.041378043 | DK12: 0.0010711986 | DL12: 0.018669833 | DM12: 0.0091434933 | DN12: -0.018541443 | DO12: 0.030556942 | DP12: 0.045953548 | DQ12: -0.03386212 | DR12: 0.018778943 | DS12: -0.035726155 | DT12: -0.024813842 | DU12: -0.045787142 | DV12: 0.016751442 | DW12: -0.0020762117 | DX12: -0.018099137 | DY12: -0.062728222 | DZ12: 0.02003889 | EA12: 0.051097633 | EB12: 0.0057859706 | EC12: -0.014883918 | ED12: -0.0069574815 | EE12: -0.026506892 | EF12: 0.039233348
A13: 20 | B13: 48 | C13: 0.10411275 | D13: 0.029877611 | E13: -0.034496619 | F13: -0.034922156 | G13: -0.01490798 | H13: 0.015930385 | I13: 0.032682863 | J13: 0.034549892 | K13: -0.04533099 | L13: -0.029135669 | M13: 0.0077086563 | N13: 0.043151952 | O13: 0.036273276 | P13: -0.020856913 | Q13: -0.017456384 | R13: 0.016510711 | S13: -0.1229153 | T13: -0.052899803 | U13: -0.054161075 | V13: 0.052779739 | W13: 0.031103088 | X13: 0.069750969 | Y13: -0.026471883 | Z13: 0.078424435 | AA13: -0.03211951 | AB13: 0.04667822 | AC13: 0.021871556 | AD13: 0.0065790452 | AE13: -0.042517211 | AF13: 0.031940464 | AG13: 0.031681783 | AH13: 0.024955207 | AI13: 0.01990991 | AJ13: 0.019886324 | AK13: 0.0033184448 | AL13: -0.049258885 | AM13: -0.014434106 | AN13: 0.10533024 | AO13: 0.0093111879 | AP13: -0.0021107071 | AQ13: -0.0023400742 | AR13: 0.020848044 | AS13: 0.023404964 | AT13: 0.086422915 | AU13: -0.015695418 | AV13: 0.079665976 | AW13: 0.0040800136 | AX13: 0.067153788 | AY13: 0.017564346 | AZ13: -0.0081034675 | BA13: -0.026188274 | BB13: 0.042875374 | BC13: 0.011283767 | BD13: 0.0033444284 | BE13: 0.027391806 | BF13: -0.12165714 | BG13: -0.088397546 | BH13: -0.041023656 | BI13: -0.021601559 | BJ13: -0.024266088 | BK13: -0.018391025 | BL13: 0.03194786 | BM13: 0.016918616 | BN13: 0.011052542 | BO13: 0.030878716 | BP13: 0.0094326957 | BQ13: 0.041653064 | BR13: -0.0066814175 | BS13: 0.0074194718 | BT13: 0.038343506 | BU13: -0.017706555 | BV13: 0.020653597 | BW13: 0.0017632378 | BX13: 0.021078068 | BY13: -0.014512398 | BZ13: 0.06597673 | CA13: 0.011020985 | CB13: 0.02601738 | CC13: -0.012530912 | CD13: 0.10508583 | CE13: 0.0092209843 | CF13: -0.012043667 | CG13: -0.058014968 | CH13: -0.0040295061 | CI13: -0.014533303 | CJ13: -0.003106088 | CK13: 0.032045269 | CL13: 0.081453366 | CM13: -0.10145222 | CN13: -0.026887566 | CO13: -0.035334344 | CP13: 0.020576996 | CQ13: 0.071178865 | CR13: 0.11164489 | CS13: -0.0095676537 | CT13: 0.043462268 | CU13: -0.10709096 | CV13: 0.077656051 | CW13: 0.010456963 | CX13: -0.030582841 | CY13: 0.041201752 | CZ13: -0.0048982162 | DA13: 0.016936626 | DB13: 0.061356185 | DC13: -0.014149867 | DD13: -0.068977059 | DE13: -0.022441996 | DF13: 0.017271632 | DG13: -0.047729084 | DH13: 0.038806517 | DI13: 0.02957042 | DJ13: 0.0070211236 | DK13: -0.023400892 | DL13: 0.022050691 | DM13: -0.011655894 | DN13: -0.012775889 | DO13: 0.037863465 | DP13: 0.044997151 | DQ13: -0.033966462 | DR13: 0.013771209 | DS13: -0.038887628 | DT13: -0.029845809 | DU13: -0.023698854 | DV13: 0.0098528048 | DW13: -0.013098229 | DX13: -0.02322961 | DY13: -0.0095046248 | DZ13: 0.030285251 | EA13: 0.062118677 | EB13: 0.00020120622 | EC13: -0.021984853 | ED13: 0.00708472 | EE13: -0.041234384 | EF13: 0.066577215
A14: 50 | B14: 19 | C14: 0.11994149 | D14: 0.083347312 | E14: -0.047525943 | F14: -0.048454143 | G14: -0.041019916 | H14: 0.0076743243 | I14: 0.04378736 | J14: 0.023309972 | K14: -0.1341787 | L14: 0.0048471972 | M14: 0.0049945201 | N14: 0.082758985 | O14: 0.037475787 | P14: -0.058345922 | Q14: -0.079297658 | R14: -0.017762309 | S14: -0.16589323 | T14: -0.06984148 | U14: -0.10426666 | V14: 0.020089127 | W14: 0.074008159 | X14: 0.11326311 | Y14: -0.0052198746 | Z14: 0.038511926 | AA14: -0.03945018 | AB14: 0.070769377 | AC14: -0.013517269 | AD14: -0.012920107 | AE14: -0.10641207 | AF14: 0.040420703 | AG14: 0.020520895 | AH14: 0.080952184 | AI14: 0.010964571 | AJ14: 0.096294977 | AK14: -0.011509463 | AL14: -0.051230183 | AM14: -0.042463856 | AN14: 0.098594667 | AO14: 0.060905705 | AP14: 0.0083517816 | AQ14: 0.02973338 | AR14: 0.0075826917 | AS14: -0.0066693384 | AT14: 0.07940348 | AU14: -0.057421613 | AV14: 0.066258749 | AW14: -0.018362932 | AX14: 0.13695103 | AY14: 0.015068119 | AZ14: -0.053348569 | BA14: -0.066889832 | BB14: 0.061734282 | BC14: -0.009820999 | BD14: 0.043327782 | BE14: 0.043787063 | BF14: -0.15382926 | BG14: -0.12530531 | BH14: -0.073413464 | BI14: 0.041031068 | BJ14: -0.068604196 | BK14: -0.0055937517 | BL14: 0.059737767 | BM14: 0.039257215 | BN14: 0.020936538 | BO14: 0.033609046 | BP14: 0.015673733 | BQ14: 0.015843524 | BR14: -0.02792943 | BS14: -0.041493955 | BT14: 0.074012962 | BU14: 0.0088548354 | BV14: 0.025727182 | BW14: 0.012507948 | BX14: 0.05497076 | BY14: -0.0065962934 | BZ14: 0.093374678 | CA14: 0.096516325 | CB14: 0.05947706 | CC14: -0.012794081 | CD14: 0.09801671 | CE14: -0.072156719 | CF14: -0.04287741 | CG14: -0.057320664 | CH14: -0.04887967 | CI14: -0.014701612 | CJ14: -0.028667855 | CK14: 0.014016364 | CL14: 0.062269955 | CM14: -0.11006897 | CN14: -0.023026689 | CO14: -0.078763759 | CP14: 0.093659358 | CQ14: 0.0322279 | CR14: 0.20771971 | CS14: 0.0044126335 | CT14: 0.061872352 | CU14: -0.101545 | CV14: 0.15139684 | CW14: 0.0082340019 | CX14: -0.090639227 | CY14: 0.09636113 | CZ14: -0.0103014 | DA14: -0.056351881 | DB14: 0.090239014 | DC14: -0.042998542 | DD14: -0.079205352 | DE14: -0.062526924 | DF14: 0.064180408 | DG14: -0.045583396 | DH14: 0.0084132404 | DI14: 0.040659135 | DJ14: 0.0087940294 | DK14: -0.077413284 | DL14: 0.040754872 | DM14: -0.032421917 | DN14: 0.044935741 | DO14: 0.10259219 | DP14: 0.0036178583 | DQ14: -0.056019286 | DR14: 0.052622519 | DS14: -0.035044906 | DT14: -0.0077542903 | DU14: -0.11891759 | DV14: 0.045153224 | DW14: -0.031091969 | DX14: -0.027689697 | DY14: -0.047660987 | DZ14: 0.021697589 | EA14: 0.10752548 | EB14: -0.025109521 | EC14: -0.043260018 | ED14: -0.033597288 | EE14: 0.0033992535 | EF14: 0.06995642
A15: 100 | B15: 10 | C15: 0.22764466 | D15: 0.016952865 | E15: -0.010198426 | F15: -0.10856229 | G15: -0.060636929 | H15: 0.050157825 | I15: 0.058431444 | J15: 0.049961465 | K15: -0.28659463 | L15: 0.032558505 | M15: 0.025497709 | N15: 0.12086815 | O15: 0.073757344 | P15: -0.064116183 | Q15: -0.045898731 | R15: -0.12669106 | S15: -0.2700079 | T15: -0.066800125 | U15: -0.13696806 | V15: -0.017131853 | W15: 0.10254359 | X15: 0.12684333 | Y15: 0.020629974 | Z15: 0.046719972 | AA15: -0.054081147 | AB15: 0.083700173 | AC15: 0.016480966 | AD15: 0.018936283 | AE15: -0.097797684 | AF15: 0.065819612 | AG15: 0.010123478 | AH15: 0.13296737 | AI15: 0.07427696 | AJ15: 0.0041844346 | AK15: -0.036999312 | AL15: -0.032360174 | AM15: -0.068631207 | AN15: 0.10168871 | AO15: 0.063369812 | AP15: 0.090555375 | AQ15: 0.036453319 | AR15: 0.017733826 | AS15: -0.048733221 | AT15: 0.070989813 | AU15: -0.077174077 | AV15: 0.037297929 | AW15: 0.015659939 | AX15: 0.12523398 | AY15: 0.028017064 | AZ15: -0.09132328 | BA15: 0.015151738 | BB15: 0.11272487 | BC15: 0.062155144 | BD15: 0.053043274 | BE15: 0.048442721 | BF15: -0.21087209 | BG15: -0.16605122 | BH15: -0.098649046 | BI15: 0.021159114 | BJ15: -0.13011026 | BK15: 0.00082375227 | BL15: 0.059403871 | BM15: 0.066824821 | BN15: 0.04014257 | BO15: 0.027734476 | BP15: 0.014184221 | BQ15: 0.012802931 | BR15: -0.050157429 | BS15: -0.016823777 | BT15: 0.089060206 | BU15: -0.01947642 | BV15: 0.058914968 | BW15: -0.03594589 | BX15: 0.028635895 | BY15: -0.061694091 | BZ15: 0.20472002 | CA15: 0.092920534 | CB15: 0.092684106 | CC15: -0.15231827 | CD15: 0.12015208 | CE15: -0.11651657 | CF15: -0.04134943 | CG15: -0.085886022 | CH15: -0.081342608 | CI15: 0.0025109388 | CJ15: -0.087044356 | CK15: 0.056672646 | CL15: 0.031421975 | CM15: -0.10811976 | CN15: -0.042634116 | CO15: -0.10697924 | CP15: 0.13009875 | CQ15: -0.02496336 | CR15: 0.18148893 | CS15: -0.0064830511 | CT15: 0.032216556 | CU15: -0.12404993 | CV15: 0.18261155 | CW15: -0.027257442 | CX15: -0.15238778 | CY15: 0.092947904 | CZ15: -0.023763335 | DA15: 0.057882147 | DB15: 0.2096634 | DC15: -0.067692432 | DD15: -0.014506726 | DE15: -0.057163635 | DF15: -0.0060545263 | DG15: -0.047917485 | DH15: -0.00093841477 | DI15: 0.054108319 | DJ15: 0.060023777 | DK15: -0.072188598 | DL15: -0.0003039932 | DM15: -0.039052117 | DN15: 0.081730712 | DO15: 0.15954541 | DP15: -0.040330193 | DQ15: -0.07293808 | DR15: 0.070010567 | DS15: -0.076241908 | DT15: -0.05271879 | DU15: -0.18864064 | DV15: 0.046727729 | DW15: -0.050448237 | DX15: -0.02154567 | DY15: 0.083673635 | DZ15: 0.036596498 | EA15: 0.10917693 | EB15: -0.05612648 | EC15: -0.076157077 | ED15: -0.072383319 | EE15: -0.0031907205 | EF15: 0.065700991
A16: 107 | B16: 9 | C16: 0.20787478 | D16: -0.00072024867 | E16: -0.0028301766 | F16: -0.099382493 | G16: -0.073696265 | H16: 0.060999005 | I16: 0.057530619 | J16: 0.046709926 | K16: -0.28467055 | L16: 0.0098865346 | M16: 0.040334455 | N16: 0.12567063 | O16: 0.079826861 | P16: -0.061045232 | Q16: -0.081478643 | R16: -0.10310969 | S16: -0.28706302 | T16: -0.06721906 | U16: -0.13006247 | V16: -0.0060221453 | W16: 0.10166568 | X16: 0.12440978 | Y16: 0.020180588 | Z16: 0.043057931 | AA16: -0.043487636 | AB16: 0.074985042 | AC16: 0.047226236 | AD16: 0.0011220258 | AE16: -0.09650236 | AF16: 0.063685843 | AG16: 0.013290753 | AH16: 0.14840163 | AI16: 0.090522649 | AJ16: -0.017629242 | AK16: -0.0079871677 | AL16: -0.0054397026 | AM16: -0.052145732 | AN16: 0.1064562 | AO16: 0.061424672 | AP16: 0.094724683 | AQ16: 0.054497753 | AR16: 0.034371979 | AS16: -0.052642718 | AT16: 0.12256404 | AU16: -0.082090272 | AV16: 0.052080835 | AW16: 0.03925293 | AX16: 0.10082977 | AY16: 0.03381259 | AZ16: -0.10490964 | BA16: -0.033911562 | BB16: 0.10803892 | BC16: 0.067121466 | BD16: 0.035936712 | BE16: 0.051410994 | BF16: -0.24778686 | BG16: -0.16122957 | BH16: -0.096162035 | BI16: 0.04898994 | BJ16: -0.096566804 | BK16: 0.0029719903 | BL16: 0.070623566 | BM16: 0.081523875 | BN16: 0.047905833 | BO16: 0.02189036 | BP16: 0.020843184 | BQ16: 0.016478016 | BR16: -0.026296848 | BS16: -0.013191573 | BT16: 0.085483191 | BU16: -0.05776511 | BV16: 0.060711239 | BW16: -0.065740927 | BX16: 0.031559238 | BY16: -0.050563733 | BZ16: 0.13158185 | CA16: 0.13046988 | CB16: 0.11586555 | CC16: -0.15907251 | CD16: 0.15507127 | CE16: -0.13259506 | CF16: -0.052800084 | CG16: -0.061727878 | CH16: -0.050448725 | CI16: 0.0042406681 | CJ16: -0.045523551 | CK16: 0.076472984 | CL16: 0.015878682 | CM16: -0.11305584 | CN16: -0.033057515 | CO16: -0.13464021 | CP16: 0.11115145 | CQ16: -0.02033378 | CR16: 0.18928653 | CS16: -0.040852188 | CT16: 0.048903526 | CU16: -0.1354717 | CV16: 0.17225152 | CW16: -0.031673114 | CX16: -0.16226598 | CY16: 0.081280638 | CZ16: -0.032724822 | DA16: 0.078106298 | DB16: 0.23166535 | DC16: -0.083264052 | DD16: -0.03174371 | DE16: -0.0345524 | DF16: -0.0026980136 | DG16: -0.045676915 | DH16: 0.003978832 | DI16: 0.045399498 | DJ16: 0.070955052 | DK16: -0.057685769 | DL16: -0.021872874 | DM16: -0.018910374 | DN16: 0.11588673 | DO16: 0.16959095 | DP16: -0.024716583 | DQ16: -0.06756052 | DR16: 0.055191252 | DS16: -0.093752065 | DT16: -0.059112975 | DU16: -0.19010824 | DV16: 0.045728317 | DW16: -0.030139112 | DX16: -0.021947728 | DY16: 0.094984864 | DZ16: 0.012649172 | EA16: 0.13979902 | EB16: -0.070875444 | EC16: -0.068501481 | ED16: -0.080284913 | EE16: -0.0043966753 | EF16: 0.042474401
A17: 120 | B17: 8 | C17: 0.20609219 | D17: -0.017334375 | E17: 0.0073790015 | F17: -0.11283752 | G17: -0.071222767 | H17: 0.076687822 | I17: 0.11372503 | J17: 0.041858395 | K17: -0.29682655 | L17: 0.0097108895 | M17: 0.064932035 | N17: 0.13594843 | O17: 0.10122677 | P17: -0.066339369 | Q17: -0.10026683 | R17: -0.13642645 | S17: -0.31065343 | T17: -0.071202015 | U17: -0.14127114 | V17: 0.0040111898 | W17: 0.11960398 | X17: 0.1168462 | Y17: 0.022928011 | Z17: 0.053868489 | AA17: -0.03520979 | AB17: 0.084852063 | AC17: 0.05872869 | AD17: 0.021912844 | AE17: -0.12715842 | AF17: 0.06142931 | AG17: 0.022740981 | AH17: 0.14702489 | AI17: 0.11486445 | AJ17: -0.02220746 | AK17: -0.013325713 | AL17: -0.027018182 | AM17: -0.09335171 | AN17: 0.11328712 | AO17: 0.012632335 | AP17: 0.09341758 | AQ17: 0.061277252 | AR17: 0.045802626 | AS17: -0.058802957 | AT17: 0.12707179 | AU17: -0.11569961 | AV17: 0.058529449 | AW17: 0.008421888 | AX17: 0.096240559 | AY17: 0.027423697 | AZ17: -0.1251576 | BA17: -0.038771615 | BB17: 0.12376406 | BC17: 0.083863195 | BD17: 0.022356482 | BE17: 0.077350242 | BF17: -0.14777683 | BG17: -0.18575158 | BH17: -0.13319111 | BI17: 0.0807384 | BJ17: -0.097868244 | BK17: -0.013822952 | BL17: 0.077482967 | BM17: 0.07599777 | BN17: 0.046915526 | BO17: 0.035179615 | BP17: 0.03599598 | BQ17: 0.01137651 | BR17: -0.0096463751 | BS17: -0.0041034691 | BT17: 0.10941638 | BU17: -0.071127819 | BV17: 0.070210303 | BW17: -0.080431713 | BX17: 0.028822965 | BY17: -0.084245468 | BZ17: 0.066857531 | CA17: 0.13087785 | CB17: 0.10916584 | CC17: -0.17495797 | CD17: 0.17295974 | CE17: -0.17511625 | CF17: -0.058238797 | CG17: -0.074714989 | CH17: -0.032969072 | CI17: 0.0037017834 | CJ17: -0.050742321 | CK17: 0.091738573 | CL17: -0.0094263448 | CM17: -0.095493871 | CN17: -0.026718061 | CO17: -0.13741288 | CP17: 0.10822138 | CQ17: 0.051907103 | CR17: 0.19640263 | CS17: -0.031345818 | CT17: 0.058653797 | CU17: -0.15535189 | CV17: 0.15147138 | CW17: -0.023155845 | CX17: -0.12500986 | CY17: 0.075608913 | CZ17: -0.031592684 | DA17: 0.048109805 | DB17: 0.22431697 | DC17: -0.098849393 | DD17: -0.029155421 | DE17: -0.024124863 | DF17: -0.015674445 | DG17: -0.047210988 | DH17: 0.012653895 | DI17: 0.035044536 | DJ17: 0.12892506 | DK17: -0.068118111 | DL17: -0.0039297317 | DM17: -0.037227476 | DN17: 0.10647996 | DO17: 0.17976293 | DP17: -0.02509743 | DQ17: -0.065244348 | DR17: 0.055884815 | DS17: -0.12431616 | DT17: -0.059811935 | DU17: -0.1595551 | DV17: 0.045148836 | DW17: -0.048235393 | DX17: 0.02303518 | DY17: 0.12601054 | DZ17: -0.0047910532 | EA17: 0.16457152 | EB17: -0.07378097 | EC17: -0.12151202 | ED17: -0.082855622 | EE17: 0.00019352115 | EF17: 0.047709767
A18: 137 | B18: 7 | C18: 0.18975112 | D18: -0.0081874671 | E18: -0.059000657 | F18: -0.13441437 | G18: -0.080794247 | H18: 0.12191279 | I18: 0.13550018 | J18: 0.043411516 | K18: -0.3586821 | L18: 0.012982487 | M18: 0.079702577 | N18: 0.14299243 | O18: 0.10367049 | P18: -0.082552612 | Q18: -0.09305959 | R18: -0.15418919 | S18: -0.38373263 | T18: -0.05424444 | U18: -0.13249502 | V18: 0.012895135 | W18: 0.13791724 | X18: 0.14345152 | Y18: 0.019232334 | Z18: 0.089234363 | AA18: -0.041705245 | AB18: 0.0846983 | AC18: 0.057823013 | AD18: 0.02659559 | AE18: -0.14352924 | AF18: 0.031873418 | AG18: 0.032493116 | AH18: 0.1630685 | AI18: 0.11808573 | AJ18: -0.0073274439 | AK18: 0.027289927 | AL18: -0.032812812 | AM18: -0.096053029 | AN18: 0.07929464 | AO18: 0.005427535 | AP18: 0.095545793 | AQ18: 0.064154974 | AR18: 0.039002474 | AS18: -0.083253128 | AT18: 0.16638581 | AU18: -0.13889821 | AV18: 0.060235665 | AW18: 0.024538034 | AX18: 0.10756087 | AY18: 0.034783279 | AZ18: -0.14840908 | BA18: -0.03530224 | BB18: 0.13765604 | BC18: 0.083201573 | BD18: -0.024016272 | BE18: 0.068361213 | BF18: -0.16498649 | BG18: -0.14671397 | BH18: -0.13789827 | BI18: 0.075991094 | BJ18: -0.098533857 | BK18: -0.058003244 | BL18: 0.081157674 | BM18: 0.10277394 | BN18: 0.05277439 | BO18: 0.020227496 | BP18: 0.04685754 | BQ18: 0.0019167841 | BR18: -0.0057481936 | BS18: -0.0039836251 | BT18: 0.11523675 | BU18: -0.080677444 | BV18: 0.080923395 | BW18: -0.085311087 | BX18: 0.019018475 | BY18: -0.12307498 | BZ18: 0.035347653 | CA18: 0.11432599 | CB18: 0.097387283 | CC18: -0.028173444 | CD18: 0.19371682 | CE18: -0.17792636 | CF18: 0.043957743 | CG18: -0.091609256 | CH18: -0.045365649 | CI18: -0.11505931 | CJ18: -0.062313678 | CK18: 0.090667784 | CL18: -0.030989545 | CM18: -0.10276961 | CN18: -0.035086254 | CO18: -0.15059751 | CP18: 0.11627032 | CQ18: 0.038242676 | CR18: 0.19372241 | CS18: -0.057690649 | CT18: 0.076870227 | CU18: -0.14456482 | CV18: 0.12702227 | CW18: -0.028328257 | CX18: -0.15307569 | CY18: 0.093178384 | CZ18: -0.091459213 | DA18: 0.076890546 | DB18: 0.22238211 | DC18: -0.082819707 | DD18: -0.041014187 | DE18: -0.038420587 | DF18: -0.028071975 | DG18: -0.054770484 | DH18: 0.013050033 | DI18: 0.018613248 | DJ18: 0.14619608 | DK18: -0.05725059 | DL18: -0.0038302741 | DM18: -0.0052506787 | DN18: 0.12510868 | DO18: 0.22032021 | DP18: -0.021510335 | DQ18: -0.061955529 | DR18: 0.076840655 | DS18: -0.147722 | DT18: -0.022601035 | DU18: -0.16258878 | DV18: 0.070527693 | DW18: -0.05797738 | DX18: 0.068177294 | DY18: 0.1657631 | DZ18: -0.043227855 | EA18: 0.19894575 | EB18: -0.09704269 | EC18: -0.14304023 | ED18: -0.080269196 | EE18: -0.0011112877 | EF18: 0.048955017
A19: 160 | B19: 6 | C19: 0.19660027 | D19: -0.020170799 | E19: -0.054898094 | F19: -0.038646682 | G19: -0.097512091 | H19: 0.14889412 | I19: 0.13465433 | J19: 0.035429585 | K19: -0.41833785 | L19: 0.043048958 | M19: 0.086210339 | N19: 0.095347886 | O19: 0.092221383 | P19: -0.092534186 | Q19: -0.081866113 | R19: -0.14558327 | S19: -0.18416012 | T19: -0.027154278 | U19: -0.13569834 | V19: 0.036618688 | W19: 0.14662099 | X19: 0.11663905 | Y19: 0.025628638 | Z19: 0.091619111 | AA19: -0.041570185 | AB19: 0.10225361 | AC19: 0.028452835 | AD19: 0.035088929 | AE19: -0.16941606 | AF19: 0.038785667 | AG19: 0.022136219 | AH19: 0.20415629 | AI19: 0.091548663 | AJ19: 0.012167192 | AK19: 0.049058785 | AL19: -0.014914608 | AM19: -0.061124131 | AN19: 0.083568294 | AO19: 0.025892903 | AP19: 0.12482825 | AQ19: 0.042375665 | AR19: -0.041144515 | AS19: -0.10919888 | AT19: 0.18459366 | AU19: -0.15301463 | AV19: -0.0030326096 | AW19: 0.022356168 | AX19: 0.080206414 | AY19: 0.02952897 | AZ19: -0.18687962 | BA19: -0.0015090166 | BB19: 0.1597462 | BC19: 0.064055486 | BD19: -0.0032343926 | BE19: 0.051131874 | BF19: -0.14180943 | BG19: -0.15330875 | BH19: -0.14049691 | BI19: 0.10128423 | BJ19: -0.058912217 | BK19: -0.051749526 | BL19: 0.079964658 | BM19: 0.1142506 | BN19: 0.067252647 | BO19: 0.025728961 | BP19: 0.062818808 | BQ19: 0.0099340445 | BR19: 0.006675246 | BS19: -0.024256339 | BT19: 0.14163268 | BU19: -0.075936251 | BV19: 0.093655241 | BW19: -0.10896696 | BX19: 0.034087785 | BY19: -0.10764974 | BZ19: 0.0034250282 | CA19: 0.056215144 | CB19: 0.078976808 | CC19: -0.024723253 | CD19: 0.2156192 | CE19: -0.19826583 | CF19: 0.079051525 | CG19: -0.057117625 | CH19: -0.042715044 | CI19: -0.11073421 | CJ19: -0.0619405 | CK19: 0.10396772 | CL19: -0.04324028 | CM19: -0.11023588 | CN19: -0.076932655 | CO19: -0.16614656 | CP19: 0.13741472 | CQ19: 0.032394608 | CR19: 0.17630672 | CS19: -0.05425045 | CT19: 0.026421201 | CU19: -0.14660754 | CV19: 0.094553008 | CW19: -0.032192133 | CX19: -0.14815029 | CY19: 0.10789212 | CZ19: -0.057499263 | DA19: 0.1196964 | DB19: 0.28613845 | DC19: -0.065587585 | DD19: -0.0062011253 | DE19: -0.033018415 | DF19: -0.021296342 | DG19: -0.066374265 | DH19: 0.043220605 | DI19: 0.058647033 | DJ19: 0.16525047 | DK19: -0.01598429 | DL19: -0.011982786 | DM19: 0.046097902 | DN19: 0.1739283 | DO19: 0.24926195 | DP19: -0.0040024609 | DQ19: -0.050623171 | DR19: 0.075962353 | DS19: -0.17799555 | DT19: -0.0050332465 | DU19: -0.19451944 | DV19: 0.071593387 | DW19: -0.056843988 | DX19: 0.094614193 | DY19: 0.15211941 | DZ19: -0.079643568 | EA19: 0.23304583 | EB19: -0.10624586 | EC19: -0.1437742 | ED19: -0.086159551 | EE19: 0.0073065267 | EF19: 0.016977955
A20: 192 | B20: 5 | C20: 0.20155105 | D20: 0.00035171826 | E20: 0.015499988 | F20: -0.091218422 | G20: -0.10036591 | H20: 0.164372 | I20: 0.15814956 | J20: 0.034471259 | K20: -0.090108654 | L20: 0.095708636 | M20: 0.10013341 | N20: 0.10192493 | O20: 0.099101484 | P20: -0.091169928 | Q20: -0.10704532 | R20: -0.19094247 | S20: -0.15518262 | T20: 0.015662911 | U20: -0.14864968 | V20: 0.012644103 | W20: 0.17308538 | X20: 0.1486972 | Y20: 0.04206749 | Z20: 0.10561696 | AA20: -0.021594553 | AB20: 0.084759841 | AC20: 0.056443346 | AD20: 0.034453903 | AE20: -0.19929286 | AF20: 0.039044678 | AG20: 0.027659219 | AH20: 0.21664245 | AI20: 0.11633676 | AJ20: 0.017241716 | AK20: 0.066966361 | AL20: -0.020780265 | AM20: -0.06752986 | AN20: 0.075470194 | AO20: 0.045285082 | AP20: 0.13972026 | AQ20: 0.033308231 | AR20: -0.029739 | AS20: -0.042291716 | AT20: 0.23912375 | AU20: -0.14307264 | AV20: -0.032246613 | AW20: 0.0068652682 | AX20: 0.11073255 | AY20: 0.038674698 | AZ20: -0.21380243 | BA20: -0.10207757 | BB20: 0.16765542 | BC20: 0.070605568 | BD20: -0.053429813 | BE20: -0.0059467971 | BF20: -0.13797126 | BG20: -0.094062056 | BH20: -0.1500573 | BI20: 0.11425567 | BJ20: -0.049139784 | BK20: -0.059233168 | BL20: 0.086292231 | BM20: 0.13691766 | BN20: 0.11855724 | BO20: -0.038461718 | BP20: 0.060407521 | BQ20: 0.015451707 | BR20: 0.012073632 | BS20: 0.0054075062 | BT20: 0.14780303 | BU20: -0.098754949 | BV20: 0.11591833 | BW20: -0.13550325 | BX20: 0.030693637 | BY20: -0.10523397 | BZ20: 0.0057200581 | CA20: -0.024248535 | CB20: -0.0001077551 | CC20: -0.026043034 | CD20: 0.1810275 | CE20: -0.2439638 | CF20: 0.10578489 | CG20: -0.075970241 | CH20: -0.022195229 | CI20: -0.085208202 | CJ20: -0.12344032 | CK20: 0.090978397 | CL20: -0.092184934 | CM20: -0.096775806 | CN20: 0.022159411 | CO20: -0.2285182 | CP20: 0.15666076 | CQ20: 0.023118045 | CR20: 0.19548611 | CS20: -0.097137099 | CT20: 0.028414407 | CU20: -0.14672801 | CV20: 0.11921413 | CW20: -0.025816403 | CX20: -0.14515419 | CY20: 0.10096666 | CZ20: -0.013062634 | DA20: 0.22461946 | DB20: 0.38248992 | DC20: -0.037332311 | DD20: -0.0035971848 | DE20: -0.010418722 | DF20: -0.045499958 | DG20: -0.052344813 | DH20: 0.048058412 | DI20: 0.074248336 | DJ20: 0.13655809 | DK20: -0.020765658 | DL20: -0.019465373 | DM20: -0.042864774 | DN20: 0.18323473 | DO20: 0.25800136 | DP20: -0.021671262 | DQ20: -0.038540311 | DR20: 0.07851266 | DS20: -0.2060811 | DT20: 0.029685339 | DU20: -0.27264433 | DV20: 0.10204218 | DW20: -0.062285392 | DX20: 0.097851218 | DY20: 0.18740183 | DZ20: 0.018115127 | EA20: 0.29368998 | EB20: -0.10631227 | EC20: -0.13100615 | ED20: -0.074625658 | EE20: 0.0017409798 | EF20: 0.020281417
A21: 241 | B21: 4 | C21: 0.21462958 | D21: -0.0003677094 | E21: -0.00027935227 | F21: -0.051097484 | G21: -0.007296138 | H21: 0.19866806 | I21: 0.14725561 | J21: 0.060435326 | K21: -0.088973017 | L21: 0.10967961 | M21: 0.07566065 | N21: 0.099587412 | O21: 0.12978246 | P21: -0.1447726 | Q21: -0.081195369 | R21: -0.14269209 | S21: -0.12859029 | T21: -0.014040364 | U21: -0.086278418 | V21: 0.053557619 | W21: 0.15778848 | X21: 0.19733718 | Y21: 0.020833083 | Z21: 0.11420399 | AA21: 0.019491044 | AB21: 0.12983958 | AC21: 0.07430113 | AD21: 0.046697425 | AE21: -0.24045611 | AF21: 0.05312561 | AG21: 0.044302778 | AH21: 0.24035126 | AI21: 0.10212368 | AJ21: 0.0051859256 | AK21: 0.10498861 | AL21: -0.037391486 | AM21: 0.063125718 | AN21: 0.11195606 | AO21: 0.047726396 | AP21: 0.18810121 | AQ21: 0.037036188 | AR21: -0.034197901 | AS21: -0.045406682 | AT21: 0.26483826 | AU21: -0.06345533 | AV21: -0.068713913 | AW21: 0.00979103 | AX21: 0.14314769 | AY21: 0.047021291 | AZ21: -0.25491127 | BA21: -0.019293208 | BB21: 0.22534614 | BC21: 0.038321148 | BD21: -0.021750863 | BE21: 0.0063505334 | BF21: -0.19911722 | BG21: -0.092285572 | BH21: -0.10684211 | BI21: 0.15387465 | BJ21: -0.031982514 | BK21: -0.06844988 | BL21: 0.14272109 | BM21: 0.15512 | BN21: 0.063647948 | BO21: -0.063857236 | BP21: 0.10450913 | BQ21: 0.054542231 | BR21: 0.012323862 | BS21: 0.0058601728 | BT21: 0.13224469 | BU21: -0.13549646 | BV21: 0.142143 | BW21: -0.1466792 | BX21: -0.0029908193 | BY21: -0.050379851 | BZ21: -0.051498204 | CA21: -0.038078939 | CB21: 0.073466099 | CC21: -0.046693549 | CD21: 0.28805606 | CE21: -0.39507594 | CF21: 0.11452616 | CG21: -0.085085335 | CH21: -0.15662644 | CI21: -0.073182727 | CJ21: -0.085627757 | CK21: 0.12705055 | CL21: -0.13389042 | CM21: -0.11623182 | CN21: 0.03053889 | CO21: -0.23779198 | CP21: 0.098307306 | CQ21: 0.022912194 | CR21: 0.23905997 | CS21: -0.061269036 | CT21: 0.047993104 | CU21: -0.15891662 | CV21: 0.15433184 | CW21: -0.030752481 | CX21: -0.15696885 | CY21: 0.15245231 | CZ21: -0.013847206 | DA21: 0.27617087 | DB21: 0.47235074 | DC21: -0.1539048 | DD21: -0.0028187944 | DE21: -0.028977737 | DF21: -0.1488089 | DG21: -0.059409519 | DH21: -0.010355572 | DI21: 0.090149203 | DJ21: 0.15660572 | DK21: -0.020966062 | DL21: -0.012736992 | DM21: 0.004254564 | DN21: 0.22029564 | DO21: 0.3316268 | DP21: -0.037108633 | DQ21: -0.028216052 | DR21: 0.050170859 | DS21: -0.20083947 | DT21: 0.0052151903 | DU21: -0.33980664 | DV21: 0.15489825 | DW21: -0.12266433 | DX21: 0.11682889 | DY21: 0.22566188 | DZ21: 0.17989102 | EA21: 0.26605683 | EB21: -0.10329556 | EC21: -0.14009402 | ED21: -0.082730048 | EE21: -0.021310592 | EF21: -0.018771264
A22: 321 | B22: 3 | C22: 0.2052803 | D22: -0.044680897 | E22: -0.041027532 | F22: -0.097433996 | G22: -0.032954824 | H22: 0.17874946 | I22: 0.12349317 | J22: 0.052598589 | K22: -0.15328677 | L22: 0.17118336 | M22: -0.22515861 | N22: 0.13328042 | O22: 0.14348035 | P22: -0.072782884 | Q22: -0.089282518 | R22: -0.18067973 | S22: -0.16964656 | T22: -0.020238612 | U22: -0.11059002 | V22: 0.038286777 | W22: 0.20748027 | X22: 0.21490005 | Y22: 0.015732208 | Z22: 0.075548269 | AA22: 0.0070480169 | AB22: 0.13443621 | AC22: 0.074420381 | AD22: 0.012467303 | AE22: -0.22862111 | AF22: 0.047182316 | AG22: 0.05284154 | AH22: 0.24762225 | AI22: 0.11100371 | AJ22: 0.013081542 | AK22: -0.068269328 | AL22: -0.0011447262 | AM22: 0.056373754 | AN22: 0.11113281 | AO22: 0.074717373 | AP22: 0.25139506 | AQ22: -0.055126721 | AR22: -0.1081837 | AS22: 0.073843703 | AT22: 0.017728371 | AU22: -0.1099146 | AV22: -0.089753982 | AW22: -0.030149389 | AX22: 0.1737634 | AY22: 0.071733385 | AZ22: -0.15490378 | BA22: -0.04917694 | BB22: 0.30192994 | BC22: -0.13083694 | BD22: -0.022174181 | BE22: 0.022216183 | BF22: -0.19910245 | BG22: 0.041231469 | BH22: -0.12770701 | BI22: 0.087318059 | BJ22: 0.010233975 | BK22: -0.041839636 | BL22: 0.16178034 | BM22: 0.19179704 | BN22: -0.015327552 | BO22: -0.050484429 | BP22: 0.07483555 | BQ22: 0.027830097 | BR22: 0.020813609 | BS22: -0.016372782 | BT22: 0.1305307 | BU22: -0.21294877 | BV22: 0.15854397 | BW22: -0.1746685 | BX22: 0.036637446 | BY22: -0.0047467864 | BZ22: -0.056322352 | CA22: -0.063406764 | CB22: 0.06360427 | CC22: -0.014985703 | CD22: 0.33387804 | CE22: -0.39338734 | CF22: 0.10077036 | CG22: -0.20708533 | CH22: -0.15360628 | CI22: -0.064617323 | CJ22: -0.10337951 | CK22: 0.036163343 | CL22: -0.2406518 | CM22: -0.21983249 | CN22: -0.0085467718 | CO22: -0.18528576 | CP22: 0.17184373 | CQ22: 0.017159616 | CR22: 0.24677277 | CS22: -0.084781936 | CT22: 0.038262615 | CU22: -0.16735391 | CV22: 0.16622268 | CW22: -0.013499799 | CX22: -0.054293295 | CY22: 0.16243987 | CZ22: -0.0075872464 | DA22: 0.30545166 | DB22: 0.59337517 | DC22: -0.14116724 | DD22: -0.031710169 | DE22: 0.017756504 | DF22: -0.097071706 | DG22: -0.071889499 | DH22: 0.034688752 | DI22: 0.081105544 | DJ22: 0.15369976 | DK22: -0.023346177 | DL22: -0.0032133307 | DM22: 0.042676549 | DN22: 0.30537503 | DO22: 0.075715816 | DP22: -0.10509906 | DQ22: -0.051850202 | DR22: -0.0060925526 | DS22: -0.19705092 | DT22: -0.027128754 | DU22: -0.37526887 | DV22: 0.15706237 | DW22: 0.0021072618 | DX22: 0.16435212 | DY22: 0.31775437 | DZ22: 0.16562625 | EA22: 0.14035616 | EB22: -0.14292708 | EC22: 0.028428812 | ED22: -0.057499219 | EE22: -0.047636659 | EF22: -0.034790246
A23: 482 | B23: 2 | C23: 0.28298927 | D23: -0.029810668 | E23: -0.080941173 | F23: -0.14166491 | G23: -0.052224174 | H23: 0.20371831 | I23: 0.14815203 | J23: -0.098162291 | K23: -0.20448948 | L23: 0.05404353 | M23: -0.26256935 | N23: 0.15641924 | O23: 0.20456438 | P23: -0.090401711 | Q23: -0.25084968 | R23: -0.089628003 | S23: -0.11372453 | T23: -0.00037336921 | U23: -0.093757422 | V23: -0.023029457 | W23: 0.33161915 | X23: 0.26408569 | Y23: 0.014659802 | Z23: 0.033032515 | AA23: 0.006606292 | AB23: 0.06403978 | AC23: 0.076346338 | AD23: 0.0150109 | AE23: -0.33234425 | AF23: 0.06690626 | AG23: 0.091873658 | AH23: -0.13564892 | AI23: 0.2091516 | AJ23: 0.02358744 | AK23: 0.018557731 | AL23: -0.051310311 | AM23: -0.020470543 | AN23: 0.2423147 | AO23: -0.0053369522 | AP23: -0.010447821 | AQ23: 0.17571221 | AR23: -0.2534608 | AS23: 0.081663621 | AT23: 0.1095059 | AU23: -0.20359589 | AV23: -0.049150067 | AW23: -0.05202691 | AX23: 0.069838154 | AY23: 0.17023398 | AZ23: -0.063753617 | BA23: 0.17208091 | BB23: -0.051049484 | BC23: -0.30082825 | BD23: 0.094830881 | BE23: -0.071430762 | BF23: -0.21000911 | BG23: -0.038322827 | BH23: -0.063365196 | BI23: 0.13821956 | BJ23: -0.058020214 | BK23: 0.0020341083 | BL23: 0.1495343 | BM23: 0.18918069 | BN23: -0.0069471708 | BO23: 0.036524942 | BP23: 0.098266399 | BQ23: 0.072047901 | BR23: 0.017844321 | BS23: -0.073275389 | BT23: 0.14364981 | BU23: -0.20568774 | BV23: 0.11346757 | BW23: -0.20215233 | BX23: -0.0082131197 | BY23: -0.010205693 | BZ23: -0.20232498 | CA23: 0.03428362 | CB23: -0.041664988 | CC23: 0.22495863 | CD23: 0.19167646 | CE23: -0.11662461 | CF23: 0.016160835 | CG23: -0.21663724 | CH23: -0.16212257 | CI23: -0.1352222 | CJ23: -0.019875368 | CK23: 0.096116995 | CL23: -0.40866101 | CM23: -0.23470497 | CN23: -0.053005178 | CO23: -0.26845098 | CP23: 0.24610177 | CQ23: -0.02470227 | CR23: 0.15099817 | CS23: -0.065159884 | CT23: 0.065390215 | CU23: -0.20210388 | CV23: 0.15333097 | CW23: 0.064165112 | CX23: -0.061859993 | CY23: 0.28171083 | CZ23: 0.061281101 | DA23: 0.51777096 | DB23: 0.86457557 | DC23: -0.1579489 | DD23: -0.092798675 | DE23: 0.060085948 | DF23: -0.19137387 | DG23: -0.067620427 | DH23: 0.1095822 | DI23: 0.18491271 | DJ23: 0.12003258 | DK23: -0.047749797 | DL23: 0.026242652 | DM23: -0.010710334 | DN23: 0.26497486 | DO23: 0.12406844 | DP23: -0.038404396 | DQ23: -0.12113204 | DR23: -0.089886003 | DS23: -0.28809658 | DT23: 0.022296457 | DU23: -0.52524171 | DV23: 0.1927414 | DW23: 0.26698913 | DX23: 0.17100279 | DY23: 0.26822193 | DZ23: 0.12933302 | EA23: -0.02875878 | EB23: -0.1382255 | EC23: 0.12320494 | ED23: 0.038900423 | EE23: -0.069212076 | EF23: -0.047782279
A24: 964 | B24: 1 | C24: 0.099113364 | D24: -0.10404901 | E24: 0.07140033 | F24: -0.22715955 | G24: 0.22576002 | H24: 0.24668673 | I24: -0.0021119332 | J24: -0.099972193 | K24: -0.021515278 | L24: 0.095623251 | M24: -0.46302754 | N24: 0.14413045 | O24: 0.23530919 | P24: -0.10424841 | Q24: 0.090144949 | R24: -0.10836549 | S24: -0.35251446 | T24: 0.12369104 | U24: -0.14851867 | V24: -0.067139303 | W24: 0.49571199 | X24: 0.11802243 | Y24: 0.0094770149 | Z24: 0.10584233 | AA24: 0.013547768 | AB24: 0.19533962 | AC24: 0.12538038 | AD24: 0.0078218389 | AE24: -0.54125812 | AF24: 0.02252201 | AG24: 0.13873572 | AH24: -0.30212276 | AI24: 0.31041424 | AJ24: 0.085435202 | AK24: 0.0014409771 | AL24: -0.10745443 | AM24: 0.014966545 | AN24: 0.22118947 | AO24: 0.066090112 | AP24: -0.41640853 | AQ24: 0.35649193 | AR24: -0.020350844 | AS24: 0.0032867737 | AT24: 0.15076898 | AU24: -0.22984102 | AV24: 0.24768466 | AW24: 0.0049875415 | AX24: 0.028306187 | AY24: 0.16812729 | AZ24: 0.037867074 | BA24: 0.10178269 | BB24: -0.086159033 | BC24: -0.80321601 | BD24: 0.18559522 | BE24: -0.046064354 | BF24: 0.064370421 | BG24: 0.090984228 | BH24: -0.14767357 | BI24: -0.028151632 | BJ24: 0.060567254 | BK24: 0.0040235469 | BL24: 0.31716429 | BM24: 0.011473019 | BN24: 0.0068493418 | BO24: -0.16110969 | BP24: 0.12335118 | BQ24: -0.064169633 | BR24: 0.042356223 | BS24: -0.0012847175 | BT24: 0.1162707 | BU24: -0.22832663 | BV24: 0.10772845 | BW24: -0.061835884 | BX24: -0.13296006 | BY24: 0.10974567 | BZ24: -0.32032943 | CA24: 0.085352139 | CB24: 0.064127083 | CC24: 0.43985451 | CD24: 0.14430631 | CE24: -0.21012144 | CF24: -0.043964634 | CG24: -0.51996897 | CH24: -0.21297288 | CI24: -0.29359964 | CJ24: 0.013109485 | CK24: 0.093530079 | CL24: 0.14175533 | CM24: -0.63643326 | CN24: -0.10773877 | CO24: -0.57240961 | CP24: 0.19806735 | CQ24: -0.16018965 | CR24: 0.13778746 | CS24: -0.10797424 | CT24: -0.11954439 | CU24: -0.052729045 | CV24: 0.18286409 | CW24: -0.0015881422 | CX24: -0.14669463 | CY24: 0.36022805 | CZ24: 0.16210691 | DA24: 0.8130224 | DB24: 0.94810959 | DC24: -0.28272978 | DD24: 0.19584472 | DE24: -0.13158559 | DF24: -0.19463806 | DG24: -0.11954529 | DH24: 0.10283284 | DI24: 0.4230988 | DJ24: 0.22936987 | DK24: -0.16602173 | DL24: 0.061360513 | DM24: -0.1083161 | DN24: 0.51684794 | DO24: 0.11561196 | DP24: -0.14433064 | DQ24: -0.05048619 | DR24: -0.02051563 | DS24: -0.21626154 | DT24: 0.029435726 | DU24: -0.77054331 | DV24: 0.75045655 | DW24: 0.38336324 | DX24: 0.17373733 | DY24: 0.032066536 | DZ24: -0.048904664 | EA24: -0.054920184 | EB24: -0.10922877 | EC24: 0.25665138 | ED24: -0.069835154 | EE24: -0.10748066 | EF24: 0.067276677
A25: 大盤 | B25: TWII | C25: -0.017446771 | D25: 0.020701061 | E25: 0.023982129 | F25: -0.006557579 | G25: 0.03184513 | H25: 0.034348533 | I25: -0.0082549328 | J25: 0.012843524 | K25: -0.051018525 | L25: 0.00087394274 | M25: 0.023389576 | N25: 0.012988972 | O25: 0.0058545887 | P25: 0.027413207 | Q25: -0.0037129361 | R25: 0.024076614 | S25: -0.012190025 | T25: -0.039749578 | U25: -0.07315545 | V25: -0.05826023 | W25: 0.00077279757 | X25: 0.044591521 | Y25: -0.02769968 | Z25: 0.0020950059 | AA25: -0.023400551 | AB25: 0.032129371 | AC25: 0.038903273 | AD25: -0.042865382 | AE25: 0.018647195 | AF25: 0.015229768 | AG25: 0.036016604 | AH25: 0.0093546114 | AI25: 0.010748251 | AJ25: 0.013357754 | AK25: -0.0053327473 | AL25: 0.0013831358 | AM25: 0.020795928 | AN25: 0.031517702 | AO25: 0.0062417165 | AP25: 0.0061452617 | AQ25: 0.016946358 | AR25: 0.03468283 | AS25: 0.0030985886 | AT25: 0.015081347 | AU25: -0.019251209 | AV25: 0.038711513 | AW25: -0.021856951 | AX25: 0.0077743007 | AY25: 0.042397247 | AZ25: -0.026308975 | BA25: 0.0095717493 | BB25: -0.024249741 | BC25: 0.020163374 | BD25: -0.0035049988 | BE25: 0.020151935 | BF25: 0.00058133623 | BG25: -0.005219701 | BH25: -0.11587176 | BI25: 0.0087252257 | BJ25: -0.016377261 | BK25: 0.020840372 | BL25: 0.044975872 | BM25: 0.023954306 | BN25: 0.030239101 | BO25: -0.043725888 | BP25: 0.02188947 | BQ25: 0.0086274303 | BR25: -0.019192954 | BS25: 0.01973513 | BT25: 0.047694337 | BU25: 0.011454817 | BV25: 0.043228621 | BW25: -0.04274743 | BX25: -0.017811292 | BY25: -0.1511531 | BZ25: 0.124224 | CA25: -0.0045572538 | CB25: 0.06021124 | CC25: 0.085992033 | CD25: -0.0058084796 | CE25: -0.006041347 | CF25: 0.0024523244 | CG25: 0.089636252 | CH25: 0.070992733 | CI25: 0.027170643 | CJ25: 0.052468428 | CK25: 0.029480661 | CL25: 0.066825081 | CM25: -0.028772229 | CN25: 0.039462516 | CO25: -0.029031087 | CP25: 0.013983883 | CQ25: -0.032276965 | CR25: 0.0031035766 | CS25: 0.025591856 | CT25: 0.044391886 | CU25: -0.030338959 | CV25: -0.0012579765 | CW25: 0.0023363565 | CX25: -0.064264145 | CY25: 0.012909779 | CZ25: -0.12547709 | DA25: 0.011690683 | DB25: 0.0063378437 | DC25: -0.11730536 | DD25: -0.036010872 | DE25: 0.1389113 | DF25: -0.051143506 | DG25: 0.076731447 | DH25: 0.015508782 | DI25: 0.023223774 | DJ25: -0.018372876 | DK25: 0.062199014 | DL25: 0.020098304 | DM25: 0.01349894 | DN25: -0.030252213 | DO25: -0.017022836 | DP25: -0.021788523 | DQ25: 0.085745625 | DR25: 0.028106744 | DS25: -0.0023031598 | DT25: 0.058471198 | DU25: 0.067658949 | DV25: 0.0050207706 | DW25: 0.037416184 | DX25: 0.084111004 | DY25: -0.036832399 | DZ25: 0.0030917028 | EA25: -0.0019576282 | EB25: 0.026459104 | EC25: -0.024752539 | ED25: 0.034115491 | EE25: 0.021061974 | EF25: -0.020277393

Sheet 夏普比率
A1: =預測IC!A1 -> NN1
B2: Time | C2: 2013/12 | D2: 2014/01 | E2: 2014/02 | F2: 2014/03 | G2: 2014/04 | H2: 2014/05 | I2: 2014/06 | J2: 2014/07 | K2: 2014/08 | L2: 2014/09 | M2: 2014/10 | N2: 2014/11 | O2: 2014/12 | P2: 2015/01 | Q2: 2015/02 | R2: 2015/03 | S2: 2015/04 | T2: 2015/05 | U2: 2015/06 | V2: 2015/07 | W2: 2015/08 | X2: 2015/09 | Y2: 2015/10 | Z2: 2015/11 | AA2: 2015/12 | AB2: 2016/01 | AC2: 2016/02 | AD2: 2016/03 | AE2: 2016/04 | AF2: 2016/05 | AG2: 2016/06 | AH2: 2016/07 | AI2: 2016/08 | AJ2: 2016/09 | AK2: 2016/10 | AL2: 2016/11 | AM2: 2016/12 | AN2: 2017/01 | AO2: 2017/02 | AP2: 2017/03 | AQ2: 2017/04 | AR2: 2017/05 | AS2: 2017/06 | AT2: 2017/07 | AU2: 2017/08 | AV2: 2017/09 | AW2: 2017/10 | AX2: 2017/11 | AY2: 2017/12 | AZ2: 2018/01 | BA2: 2018/02 | BB2: 2018/03 | BC2: 2018/04 | BD2: 2018/05 | BE2: 2018/06 | BF2: 2018/07 | BG2: 2018/08 | BH2: 2018/09 | BI2: 2018/10 | BJ2: 2018/11 | BK2: 2018/12 | BL2: 2019/01 | BM2: 2019/02 | BN2: 2019/03 | BO2: 2019/04 | BP2: 2019/05 | BQ2: 2019/06 | BR2: 2019/07 | BS2: 2019/08 | BT2: 2019/09 | BU2: 2019/10 | BV2: 2019/11 | BW2: 2019/12 | BX2: 2020/01 | BY2: 2020/02 | BZ2: 2020/03 | CA2: 2020/04 | CB2: 2020/05 | CC2: 2020/06 | CD2: 2020/07 | CE2: 2020/08 | CF2: 2020/09 | CG2: 2020/10 | CH2: 2020/11 | CI2: 2020/12 | CJ2: 2021/01 | CK2: 2021/02 | CL2: 2021/03 | CM2: 2021/04 | CN2: 2021/05 | CO2: 2021/06 | CP2: 2021/07 | CQ2: 2021/08 | CR2: 2021/09 | CS2: 2021/10 | CT2: 2021/11 | CU2: 2021/12 | CV2: 2022/01 | CW2: 2022/02 | CX2: 2022/03 | CY2: 2022/04 | CZ2: 2022/05 | DA2: 2022/06 | DB2: 2022/07 | DC2: 2022/08 | DD2: 2022/09 | DE2: 2022/10 | DF2: 2022/11 | DG2: 2022/12 | DH2: 2023/01 | DI2: 2023/02 | DJ2: 2023/03 | DK2: 2023/04 | DL2: 2023/05 | DM2: 2023/06 | DN2: 2023/07 | DO2: 2023/08 | DP2: 2023/09 | DQ2: 2023/10 | DR2: 2023/11 | DS2: 2023/12 | DT2: 2024/01 | DU2: 2024/02 | DV2: 2024/03 | DW2: 2024/04 | DX2: 2024/05 | DY2: 2024/06 | DZ2: 2024/07 | EA2: 2024/08 | EB2: 2024/09 | EC2: 2024/10 | ED2: 2024/11 | EE2: 2024/12 | EF2: 2025/01 | EG2: 2025/02
B3: bm | C3: 0.036997014 | D3: 0.033297818 | E3: 0.015421638 | F3: 0.016456983 | G3: 0.017226211 | H3: 0.028764108 | I3: 0.024279328 | J3: 0.027316419 | K3: 0.030174005 | L3: 0.025236297 | M3: 0.032729104 | N3: 0.031554761 | O3: 0.034033302 | P3: 0.033212911 | Q3: 0.029103335 | R3: 0.026473653 | S3: 0.028295346 | T3: 0.022620728 | U3: 0.016144007 | V3: 0.025033178 | W3: 0.045784045 | X3: 0.043057814 | Y3: 0.037785746 | Z3: 0.024097455 | AA3: 0.030094427 | AB3: 0.028087063 | AC3: 0.033771067 | AD3: 0.034131704 | AE3: 0.034141409 | AF3: 0.013117941 | AG3: 0.024857354 | AH3: 0.031884444 | AI3: 0.036385761 | AJ3: 0.035948919 | AK3: 0.043482831 | AL3: 0.038462078 | AM3: 0.039410244 | AN3: 0.050743621 | AO3: 0.053684812 | AP3: 0.049314899 | AQ3: 0.032773688 | AR3: 0.028295341 | AS3: 0.028377803 | AT3: 0.023069229 | AU3: 0.029397033 | AV3: 0.031037852 | AW3: 0.026297924 | AX3: 0.026164811 | AY3: 0.032053784 | AZ3: 0.034477531 | BA3: 0.029331891 | BB3: 0.034324948 | BC3: 0.037421777 | BD3: 0.031413722 | BE3: 0.032006411 | BF3: 0.028281828 | BG3: 0.041103437 | BH3: 0.045198779 | BI3: 0.04158804 | BJ3: 0.040723406 | BK3: 0.0363277 | BL3: 0.036173192 | BM3: 0.037708588 | BN3: 0.030814038 | BO3: 0.030655856 | BP3: 0.034399632 | BQ3: 0.03486865 | BR3: 0.03632404 | BS3: 0.036164468 | BT3: 0.038668895 | BU3: 0.041103484 | BV3: 0.028684133 | BW3: 0.03521651 | BX3: 0.0407672 | BY3: 0.021603538 | BZ3: 0.030433669 | CA3: 0.037311958 | CB3: 0.027612053 | CC3: 0.019742955 | CD3: 0.0077914602 | CE3: 0.022526807 | CF3: 0.034778188 | CG3: 0.032581362 | CH3: 0.040909001 | CI3: 0.039050253 | CJ3: 0.0245619 | CK3: 0.034134462 | CL3: 0.035925938 | CM3: 0.042466042 | CN3: 0.036523907 | CO3: 0.03765915 | CP3: 0.039957834 | CQ3: -0.0045921903 | CR3: 0.01500343 | CS3: 0.022458754 | CT3: 0.040972168 | CU3: 0.038942373 | CV3: 0.043015001 | CW3: 0.0397066 | CX3: 0.039171023 | CY3: 0.034940835 | CZ3: 0.036026834 | DA3: 0.044509548 | DB3: 0.039322897 | DC3: 0.037933403 | DD3: 0.039075001 | DE3: 0.041993976 | DF3: 0.041965349 | DG3: 0.040382245 | DH3: 0.03678724 | DI3: 0.036877766 | DJ3: 0.033682094 | DK3: 0.036536443 | DL3: 0.031530556 | DM3: 0.028662238 | DN3: 0.030844743 | DO3: 0.033675364 | DP3: 0.035102178 | DQ3: 0.036708207 | DR3: 0.034114422 | DS3: 0.036715906 | DT3: 0.034828053 | DU3: 0.023365577 | DV3: 0.025240939 | DW3: 0.035159203 | DX3: 0.032304964 | DY3: 0.023258217 | DZ3: 0.028308752 | EA3: 0.031397322 | EB3: 0.037230813 | EC3: 0.03334609 | ED3: 0.034186641 | EE3: 0.025041158 | EF3: 0.034121435
B4: size | C4: -0.049660318 | D4: -0.06445346 | E4: -0.095804929 | F4: -0.076694249 | G4: -0.02651532 | H4: -0.03415165 | I4: -0.04619091 | J4: -0.046178363 | K4: -0.045931909 | L4: -0.04081179 | M4: -0.018734141 | N4: -0.035831184 | O4: -0.057022861 | P4: -0.042462624 | Q4: -0.037772239 | R4: -0.028628159 | S4: -0.030997759 | T4: -0.0067040182 | U4: -0.037956684 | V4: -0.029502006 | W4: -0.041243237 | X4: -0.054483331 | Y4: -0.057374084 | Z4: -0.050628324 | AA4: -0.042319641 | AB4: -0.03427378 | AC4: -0.038455291 | AD4: -0.032603255 | AE4: -0.034794942 | AF4: -0.0016393719 | AG4: -0.03223915 | AH4: -0.025692957 | AI4: -0.030088885 | AJ4: -0.029719525 | AK4: -0.022742981 | AL4: -0.025322144 | AM4: -0.024117366 | AN4: -0.027272205 | AO4: -0.02838312 | AP4: -0.023965544 | AQ4: -0.030304468 | AR4: -0.017736018 | AS4: -0.014939197 | AT4: -0.013608707 | AU4: -0.016423914 | AV4: -0.024039604 | AW4: -0.021378703 | AX4: -0.023051307 | AY4: -0.023942341 | AZ4: -0.015978329 | BA4: -0.029633645 | BB4: -0.036923113 | BC4: -0.022611704 | BD4: -0.02696564 | BE4: -0.030957563 | BF4: -0.018181884 | BG4: -0.015961032 | BH4: -0.021358658 | BI4: -0.018895749 | BJ4: -0.021052816 | BK4: -0.02661183 | BL4: -0.017576751 | BM4: -0.021846036 | BN4: -0.013750921 | BO4: -0.0065027888 | BP4: -0.01217171 | BQ4: 0.00022277284 | BR4: -0.005245064 | BS4: -0.012938426 | BT4: -0.01635034 | BU4: -0.0017286047 | BV4: 0.015184016 | BW4: -0.0037692826 | BX4: -0.016045217 | BY4: -0.018894587 | BZ4: -0.0041566141 | CA4: -0.0182235 | CB4: -0.022303988 | CC4: -0.041111881 | CD4: -0.032535264 | CE4: -0.030323127 | CF4: -0.061293035 | CG4: -0.0441696 | CH4: -0.026870448 | CI4: -0.017734729 | CJ4: -0.011493971 | CK4: -0.01591057 | CL4: -0.015536443 | CM4: -0.01914162 | CN4: 0.0080306048 | CO4: 0.0041846284 | CP4: -0.0074834121 | CQ4: -0.00067070377 | CR4: -0.019179488 | CS4: -0.023347226 | CT4: -0.021789124 | CU4: -0.029507372 | CV4: -0.024862939 | CW4: -0.022835803 | CX4: -0.022235555 | CY4: -0.025586671 | CZ4: -0.030230897 | DA4: -0.043223926 | DB4: -0.044724836 | DC4: -0.070760187 | DD4: -0.057609849 | DE4: -0.034042017 | DF4: -0.027183612 | DG4: -0.03505246 | DH4: -0.0084282458 | DI4: -0.036370698 | DJ4: -0.038760924 | DK4: -0.027971575 | DL4: -0.016270629 | DM4: -0.017815732 | DN4: -0.0080526822 | DO4: -0.023536384 | DP4: -0.02948732 | DQ4: -0.037657448 | DR4: -0.029648059 | DS4: -0.030189606 | DT4: -0.041055976 | DU4: -0.037310577 | DV4: -0.0089387634 | DW4: -0.018377446 | DX4: -0.030385798 | DY4: -0.033048756 | DZ4: -0.030982286 | EA4: -0.031659362 | EB4: -0.036490653 | EC4: -0.041069205 | ED4: -0.031004875 | EE4: -0.023075953 | EF4: -0.01142086
