Workbook

Sheet 預測IC
A1: NN3
B2: Time | C2: 2013/12 | D2: 2014/01 | E2: 2014/02 | F2: 2014/03 | G2: 2014/04 | H2: 2014/05 | I2: 2014/06 | J2: 2014/07 | K2: 2014/08 | L2: 2014/09 | M2: 2014/10 | N2: 2014/11 | O2: 2014/12 | P2: 2015/01 | Q2: 2015/02 | R2: 2015/03 | S2: 2015/04 | T2: 2015/05 | U2: 2015/06 | V2: 2015/07 | W2: 2015/08 | X2: 2015/09 | Y2: 2015/10 | Z2: 2015/11 | AA2: 2015/12 | AB2: 2016/01 | AC2: 2016/02 | AD2: 2016/03 | AE2: 2016/04 | AF2: 2016/05 | AG2: 2016/06 | AH2: 2016/07 | AI2: 2016/08 | AJ2: 2016/09 | AK2: 2016/10 | AL2: 2016/11 | AM2: 2016/12 | AN2: 2017/01 | AO2: 2017/02 | AP2: 2017/03 | AQ2: 2017/04 | AR2: 2017/05 | AS2: 2017/06 | AT2: 2017/07 | AU2: 2017/08 | AV2: 2017/09 | AW2: 2017/10 | AX2: 2017/11 | AY2: 2017/12 | AZ2: 2018/01 | BA2: 2018/02 | BB2: 2018/03 | BC2: 2018/04 | BD2: 2018/05 | BE2: 2018/06 | BF2: 2018/07 | BG2: 2018/08 | BH2: 2018/09 | BI2: 2018/10 | BJ2: 2018/11 | BK2: 2018/12 | BL2: 2019/01 | BM2: 2019/02 | BN2: 2019/03 | BO2: 2019/04 | BP2: 2019/05 | BQ2: 2019/06 | BR2: 2019/07 | BS2: 2019/08 | BT2: 2019/09 | BU2: 2019/10 | BV2: 2019/11 | BW2: 2019/12 | BX2: 2020/01 | BY2: 2020/02 | BZ2: 2020/03 | CA2: 2020/04 | CB2: 2020/05 | CC2: 2020/06 | CD2: 2020/07 | CE2: 2020/08 | CF2: 2020/09 | CG2: 2020/10 | CH2: 2020/11 | CI2: 2020/12 | CJ2: 2021/01 | CK2: 2021/02 | CL2: 2021/03 | CM2: 2021/04 | CN2: 2021/05 | CO2: 2021/06 | CP2: 2021/07 | CQ2: 2021/08 | CR2: 2021/09 | CS2: 2021/10 | CT2: 2021/11 | CU2: 2021/12 | CV2: 2022/01 | CW2: 2022/02 | CX2: 2022/03 | CY2: 2022/04 | CZ2: 2022/05 | DA2: 2022/06 | DB2: 2022/07 | DC2: 2022/08 | DD2: 2022/09 | DE2: 2022/10 | DF2: 2022/11 | DG2: 2022/12 | DH2: 2023/01 | DI2: 2023/02 | DJ2: 2023/03 | DK2: 2023/04 | DL2: 2023/05 | DM2: 2023/06 | DN2: 2023/07 | DO2: 2023/08 | DP2: 2023/09 | DQ2: 2023/10 | DR2: 2023/11 | DS2: 2023/12 | DT2: 2024/01 | DU2: 2024/02 | DV2: 2024/03 | DW2: 2024/04 | DX2: 2024/05 | DY2: 2024/06 | DZ2: 2024/07 | EA2: 2024/08 | EB2: 2024/09 | EC2: 2024/10 | ED2: 2024/11 | EE2: 2024/12 | EF2: 2025/01 | EG2: 2025/02
B3: bm | C3: 0.031330206 | D3: -0.017543647 | E3: 0.029643897 | F3: 0.028182985 | G3: 0.041800492 | H3: 0.017699908 | I3: 0.012562056 | J3: 0.0012357431 | K3: 0.03579127 | L3: 0.06672582 | M3: 0.013276166 | N3: -0.0013405997 | O3: -0.0039153537 | P3: 0.023424895 | Q3: 0.020386307 | R3: 0.019572005 | S3: 0.022870889 | T3: 0.0043855454 | U3: -0.0085439961 | V3: -0.0085163033 | W3: -0.017971992 | X3: -0.011634784 | Y3: -0.026567305 | Z3: -0.027729809 | AA3: 0.07440342 | AB3: -0.027647037 | AC3: -0.027917437 | AD3: -0.031291369 | AE3: -0.020633645 | AF3: -0.035181422 | AG3: -0.01247499 | AH3: -0.022227593 | AI3: 0.028354397 | AJ3: 0.017696382 | AK3: -0.0015488248 | AL3: 0.060541511 | AM3: 0.042939704 | AN3: 0.046451166 | AO3: 0.046414647 | AP3: 0.027322842 | AQ3: 0.049711406 | AR3: 0.040726095 | AS3: 0.037940711 | AT3: 0.043215282 | AU3: 0.035848293 | AV3: 0.048106551 | AW3: 0.25755826 | AX3: 0.023971893 | AY3: 0.056368217 | AZ3: 0.044408236 | BA3: 0.040217362 | BB3: 0.03921549 | BC3: 0.051480398 | BD3: 0.049942177 | BE3: 0.049302526 | BF3: 0.050215017 | BG3: 0.044806387 | BH3: 0.072218522 | BI3: 0.053198006 | BJ3: 0.050947383 | BK3: 0.046847828 | BL3: 0.051777665 | BM3: 0.045751151 | BN3: 0.051456984 | BO3: 0.054446146 | BP3: 0.051880281 | BQ3: 0.049081109 | BR3: 0.030115355 | BS3: 0.048800111 | BT3: 0.048635218 | BU3: 0.045633737 | BV3: 0.049472287 | BW3: 0.04460188 | BX3: 0.045671009 | BY3: 0.036897704 | BZ3: 0.2139428 | CA3: 0.027052136 | CB3: 0.046074998 | CC3: 0.072226599 | CD3: 0.034700908 | CE3: 0.036362294 | CF3: 0.047756139 | CG3: 0.036376581 | CH3: 0.043285508 | CI3: 0.042804375 | CJ3: 0.043789677 | CK3: 0.041936092 | CL3: 0.045073912 | CM3: 0.057426576 | CN3: 0.048870686 | CO3: 0.046467092 | CP3: 0.045427285 | CQ3: 0.043254118 | CR3: 0.042831581 | CS3: 0.041360334 | CT3: 0.023747286 | CU3: 0.039278172 | CV3: 0.040995765 | CW3: 0.036699787 | CX3: 0.03876495 | CY3: 0.037805531 | CZ3: 0.043257263 | DA3: 0.044850636 | DB3: 0.043851811 | DC3: 0.049191009 | DD3: 0.042120047 | DE3: 0.047127001 | DF3: 0.038079627 | DG3: 0.038307089 | DH3: 0.039209746 | DI3: 0.050754562 | DJ3: 0.049327295 | DK3: 0.046511237 | DL3: 0.042277504 | DM3: 0.032305263 | DN3: 0.046072427 | DO3: 0.048485249 | DP3: 0.046022162 | DQ3: 0.044537414 | DR3: 0.044425271 | DS3: 0.042646576 | DT3: 0.046090584 | DU3: 0.043128092 | DV3: 0.041349083 | DW3: 0.040377732 | DX3: 0.046240631 | DY3: 0.045292761 | DZ3: 0.038002156 | EA3: 0.043337245 | EB3: 0.035762075 | EC3: 0.030851878 | ED3: 0.040065717 | EE3: 0.043372519 | EF3: 0.046325836
B4: size | C4: -0.022946816 | D4: -0.03252884 | E4: -0.022317033 | F4: -0.030678758 | G4: -0.032594331 | H4: -0.027283197 | I4: -0.036774721 | J4: -0.036947548 | K4: -0.034350142 | L4: -0.035141915 | M4: -0.036390312 | N4: -0.028046655 | O4: -0.031360816 | P4: -0.038859572 | Q4: -0.032996118 | R4: -0.033478595 | S4: -0.030273415 | T4: -0.029860206 | U4: -0.028853958 | V4: -0.028230349 | W4: -0.027426424 | X4: -0.028772751 | Y4: -0.030104211 | Z4: -0.030214574 | AA4: -0.029737558 | AB4: -0.02885131 | AC4: -0.029060299 | AD4: -0.028935431 | AE4: -0.029848391 | AF4: -0.028637772 | AG4: -0.028286912 | AH4: -0.018820291 | AI4: -0.03735894 | AJ4: -0.03376469 | AK4: -0.033512142 | AL4: -0.026952209 | AM4: -0.029780874 | AN4: -0.024186648 | AO4: -0.035795771 | AP4: -0.035298556 | AQ4: -0.032549217 | AR4: -0.026099775 | AS4: -0.029556919 | AT4: -0.025735412 | AU4: -0.030931229 | AV4: -0.033240151 | AW4: -0.034350481 | AX4: -0.033253677 | AY4: -0.034111623 | AZ4: -0.027224915 | BA4: -0.031113092 | BB4: -0.028748853 | BC4: -0.031344336 | BD4: -0.031253476 | BE4: -0.032918938 | BF4: -0.030730952 | BG4: -0.032038067 | BH4: -0.029968824 | BI4: -0.03113761 | BJ4: -0.030530032 | BK4: -0.032626651 | BL4: -0.031143451 | BM4: -0.031869125 | BN4: -0.0089618694 | BO4: -0.02234176 | BP4: -0.035501461 | BQ4: -0.032422189 | BR4: -0.012115268 | BS4: -0.034664404 | BT4: -0.025803247 | BU4: -0.036140274 | BV4: -0.03358756 | BW4: -0.022672802 | BX4: -0.032804973 | BY4: -0.031771816 | BZ4: -0.035874113 | CA4: -0.032339249 | CB4: -0.025078919 | CC4: -0.029253673 | CD4: -0.026061168 | CE4: -0.031506848 | CF4: -0.030835303 | CG4: -0.030558078 | CH4: -0.031195812 | CI4: -0.03090176 | CJ4: -0.033136498 | CK4: -0.03193694 | CL4: -0.031432364 | CM4: -0.030552488 | CN4: -0.03156383 | CO4: -0.030369364 | CP4: -0.030010061 | CQ4: -0.031453073 | CR4: -0.029659985 | CS4: -0.030953852 | CT4: -0.022892835 | CU4: -0.026670391 | CV4: -0.02843071 | CW4: -0.032202706 | CX4: -0.027807113 | CY4: -0.027818114 | CZ4: -0.025765225 | DA4: -0.028357303 | DB4: -0.033542968 | DC4: -0.032485206 | DD4: -0.032151666 | DE4: -0.029662402 | DF4: -0.030016089 | DG4: -0.027544236 | DH4: -0.029481679 | DI4: -0.029836735 | DJ4: -0.030232292 | DK4: -0.029773425 | DL4: -0.030361593 | DM4: -0.028258214 | DN4: -0.027416492 | DO4: -0.028671181 | DP4: -0.026597379 | DQ4: -0.027629543 | DR4: -0.028683992 | DS4: -0.028038638 | DT4: -0.028481221 | DU4: -0.028131869 | DV4: -0.028057158 | DW4: -0.026135134 | DX4: -0.027580081 | DY4: -0.029757338 | DZ4: -0.028591992 | EA4: -0.026999522 | EB4: -0.02658944 | EC4: -0.028255623 | ED4: -0.024481362 | EE4: -0.034881096 | EF4: -0.028714798
B5: mom | C5: -0.004058179 | D5: -0.0070305788 | E5: -0.0055704452 | F5: -0.0046082139 | G5: -0.0078217024 | H5: -0.0067892699 | I5: -0.0066186492 | J5: -0.0064537222 | K5: -0.0072179409 | L5: -0.0075036068 | M5: -0.0055860877 | N5: 0.012057774 | O5: 0.021040574 | P5: 0.017183207 | Q5: 0.0038061368 | R5: -0.0048372317 | S5: -0.0016025492 | T5: 0.0035364544 | U5: 0.0021403963 | V5: 0.00060599193 | W5: 0.0005890812 | X5: -0.0038637295 | Y5: -0.011012747 | Z5: -0.003187824 | AA5: -0.01046215 | AB5: -0.0082556549 | AC5: -0.016103683 | AD5: -0.011081633 | AE5: -0.0093202144 | AF5: -0.0047228439 | AG5: -0.0058480459 | AH5: -0.0049915235 | AI5: -0.0036832264 | AJ5: -0.0036150045 | AK5: -0.004623584 | AL5: -0.0053735496 | AM5: -0.0080364374 | AN5: -0.0048419638 | AO5: -0.0036342754 | AP5: -0.0063295281 | AQ5: -0.00090462592 | AR5: -0.0029117612 | AS5: -0.0018755771 | AT5: 0.01676389 | AU5: -0.012358704 | AV5: 0.01113764 | AW5: 0.0068921894 | AX5: -0.012156531 | AY5: -0.00078160246 | AZ5: 0.010525933 | BA5: -0.0010518157 | BB5: -0.0076166745 | BC5: 0.0011649788 | BD5: -0.017264392 | BE5: -0.0063144346 | BF5: 0.00035074475 | BG5: -0.007133496 | BH5: -0.0041654566 | BI5: 0.00043993082 | BJ5: -0.00029990479 | BK5: -0.0080823526 | BL5: -0.0019032802 | BM5: -0.0030310731 | BN5: -0.00072125701 | BO5: -0.004447924 | BP5: -0.00063404883 | BQ5: 0.00085474947 | BR5: 0.00053479197 | BS5: -0.00072659482 | BT5: 0.00023761881 | BU5: -0.0039665578 | BV5: -0.0015995716 | BW5: -0.0038771285 | BX5: -0.0021470857 | BY5: -0.0026197792 | BZ5: 0.0009647907 | CA5: -0.016296295 | CB5: -0.01730866 | CC5: -0.0096325967 | CD5: -0.0060692187 | CE5: 0.0056500481 | CF5: -0.0050238585 | CG5: -0.0010497671 | CH5: -0.0024338539 | CI5: -0.005816041 | CJ5: 0.0053073554 | CK5: -0.0065996735 | CL5: -0.0075646639 | CM5: 0.004414422 | CN5: -0.0017971381 | CO5: 0.0023375279 | CP5: -0.003601315 | CQ5: -0.0043951133 | CR5: -0.00046630308 | CS5: -0.0048435549 | CT5: -0.00014159325 | CU5: -0.003582235 | CV5: -0.00050776661 | CW5: -0.004188884 | CX5: -0.001538418 | CY5: -0.0022514616 | CZ5: 0.00011980097 | DA5: -0.0013928759 | DB5: -0.0031657913 | DC5: -0.0038332227 | DD5: -0.0047448631 | DE5: -0.0045543034 | DF5: -0.019639993 | DG5: -0.0053460952 | DH5: -0.0043691969 | DI5: -0.013279116 | DJ5: -0.011888301 | DK5: -0.009788231 | DL5: -0.0026799133 | DM5: 0.0018919624 | DN5: -0.0035755492 | DO5: 0.0018424713 | DP5: -0.0045598447 | DQ5: -0.0045280247 | DR5: -0.0079675084 | DS5: -0.0036320081 | DT5: -0.00024074421 | DU5: -0.0018284139 | DV5: -0.0026720865 | DW5: 0.00015958725 | DX5: -0.0051815659 | DY5: -0.0032462212 | DZ5: -0.0019827848 | EA5: -0.0025347143 | EB5: -0.0044873073 | EC5: -0.0053789192 | ED5: -0.00633974 | EE5: -0.0059063872 | EF5: -0.0062110182
A6: 選絕對值最大 | C6: {=MATCH(MAX(ABS(C3:C5)), ABS(C3:C5), 0)} -> 1 | D6: {=MATCH(MAX(ABS(D3:D5)), ABS(D3:D5), 0)} -> 2 | E6: {=MATCH(MAX(ABS(E3:E5)), ABS(E3:E5), 0)} -> 1 | F6: {=MATCH(MAX(ABS(F3:F5)), ABS(F3:F5), 0)} -> 2 | G6: {=MATCH(MAX(ABS(G3:G5)), ABS(G3:G5), 0)} -> 1 | H6: {=MATCH(MAX(ABS(H3:H5)), ABS(H3:H5), 0)} -> 2 | I6: {=MATCH(MAX(ABS(I3:I5)), ABS(I3:I5), 0)} -> 2 | J6: {=MATCH(MAX(ABS(J3:J5)), ABS(J3:J5), 0)} -> 2 | ... EG6: {=MATCH(MAX(ABS(EG3:EG5)), ABS(EG3:EG5), 0)} -> 1
C7: =IF(C6=1,"bm",IF(C6=2,"size",IF(C6=3,"mom"))) -> bm | D7: =IF(D6=1,"bm",IF(D6=2,"size",IF(D6=3,"mom"))) -> size | E7: =IF(E6=1,"bm",IF(E6=2,"size",IF(E6=3,"mom"))) -> bm | F7: =IF(F6=1,"bm",IF(F6=2,"size",IF(F6=3,"mom"))) -> size | G7: =IF(G6=1,"bm",IF(G6=2,"size",IF(G6=3,"mom"))) -> bm | H7: =IF(H6=1,"bm",IF(H6=2,"size",IF(H6=3,"mom"))) -> size | I7: =IF(I6=1,"bm",IF(I6=2,"size",IF(I6=3,"mom"))) -> size | J7: =IF(J6=1,"bm",IF(J6=2,"size",IF(J6=3,"mom"))) -> size | ... EG7: =IF(EG6=1,"bm",IF(EG6=2,"size",IF(EG6=3,"mom"))) -> bm
C8: =IF(C6=1,C3,IF(C6=2,C4,IF(C6=3,C5))) -> 0.031330206 | D8: =IF(D6=1,D3,IF(D6=2,D4,IF(D6=3,D5))) -> -0.03252884 | E8: =IF(E6=1,E3,IF(E6=2,E4,IF(E6=3,E5))) -> 0.029643897 | F8: =IF(F6=1,F3,IF(F6=2,F4,IF(F6=3,F5))) -> -0.030678758 | G8: =IF(G6=1,G3,IF(G6=2,G4,IF(G6=3,G5))) -> 0.041800492 | H8: =IF(H6=1,H3,IF(H6=2,H4,IF(H6=3,H5))) -> -0.027283197 | I8: =IF(I6=1,I3,IF(I6=2,I4,IF(I6=3,I5))) -> -0.036774721 | J8: =IF(J6=1,J3,IF(J6=2,J4,IF(J6=3,J5))) -> -0.036947548 | ... EG8: =IF(EG6=1,EG3,IF(EG6=2,EG4,IF(EG6=3,EG5))) -> 0
A10: 投資組合 | C10: 公司數 | D10: 964
A11: 等第 | B11: 分數 | C11: 2014/01 | D11: 2014/02 | E11: 2014/03 | F11: 2014/04 | G11: 2014/05 | H11: 2014/06 | I11: 2014/07 | J11: 2014/08 | K11: 2014/09 | L11: 2014/10 | M11: 2014/11 | N11: 2014/12 | O11: 2015/01 | P11: 2015/02 | Q11: 2015/03 | R11: 2015/04 | S11: 2015/05 | T11: 2015/06 | U11: 2015/07 | V11: 2015/08 | W11: 2015/09 | X11: 2015/10 | Y11: 2015/11 | Z11: 2015/12 | AA11: 2016/01 | AB11: 2016/02 | AC11: 2016/03 | AD11: 2016/04 | AE11: 2016/05 | AF11: 2016/06 | AG11: 2016/07 | AH11: 2016/08 | AI11: 2016/09 | AJ11: 2016/10 | AK11: 2016/11 | AL11: 2016/12 | AM11: 2017/01 | AN11: 2017/02 | AO11: 2017/03 | AP11: 2017/04 | AQ11: 2017/05 | AR11: 2017/06 | AS11: 2017/07 | AT11: 2017/08 | AU11: 2017/09 | AV11: 2017/10 | AW11: 2017/11 | AX11: 2017/12 | AY11: 2018/01 | AZ11: 2018/02 | BA11: 2018/03 | BB11: 2018/04 | BC11: 2018/05 | BD11: 2018/06 | BE11: 2018/07 | BF11: 2018/08 | BG11: 2018/09 | BH11: 2018/10 | BI11: 2018/11 | BJ11: 2018/12 | BK11: 2019/01 | BL11: 2019/02 | BM11: 2019/03 | BN11: 2019/04 | BO11: 2019/05 | BP11: 2019/06 | BQ11: 2019/07 | BR11: 2019/08 | BS11: 2019/09 | BT11: 2019/10 | BU11: 2019/11 | BV11: 2019/12 | BW11: 2020/01 | BX11: 2020/02 | BY11: 2020/03 | BZ11: 2020/04 | CA11: 2020/05 | CB11: 2020/06 | CC11: 2020/07 | CD11: 2020/08 | CE11: 2020/09 | CF11: 2020/10 | CG11: 2020/11 | CH11: 2020/12 | CI11: 2021/01 | CJ11: 2021/02 | CK11: 2021/03 | CL11: 2021/04 | CM11: 2021/05 | CN11: 2021/06 | CO11: 2021/07 | CP11: 2021/08 | CQ11: 2021/09 | CR11: 2021/10 | CS11: 2021/11 | CT11: 2021/12 | CU11: 2022/01 | CV11: 2022/02 | CW11: 2022/03 | CX11: 2022/04 | CY11: 2022/05 | CZ11: 2022/06 | DA11: 2022/07 | DB11: 2022/08 | DC11: 2022/09 | DD11: 2022/10 | DE11: 2022/11 | DF11: 2022/12 | DG11: 2023/01 | DH11: 2023/02 | DI11: 2023/03 | DJ11: 2023/04 | DK11: 2023/05 | DL11: 2023/06 | DM11: 2023/07 | DN11: 2023/08 | DO11: 2023/09 | DP11: 2023/10 | DQ11: 2023/11 | DR11: 2023/12 | DS11: 2024/01 | DT11: 2024/02 | DU11: 2024/03 | DV11: 2024/04 | DW11: 2024/05 | DX11: 2024/06 | DY11: 2024/07 | DZ11: 2024/08 | EA11: 2024/09 | EB11: 2024/10 | EC11: 2024/11 | ED11: 2024/12 | EE11: 2025/01 | EF11: 2025/02
A12: 10 | B12: 96 | C12: 0.047013509 | D12: 0.11468863 | E12: -0.0067540284 | F12: 0.013421104 | G12: 0.0079043467 | H12: 0.038530512 | I12: 0.012809789 | J12: -0.029408123 | K12: -0.010988404 | L12: -0.0022772308 | M12: -0.00039647701 | N12: 0.069326987 | O12: 0.017240739 | P12: 0.00022997129 | Q12: 0.035269885 | R12: 0.0066628838 | S12: -0.016472395 | T12: -0.0077398001 | U12: -0.016178599 | V12: 0.0062044701 | W12: 0.064039415 | X12: 0.02707389 | Y12: 0.015440368 | Z12: 0.0051659076 | AA12: -0.039403661 | AB12: -0.0037114184 | AC12: 0.0051673798 | AD12: -0.00584711 | AE12: -0.058316963 | AF12: -0.020432151 | AG12: 0.012079128 | AH12: -0.013405805 | AI12: 0.023246459 | AJ12: 0.021062263 | AK12: 0.0095035079 | AL12: 0.017859003 | AM12: 0.030086116 | AN12: 0.069233234 | AO12: 0.002228793 | AP12: -0.0046339365 | AQ12: -0.0076219364 | AR12: 0.013526259 | AS12: 0.019099718 | AT12: 0.013834905 | AU12: 0.020708659 | AV12: -0.041360085 | AW12: 0.00062147702 | AX12: -0.0086580852 | AY12: 0.024955293 | AZ12: -0.0023000261 | BA12: 0.0049378882 | BB12: 0.015274605 | BC12: 0.012272789 | BD12: 0.013630557 | BE12: 0.01860881 | BF12: 0.067792352 | BG12: 0.033670862 | BH12: 0.01422336 | BI12: 0.050021253 | BJ12: -0.00079599332 | BK12: -0.021284665 | BL12: 0.024709246 | BM12: -0.005169092 | BN12: 0.011516536 | BO12: 0.02424631 | BP12: -0.010508985 | BQ12: 0.01389675 | BR12: -0.0022610085 | BS12: 0.018863293 | BT12: 0.022031469 | BU12: 0.0087815171 | BV12: 0.023062456 | BW12: -0.029483769 | BX12: 0.011477162 | BY12: -0.0333708 | BZ12: 0.045356946 | CA12: 0.014580558 | CB12: 0.0019432421 | CC12: -0.016770964 | CD12: 0.11093363 | CE12: 0.011619408 | CF12: 0.027767583 | CG12: 0.041857234 | CH12: 0.063297372 | CI12: -0.034655912 | CJ12: 0.01544518 | CK12: 0.012803144 | CL12: 0.11801561 | CM12: -0.015219726 | CN12: -0.027083701 | CO12: -0.027266127 | CP12: 0.045299021 | CQ12: 0.036572195 | CR12: 0.0021178784 | CS12: -0.015201648 | CT12: -0.00082403602 | CU12: 0.035623716 | CV12: 0.0081126264 | CW12: 0.0055479247 | CX12: 0.060989883 | CY12: -0.0059829422 | CZ12: 0.077792327 | DA12: 0.0056037841 | DB12: -0.022981876 | DC12: 0.033973203 | DD12: 0.024888978 | DE12: 0.0011981084 | DF12: -0.0068345257 | DG12: -0.00094770894 | DH12: -0.003822682 | DI12: -0.054443173 | DJ12: 0.0080625983 | DK12: -0.015945953 | DL12: -0.00035467602 | DM12: -0.0048403492 | DN12: 0.042410365 | DO12: 0.022599734 | DP12: 0.03258445 | DQ12: -0.022769865 | DR12: 0.018778943 | DS12: -0.035726155 | DT12: -0.045297883 | DU12: 0.013752648 | DV12: 0.048550824 | DW12: 0.043725564 | DX12: -0.050152081 | DY12: 0.01535727 | DZ12: -0.0041357255 | EA12: 0.064003941 | EB12: 0.0028283268 | EC12: 0.02665151 | ED12: -0.060508153 | EE12: 0.011917096 | EF12: 0.039233348
A13: 20 | B13: 48 | C13: 0.042506118 | D13: 0.12374503 | E13: -0.034496619 | F13: -0.01145524 | G13: -0.01490798 | H13: 0.029989632 | I13: 0.029130595 | J13: -0.043899227 | K13: -0.04533099 | L13: -0.029135669 | M13: 0.025687102 | N13: 0.099806917 | O13: 0.039789292 | P13: 0.016791628 | Q13: 0.073224368 | R13: 0.014159944 | S13: -0.012243671 | T13: -0.02210402 | U13: 0.0015970162 | V13: -0.020094328 | W13: 0.075476562 | X13: 0.053276895 | Y13: 0.013920993 | Z13: 0.020583761 | AA13: -0.03211951 | AB13: -0.016036099 | AC13: 0.0080314398 | AD13: -0.0065790452 | AE13: -0.065719382 | AF13: -0.031940464 | AG13: 0.0032823102 | AH13: -0.0096413392 | AI13: 0.01990991 | AJ13: 0.019886324 | AK13: 0.0033184448 | AL13: 0.023151429 | AM13: 0.046282444 | AN13: 0.10533024 | AO13: 0.0093111879 | AP13: -0.0065879899 | AQ13: -0.0060492888 | AR13: 0.010689186 | AS13: 0.041313118 | AT13: 0.040463088 | AU13: 0.040976126 | AV13: -0.0094754726 | AW13: 0.0040800136 | AX13: -0.011880968 | AY13: 0.017564346 | AZ13: -0.0081034675 | BA13: 0.0065409376 | BB13: 0.042875374 | BC13: 0.011283767 | BD13: 0.0033444284 | BE13: 0.027391806 | BF13: 0.083929415 | BG13: 0.046566462 | BH13: 0.0084757298 | BI13: 0.052409132 | BJ13: -0.016847086 | BK13: -0.018391025 | BL13: 0.03194786 | BM13: 0.016918616 | BN13: 0.011052542 | BO13: 0.030878716 | BP13: 0.0094326957 | BQ13: 0.041653064 | BR13: -0.0066814175 | BS13: 0.0074194718 | BT13: 0.038343506 | BU13: 0.017706555 | BV13: 0.020653597 | BW13: 0.0017632378 | BX13: 0.021078068 | BY13: -0.014512398 | BZ13: 0.076138123 | CA13: 0.024012674 | CB13: -0.0065958267 | CC13: -0.012530912 | CD13: 0.10508583 | CE13: 0.0092209843 | CF13: 0.044514267 | CG13: 0.040449063 | CH13: 0.058334612 | CI13: -0.051853509 | CJ13: -0.003106088 | CK13: 0.032045269 | CL13: 0.081453366 | CM13: -0.010296804 | CN13: -0.026887566 | CO13: -0.013457459 | CP13: 0.06972654 | CQ13: 0.03818495 | CR13: 0.008279781 | CS13: 0.010833051 | CT13: 0.0080707993 | CU13: 0.037161402 | CV13: -0.0029533122 | CW13: 0.0059770309 | CX13: 0.060033255 | CY13: -0.01311874 | CZ13: 0.05722422 | DA13: -0.0055836769 | DB13: -0.04176157 | DC13: 0.029775566 | DD13: 0.010697601 | DE13: 0.0059289571 | DF13: -0.028518797 | DG13: -0.0016306572 | DH13: 0.011295768 | DI13: -0.045977025 | DJ13: -0.0033317562 | DK13: 0.012409074 | DL13: -0.016300246 | DM13: -0.006658869 | DN13: 0.011499578 | DO13: 0.046891412 | DP13: 0.048786636 | DQ13: -0.026430081 | DR13: 0.013771209 | DS13: -0.038887628 | DT13: -0.035426301 | DU13: 0.018705164 | DV13: 0.079620144 | DW13: 0.04441779 | DX13: -0.06452338 | DY13: 0.035386045 | DZ13: -0.014608814 | EA13: 0.073242869 | EB13: 0.021373218 | EC13: 0.041659753 | ED13: -0.065682094 | EE13: 0.0079525936 | EF13: 0.066577215
A14: 50 | B14: 19 | C14: -0.037017512 | D14: 0.22230845 | E14: -0.047525943 | F14: 0.034542464 | G14: -0.041019916 | H14: 0.059587806 | I14: 0.077114962 | J14: -0.10509439 | K14: -0.1341787 | L14: 0.0048471972 | M14: -0.075951543 | N14: 0.20483258 | O14: 0.039642308 | P14: 0.047779764 | Q14: 0.058237946 | R14: -0.014151796 | S14: 0.0385341 | T14: -0.017360731 | U14: 0.03657913 | V14: -0.038375546 | W14: 0.11616579 | X14: 0.053581709 | Y14: -0.016762663 | Z14: 0.021252201 | AA14: -0.03945018 | AB14: -0.074982913 | AC14: -0.029292084 | AD14: 0.012920107 | AE14: -0.0040189068 | AF14: -0.040420703 | AG14: 0.006390201 | AH14: -0.0052502779 | AI14: 0.010964571 | AJ14: 0.096294977 | AK14: -0.011509463 | AL14: 0.03796919 | AM14: 0.061242166 | AN14: 0.098594667 | AO14: 0.060905705 | AP14: 0.0070548285 | AQ14: -0.00036796774 | AR14: 0.03764584 | AS14: 0.085376986 | AT14: 0.03450658 | AU14: 0.039991649 | AV14: -0.018682885 | AW14: -0.018362932 | AX14: 0.00082158805 | AY14: 0.015068119 | AZ14: -0.053348569 | BA14: 0.017621646 | BB14: 0.061734282 | BC14: -0.009820999 | BD14: 0.043327782 | BE14: 0.043787063 | BF14: 0.040770522 | BG14: 0.041374264 | BH14: 0.0053427556 | BI14: 0.050185213 | BJ14: -0.020017224 | BK14: -0.0055937517 | BL14: 0.059737767 | BM14: 0.039257215 | BN14: 0.020936538 | BO14: 0.033609046 | BP14: 0.015673733 | BQ14: 0.015843524 | BR14: -0.02792943 | BS14: -0.041493955 | BT14: 0.074012962 | BU14: -0.0088548354 | BV14: 0.025727182 | BW14: 0.012507948 | BX14: 0.05497076 | BY14: -0.0065962934 | BZ14: 0.060034057 | CA14: 0.033455158 | CB14: 0.022127617 | CC14: -0.012794081 | CD14: 0.09801671 | CE14: -0.072156719 | CF14: 0.092330683 | CG14: 0.053067028 | CH14: 0.064661392 | CI14: -0.10588478 | CJ14: -0.028667855 | CK14: 0.014016364 | CL14: 0.062269955 | CM14: 0.03204001 | CN14: -0.023026689 | CO14: -0.07358772 | CP14: 0.099809331 | CQ14: 0.053211628 | CR14: 0.055909138 | CS14: 0.05902712 | CT14: 0.019100577 | CU14: -0.043917103 | CV14: 0.022745715 | CW14: -0.0033983825 | CX14: 0.036299409 | CY14: -0.02875912 | CZ14: 0.064063563 | DA14: -0.024304289 | DB14: -0.023561073 | DC14: 0.023632609 | DD14: -0.01675855 | DE14: 0.0053842996 | DF14: -0.035856631 | DG14: 0.011446556 | DH14: 0.0047748372 | DI14: -0.05859782 | DJ14: 0.0010237243 | DK14: 0.019071063 | DL14: -0.015165162 | DM14: 0.0055042691 | DN14: 0.042662496 | DO14: 0.041375645 | DP14: 0.043539716 | DQ14: -0.08936786 | DR14: 0.052622519 | DS14: -0.035044906 | DT14: -0.044516954 | DU14: -0.044914949 | DV14: 0.10826235 | DW14: 0.098344367 | DX14: -0.10193151 | DY14: 0.03799708 | DZ14: -0.021881573 | EA14: 0.078105266 | EB14: 0.033177333 | EC14: 0.0060793821 | ED14: -0.10262971 | EE14: 0.018867157 | EF14: 0.06995642
A15: 100 | B15: 10 | C15: -0.096503142 | D15: 0.37270922 | E15: -0.010198426 | F15: 0.090303713 | G15: -0.060636929 | H15: 0.1188437 | I15: 0.12672874 | J15: -0.06452469 | K15: -0.28659463 | L15: 0.032558505 | M15: -0.18849205 | N15: 0.33030934 | O15: 0.046103493 | P15: 0.052983283 | Q15: 0.10037535 | R15: 0.016755436 | S15: -0.043033934 | T15: -0.049338673 | U15: 0.046790243 | V15: -0.085680882 | W15: 0.10693456 | X15: 0.078436412 | Y15: -0.024188619 | Z15: -0.023656419 | AA15: -0.054081147 | AB15: -0.073995952 | AC15: -0.04005513 | AD15: -0.018936283 | AE15: 0.047286476 | AF15: -0.065819612 | AG15: -0.0097453106 | AH15: 0.033604373 | AI15: 0.07427696 | AJ15: 0.0041844346 | AK15: -0.036999312 | AL15: 0.044431662 | AM15: 0.055122622 | AN15: 0.10168871 | AO15: 0.063369812 | AP15: 0.012581945 | AQ15: -0.037367127 | AR15: 0.090293855 | AS15: 0.053821179 | AT15: 0.065254991 | AU15: 0.039943261 | AV15: -0.047226818 | AW15: 0.015659939 | AX15: 0.0041596917 | AY15: 0.028017064 | AZ15: -0.09132328 | BA15: 0.010613515 | BB15: 0.11272487 | BC15: 0.062155144 | BD15: 0.053043274 | BE15: 0.048442721 | BF15: 0.047662979 | BG15: 0.0024895387 | BH15: 0.034441845 | BI15: 0.068586659 | BJ15: -0.011265027 | BK15: 0.00082375227 | BL15: 0.059403871 | BM15: 0.066824821 | BN15: 0.04014257 | BO15: 0.027734476 | BP15: 0.014184221 | BQ15: 0.012802931 | BR15: -0.050157429 | BS15: -0.016823777 | BT15: 0.089060206 | BU15: 0.01947642 | BV15: 0.058914968 | BW15: -0.03594589 | BX15: 0.028635895 | BY15: -0.061694091 | BZ15: 0.10290647 | CA15: 0.029964009 | CB15: 0.015056894 | CC15: -0.15231827 | CD15: 0.12015208 | CE15: -0.11651657 | CF15: 0.09435665 | CG15: -0.0042988793 | CH15: 0.062885958 | CI15: -0.038798415 | CJ15: -0.087044356 | CK15: 0.056672646 | CL15: 0.031421975 | CM15: 0.074631116 | CN15: -0.042634116 | CO15: -0.12944902 | CP15: 0.12753584 | CQ15: 0.037378011 | CR15: 0.04823707 | CS15: 0.060185172 | CT15: 0.007394575 | CU15: -0.06317866 | CV15: -0.0061418469 | CW15: -0.01248466 | CX15: 0.024039607 | CY15: -0.042470673 | CZ15: 0.079886948 | DA15: -0.026375835 | DB15: -0.030226618 | DC15: 0.03507515 | DD15: -0.04939369 | DE15: 0.024948715 | DF15: -0.042391306 | DG15: 0.016196732 | DH15: -0.018709011 | DI15: -0.011718449 | DJ15: -0.051853853 | DK15: 0.10177483 | DL15: 0.062635494 | DM15: -0.023808547 | DN15: 0.043996497 | DO15: 0.046296727 | DP15: 0.023735602 | DQ15: -0.095040907 | DR15: 0.070010567 | DS15: -0.076241908 | DT15: -0.072163632 | DU15: -0.045770729 | DV15: 0.13976836 | DW15: 0.025538627 | DX15: -0.11861625 | DY15: 0.10653917 | DZ15: -0.018920244 | EA15: 0.027338726 | EB15: 0.048518573 | EC15: 0.066081856 | ED15: -0.11335706 | EE15: -0.016245415 | EF15: 0.065700991
A16: 107 | B16: 9 | C16: -0.027383645 | D16: 0.40819498 | E16: -0.0028301766 | F16: 0.12425979 | G16: -0.073696265 | H16: 0.072848056 | I16: 0.1117923 | J16: -0.068694033 | K16: -0.28467055 | L16: 0.0098865346 | M16: -0.1948764 | N16: 0.36698761 | O16: 0.015621092 | P16: 0.061979735 | Q16: 0.096618173 | R16: 0.019182762 | S16: -0.042415183 | T16: -0.023226785 | U16: 0.048651516 | V16: -0.10431618 | W16: 0.078373488 | X16: 0.073678278 | Y16: -0.0042874471 | Z16: -0.020075795 | AA16: -0.043487636 | AB16: -0.071016126 | AC16: -0.041040523 | AD16: -0.0011220258 | AE16: 0.051534992 | AF16: -0.063685843 | AG16: -0.0083019076 | AH16: 0.0317654 | AI16: 0.090522649 | AJ16: -0.017629242 | AK16: -0.0079871677 | AL16: 0.048688933 | AM16: 0.066076731 | AN16: 0.1064562 | AO16: 0.061424672 | AP16: 0.0052398896 | AQ16: -0.0384662 | AR16: 0.10329118 | AS16: 0.065068225 | AT16: 0.049547155 | AU16: 0.041826838 | AV16: -0.0090725068 | AW16: 0.03925293 | AX16: -0.0068578552 | AY16: 0.03381259 | AZ16: -0.10490964 | BA16: 0.014923105 | BB16: 0.10803892 | BC16: 0.067121466 | BD16: 0.035936712 | BE16: 0.051410994 | BF16: 0.064268054 | BG16: 0.013473282 | BH16: -0.013775614 | BI16: 0.041443808 | BJ16: -0.020503816 | BK16: 0.0029719903 | BL16: 0.070623566 | BM16: 0.081523875 | BN16: 0.047905833 | BO16: 0.02189036 | BP16: 0.020843184 | BQ16: 0.016478016 | BR16: -0.026296848 | BS16: -0.013191573 | BT16: 0.085483191 | BU16: 0.05776511 | BV16: 0.060711239 | BW16: -0.065740927 | BX16: 0.031559238 | BY16: -0.050563733 | BZ16: 0.11152585 | CA16: 0.02743217 | CB16: -0.001428045 | CC16: -0.15907251 | CD16: 0.15507127 | CE16: -0.13259506 | CF16: 0.10520126 | CG16: -0.005378519 | CH16: 0.041697415 | CI16: -0.038709882 | CJ16: -0.045523551 | CK16: 0.076472984 | CL16: 0.015878682 | CM16: 0.088988628 | CN16: -0.033057515 | CO16: -0.18245195 | CP16: 0.13663169 | CQ16: 0.041435606 | CR16: 0.048299767 | CS16: 0.06655916 | CT16: 0.0050674065 | CU16: -0.063434654 | CV16: -0.016751084 | CW16: -0.0091941595 | CX16: 0.012240285 | CY16: -0.049117049 | CZ16: 0.10263326 | DA16: -0.029804794 | DB16: -0.04271217 | DC16: 0.042942362 | DD16: -0.070070935 | DE16: 0.034444372 | DF16: -0.023146433 | DG16: 0.014452948 | DH16: -0.019129343 | DI16: -0.013233426 | DJ16: -0.029141406 | DK16: 0.13359436 | DL16: 0.065113036 | DM16: -0.03033095 | DN16: 0.042437853 | DO16: 0.053221908 | DP16: 0.019841949 | DQ16: -0.083033658 | DR16: 0.055191252 | DS16: -0.093752065 | DT16: -0.10053413 | DU16: -0.064473734 | DV16: 0.13695373 | DW16: 0.04091773 | DX16: -0.12528471 | DY16: 0.11635433 | DZ16: -0.03127708 | EA16: 0.046661372 | EB16: 0.078610639 | EC16: 0.063532067 | ED16: -0.11541675 | EE16: -0.023090712 | EF16: 0.042474401
A17: 120 | B17: 8 | C17: -0.041028984 | D17: 0.43958849 | E17: 0.0073790015 | F17: 0.14677181 | G17: -0.071222767 | H17: 0.10499405 | I17: 0.067489655 | J17: -0.11529907 | K17: -0.29682655 | L17: 0.0097108895 | M17: -0.22694064 | N17: 0.40510801 | O17: 0.024632055 | P17: 0.076915604 | Q17: 0.10643025 | R17: 0.0019752513 | S17: -0.055132026 | T17: -0.023507589 | U17: 0.052290234 | V17: -0.1163563 | W17: 0.079141989 | X17: 0.10018597 | Y17: 0.0015005013 | Z17: -0.02160849 | AA17: -0.03520979 | AB17: -0.058334161 | AC17: -0.040799011 | AD17: -0.021912844 | AE17: 0.0594435 | AF17: -0.06142931 | AG17: -0.0013516708 | AH17: 0.035472619 | AI17: 0.11486445 | AJ17: -0.02220746 | AK17: -0.013325713 | AL17: 0.050724406 | AM17: 0.075369368 | AN17: 0.11328712 | AO17: 0.012632335 | AP17: 0.0037580716 | AQ17: -0.060527137 | AR17: 0.11393071 | AS17: 0.056323562 | AT17: 0.052267806 | AU17: 0.054555507 | AV17: -0.021205903 | AW17: 0.008421888 | AX17: 0.010590388 | AY17: 0.027423697 | AZ17: -0.1251576 | BA17: 0.0098251791 | BB17: 0.12376406 | BC17: 0.083863195 | BD17: 0.022356482 | BE17: 0.077350242 | BF17: 0.055197497 | BG17: -0.035394236 | BH17: 0.013519461 | BI17: 0.087111945 | BJ17: -0.0098580643 | BK17: -0.013822952 | BL17: 0.077482967 | BM17: 0.07599777 | BN17: 0.046915526 | BO17: 0.035179615 | BP17: 0.03599598 | BQ17: 0.01137651 | BR17: -0.0096463751 | BS17: -0.0041034691 | BT17: 0.10941638 | BU17: 0.071127819 | BV17: 0.070210303 | BW17: -0.080431713 | BX17: 0.028822965 | BY17: -0.084245468 | BZ17: 0.12057816 | CA17: 0.027196784 | CB17: -0.010477707 | CC17: -0.17495797 | CD17: 0.17295974 | CE17: -0.17511625 | CF17: 0.098746197 | CG17: -0.015527105 | CH17: 0.058636447 | CI17: -0.014531185 | CJ17: -0.050742321 | CK17: 0.091738573 | CL17: -0.0094263448 | CM17: 0.13456934 | CN17: -0.026718061 | CO17: -0.20253863 | CP17: 0.14815927 | CQ17: 0.041087933 | CR17: 0.050676491 | CS17: 0.096841631 | CT17: 0.049260056 | CU17: -0.074408308 | CV17: 0.0038796079 | CW17: -0.019761854 | CX17: 0.010772395 | CY17: -0.049383299 | CZ17: 0.12424884 | DA17: -0.043895859 | DB17: -0.034883011 | DC17: 0.043363469 | DD17: -0.085133933 | DE17: 0.043723416 | DF17: -0.01123137 | DG17: -0.0018392819 | DH17: -0.038726651 | DI17: -0.0052932443 | DJ17: -0.045336158 | DK17: 0.15603643 | DL17: 0.073515601 | DM17: -0.052252911 | DN17: 0.035489033 | DO17: 0.05345137 | DP17: -0.016518508 | DQ17: -0.10770247 | DR17: 0.055884815 | DS17: -0.12431616 | DT17: -0.09313895 | DU17: -0.071730706 | DV17: 0.1177654 | DW17: 0.048681483 | DX17: -0.12953898 | DY17: 0.11213845 | DZ17: -0.031828173 | EA17: 0.011817924 | EB17: 0.087100349 | EC17: 0.016425217 | ED17: -0.12832444 | EE17: -0.02541336 | EF17: 0.047709767
A18: 137 | B18: 7 | C18: -0.053942228 | D18: 0.40188368 | E18: -0.059000657 | F18: 0.21209065 | G18: -0.080794247 | H18: 0.12853956 | I18: 0.054952663 | J18: -0.12516179 | K18: -0.3586821 | L18: 0.012982487 | M18: -0.25351319 | N18: 0.46182002 | O18: 0.024323875 | P18: 0.054569613 | Q18: 0.12173637 | R18: 0.019326199 | S18: -0.06901334 | T18: -0.0050281402 | U18: 0.028135528 | V18: -0.13125393 | W18: 0.07729628 | X18: 0.12712281 | Y18: 0.024213808 | Z18: -0.016905716 | AA18: -0.041705245 | AB18: -0.061713851 | AC18: -0.074719823 | AD18: -0.02659559 | AE18: 0.077201592 | AF18: -0.031873418 | AG18: -0.0086183644 | AH18: 0.040197461 | AI18: 0.11808573 | AJ18: -0.0073274439 | AK18: 0.027289927 | AL18: 0.047527764 | AM18: 0.066643405 | AN18: 0.07929464 | AO18: 0.005427535 | AP18: 0.0020144314 | AQ18: -0.076230845 | AR18: 0.12454551 | AS18: 0.085826552 | AT18: 0.04332565 | AU18: 0.064575644 | AV18: -0.028768756 | AW18: 0.024538034 | AX18: 0.033602068 | AY18: 0.034783279 | AZ18: -0.14840908 | BA18: 0.00063231092 | BB18: 0.13765604 | BC18: 0.083201573 | BD18: -0.024016272 | BE18: 0.068361213 | BF18: 0.045884536 | BG18: -0.016806241 | BH18: 0.020503853 | BI18: 0.10900001 | BJ18: 0.0059560641 | BK18: -0.058003244 | BL18: 0.081157674 | BM18: 0.10277394 | BN18: 0.05277439 | BO18: 0.020227496 | BP18: 0.04685754 | BQ18: 0.0019167841 | BR18: -0.0057481936 | BS18: -0.0039836251 | BT18: 0.11523675 | BU18: 0.080677444 | BV18: 0.080923395 | BW18: -0.085311087 | BX18: 0.019018475 | BY18: -0.12307498 | BZ18: 0.15331999 | CA18: 0.033286165 | CB18: -0.024577357 | CC18: -0.028173444 | CD18: 0.19371682 | CE18: -0.17792636 | CF18: 0.071817592 | CG18: -0.0028013589 | CH18: 0.16265705 | CI18: -0.03886914 | CJ18: -0.062313678 | CK18: 0.090667784 | CL18: -0.030989545 | CM18: 0.14364854 | CN18: -0.035086254 | CO18: -0.23157388 | CP18: 0.16283911 | CQ18: 0.047976536 | CR18: 0.055156129 | CS18: 0.078027247 | CT18: 0.090515429 | CU18: -0.071648691 | CV18: 0.091040282 | CW18: -0.0084560856 | CX18: 0.061560186 | CY18: -0.051357414 | CZ18: 0.13284286 | DA18: -0.04738094 | DB18: -0.045735209 | DC18: 0.036408781 | DD18: -0.082462353 | DE18: 0.049173445 | DF18: -0.035042779 | DG18: -0.0076194732 | DH18: -0.028038013 | DI18: -0.016114629 | DJ18: -0.04520404 | DK18: 0.15851363 | DL18: 0.081397743 | DM18: -0.066508141 | DN18: -0.016722064 | DO18: 0.042104908 | DP18: -0.020604686 | DQ18: -0.10072728 | DR18: 0.076840655 | DS18: -0.147722 | DT18: -0.11601739 | DU18: -0.096895186 | DV18: 0.10564061 | DW18: 0.081908692 | DX18: -0.15360298 | DY18: 0.097428037 | DZ18: -0.075516359 | EA18: -0.0063615627 | EB18: 0.099846378 | EC18: 0.0027641154 | ED18: -0.11047802 | EE18: -0.013853754 | EF18: 0.048955017
A19: 160 | B19: 6 | C19: -0.077959416 | D19: 0.40752071 | E19: -0.054898094 | F19: 0.23617047 | G19: -0.097512091 | H19: 0.17761032 | I19: 0.047463405 | J19: -0.15623035 | K19: -0.41833785 | L19: 0.043048958 | M19: -0.26154184 | N19: 0.53237404 | O19: -0.019797434 | P19: 0.022785213 | Q19: 0.17046229 | R19: 0.041942629 | S19: -0.078696261 | T19: -0.10952586 | U19: 0.044186858 | V19: -0.11868446 | W19: 0.072415569 | X19: 0.12292315 | Y19: 0.024064305 | Z19: -0.022223239 | AA19: -0.041570185 | AB19: -0.060762351 | AC19: -0.083512867 | AD19: -0.035088929 | AE19: 0.11523187 | AF19: -0.038785667 | AG19: 0.019297545 | AH19: 0.056557715 | AI19: 0.091548663 | AJ19: 0.012167192 | AK19: 0.049058785 | AL19: 0.070270946 | AM19: 0.043106012 | AN19: 0.083568294 | AO19: 0.025892903 | AP19: 0.0097121209 | AQ19: -0.088252757 | AR19: 0.15351756 | AS19: 0.097796955 | AT19: 0.049294982 | AU19: 0.076428716 | AV19: -0.050033021 | AW19: 0.022356168 | AX19: 0.06406211 | AY19: 0.02952897 | AZ19: -0.18687962 | BA19: -0.034363884 | BB19: 0.1597462 | BC19: 0.064055486 | BD19: -0.0032343926 | BE19: 0.051131874 | BF19: 0.013570974 | BG19: -0.016343658 | BH19: 0.0020182017 | BI19: 0.12779863 | BJ19: 0.021707302 | BK19: -0.051749526 | BL19: 0.079964658 | BM19: 0.1142506 | BN19: 0.067252647 | BO19: 0.025728961 | BP19: 0.062818808 | BQ19: 0.0099340445 | BR19: 0.006675246 | BS19: -0.024256339 | BT19: 0.14163268 | BU19: 0.075936251 | BV19: 0.093655241 | BW19: -0.10896696 | BX19: 0.034087785 | BY19: -0.10764974 | BZ19: 0.068702125 | CA19: 0.035609795 | CB19: -0.048041169 | CC19: -0.024723253 | CD19: 0.2156192 | CE19: -0.19826583 | CF19: 0.079904397 | CG19: -0.05063353 | CH19: 0.15288987 | CI19: -0.037066946 | CJ19: -0.0619405 | CK19: 0.10396772 | CL19: -0.04324028 | CM19: 0.17534764 | CN19: -0.076932655 | CO19: -0.2724544 | CP19: 0.1590326 | CQ19: -0.0027299082 | CR19: 0.04969419 | CS19: 0.060700851 | CT19: 0.12262043 | CU19: -0.083436397 | CV19: 0.10197986 | CW19: -0.021901808 | CX19: 0.057634726 | CY19: -0.07092187 | CZ19: 0.11285183 | DA19: -0.058223877 | DB19: -0.035720899 | DC19: -0.0351794 | DD19: -0.10625734 | DE19: 0.054024955 | DF19: -0.069693047 | DG19: -0.012746475 | DH19: -0.00015698313 | DI19: 0.0036664244 | DJ19: -0.048514351 | DK19: 0.12414459 | DL19: 0.070167408 | DM19: -0.081952255 | DN19: 0.0024751231 | DO19: 0.055126563 | DP19: 0.027838014 | DQ19: -0.12048938 | DR19: 0.075962353 | DS19: -0.17799555 | DT19: -0.1331285 | DU19: -0.1428307 | DV19: 0.11152471 | DW19: 0.060609139 | DX19: -0.13836513 | DY19: 0.070109578 | DZ19: -0.11192083 | EA19: -0.028079353 | EB19: 0.02177277 | EC19: -0.012190043 | ED19: -0.15093532 | EE19: 0.012634043 | EF19: 0.016977955
A20: 192 | B20: 5 | C20: -0.1393246 | D20: 0.38202502 | E20: 0.015499988 | F20: 0.18241962 | G20: -0.10036591 | H20: 0.14393228 | I20: 0.027935542 | J20: -0.13320729 | K20: -0.090108654 | L20: 0.095708636 | M20: -0.26869383 | N20: 0.50001148 | O20: -0.11011453 | P20: 0.040028495 | Q20: 0.22482481 | R20: 0.066469633 | S20: -0.057341083 | T20: -0.10084553 | U20: 0.032237658 | V20: -0.13628806 | W20: 0.091084869 | X20: 0.15004231 | Y20: -0.0048557579 | Z20: 0.02915735 | AA20: -0.021594553 | AB20: -0.060423624 | AC20: -0.096309043 | AD20: -0.034453903 | AE20: 0.01731115 | AF20: -0.039044678 | AG20: -0.0062417404 | AH20: 0.090178201 | AI20: 0.11633676 | AJ20: 0.017241716 | AK20: 0.066966361 | AL20: 0.072893452 | AM20: 0.033095981 | AN20: 0.075470194 | AO20: 0.045285082 | AP20: 0.012604516 | AQ20: 0.027452485 | AR20: 0.170049 | AS20: 0.11209581 | AT20: 0.0058587738 | AU20: 0.075692387 | AV20: -0.054625714 | AW20: 0.0068652682 | AX20: 0.085886175 | AY20: 0.038674698 | AZ20: -0.21380243 | BA20: -0.036798865 | BB20: 0.16765542 | BC20: 0.070605568 | BD20: -0.053429813 | BE20: -0.0059467971 | BF20: 0.0056885823 | BG20: -0.0069261427 | BH20: -0.071606447 | BI20: 0.13174527 | BJ20: 0.021629512 | BK20: -0.059233168 | BL20: 0.086292231 | BM20: 0.13691766 | BN20: 0.11855724 | BO20: -0.038461718 | BP20: 0.060407521 | BQ20: 0.015451707 | BR20: 0.012073632 | BS20: 0.0054075062 | BT20: 0.14780303 | BU20: 0.098754949 | BV20: 0.11591833 | BW20: -0.13550325 | BX20: 0.030693637 | BY20: -0.10523397 | BZ20: 0.090271404 | CA20: 0.050216826 | CB20: -0.03825195 | CC20: -0.026043034 | CD20: 0.1810275 | CE20: -0.2439638 | CF20: 0.080957937 | CG20: -0.099052889 | CH20: 0.071864026 | CI20: -0.030394674 | CJ20: -0.12344032 | CK20: 0.090978397 | CL20: -0.092184934 | CM20: 0.18905117 | CN20: 0.022159411 | CO20: -0.41597134 | CP20: 0.19203121 | CQ20: 0.0061113579 | CR20: 0.073116245 | CS20: 0.088364277 | CT20: 0.090474037 | CU20: -0.094867658 | CV20: 0.092511076 | CW20: 0.0099530629 | CX20: 0.090298551 | CY20: -0.012479733 | CZ20: 0.15516165 | DA20: -0.047471893 | DB20: -0.05690271 | DC20: -0.049613069 | DD20: -0.14810881 | DE20: -0.026749864 | DF20: 0.00085912153 | DG20: -0.0042022106 | DH20: -0.010975412 | DI20: -0.022876732 | DJ20: -0.039459946 | DK20: 0.084953981 | DL20: 0.075826636 | DM20: 0.0092836503 | DN20: 0.058019207 | DO20: 0.065815802 | DP20: 0.0098305314 | DQ20: -0.18720732 | DR20: 0.07851266 | DS20: -0.2060811 | DT20: -0.13343598 | DU20: -0.17206911 | DV20: 0.12934547 | DW20: 0.069060204 | DX20: -0.15386633 | DY20: 0.053618609 | DZ20: -0.084474578 | EA20: 0.014917025 | EB20: 0.039067633 | EC20: 0.034049581 | ED20: -0.17691886 | EE20: 0.0023672309 | EF20: 0.020281417
A21: 241 | B21: 4 | C21: -0.19764916 | D21: 0.12638792 | E21: -0.00027935227 | F21: 0.2034135 | G21: -0.007296138 | H21: 0.16216409 | I21: 0.014111278 | J21: -0.13674292 | K21: -0.088973017 | L21: 0.10967961 | M21: -0.19988497 | N21: 0.58489126 | O21: -0.13927749 | P21: 0.045427193 | Q21: 0.27408345 | R21: 0.084905231 | S21: -0.036563292 | T21: -0.13112036 | U21: -0.0098246407 | V21: -0.13175049 | W21: 0.12449862 | X21: 0.20780127 | Y21: -0.01014366 | Z21: 0.039457716 | AA21: 0.019491044 | AB21: -0.065287595 | AC21: -0.15954227 | AD21: -0.046697425 | AE21: 0.010311611 | AF21: -0.05312561 | AG21: -0.010570753 | AH21: 0.10758136 | AI21: 0.10212368 | AJ21: 0.0051859256 | AK21: 0.10498861 | AL21: 0.065379823 | AM21: 0.068535807 | AN21: 0.11195606 | AO21: 0.047726396 | AP21: 0.018942379 | AQ21: 0.076865507 | AR21: 0.20518228 | AS21: 0.064455869 | AT21: -0.0024929113 | AU21: 0.047809632 | AV21: -0.05552078 | AW21: 0.00979103 | AX21: 0.066006052 | AY21: 0.047021291 | AZ21: -0.25491127 | BA21: -0.071032182 | BB21: 0.22534614 | BC21: 0.038321148 | BD21: -0.021750863 | BE21: 0.0063505334 | BF21: 0.0035771002 | BG21: 0.036635189 | BH21: -0.076321363 | BI21: 0.1659696 | BJ21: 0.023579026 | BK21: -0.06844988 | BL21: 0.14272109 | BM21: 0.15512 | BN21: 0.063647948 | BO21: -0.063857236 | BP21: 0.10450913 | BQ21: 0.054542231 | BR21: 0.012323862 | BS21: 0.0058601728 | BT21: 0.13224469 | BU21: 0.13549646 | BV21: 0.142143 | BW21: -0.1466792 | BX21: -0.0029908193 | BY21: -0.050379851 | BZ21: 0.047662929 | CA21: 0.095059434 | CB21: -0.063421391 | CC21: -0.046693549 | CD21: 0.28805606 | CE21: -0.39507594 | CF21: 0.13126568 | CG21: -0.14375119 | CH21: 0.080100321 | CI21: -0.080499616 | CJ21: -0.085627757 | CK21: 0.12705055 | CL21: -0.13389042 | CM21: 0.22550299 | CN21: 0.03053889 | CO21: -0.51486525 | CP21: 0.22270006 | CQ21: 0.0032880917 | CR21: 0.090824278 | CS21: 0.069646396 | CT21: 0.082292873 | CU21: -0.06267356 | CV21: 0.098225632 | CW21: 0.065005417 | CX21: 0.10212218 | CY21: -0.0084819164 | CZ21: 0.23745137 | DA21: 0.0011922565 | DB21: -0.051624434 | DC21: -0.045047559 | DD21: 0.12132269 | DE21: 0.012238109 | DF21: 0.021560881 | DG21: 0.0078463781 | DH21: 0.01407682 | DI21: 0.034407478 | DJ21: -0.037911313 | DK21: 0.13950271 | DL21: 0.098364939 | DM21: -0.02983412 | DN21: 0.071197612 | DO21: 0.082445792 | DP21: 0.024266155 | DQ21: -0.15474119 | DR21: 0.050170859 | DS21: -0.20083947 | DT21: -0.1705708 | DU21: -0.028090294 | DV21: 0.14027598 | DW21: 0.12824787 | DX21: -0.18596621 | DY21: 0.024595996 | DZ21: -0.052844067 | EA21: -0.024865522 | EB21: 0.0084081462 | EC21: 0.014037055 | ED21: -0.054498856 | EE21: 0.014428852 | EF21: -0.018771264
A22: 321 | B22: 3 | C22: 0.064235718 | D22: 0.14242785 | E22: -0.041027532 | F22: -0.13986745 | G22: -0.032954824 | H22: 0.12417806 | I22: 0.017437343 | J22: -0.1042535 | K22: -0.15328677 | L22: 0.17118336 | M22: -0.18466279 | N22: 0.75614344 | O22: -0.066442332 | P22: 0.090630874 | Q22: 0.12727089 | R22: 0.066698293 | S22: -0.039234144 | T22: -0.10484897 | U22: 0.052488906 | V22: -0.1756249 | W22: 0.15804775 | X22: 0.25720235 | Y22: -0.069853332 | Z22: 0.023866122 | AA22: 0.0070480169 | AB22: -0.038274054 | AC22: -0.17721308 | AD22: -0.012467303 | AE22: -0.085147686 | AF22: -0.047182316 | AG22: -0.045973813 | AH22: 0.10586596 | AI22: 0.11100371 | AJ22: 0.013081542 | AK22: -0.068269328 | AL22: 0.040340967 | AM22: 0.084088903 | AN22: 0.11113281 | AO22: 0.074717373 | AP22: 0.020492729 | AQ22: 0.079426117 | AR22: 0.25053268 | AS22: 0.082810439 | AT22: -0.025136362 | AU22: 0.033500452 | AV22: -0.059813177 | AW22: -0.030149389 | AX22: -0.10776064 | AY22: 0.071733385 | AZ22: -0.15490378 | BA22: -0.045598425 | BB22: 0.30192994 | BC22: -0.13083694 | BD22: -0.022174181 | BE22: 0.022216183 | BF22: 0.013638817 | BG22: 0.046279512 | BH22: -0.12796054 | BI22: 0.11108872 | BJ22: 0.054996415 | BK22: -0.041839636 | BL22: 0.16178034 | BM22: 0.19179704 | BN22: -0.015327552 | BO22: -0.050484429 | BP22: 0.07483555 | BQ22: 0.027830097 | BR22: 0.020813609 | BS22: -0.016372782 | BT22: 0.1305307 | BU22: 0.21294877 | BV22: 0.15854397 | BW22: -0.1746685 | BX22: 0.036637446 | BY22: -0.0047467864 | BZ22: 0.047257736 | CA22: 0.14407874 | CB22: -0.14899328 | CC22: -0.014985703 | CD22: 0.33387804 | CE22: -0.39338734 | CF22: 0.18879979 | CG22: -0.20326309 | CH22: 0.11591877 | CI22: -0.11777975 | CJ22: -0.10337951 | CK22: 0.036163343 | CL22: -0.2406518 | CM22: 0.320432 | CN22: -0.0085467718 | CO22: -0.64995647 | CP22: 0.25940856 | CQ22: -0.012333779 | CR22: 0.16185042 | CS22: -0.015202184 | CT22: 0.058232521 | CU22: -0.12023171 | CV22: 0.1122337 | CW22: 0.036451253 | CX22: 0.0037495933 | CY22: -0.0079888258 | CZ22: 0.26292048 | DA22: -0.0039917539 | DB22: -0.058383507 | DC22: -0.020724784 | DD22: 0.1478941 | DE22: -0.005491758 | DF22: 0.017031775 | DG22: 0.031985043 | DH22: 0.013945346 | DI22: 0.063560999 | DJ22: -0.050246006 | DK22: 0.17913471 | DL22: 0.12494165 | DM22: -0.063466051 | DN22: 0.046763328 | DO22: 0.1234375 | DP22: 0.010227258 | DQ22: -0.131031 | DR22: -0.0060925526 | DS22: -0.19705092 | DT22: -0.058357009 | DU22: -0.057495391 | DV22: 0.12570512 | DW22: 0.078389724 | DX22: -0.22244261 | DY22: -0.0081471166 | DZ22: -0.10374798 | EA22: -0.070548649 | EB22: -0.080596728 | EC22: 0.021495102 | ED22: -0.077413567 | EE22: 0.033446304 | EF22: -0.034790246
A23: 482 | B23: 2 | C23: -0.034987009 | D23: 0.25409263 | E23: -0.080941173 | F23: -0.0037402329 | G23: -0.052224174 | H23: -0.018188471 | I23: -0.036386489 | J23: -0.11487751 | K23: -0.20448948 | L23: 0.05404353 | M23: -0.14728697 | N23: 0.97590144 | O23: -0.12289971 | P23: 0.054681526 | Q23: 0.29117349 | R23: 0.062821978 | S23: -0.072572664 | T23: -0.084676176 | U23: 0.059241789 | V23: -0.2324772 | W23: 0.25954732 | X23: 0.19455646 | Y23: -0.067949922 | Z23: 0.041051967 | AA23: 0.006606292 | AB23: -0.047748945 | AC23: -0.23400862 | AD23: -0.0150109 | AE23: -0.22171324 | AF23: -0.06690626 | AG23: -0.0020576771 | AH23: 0.084171585 | AI23: 0.2091516 | AJ23: 0.02358744 | AK23: 0.018557731 | AL23: 0.13143171 | AM23: 0.007769489 | AN23: 0.2423147 | AO23: -0.0053369522 | AP23: -0.16526637 | AQ23: 0.089424992 | AR23: 0.33674404 | AS23: -0.014706888 | AT23: -0.041427722 | AU23: 0.033145526 | AV23: -0.027638994 | AW23: -0.05202691 | AX23: 0.065137154 | AY23: 0.17023398 | AZ23: -0.063753617 | BA23: 0.0096467801 | BB23: -0.051049484 | BC23: -0.30082825 | BD23: 0.094830881 | BE23: -0.071430762 | BF23: -0.022846991 | BG23: 0.074761471 | BH23: -0.20348398 | BI23: 0.19111208 | BJ23: 0.10400332 | BK23: 0.0020341083 | BL23: 0.1495343 | BM23: 0.18918069 | BN23: -0.0069471708 | BO23: 0.036524942 | BP23: 0.098266399 | BQ23: 0.072047901 | BR23: 0.017844321 | BS23: -0.073275389 | BT23: 0.14364981 | BU23: 0.20568774 | BV23: 0.11346757 | BW23: -0.20215233 | BX23: -0.0082131197 | BY23: -0.010205693 | BZ23: 0.0076697624 | CA23: 0.20637272 | CB23: -0.2176142 | CC23: 0.22495863 | CD23: 0.19167646 | CE23: -0.11662461 | CF23: 0.15713491 | CG23: -0.39324379 | CH23: 0.18019645 | CI23: -0.30989942 | CJ23: -0.019875368 | CK23: 0.096116995 | CL23: -0.40866101 | CM23: 0.38673295 | CN23: -0.053005178 | CO23: -0.90892329 | CP23: 0.31136074 | CQ23: -0.0091837445 | CR23: 0.011597804 | CS23: -0.036974219 | CT23: 0.045662542 | CU23: -0.021056596 | CV23: -0.022245137 | CW23: 0.10090133 | CX23: -0.088716994 | CY23: 0.022046531 | CZ23: 0.18199879 | DA23: -0.030982136 | DB23: -0.015955157 | DC23: 0.11919049 | DD23: 0.21341104 | DE23: -0.009395226 | DF23: 0.061942127 | DG23: 0.038270012 | DH23: 0.055413447 | DI23: 0.053479597 | DJ23: -0.087058008 | DK23: 0.27783322 | DL23: 0.21610106 | DM23: -0.019497305 | DN23: 0.006497196 | DO23: 0.1640913 | DP23: 0.047088233 | DQ23: -0.170211 | DR23: -0.089886003 | DS23: -0.28809658 | DT23: -0.12395522 | DU23: 0.034287185 | DV23: 0.27627161 | DW23: 0.14122823 | DX23: -0.31349321 | DY23: 0.16987683 | DZ23: -0.10287302 | EA23: -0.023448908 | EB23: -0.06275344 | EC23: -0.036584316 | ED23: -0.091425905 | EE23: 0.059050684 | EF23: -0.047782279
A24: 964 | B24: 1 | C24: 0.16299314 | D24: 0.10060991 | E24: 0.07140033 | F24: 0.075326494 | G24: 0.22576002 | H24: 0.035855797 | I24: 0.016927089 | J24: -0.1154628 | K24: -0.021515278 | L24: 0.095623251 | M24: -0.21778567 | N24: 1.7690314 | O24: -0.24427786 | P24: 0.0017362889 | Q24: -0.0028471356 | R24: -0.027822824 | S24: -0.01105446 | T24: -0.2878166 | U24: 0.28585629 | V24: -0.098678511 | W24: -0.16456452 | X24: -0.00089887647 | Y24: -0.12031749 | Z24: -0.024394549 | AA24: 0.013547768 | AB24: -0.18425142 | AC24: -0.24616896 | AD24: -0.0078218389 | AE24: -0.17526882 | AF24: -0.02252201 | AG24: 0.10590047 | AH24: 0.05669736 | AI24: 0.31041424 | AJ24: 0.085435202 | AK24: 0.0014409771 | AL24: -0.054676935 | AM24: -0.018919281 | AN24: 0.22118947 | AO24: 0.066090112 | AP24: -0.16448669 | AQ24: 0.047076973 | AR24: 0.0096392566 | AS24: -0.027956077 | AT24: 0.030459207 | AU24: 0.04409532 | AV24: -0.087151952 | AW24: 0.0049875415 | AX24: -0.025561798 | AY24: 0.16812729 | AZ24: 0.037867074 | BA24: -0.053794732 | BB24: -0.086159033 | BC24: -0.80321601 | BD24: 0.18559522 | BE24: -0.046064354 | BF24: 0.087651336 | BG24: 0.026835966 | BH24: -0.38625534 | BI24: 0.22362911 | BJ24: 0.0033483158 | BK24: 0.0040235469 | BL24: 0.31716429 | BM24: 0.011473019 | BN24: 0.0068493418 | BO24: -0.16110969 | BP24: 0.12335118 | BQ24: -0.064169633 | BR24: 0.042356223 | BS24: -0.0012847175 | BT24: 0.1162707 | BU24: 0.22832663 | BV24: 0.10772845 | BW24: -0.061835884 | BX24: -0.13296006 | BY24: 0.10974567 | BZ24: 0.2588929 | CA24: 0.10002492 | CB24: 0.20876197 | CC24: 0.43985451 | CD24: 0.14430631 | CE24: -0.21012144 | CF24: 0.22172136 | CG24: -0.32381798 | CH24: 0.3542773 | CI24: 0.32845182 | CJ24: 0.013109485 | CK24: 0.093530079 | CL24: 0.14175533 | CM24: 0.54958711 | CN24: -0.10773877 | CO24: -0.77665322 | CP24: 0.1603442 | CQ24: 0.11468717 | CR24: 0.061084838 | CS24: -0.085895233 | CT24: 0.096419008 | CU24: -0.072751348 | CV24: 0.015064048 | CW24: 0.17511717 | CX24: 0.055207194 | CY24: -0.080066905 | CZ24: 0.11220663 | DA24: 0.024511204 | DB24: -0.19546067 | DC24: 0.19117576 | DD24: 0.15338138 | DE24: -0.17606276 | DF24: -0.10466498 | DG24: 0.059105834 | DH24: 0.00084652507 | DI24: 0.14187546 | DJ24: -0.13248861 | DK24: 0.33950921 | DL24: 0.21310443 | DM24: -0.14143953 | DN24: 0.23333457 | DO24: 0.1854408 | DP24: 0.11437343 | DQ24: -0.13297735 | DR24: -0.02051563 | DS24: -0.21626154 | DT24: -0.038362866 | DU24: -0.047638587 | DV24: 0.1582247 | DW24: 0.10885709 | DX24: -0.31159313 | DY24: 0.34380429 | DZ24: -0.050469182 | EA24: 0.077350922 | EB24: -0.029582176 | EC24: -0.014309919 | ED24: -0.056172845 | EE24: 0.11342944 | EF24: 0.067276677
A25: 大盤 | B25: TWII | C25: -0.017446771 | D25: 0.020701061 | E25: 0.023982129 | F25: -0.006557579 | G25: 0.03184513 | H25: 0.034348533 | I25: -0.0082549328 | J25: 0.012843524 | K25: -0.051018525 | L25: 0.00087394274 | M25: 0.023389576 | N25: 0.012988972 | O25: 0.0058545887 | P25: 0.027413207 | Q25: -0.0037129361 | R25: 0.024076614 | S25: -0.012190025 | T25: -0.039749578 | U25: -0.07315545 | V25: -0.05826023 | W25: 0.00077279757 | X25: 0.044591521 | Y25: -0.02769968 | Z25: 0.0020950059 | AA25: -0.023400551 | AB25: 0.032129371 | AC25: 0.038903273 | AD25: -0.042865382 | AE25: 0.018647195 | AF25: 0.015229768 | AG25: 0.036016604 | AH25: 0.0093546114 | AI25: 0.010748251 | AJ25: 0.013357754 | AK25: -0.0053327473 | AL25: 0.0013831358 | AM25: 0.020795928 | AN25: 0.031517702 | AO25: 0.0062417165 | AP25: 0.0061452617 | AQ25: 0.016946358 | AR25: 0.03468283 | AS25: 0.0030985886 | AT25: 0.015081347 | AU25: -0.019251209 | AV25: 0.038711513 | AW25: -0.021856951 | AX25: 0.0077743007 | AY25: 0.042397247 | AZ25: -0.026308975 | BA25: 0.0095717493 | BB25: -0.024249741 | BC25: 0.020163374 | BD25: -0.0035049988 | BE25: 0.020151935 | BF25: 0.00058133623 | BG25: -0.005219701 | BH25: -0.11587176 | BI25: 0.0087252257 | BJ25: -0.016377261 | BK25: 0.020840372 | BL25: 0.044975872 | BM25: 0.023954306 | BN25: 0.030239101 | BO25: -0.043725888 | BP25: 0.02188947 | BQ25: 0.0086274303 | BR25: -0.019192954 | BS25: 0.01973513 | BT25: 0.047694337 | BU25: 0.011454817 | BV25: 0.043228621 | BW25: -0.04274743 | BX25: -0.017811292 | BY25: -0.1511531 | BZ25: 0.124224 | CA25: -0.0045572538 | CB25: 0.06021124 | CC25: 0.085992033 | CD25: -0.0058084796 | CE25: -0.006041347 | CF25: 0.0024523244 | CG25: 0.089636252 | CH25: 0.070992733 | CI25: 0.027170643 | CJ25: 0.052468428 | CK25: 0.029480661 | CL25: 0.066825081 | CM25: -0.028772229 | CN25: 0.039462516 | CO25: -0.029031087 | CP25: 0.013983883 | CQ25: -0.032276965 | CR25: 0.0031035766 | CS25: 0.025591856 | CT25: 0.044391886 | CU25: -0.030338959 | CV25: -0.0012579765 | CW25: 0.0023363565 | CX25: -0.064264145 | CY25: 0.012909779 | CZ25: -0.12547709 | DA25: 0.011690683 | DB25: 0.0063378437 | DC25: -0.11730536 | DD25: -0.036010872 | DE25: 0.1389113 | DF25: -0.051143506 | DG25: 0.076731447 | DH25: 0.015508782 | DI25: 0.023223774 | DJ25: -0.018372876 | DK25: 0.062199014 | DL25: 0.020098304 | DM25: 0.01349894 | DN25: -0.030252213 | DO25: -0.017022836 | DP25: -0.021788523 | DQ25: 0.085745625 | DR25: 0.028106744 | DS25: -0.0023031598 | DT25: 0.058471198 | DU25: 0.067658949 | DV25: 0.0050207706 | DW25: 0.037416184 | DX25: 0.084111004 | DY25: -0.036832399 | DZ25: 0.0030917028 | EA25: -0.0019576282 | EB25: 0.026459104 | EC25: -0.024752539 | ED25: 0.034115491 | EE25: 0.021061974 | EF25: -0.020277393

Sheet 夏普比率
A1: =預測IC!A1 -> NN3
B2: Time | C2: 2013/12 | D2: 2014/01 | E2: 2014/02 | F2: 2014/03 | G2: 2014/04 | H2: 2014/05 | I2: 2014/06 | J2: 2014/07 | K2: 2014/08 | L2: 2014/09 | M2: 2014/10 | N2: 2014/11 | O2: 2014/12 | P2: 2015/01 | Q2: 2015/02 | R2: 2015/03 | S2: 2015/04 | T2: 2015/05 | U2: 2015/06 | V2: 2015/07 | W2: 2015/08 | X2: 2015/09 | Y2: 2015/10 | Z2: 2015/11 | AA2: 2015/12 | AB2: 2016/01 | AC2: 2016/02 | AD2: 2016/03 | AE2: 2016/04 | AF2: 2016/05 | AG2: 2016/06 | AH2: 2016/07 | AI2: 2016/08 | AJ2: 2016/09 | AK2: 2016/10 | AL2: 2016/11 | AM2: 2016/12 | AN2: 2017/01 | AO2: 2017/02 | AP2: 2017/03 | AQ2: 2017/04 | AR2: 2017/05 | AS2: 2017/06 | AT2: 2017/07 | AU2: 2017/08 | AV2: 2017/09 | AW2: 2017/10 | AX2: 2017/11 | AY2: 2017/12 | AZ2: 2018/01 | BA2: 2018/02 | BB2: 2018/03 | BC2: 2018/04 | BD2: 2018/05 | BE2: 2018/06 | BF2: 2018/07 | BG2: 2018/08 | BH2: 2018/09 | BI2: 2018/10 | BJ2: 2018/11 | BK2: 2018/12 | BL2: 2019/01 | BM2: 2019/02 | BN2: 2019/03 | BO2: 2019/04 | BP2: 2019/05 | BQ2: 2019/06 | BR2: 2019/07 | BS2: 2019/08 | BT2: 2019/09 | BU2: 2019/10 | BV2: 2019/11 | BW2: 2019/12 | BX2: 2020/01 | BY2: 2020/02 | BZ2: 2020/03 | CA2: 2020/04 | CB2: 2020/05 | CC2: 2020/06 | CD2: 2020/07 | CE2: 2020/08 | CF2: 2020/09 | CG2: 2020/10 | CH2: 2020/11 | CI2: 2020/12 | CJ2: 2021/01 | CK2: 2021/02 | CL2: 2021/03 | CM2: 2021/04 | CN2: 2021/05 | CO2: 2021/06 | CP2: 2021/07 | CQ2: 2021/08 | CR2: 2021/09 | CS2: 2021/10 | CT2: 2021/11 | CU2: 2021/12 | CV2: 2022/01 | CW2: 2022/02 | CX2: 2022/03 | CY2: 2022/04 | CZ2: 2022/05 | DA2: 2022/06 | DB2: 2022/07 | DC2: 2022/08 | DD2: 2022/09 | DE2: 2022/10 | DF2: 2022/11 | DG2: 2022/12 | DH2: 2023/01 | DI2: 2023/02 | DJ2: 2023/03 | DK2: 2023/04 | DL2: 2023/05 | DM2: 2023/06 | DN2: 2023/07 | DO2: 2023/08 | DP2: 2023/09 | DQ2: 2023/10 | DR2: 2023/11 | DS2: 2023/12 | DT2: 2024/01 | DU2: 2024/02 | DV2: 2024/03 | DW2: 2024/04 | DX2: 2024/05 | DY2: 2024/06 | DZ2: 2024/07 | EA2: 2024/08 | EB2: 2024/09 | EC2: 2024/10 | ED2: 2024/11 | EE2: 2024/12 | EF2: 2025/01 | EG2: 2025/02
B3: bm | C3: 0.036997014 | D3: 0.033297818 | E3: 0.015421638 | F3: 0.016456983 | G3: 0.017226211 | H3: 0.028764108 | I3: 0.024279328 | J3: 0.027316419 | K3: 0.030174005 | L3: 0.025236297 | M3: 0.032729104 | N3: 0.031554761 | O3: 0.034033302 | P3: 0.033212911 | Q3: 0.029103335 | R3: 0.026473653 | S3: 0.028295346 | T3: 0.022620728 | U3: 0.016144007 | V3: 0.025033178 | W3: 0.045784045 | X3: 0.043057814 | Y3: 0.037785746 | Z3: 0.024097455 | AA3: 0.030094427 | AB3: 0.028087063 | AC3: 0.033771067 | AD3: 0.034131704 | AE3: 0.034141409 | AF3: 0.013117941 | AG3: 0.024857354 | AH3: 0.031884444 | AI3: 0.036385761 | AJ3: 0.035948919 | AK3: 0.043482831 | AL3: 0.038462078 | AM3: 0.039410244 | AN3: 0.050743621 | AO3: 0.053684812 | AP3: 0.049314899 | AQ3: 0.032773688 | AR3: 0.028295341 | AS3: 0.028377803 | AT3: 0.023069229 | AU3: 0.029397033 | AV3: 0.031037852 | AW3: 0.026297924 | AX3: 0.026164811 | AY3: 0.032053784 | AZ3: 0.034477531 | BA3: 0.029331891 | BB3: 0.034324948 | BC3: 0.037421777 | BD3: 0.031413722 | BE3: 0.032006411 | BF3: 0.028281828 | BG3: 0.041103437 | BH3: 0.045198779 | BI3: 0.04158804 | BJ3: 0.040723406 | BK3: 0.0363277 | BL3: 0.036173192 | BM3: 0.037708588 | BN3: 0.030814038 | BO3: 0.030655856 | BP3: 0.034399632 | BQ3: 0.03486865 | BR3: 0.03632404 | BS3: 0.036164468 | BT3: 0.038668895 | BU3: 0.041103484 | BV3: 0.028684133 | BW3: 0.03521651 | BX3: 0.0407672 | BY3: 0.021603538 | BZ3: 0.030433669 | CA3: 0.037311958 | CB3: 0.027612053 | CC3: 0.019742955 | CD3: 0.0077914602 | CE3: 0.022526807 | CF3: 0.034778188 | CG3: 0.032581362 | CH3: 0.040909001 | CI3: 0.039050253 | CJ3: 0.0245619 | CK3: 0.034134462 | CL3: 0.035925938 | CM3: 0.042466042 | CN3: 0.036523907 | CO3: 0.03765915 | CP3: 0.039957834 | CQ3: -0.0045921903 | CR3: 0.01500343 | CS3: 0.022458754 | CT3: 0.040972168 | CU3: 0.038942373 | CV3: 0.043015001 | CW3: 0.0397066 | CX3: 0.039171023 | CY3: 0.034940835 | CZ3: 0.036026834 | DA3: 0.044509548 | DB3: 0.039322897 | DC3: 0.037933403 | DD3: 0.039075001 | DE3: 0.041993976 | DF3: 0.041965349 | DG3: 0.040382245 | DH3: 0.03678724 | DI3: 0.036877766 | DJ3: 0.033682094 | DK3: 0.036536443 | DL3: 0.031530556 | DM3: 0.028662238 | DN3: 0.030844743 | DO3: 0.033675364 | DP3: 0.035102178 | DQ3: 0.036708207 | DR3: 0.034114422 | DS3: 0.036715906 | DT3: 0.034828053 | DU3: 0.023365577 | DV3: 0.025240939 | DW3: 0.035159203 | DX3: 0.032304964 | DY3: 0.023258217 | DZ3: 0.028308752 | EA3: 0.031397322 | EB3: 0.037230813 | EC3: 0.03334609 | ED3: 0.034186641 | EE3: 0.025041158 | EF3: 0.034121435
B4: size | C4: -0.049660318 | D4: -0.06445346 | E4: -0.095804929 | F4: -0.076694249 | G4: -0.02651532 | H4: -0.03415165 | I4: -0.04619091 | J4: -0.046178363 | K4: -0.045931909 | L4: -0.04081179 | M4: -0.018734141 | N4: -0.035831184 | O4: -0.057022861 | P4: -0.042462624 | Q4: -0.037772239 | R4: -0.028628159 | S4: -0.030997759 | T4: -0.0067040182 | U4: -0.037956684 | V4: -0.029502006 | W4: -0.041243237 | X4: -0.054483331 | Y4: -0.057374084 | Z4: -0.050628324 | AA4: -0.042319641 | AB4: -0.03427378 | AC4: -0.038455291 | AD4: -0.032603255 | AE4: -0.034794942 | AF4: -0.0016393719 | AG4: -0.03223915 | AH4: -0.025692957 | AI4: -0.030088885 | AJ4: -0.029719525 | AK4: -0.022742981 | AL4: -0.025322144 | AM4: -0.024117366 | AN4: -0.027272205 | AO4: -0.02838312 | AP4: -0.023965544 | AQ4: -0.030304468 | AR4: -0.017736018 | AS4: -0.014939197 | AT4: -0.013608707 | AU4: -0.016423914 | AV4: -0.024039604 | AW4: -0.021378703 | AX4: -0.023051307 | AY4: -0.023942341 | AZ4: -0.015978329 | BA4: -0.029633645 | BB4: -0.036923113 | BC4: -0.022611704 | BD4: -0.02696564 | BE4: -0.030957563 | BF4: -0.018181884 | BG4: -0.015961032 | BH4: -0.021358658 | BI4: -0.018895749 | BJ4: -0.021052816 | BK4: -0.02661183 | BL4: -0.017576751 | BM4: -0.021846036 | BN4: -0.013750921 | BO4: -0.0065027888 | BP4: -0.01217171 | BQ4: 0.00022277284 | BR4: -0.005245064 | BS4: -0.012938426 | BT4: -0.01635034 | BU4: -0.0017286047 | BV4: 0.015184016 | BW4: -0.0037692826 | BX4: -0.016045217 | BY4: -0.018894587 | BZ4: -0.0041566141 | CA4: -0.0182235 | CB4: -0.022303988 | CC4: -0.041111881 | CD4: -0.032535264 | CE4: -0.030323127 | CF4: -0.061293035 | CG4: -0.0441696 | CH4: -0.026870448 | CI4: -0.017734729 | CJ4: -0.011493971 | CK4: -0.01591057 | CL4: -0.015536443 | CM4: -0.01914162 | CN4: 0.0080306048 | CO4: 0.0041846284 | CP4: -0.0074834121 | CQ4: -0.00067070377 | CR4: -0.019179488 | CS4: -0.023347226 | CT4: -0.021789124 | CU4: -0.029507372 | CV4: -0.024862939 | CW4: -0.022835803 | CX4: -0.022235555 | CY4: -0.025586671 | CZ4: -0.030230897 | DA4: -0.043223926 | DB4: -0.044724836 | DC4: -0.070760187 | DD4: -0.057609849 | DE4: -0.034042017 | DF4: -0.027183612 | DG4: -0.03505246 | DH4: -0.0084282458 | DI4: -0.036370698 | DJ4: -0.038760924 | DK4: -0.027971575 | DL4: -0.016270629 | DM4: -0.017815732 | DN4: -0.0080526822 | DO4: -0.023536384 | DP4: -0.02948732 | DQ4: -0.037657448 | DR4: -0.029648059 | DS4: -0.030189606 | DT4: -0.041055976 | DU4: -0.037310577 | DV4: -0.0089387634 | DW4: -0.018377446 | DX4: -0.030385798 | DY4: -0.033048756 | DZ4: -0.030982286 | EA4: -0.031659362 | EB4: -0.036490653 | EC4: -0.041069205 | ED4: -0.031004875 | EE4: -0.023075953 | EF4: -0.01142086
